Workbook

Sheet Resumen
A2: Resumen Artesanal por unidad de pesquería, 2014
A3: 42016
A4: Recurso | B4: Unidad de pesquería | C4: Cuota Global (t) | D4: Desembarque total (t) | E4: Saldo total (t) | F4: % consumido 2014 | G4: % consumido 2012 | H4: % consumido 2011
A5: Jurel | B5: NACIONAL | C5: =+SUM(Global!C17+Global!C18+Global!C19+Global!C22+Global!C23+Global!C24+Global!C25) -> 12564 | D5: =+SUM(Global!D17+Global!D18+Global!D19+Global!D22+Global!D23+Global!D24+Global!D25) -> 14225.728 | E5: =+C5-D5 -> -1661.7281 | F5: =+D5/C5 -> 1.1322611
B6: RAE | C6: =+(Global!C20+Global!C21+Global!C26+Global!C27) -> 13329 | D6: =+(Global!D20+Global!D21+Global!D26+Global!D27) -> 5218.46 | E6: =+C6-D6 -> 8110.54 | F6: =+D6/C6 -> 0.39151174
A7: Anchoveta | B7: NACIONAL | C7: =+SUM(Global!C6+Global!C7+Global!C8+Global!C11+Global!C14) -> 138061 | D7: =+SUM(Global!D6+Global!D7+Global!D8+Global!D11+Global!D14) -> 125398.82 | E7: =+C7-D7 -> 12662.175 | F7: =+D7/C7 -> 0.90828565
B8: RAE | C8: =+SUM(Global!C9+Global!C10+Global!C12+Global!C13+Global!C15+Global!C16) -> 30387 | D8: =+SUM(Global!D9+Global!D10+Global!D12+Global!D13+Global!D15+Global!D16) -> 28280.452 | E8: =+C8-D8 -> 2106.548 | F8: =+D8/C8 -> 0.93067601
A9: Sardina común | B9: NACIONAL | C9: =+SUM(Global!C33+Global!C36) -> 7920 | D9: =+SUM(Global!D33+Global!D36) -> 7771.949 | E9: =+C9-D9 -> 148.051 | F9: =+D9/C9 -> 0.98130669
B10: RAE | C10: =+SUM(Global!C32+Global!C34+Global!C35+Global!C37+Global!C38) -> 434018 | D10: =+SUM(Global!D32+Global!D34+Global!D35+Global!D37+Global!D38) -> 393858.99 | E10: =+C10-D10 -> 40159.006 | F10: =+D10/C10 -> 0.90747157
A11: Sardina española | B11: NACIONAL | C11: =+Global!C28+Global!C29+Global!C30+Global!C31 -> 1242 | D11: =+Global!D28+Global!D29+Global!D30+Global!D31 -> 141.664 | E11: =+C11-D11 -> 1100.336 | F11: =+D11/C11 -> 0.11406119
B12: RAE
A13: Sardina Austral | B13: NACIONAL | C13: =+Global!C39+Global!C40 -> 30293 | D13: =+Global!D39+Global!D40 -> 26834.114 | E13: =+C13-D13 -> 3458.886 | F13: =+D13/C13 -> 0.88581897
B14: RAE

Sheet Global
A2: Resumen Global Cuotas Artesanales 2014
A3: 42016
A5: Recurso | B5: Unidad de pesquería | C5: Cuota Global (t) | D5: Desembarque total (t) | E5: Saldo total (t) | F5: % consumido 2014 | G5: % consumido 2013
A6: Anchoveta | B6: XV y I | C6: =+'Res. Global'!C7 -> 89242 | D6: =+'Res. Global'!H7 -> 89200.678 | E6: =+C6-D6 -> 41.322 | F6: =+D6/C6 -> 0.99953697
B7: II | C7: =+'Res. Global'!C9 -> 30704 | D7: =+'Res. Global'!H9 -> 24018.544 | E7: =+C7-D7 -> 6685.456 | F7: =+D7/C7 -> 0.78226107
B8: III | C8: =+'Res. Global'!C11 -> 17702 | D8: =+'Res. Global'!H11 -> 12041.708 | E8: =+C8-D8 -> 5660.292 | F8: =+D8/C8 -> 0.68024562
B9: IV RAE | C9: =+'Res. Global'!C13 -> 7586 | D9: =+'Res. Global'!H13 -> 7221.178 | E9: =+C9-D9 -> 364.822 | F9: =+D9/C9 -> 0.95190852
B10: V RAE | C10: =+'Res. Global'!C15 -> 2003 | D10: =+'Res. Global'!H15 -> 2156.396 | E10: =+C10-D10 -> -153.396 | F10: =+D10/C10 -> 1.0765831
B11: VI | C11: =+'Res. Global'!C18 -> 13 | D11: =+'Res. Global'!H18 -> 0 | E11: =+C11-D11 -> 13 | F11: =+D11/C11 -> 0
B12: VII RAE | C12: =+'Res. Global'!C21 -> 214 | D12: =+'Res. Global'!H21 -> 192.185 | E12: =+C12-D12 -> 21.815 | F12: =+D12/C12 -> 0.89806075
B13: VIII RAE (sin descarte) | C13: =+'Res. Global'!C24 -> 16688 | D13: =+'Res. Global'!H24 -> 17537.687 | E13: =+C13-D13 -> -849.687 | F13: =+D13/C13 -> 1.050916
B14: IX | C14: =+'Res. Global'!C26 -> 400 | D14: =+'Res. Global'!H26 -> 137.895 | E14: =+C14-D14 -> 262.105 | F14: =+D14/C14 -> 0.3447375
B15: XIV RAE | C15: =+'Res. Global'!C29 -> 2411 | D15: =+'Res. Global'!H29 -> 880.811 | E15: =+C15-D15 -> 1530.189 | F15: =+D15/C15 -> 0.36533015
B16: X RAE | C16: =+'Res. Global'!C32 -> 1485 | D16: =+'Res. Global'!H32 -> 292.195 | E16: =+C16-D16 -> 1192.805 | F16: =+D16/C16 -> 0.19676431
A17: Jurel | B17: XV y I | C17: =+'Res. Global'!C34 -> 991 | D17: =+'Res. Global'!H34 -> 156.787 | E17: =+C17-D17 -> 834.213 | F17: =+D17/C17 -> 0.1582109
B18: II | C18: =+'Res. Global'!C36 -> 991 | D18: =+'Res. Global'!H36 -> 1165.537 | E18: =+C18-D18 -> -174.537 | F18: =+D18/C18 -> 1.1761221
B19: III | C19: =+'Res. Global'!C38 -> 4109 | D19: =+'Res. Global'!H38 -> 3929.5381 | E19: =+C19-D19 -> 179.46188 | F19: =+D19/C19 -> 0.95632468
B20: IV RAE | C20: =+'Res. Global'!C40 -> 6205 | D20: =+'Res. Global'!H40 -> 3795.753 | E20: =+C20-D20 -> 2409.247 | F20: =+D20/C20 -> 0.6117249
B21: V RAE | C21: =+'Res. Global'!C42 -> 1526 | D21: =+'Res. Global'!H42 -> 1378.779 | E21: =+C21-D21 -> 147.221 | F21: =+D21/C21 -> 0.9035249
B22: VI | C22: =+'Res. Global'!C44 -> 12 | D22: =+'Res. Global'!H44 -> 0.516 | E22: =+C22-D22 -> 11.484 | F22: =+D22/C22 -> 0.043
B23: VII | C23: =+'Res. Global'!C46 -> 96 | D23: =+'Res. Global'!H46 -> 51.32 | E23: =+C23-D23 -> 44.68 | F23: =+D23/C23 -> 0.53458333
B24: VIII | C24: =+'Res. Global'!C48 -> 6225 | D24: =+'Res. Global'!H48 -> 8922.03 | E24: =+C24-D24 -> -2697.03 | F24: =+D24/C24 -> 1.4332578
B25: IX | C25: =+'Res. Global'!C50 -> 140 | D25: =+'Res. Global'!H50 -> 0 | E25: =+C25-D25 -> 140 | F25: =+D25/C25 -> 0
B26: XIV RAE | C26: =+'Res. Global'!C52 -> 728 | D26: =+'Res. Global'!H52 -> 0.015 | E26: =+C26-D26 -> 727.985 | F26: =+D26/C26 -> 2.0604396e-05
B27: X RAE | C27: =+'Res. Global'!C54 -> 4870 | D27: =+'Res. Global'!H54 -> 43.913 | E27: =+C27-D27 -> 4826.087 | F27: =+D27/C27 -> 0.0090170431
A28: Sardina española | B28: XV y I | C28: =+'Res. Global'!C56 -> 186 | D28: =+'Res. Global'!H56 -> 0.85 | E28: =+C28-D28 -> 185.15 | F28: =+D28/C28 -> 0.0045698925
B29: II | C29: =+'Res. Global'!C58 -> 706 | D29: =+'Res. Global'!H58 -> 139.12 | E29: =+C29-D29 -> 566.88 | F29: =+D29/C29 -> 0.19705382 | I29: 186
B30: III | C30: =+'Res. Global'!C60 -> 245 | D30: =+'Res. Global'!H60 -> 1.562 | E30: =+C30-D30 -> 243.438 | F30: =+D30/C30 -> 0.0063755102 | I30: 706
B31: IV | C31: =+'Res. Global'!C61 -> 105 | D31: =+'Res. Global'!H61 -> 0.132 | E31: =+C31-D31 -> 104.868 | F31: =+D31/C31 -> 0.0012571429 | I31: 245
A32: Sardina común | B32: V RAE | C32: =+'Res. Global'!C62 -> 9314 | D32: =+'Res. Global'!H62 -> 10053.021 | E32: =+C32-D32 -> -739.021 | F32: =+D32/C32 -> 1.0793452 | I32: 105
B33: VI | C33: =+'Res. Global'!C65 -> 146 | D33: =+'Res. Global'!H65 -> 0 | E33: =+C33-D33 -> 146 | F33: =+D33/C33 -> 0 | I33: =SUM(I29:I32) -> 1242
B34: VII RAE | C34: =+'Res. Global'!C68 -> 1923 | D34: =+'Res. Global'!H68 -> 1703.1 | E34: =+C34-D34 -> 219.9 | F34: =+D34/C34 -> 0.88564743
B35: VIII RAE | C35: =+'Res. Global'!C71 -> 349489 | D35: =+'Res. Global'!H71 -> 323439.11 | E35: =+C35-D35 -> 26049.89 | F35: =+D35/C35 -> 0.92546292
B36: IX | C36: =+'Res. Global'!C73 -> 7774 | D36: =+'Res. Global'!H73 -> 7771.949 | E36: =+C36-D36 -> 2.051 | F36: =+D36/C36 -> 0.99973617
B37: XIV RAE | C37: =+'Res. Global'!C76 -> 49596 | D37: =+'Res. Global'!H76 -> 57334.998 | E37: =+C37-D37 -> -7738.998 | F37: =+D37/C37 -> 1.1560408
B38: X RAE | C38: =+'Res. Global'!C79 -> 23696 | D38: =+'Res. Global'!H79 -> 1328.765 | E38: =+C38-D38 -> 22367.235 | F38: =+D38/C38 -> 0.056075498
A39: Sardina Austral | B39: X | C39: =+'Res. Global'!C81 -> 22503 | D39: =+'Res. Global'!H81 -> 22333.784 | E39: =+C39-D39 -> 169.216 | F39: =+D39/C39 -> 0.99248029
B40: XI | C40: =+'Res. Global'!C83 -> 7790 | D40: =+'Res. Global'!H83 -> 4500.33 | E40: =+C40-D40 -> 3289.67 | F40: =+D40/C40 -> 0.57770603
A41: Anchoveta | B41: VIII Descarte Res Nº 946 | D41: =+'Res. Global'!H86 -> 19380.537
C43: =SUM(C6:C40) -> 667814 | D43: =SUM(D6:D40) -> 601730.19 | E43: =SUM(E6:E40) -> 66083.813
...

Sheet Res. Global
A2: Resumen por Periodo Cuota Artesanal 2014
A3: 42016
E5: Cuota (t) | G5: Desembarque (t) | I5: Saldo (t) | K5: Saldo % | M5: Fecha de Cierre
A6: Recurso | B6: Unidad de Pesquería | C6: Cuota Global (t) | D6: Período | E6: Asignada | F6: Efectiva | G6: Período | H6: Global | I6: Período | J6: Global | K6: Período | L6: Global
A7: Anchoveta | B7: XV y I | C7: =SUM(E7:E8) -> 89242 | D7: Ene - Jun | E7: 76062 | F7: =+E7 -> 76062 | G7: =+SUM(Anchoveta!AL7:AL12) -> 77889.68 | H7: =SUM(G7:G8) -> 89200.678 | I7: =+F7-G7 -> -1827.68 | J7: =C7-H7 -> 41.322 | K7: =1-G7/F7 -> -0.024028819 | L7: =1-H7/C7 -> 0.0004630331
D8: Jul - Dic | E8: =5680+7500 -> 13180 | F8: =+E8+I7 -> 11352.32 | G8: =+SUM(Anchoveta!AL13:AL18) -> 11310.998 | I8: =+F8-G8 -> 41.322 | K8: =1-G8/F8 -> 0.0036399608 | M8: 41838
B9: II | C9: =SUM(E9:E10) -> 30704 | D9: Ene - Jun | E9: 23028 | F9: =+E9 -> 23028 | G9: =+SUM(Anchoveta!B23:B29) -> 7503.897 | H9: =SUM(G9:G10) -> 24018.544 | I9: =+F9-G9 -> 15524.103 | J9: =C9-H9 -> 6685.456 | K9: =1-G9/F9 -> 0.67414031 | L9: =1-H9/C9 -> 0.21773893 | N9: 01 07 2014
D10: Jul - Dic | E10: 7676 | F10: =+E10+I9 -> 23200.103 | G10: =+SUM(Anchoveta!B30:B35) -> 16514.647 | I10: =+F10-G10 -> 6685.456 | K10: =1-G10/F10 -> 0.28816493
B11: III | C11: =SUM(E11:E12) -> 17702 | D11: Ene - oct | E11: 16817 | F11: =+E11 -> 16817 | G11: =+SUM(Anchoveta!B40:B49) -> 12035.498 | H11: =SUM(G11:G12) -> 12041.708 | I11: =+F11-G11 -> 4781.502 | J11: =C11-H11 -> 5660.292 | K11: =1-G11/F11 -> 0.2843255 | L11: =1-H11/C11 -> 0.31975438
C12: =SUM(E12:E13) -> 8092 | D12: Nov - Dic | E12: 885 | F12: =+E12+I11 -> 5666.502 | G12: =+SUM(Anchoveta!B50:B51) -> 6.21 | H12: =SUM(G12:G13) -> 7226.888 | I12: =+F12-G12 -> 5660.292 | J12: =+C12-H12 -> 865.112 | K12: =1-G12/F12 -> 0.99890409
B13: IV (RAE por Org) | C13: =SUM(E13:E14) -> 7586 | D13: Ene - oct | E13: 7207 | F13: =+E13 -> 7207 | G13: =+'Resumen RAE Anchoveta'!F10 -> 7220.678 | H13: =SUM(G13:G14) -> 7221.178 | I13: =+F13-G13 -> -13.678 | J13: =C13-H13 -> 364.822 | K13: =1-G13/F13 -> -0.0018978771 | L13: =1-H13/C13 -> 0.048091484
C14: =SUM(E14:E16) -> 2282 | D14: Nov - Dic | E14: 379 | F14: =+E14+I13 -> 365.322 | G14: =+'Resumen RAE Anchoveta'!F16 -> 0.5 | H14: =SUM(G14:G16) -> 2156.896 | I14: =+F14-G14 -> 364.822 | J14: =+C14-H14 -> 125.104 | K14: =1-G14/F14 -> 0.99863134
B15: V (RAE por Org) | C15: =SUM(E15:E17) -> 2003 | D15: Ene-Abr | E15: 1703 | F15: =+E15 -> 1703 | G15: =+SUM('Resumen RAE Anchoveta'!F23) -> 2156.396 | H15: =SUM(G15:G17) -> 2156.396 | I15: =+F15-G15 -> -453.396 | J15: =+C15-H15 -> -153.396 | K15: =1-G15/F15 -> -0.26623371 | L15: =1-H15/C15 -> -0.076583125 | M15: 20 03 2014
D16: May-Ago | E16: 200 | F16: =+E16+I15 -> -253.396 | G16: =+SUM('Resumen RAE Anchoveta'!F28) -> 0 | I16: =+F16-G16 -> -253.396 | K16: =1-G16/F16 -> 1 | M16: 07 04 2014
D17: Sep-Dic | E17: 100 | F17: =+E17+I16 -> -153.396 | G17: =+SUM('Resumen RAE Anchoveta'!F33) -> 0 | I17: =+F17-G17 -> -153.396 | K17: =1-G17/F17 -> 1
B18: VI | C18: =SUM(E18:E20) -> 13 | D18: Ene-Abr | E18: 11 | F18: =+E18 -> 11 | G18: =+SUM(Anchoveta!B89:B92) -> 0 | H18: =SUM(G18:G20) -> 0 | I18: =+F18-G18 -> 11 | J18: =+C18-H18 -> 13 | K18: =1-G18/F18 -> 1 | L18: =1-H18/C18 -> 1
D19: May-Ago | E19: 1 | F19: =+E19+I18 -> 12 | G19: =+SUM(Anchoveta!B93:B96) -> 0 | I19: =+F19-G19 -> 12 | K19: =1-G19/F19 -> 1
D20: Sep-Dic | E20: 1 | F20: =+E20+I19 -> 13 | G20: =+SUM(Anchoveta!B97:B100) -> 0 | I20: =+F20-G20 -> 13 | K20: =1-G20/F20 -> 1
B21: VII (RAE por Org) | C21: =SUM(E21:E23) -> 214 | D21: Ene-Abr | E21: 182 | F21: =+E21 -> 182 | G21: =+SUM('Resumen RAE Anchoveta'!F41) -> 90.097 | H21: =SUM(G21:G23) -> 192.185 | I21: =+F21-G21 -> 91.903 | J21: =+C21-H21 -> 21.815 | K21: =1-G21/F21 -> 0.50496154 | L21: =1-H21/C21 -> 0.10193925
D22: May-Ago | E22: 21 | F22: =+E22+I21 -> 112.903 | G22: =+SUM('Resumen RAE Anchoveta'!F47) -> 84.067 | I22: =+F22-G22 -> 28.836 | K22: =1-G22/F22 -> 0.25540508
D23: Sep-Dic | E23: 11 | F23: =+E23+I22 -> 39.836 | G23: =+SUM('Resumen RAE Anchoveta'!F53) -> 18.021 | I23: =+F23-G23 -> 21.815 | K23: =1-G23/F23 -> 0.54762024
B24: VIII (RAE por Org)(sin descarte) | C24: =SUM(E24:E25) -> 16688 | D24: Ene- Ago | E24: 15854 | F24: =+E24 -> 15854 | G24: =+SUM('Resumen RAE Anchoveta'!F122) -> 15355.553 | H24: =SUM(G24:G25) -> 17537.687 | I24: =+F24-G24 -> 498.447 | J24: =+C24-H24 -> -849.687 | K24: =1-G24/F24 -> 0.031439826 | L24: =1-H24/C24 -> -0.050916047
D25: Sep - Dic | E25: 834 | F25: =+E25+I24 -> 1332.447 | G25: =+SUM('Resumen RAE Anchoveta'!F189) -> 2182.134 | I25: =+F25-G25 -> -849.687 | K25: =1-G25/F25 -> -0.63768915
B26: IX | C26: =SUM(E26:E28) -> 400 | D26: Ene-Abr | E26: 340 | F26: =+E26 -> 340 | G26: =+SUM(Anchoveta!B138:B141) -> 105.482 | H26: =SUM(G26:G28) -> 137.895 | I26: =+F26-G26 -> 234.518 | J26: =+C26-H26 -> 262.105 | K26: =1-G26/F26 -> 0.68975882 | L26: =1-H26/C26 -> 0.6552625
D27: May-Ago | E27: 59 | F27: =+E27+I26 -> 293.518 | G27: =+SUM(Anchoveta!B142:B145) -> 32.413 | I27: =+F27-G27 -> 261.105 | K27: =1-G27/F27 -> 0.88957066
D28: Sep-Dic | E28: 1 | F28: =+E28+I27 -> 262.105 | G28: =+SUM(Anchoveta!B146:B149) -> 0 | I28: =+F28-G28 -> 262.105 | K28: =1-G28/F28 -> 1
B29: XIV (RAE por ORG) | C29: =SUM(E29:E31) -> 2411 | D29: Ene-Abr | E29: 2049 | F29: =+E29 -> 2049 | G29: =+SUM('Resumen RAE Anchoveta'!F211) -> 783.774 | H29: =SUM(G29:G31) -> 880.811 | I29: =+F29-G29 -> 1265.226 | J29: =+C29-H29 -> 1530.189 | K29: =1-G29/F29 -> 0.61748463 | L29: =1-H29/C29 -> 0.63466985
D30: May-Ago | E30: 241 | F30: =+E30+I29 -> 1506.226 | G30: =+SUM('Resumen RAE Anchoveta'!F231) -> 65.917 | I30: =+F30-G30 -> 1440.309 | K30: =1-G30/F30 -> 0.95623698
D31: Sep-Dic | E31: 121 | F31: =+E31+I30 -> 1561.309 | G31: =+SUM('Resumen RAE Anchoveta'!F251) -> 31.12 | I31: =+F31-G31 -> 1530.189 | K31: =1-G31/F31 -> 0.98006801
B32: X (RAE por Org) | C32: =SUM(E32:E33) -> 1485 | D32: Ene-Jun | E32: 1188 | F32: =+E32 -> 1188 | G32: =+SUM('Resumen RAE Anchoveta'!F269) -> 104.574 | H32: =SUM(G32:G33) -> 292.195 | I32: =+F32-G32 -> 1083.426 | J32: =+C32-H32 -> 1192.805 | K32: =1-G32/F32 -> 0.91197475 | L32: =1-H32/C32 -> 0.80323569 | W32: 898.5 | Y32: 0.856
D33: Jul-Dic | E33: 297 | F33: =+E33+I32 -> 1380.426 | G33: =+SUM('Resumen RAE Anchoveta'!F285) -> 187.621 | I33: =+F33-G33 -> 1192.805 | K33: =1-G33/F33 -> 0.86408471 | W33: 898.5
A34: JUREL | B34: XV y I | C34: =SUM(E34:E35) -> 991 | D34: Ene - Sep | E34: 941 | F34: =+E34 -> 941 | G34: =+SUM(Jurel!B7:B15) -> 156.787 | H34: =SUM(G34:G35) -> 156.787 | I34: =+F34-G34 -> 784.213 | J34: =+C34-H34 -> 834.213 | K34: =1-G34/F34 -> 0.83338257 | L34: =1-H34/C34 -> 0.8417891 | Y34: 40.414
C35: =SUM(E35:E36) -> 991 | D35: Oct-Dic | E35: 50 | F35: =+E35+I34 -> 834.213 | G35: =+SUM(Jurel!B16:B18) -> 0 | H35: =SUM(G35:G36) -> 1165.537 | I35: =+F35-G35 -> 834.213 | J35: =+C35-H35 -> -174.537 | K35: =1-G35/F35 -> 1 | L35: =1-H35/C35 -> -0.1761221 | Y35: 2027.273
B36: II | C36: =SUM(E36:E37) -> 991 | D36: Ene - Sep | E36: 941 | F36: =+E36 -> 941 | G36: =+SUM(Jurel!B23:B32) -> 1165.537 | H36: =SUM(G36:G37) -> 1165.537 | I36: =+F36-G36 -> -224.537 | J36: =+C36-H36 -> -174.537 | K36: =1-G36/F36 -> -0.2386153 | L36: =1-H36/C36 -> -0.1761221 | W36: 2237
B37: II | C37: =SUM(E37:E38) -> 4154 | D37: Oct-Dic | E37: 50 | F37: =+E37+I36 -> -174.537 | G37: =+SUM(Jurel!B33:B34) -> 0 | H37: =SUM(G37:G38) -> 3616.9681 | I37: =+F37-G37 -> -174.537 | J37: =+C37-H37 -> 537.03188 | K37: =1-G37/F37 -> 1 | L37: =1-H37/C37 -> 0.12928066 | M37: 41821 | Y37: 2261.788
B38: III | C38: =SUM(E38:E39) -> 4109 | D38: Ene - Oct | E38: =2654+1450 -> 4104 | F38: =+E38 -> 4104 | G38: =+SUM(Jurel!AL39:AL48) -> 3616.9681 | H38: =SUM(G38:G39) -> 3929.5381 | I38: =+F38-G38 -> 487.03188 | J38: =+C38-H38 -> 179.46188 | K38: =1-G38/F38 -> 0.11867249 | L38: =1-H38/C38 -> 0.043675318 | M38: 04 03 2014/06-06-2014 | W38: 5219
D39: Nov - Dic | E39: 5 | F39: =+E39+I38 -> 492.03188 | G39: =+SUM(Jurel!AL49:AL50) -> 312.57 | H39: =SUM(G39:G40) -> 4041.915 | I39: =+F39-G39 -> 179.46188 | J39: =+C39-H39 -> -4041.915 | K39: =1-G39/F39 -> 0.36473628 | L39: =1-H39/C39 -> #DIV/0! | M39: 41838 | Y39: 41.409
B40: IV (RAE por Org) | C40: =SUM(E40:E41) -> 6205 | D40: Ene - Oct | E40: 5895 | F40: =+E40 -> 5895 | G40: =+('Resumen RAE Jurel'!F10) -> 3729.345 | H40: =SUM(G40:G41) -> 3795.753 | I40: =+F40-G40 -> 2165.655 | J40: =+C40-H40 -> 2409.247 | K40: =1-G40/F40 -> 0.3673715 | L40: =1-H40/C40 -> 0.3882751 | W40: 2457
C41: =SUM(E41:E42) -> 1690 | D41: Nov - Dic | E41: 310 | F41: =+E41+I40 -> 2475.655 | G41: =+'Resumen RAE Jurel'!F16 -> 66.408 | H41: =SUM(G41:G42) -> 97.039 | I41: =+F41-G41 -> 2409.247 | J41: =+C41-H41 -> 1592.961 | K41: =1-G41/F41 -> 0.97317558 | L41: =1-H41/C41 -> 0.94258047
B42: V (RAE por Org) | C42: =SUM(E42:E43) -> 1526 | D42: Ene - Sep | E42: 1380 | F42: =+E42 -> 1380 | G42: =+'Resumen RAE Jurel'!F24 -> 30.631 | H42: =SUM(G42:G43) -> 1378.779 | I42: =+F42-G42 -> 1349.369 | J42: =+C42-H42 -> 147.221 | K42: =1-G42/F42 -> 0.97780362 | L42: =1-H42/C42 -> 0.096475098 | W42: 10 | Y42: 0.207
...

Sheet Resumen RAE Anchoveta
A2: Resumen RAE Anchoveta 2014
A4: IV Región, de Coquimbo
A6: Organización | B6: Periodo | C6: Cuota asignada (t) | D6: TRAPASOS | E6: Cuota efectiva (t) | F6: Desembarque (t) | G6: Saldo (t) | H6: % | I6: Fecha de Cierre
A7: A.G. de pescadores Art. Y Buzos Marisc. De Coquimbo IV Región | B7: Ene-Oct | C7: 52.52 | E7: =+C7 -> 52.52 | F7: =+SUM('RAE Anchoveta'!B8:B17) -> 32.524 | G7: =+E7-F7 -> 19.996 | H7: =+G7/E7 -> 0.38073115
A8: Cooperativa de Armadores Cerqueros IV Región | B8: Ene-Oct | C8: 7144.96 | E8: =+C8+D8 -> 7144.96 | F8: =+SUM('RAE Anchoveta'!B24:B33) -> 7181.428 | G8: =+E8-F8 -> -36.468 | H8: =+G8/E8 -> -0.0051040174 | L8: Atencion
A9: Cuota Residual - Bolson | B9: Ene-Oct | C9: 9.52 | E9: =+C9 -> 9.52 | F9: =+SUM('RAE Anchoveta'!B40:B49) -> 6.726 | G9: =+E9-F9 -> 2.794 | H9: =+G9/E9 -> 0.29348739
A10: Total | B10: Ene-Oct | C10: =SUM(C7:C9) -> 7207 | E10: =SUM(E7:E9) -> 7207 | F10: =SUM(F7:F9) -> 7220.678 | G10: =+E10-F10 -> -13.678
C11: 105
A12: Organización | B12: Periodo | C12: Cuota asignada (t) | D12: TRAPASOS | E12: Cuota efectiva (t) | F12: Desembarque (t) | G12: Saldo (t) | H12: % | I12: Fecha de Cierre
A13: A.G. de pescadores Art. Y Buzos Marisc. De Coquimbo IV Región | B13: Nov-Dic | C13: 2.76 | E13: =+C13+G7 -> 22.756 | F13: =+SUM('RAE Anchoveta'!B18:B19) -> 0.5 | G13: =+E13-F13 -> 22.256 | H13: =+G13/E13 -> 0.97802777
A14: Cooperativa de Armadores Cerqueros IV Región | B14: Nov-Dic | C14: 375.74 | E14: =+C14+G8 -> 339.272 | F14: =+SUM('RAE Anchoveta'!B34:B35) -> 0 | G14: =+E14-F14 -> 339.272 | H14: =+G14/E14 -> 1
A15: Cuota Residual - Bolson | B15: Nov-Dic | C15: 0.5 | E15: =+C15+G9 -> 3.294 | F15: =+SUM('RAE Anchoveta'!B50:B51) -> 0 | G15: =+E15-F15 -> 3.294 | H15: =+G15/E15 -> 1
A16: Total | B16: Nov-Dic | C16: =SUM(C13:C15) -> 379 | E16: =+C16 -> 379 | F16: =SUM(F13:F15) -> 0.5 | G16: =+E16-F16 -> 378.5
A18: V Región, de Valparaíso
A20: Organización | B20: Periodo | C20: Cuota asignada (t) | D20: Traspasos | E20: Cuota efectiva (t) | F20: Desembarque (t) | G20: Saldo (t) | H20: % | I20: Fecha de Cierre
A21: A.G. Armadores Artesanales San Antonio R.A.G. 2510 | B21: Ene-Abr | C21: 1981 | E21: =+C21+D21 -> 1981 | F21: =+SUM('RAE Anchoveta'!B58:B61) -> 2117.276 | G21: =+E21-F21 -> -136.276 | H21: =+G21/E21 -> -0.068791519 | I21: 07 04 2014 | L21: Atencion
A22: Pescadores artesanales no afiliados | B22: Ene-Abr | C22: 17 | E22: =+C22+D22 -> 17 | F22: =+SUM('RAE Anchoveta'!B74:B77) -> 39.12 | G22: =+E22-F22 -> -22.12 | H22: =+G22/E22 -> -1.3011765 | I22: 20 03 2014 | L22: Atencion
A23: Total | B23: Ene-Abr | C23: =SUM(C21:C22) -> 1998 | E23: =SUM(E21:E22) -> 1998 | F23: =SUM(F21:F22) -> 2156.396 | G23: =+E23-F23 -> -158.396
A25: Organización | B25: Periodo | C25: Cuota asignada (t) | E25: Cuota efectiva (t) | F25: Desembarque (t) | G25: Saldo (t) | H25: % | I25: Fecha de Cierre
A26: A.G. Armadores Artesanales San Antonio R.A.G. 2510 | B26: May-Ago | C26: 1 | E26: =+C26+G21+D26 -> -135.276 | F26: =+SUM('RAE Anchoveta'!B62:B65) -> 0 | G26: =+E26-F26 -> -135.276 | H26: =+G26/E26 -> 1 | I26: 07 04 2014
A27: Pescadores artesanales no afiliados | B27: May-Ago | C27: 2 | E27: =+C27+G22+D27 -> -20.12 | F27: =+SUM('RAE Anchoveta'!B78:B81) -> 0 | G27: =+E27-F27 -> -20.12 | H27: =+G27/E27 -> 1 | I27: 20 03 2014
A28: Total | B28: May-Ago | C28: =SUM(C26:C27) -> 3 | E28: =+C28+G23 -> -155.396 | F28: =SUM(F26:F27) -> 0 | G28: =+E28-F28 -> -155.396
A30: Organización | B30: Periodo | C30: Cuota asignada (t) | E30: Cuota efectiva (t) | F30: Desembarque (t) | G30: Saldo (t) | H30: % | I30: Fecha de Cierre
A31: A.G. Armadores Artesanales San Antonio R.A.G. 2510 | B31: Sep-Dic | C31: 1 | E31: =+C31+G26+D31 -> -134.276 | F31: =+SUM('RAE Anchoveta'!B66:B69) -> 0 | G31: =+E31-F31 -> -134.276 | H31: =+G31/E31 -> 1 | I31: 07 04 2014
A32: Pescadores artesanales no afiliados | B32: Sep-Dic | C32: 1 | E32: =+C32+G27+D32 -> -19.12 | F32: =+SUM('RAE Anchoveta'!B82:B85) -> 0 | G32: =+E32-F32 -> -19.12 | H32: =+G32/E32 -> 1 | I32: 20 03 2014
A33: Total | B33: Sep-Dic | C33: =SUM(C31:C32) -> 2 | E33: =+C33+G28 -> -153.396 | F33: =SUM(F31:F32) -> 0 | G33: =+E33-F33 -> -153.396
A35: VII Región, deL Maule
A37: Organización | B37: Periodo | C37: Cuota asignada (t) | D37: TRASPASOS | E37: Cuota efectiva (t) | F37: Desembarque (t) | G37: Saldo (t) | H37: % | I37: Fecha de Cierre
A38: STI:.de Pescadores "Pelágicos del Maule" Constitución, R.S.U. N° 07050150 | B38: Ene-Abr | C38: 144.644 | E38: =+C38+D38 -> 144.644 | F38: =+SUM('RAE Anchoveta'!B91:B94) -> 90.097 | G38: =+E38-F38 -> 54.547 | H38: =+G38/E38 -> 0.37711208
A39: STI. AGUA LIMPIA RSU. N° 07050118 | B39: Ene-Abr | C39: 1.638 | E39: =+C39+D39 -> 1.638 | F39: =+SUM('RAE Anchoveta'!B107:B110) -> 0 | G39: =+E39-F39 -> 1.638 | H39: =+G39/E39 -> 1
A40: Cuota Residual | B40: Ene-Abr | C40: 8.718 | E40: =+C40+D40 -> 8.718 | F40: =+SUM('RAE Anchoveta'!B123:B126) -> 0 | G40: =+E40-F40 -> 8.718 | H40: =+G40/E40 -> 1
A41: Total | B41: Ene-Abr | C41: =SUM(C38:C40) -> 155 | E41: =SUM(E38:E40) -> 155 | F41: =SUM(F38:F40) -> 90.097 | G41: =+E41-F41 -> 64.903
A43: Organización | B43: Periodo | C43: Cuota asignada (t) | E43: Cuota efectiva (t) | F43: Desembarque (t) | G43: Saldo (t) | H43: % | I43: Fecha de Cierre
A44: STI:.de Pescadores "Pelágicos del Maule" Constitución, R.S.U. N° 07050150 | B44: May-Ago | C44: 19.805 | E44: =+C44+G38+D44 -> 74.352 | F44: =+SUM('RAE Anchoveta'!B95:B98) -> 84.067 | G44: =+E44-F44 -> -9.715 | H44: =+G44/E44 -> -0.13066226
A45: STI. AGUA LIMPIA RSU. N° 07050118 | B45: May-Ago | C45: 0.189 | E45: =+C45+G39+D45 -> 1.827 | F45: =+SUM('RAE Anchoveta'!B111:B114) -> 0 | G45: =+E45-F45 -> 1.827 | H45: =+G45/E45 -> 1
A46: Cuota Residual | B46: May-Ago | C46: 1.006 | E46: =+C46+G40+D46 -> 9.724 | F46: =+SUM('RAE Anchoveta'!B127:B130) -> 0 | G46: =+E46-F46 -> 9.724 | H46: =+G46/E46 -> 1
A47: Total | B47: May-Ago | C47: =SUM(C44:C46) -> 21 | E47: =+C47+G41 -> 85.903 | F47: =SUM(F44:F46) -> 84.067 | G47: =+E47-F47 -> 1.836
A49: Organización | B49: Periodo | C49: Cuota asignada (t) | E49: Cuota efectiva (t) | F49: Desembarque (t) | G49: Saldo (t) | H49: % | I49: Fecha de Cierre
A50: STI:.de Pescadores "Pelágicos del Maule" Constitución, R.S.U. N° 07050150 | B50: Sep-Dic | C50: 10.374 | E50: =+C50+G44+D50 -> 0.659 | F50: =+SUM('RAE Anchoveta'!B99:B102) -> 2.282 | G50: =+E50-F50 -> -1.623 | H50: =+G50/E50 -> -2.4628225
A51: STI. AGUA LIMPIA RSU. N° 07050118 | B51: Sep-Dic | C51: 0.099 | E51: =+C51+G45+D51 -> 1.926 | F51: =+SUM('RAE Anchoveta'!B115:B118) -> 0 | G51: =+E51-F51 -> 1.926 | H51: =+G51/E51 -> 1
...

Sheet RAE Anchoveta
A2: RAE Anchoveta 2014
A4: IV REGIÓN | AI4: Promedio Consumo Anual Flota
A6: A.G. de pescadores Artesanales y Buzos Mariscadores de Coquimbo - IV Región
A7: Mes | B7: Total mes | C7: 1 | D7: 2 | E7: 3 | F7: 4 | G7: 5 | H7: 6 | I7: 7 | J7: 8 | K7: 9 | L7: 10 | M7: 11 | N7: 12 | O7: 13 | P7: 14 | Q7: 15 | R7: 16 | S7: 17 | T7: 18 | U7: 19 | V7: 20 | W7: 21 | X7: 22 | Y7: 23 | Z7: 24 | AA7: 25 | AB7: 26 | AC7: 27 | AD7: 28 | AE7: 29 | AF7: 30 | AG7: 31 | AH7: TOTAL | AI7: Xc | AJ7: =(B20/COUNTIF($C$8:$AG$19,">0")) -> 4.128
A8: Enero | B8: =+AH8 -> 0.4 | C8: 0 | D8: 0 | E8: 0 | F8: 0 | G8: 0 | H8: 0 | I8: 0 | J8: 0 | K8: 0 | L8: 0 | M8: 0 | N8: 0 | O8: 0 | P8: 0 | Q8: 0.4 | R8: 0 | S8: 0 | T8: 0 | U8: 0 | V8: 0 | W8: 0 | X8: 0 | Y8: 0 | Z8: 0 | AA8: 0 | AB8: 0 | AC8: 0 | AD8: 0 | AE8: 0 | AF8: 0 | AG8: 0 | AH8: =SUM(C8:AG8) -> 0.4 | AJ8: =+'Resumen RAE Anchoveta'!G13 -> 22.256
A9: Febrero | B9: =+AH9 -> 0 | C9: 0 | D9: 0 | E9: 0 | F9: 0 | G9: 0 | H9: 0 | I9: 0 | J9: 0 | K9: 0 | L9: 0 | M9: 0 | N9: 0 | O9: 0 | P9: 0 | Q9: 0 | R9: 0 | S9: 0 | T9: 0 | U9: 0 | V9: 0 | W9: 0 | X9: 0 | Y9: 0 | Z9: 0 | AA9: 0 | AB9: 0 | AC9: 0 | AD9: 0 | AH9: =SUM(C9:AG9) -> 0 | AJ9: =+AJ8/AJ7 -> 5.3914729
A10: Marzo | B10: =+AH10 -> 4.853 | C10: 0 | D10: 0 | E10: 0 | F10: 0 | G10: 0 | H10: 0 | I10: 0 | J10: 0 | K10: 0 | L10: 0 | M10: 0 | N10: 4.853 | O10: 0 | P10: 0 | Q10: 0 | R10: 0 | S10: 0 | T10: 0 | U10: 0 | V10: 0 | W10: 0 | X10: 0 | Y10: 0 | Z10: 0 | AA10: 0 | AB10: 0 | AC10: 0 | AD10: 0 | AE10: 0 | AF10: 0 | AG10: 0 | AH10: =SUM(C10:AG10) -> 4.853
A11: Abril | B11: =+AH11 -> 19.836 | C11: 0 | D11: 0 | E11: 4.807 | F11: 0 | G11: 0 | H11: 0 | I11: 0 | J11: 0 | K11: 0 | L11: 0 | M11: 0 | N11: 0 | O11: 0 | P11: 0 | Q11: 0 | R11: 3 | S11: 0 | T11: 0 | U11: 0 | V11: 0 | W11: 12.029 | X11: 0 | Y11: 0 | Z11: 0 | AA11: 0 | AB11: 0 | AC11: 0 | AD11: 0 | AE11: 0 | AF11: 0 | AH11: =SUM(C11:AG11) -> 19.836
A12: Mayo | B12: =+AH12 -> 0 | C12: 0 | D12: 0 | E12: 0 | F12: 0 | G12: 0 | H12: 0 | I12: 0 | J12: 0 | K12: 0 | L12: 0 | M12: 0 | N12: 0 | O12: 0 | P12: 0 | Q12: 0 | R12: 0 | S12: 0 | T12: 0 | U12: 0 | V12: 0 | W12: 0 | X12: 0 | Y12: 0 | Z12: 0 | AA12: 0 | AB12: 0 | AC12: 0 | AD12: 0 | AE12: 0 | AF12: 0 | AG12: 0 | AH12: =SUM(C12:AG12) -> 0
A13: Junio | B13: =+AH13 -> 0 | C13: 0 | D13: 0 | E13: 0 | F13: 0 | G13: 0 | H13: 0 | I13: 0 | J13: 0 | K13: 0 | L13: 0 | M13: 0 | N13: 0 | O13: 0 | P13: 0 | Q13: 0 | R13: 0 | S13: 0 | T13: 0 | U13: 0 | V13: 0 | W13: 0 | X13: 0 | Y13: 0 | Z13: 0 | AA13: 0 | AB13: 0 | AC13: 0 | AD13: 0 | AE13: 0 | AF13: 0 | AH13: =SUM(C13:AG13) -> 0
A14: Julio | B14: =+AH14 -> 0 | C14: 0 | D14: 0 | E14: 0 | F14: 0 | G14: 0 | H14: 0 | I14: 0 | J14: 0 | K14: 0 | L14: 0 | M14: 0 | N14: 0 | O14: 0 | P14: 0 | Q14: 0 | R14: 0 | S14: 0 | T14: 0 | U14: 0 | V14: 0 | W14: 0 | X14: 0 | Y14: 0 | Z14: 0 | AA14: 0 | AB14: 0 | AC14: 0 | AD14: 0 | AE14: 0 | AF14: 0 | AG14: 0 | AH14: =SUM(C14:AG14) -> 0
A15: Agosto | B15: =+AH15 -> 0 | C15: 0 | D15: 0 | E15: 0 | F15: 0 | G15: 0 | H15: 0 | I15: 0 | J15: 0 | K15: 0 | L15: 0 | M15: 0 | N15: 0 | O15: 0 | P15: 0 | Q15: 0 | R15: 0 | S15: 0 | T15: 0 | U15: 0 | V15: 0 | W15: 0 | X15: 0 | Y15: 0 | Z15: 0 | AA15: 0 | AB15: 0 | AC15: 0 | AD15: 0 | AE15: 0 | AF15: 0 | AG15: 0 | AH15: =SUM(C15:AG15) -> 0
A16: Septiembre | B16: =+AH16 -> 0 | C16: VEDA | AH16: =SUM(C16:AG16) -> 0
A17: Octubre | B17: =+AH17 -> 7.435 | C17: 0 | D17: 0 | E17: 0 | F17: 0 | G17: 0 | H17: 6.935 | I17: 0 | J17: 0 | K17: 0 | L17: 0 | M17: 0.5 | N17: 0 | O17: 0 | P17: 0 | Q17: 0 | R17: 0 | S17: 0 | T17: 0 | U17: 0 | V17: 0 | W17: 0 | X17: 0 | Y17: 0 | Z17: 0 | AA17: 0 | AB17: 0 | AC17: 0 | AD17: 0 | AE17: 0 | AF17: 0 | AG17: 0 | AH17: =SUM(C17:AG17) -> 7.435
A18: Noviembre | B18: =+AH18 -> 0 | C18: 0 | D18: 0 | E18: 0 | F18: 0 | G18: 0 | H18: 0 | I18: 0 | J18: 0 | K18: 0 | L18: 0 | M18: 0 | N18: 0 | O18: 0 | P18: 0 | Q18: 0 | R18: 0 | S18: 0 | T18: 0 | U18: 0 | V18: 0 | W18: 0 | X18: 0 | Y18: 0 | Z18: 0 | AA18: 0 | AB18: 0 | AC18: 0 | AD18: 0 | AE18: 0 | AF18: 0 | AH18: =SUM(C18:AG18) -> 0
A19: Diciembre | B19: =+AH19 -> 0.5 | C19: 0 | D19: 0 | E19: 0 | F19: 0 | G19: 0 | H19: 0 | I19: 0 | J19: 0 | K19: 0 | L19: 0 | M19: 0 | N19: 0 | O19: 0 | P19: 0 | Q19: 0 | R19: 0 | S19: 0 | T19: 0 | U19: 0 | V19: 0.5 | W19: 0 | X19: 0 | Y19: 0 | Z19: 0 | AA19: 0 | AB19: 0 | AC19: 0 | AD19: 0 | AE19: 0 | AF19: 0 | AG19: 0 | AH19: =SUM(C19:AG19) -> 0.5
A20: TOTAL | B20: =SUM(B8:B19) -> 33.024 | C20: =SUM(C8:C19) -> 0 | D20: =SUM(D8:D19) -> 0 | E20: =SUM(E8:E19) -> 4.807 | F20: =SUM(F8:F19) -> 0 | G20: =SUM(G8:G19) -> 0 | H20: =SUM(H8:H19) -> 6.935 | I20: =SUM(I8:I19) -> 0 | ... AH20: =SUM(AH8:AH19) -> 33.024
A22: Cooperativa de Armadores Cerqueros IV región
A23: Mes | B23: Total mes | C23: 1 | D23: 2 | E23: 3 | F23: 4 | G23: 5 | H23: 6 | I23: 7 | J23: 8 | K23: 9 | L23: 10 | M23: 11 | N23: 12 | O23: 13 | P23: 14 | Q23: 15 | R23: 16 | S23: 17 | T23: 18 | U23: 19 | V23: 20 | W23: 21 | X23: 22 | Y23: 23 | Z23: 24 | AA23: 25 | AB23: 26 | AC23: 27 | AD23: 28 | AE23: 29 | AF23: 30 | AG23: 31 | AH23: TOTAL | AI23: Xc | AJ23: =(B36/COUNTIF($C$24:$AG$35,">0")) -> 123.81772
A24: Enero | B24: =+AH24 -> 871.278 | C24: 0 | D24: 0 | E24: 6.116 | F24: 0 | G24: 0 | H24: 125.139 | I24: 5.567 | J24: 0 | K24: 2.797 | L24: 0 | M24: 64.142 | N24: 0 | O24: 68.526 | P24: 0 | Q24: 11.957 | R24: 47.883 | S24: 25.648 | T24: 1.463 | U24: 0 | V24: 0 | W24: 13.548 | X24: 10.581 | Y24: 15.563 | Z24: 9.319 | AA24: 70.817 | AB24: 0 | AC24: 88.011 | AD24: 18.571 | AE24: 72.51 | AF24: 128.241 | AG24: 84.879 | AH24: =SUM(C24:AG24) -> 871.278 | AJ24: =+'Resumen RAE Anchoveta'!G14 -> 339.272
A25: Febrero | B25: =+AH25 -> 300.345 | C25: 80.736 | D25: 0 | E25: 79.716 | F25: 0 | G25: 61.029 | H25: 69.938 | I25: 0 | J25: 0 | K25: 0 | L25: 0 | M25: 0 | N25: 0 | O25: 0 | P25: 0 | Q25: 0 | R25: 0 | S25: 0 | T25: 0 | U25: 0 | V25: 0 | W25: 0 | X25: 0 | Y25: 0 | Z25: 0 | AA25: 8.926 | AB25: 0 | AC25: 0 | AD25: 0 | AH25: =SUM(C25:AG25) -> 300.345 | AJ25: =+AJ24/AJ23 -> 2.7400924
A26: Marzo | B26: =+AH26 -> 2664.947 | C26: 0 | D26: 0 | E26: 0 | F26: 0 | G26: 0 | H26: 0 | I26: 0 | J26: 0 | K26: 0 | L26: 0 | M26: 0 | N26: 35.913 | O26: 0 | P26: 156.131 | Q26: 30.302 | R26: 0 | S26: 196.246 | T26: 149.609 | U26: 210.739 | V26: 467.599 | W26: 445.705 | X26: 186.914 | Y26: 44.417 | Z26: 17.004 | AA26: 305.517 | AB26: 82.96 | AC26: 153.762 | AD26: 55.805 | AE26: 0 | AF26: 0 | AG26: 126.324 | AH26: =SUM(C26:AG26) -> 2664.947
A27: Abril | B27: =+AH27 -> 3344.858 | C27: 25.018 | D27: 0 | E27: 36.329 | F27: 227.268 | G27: 34.607 | H27: 0 | I27: 269.383 | J27: 123.563 | K27: 0 | L27: 27.649 | M27: 0 | N27: 0 | O27: 0 | P27: 133.101 | Q27: 263.151 | R27: 77.975 | S27: 0 | T27: 0 | U27: 0 | V27: 0 | W27: 201.602 | X27: 341.665 | Y27: 125.876 | Z27: 545.293 | AA27: 313.946 | AB27: 276.327 | AC27: 0 | AD27: 322.105 | AE27: 0 | AF27: 0 | AH27: =SUM(C27:AG27) -> 3344.858
A28: Mayo | B28: =+AH28 -> 0 | C28: 0 | D28: 0 | E28: 0 | F28: 0 | G28: 0 | H28: 0 | I28: 0 | J28: 0 | K28: 0 | L28: 0 | M28: 0 | N28: 0 | O28: 0 | P28: 0 | Q28: 0 | R28: 0 | S28: 0 | T28: 0 | U28: 0 | V28: 0 | W28: 0 | X28: 0 | Y28: 0 | Z28: 0 | AA28: 0 | AB28: 0 | AC28: 0 | AD28: 0 | AE28: 0 | AF28: 0 | AG28: 0 | AH28: =SUM(C28:AG28) -> 0
A29: Junio | B29: =+AH29 -> 0 | AH29: =SUM(C29:AG29) -> 0
A30: Julio | B30: =+AH30 -> 0 | AH30: =SUM(C30:AG30) -> 0
A31: Agosto | B31: =+AH31 -> 0
A32: Septiembre | B32: =+AH32 -> 0
A33: Octubre | B33: =+AH33 -> 0 | AH33: =SUM(C33:AG33) -> 0
A34: Noviembre | B34: =+AH34 -> 0 | AH34: =SUM(C34:AG34) -> 0
A35: Diciembre | B35: =+AH35 -> 0 | AH35: =SUM(C35:AG35) -> 0
A36: TOTAL | B36: =SUM(B24:B35) -> 7181.428 | C36: =SUM(C24:C35) -> 105.754 | D36: =SUM(D24:D35) -> 0 | E36: =SUM(E24:E35) -> 122.161 | F36: =SUM(F24:F35) -> 227.268 | G36: =SUM(G24:G35) -> 95.636 | H36: =SUM(H24:H35) -> 195.077 | I36: =SUM(I24:I35) -> 274.95 | ... AH36: =SUM(AH24:AH35) -> 7181.428
A38: Cuota residual - Bolson
A39: Mes | B39: Total mes | C39: 1 | D39: 2 | E39: 3 | F39: 4 | G39: 5 | H39: 6 | I39: 7 | J39: 8 | K39: 9 | L39: 10 | M39: 11 | N39: 12 | O39: 13 | P39: 14 | Q39: 15 | R39: 16 | S39: 17 | T39: 18 | U39: 19 | V39: 20 | W39: 21 | X39: 22 | Y39: 23 | Z39: 24 | AA39: 25 | AB39: 26 | AC39: 27 | AD39: 28 | AE39: 29 | AF39: 30 | AG39: 31 | AH39: TOTAL | AI39: Xc | AJ39: =(B52/COUNTIF($C$40:$AG$51,">0")) -> 0.30572727
A40: Enero | B40: =+AH40 -> 0.268 | C40: 0 | D40: 0 | E40: 0 | F40: 0 | G40: 0 | H40: 0 | I40: 0.015 | J40: 0 | K40: 0.015 | L40: 0 | M40: 0 | N40: 0 | O40: 0 | P40: 0.012 | Q40: 0 | R40: 0 | S40: 0 | T40: 0.001 | U40: 0.06 | V40: 0 | W40: 0 | X40: 0 | Y40: 0 | Z40: 0.07 | AA40: 0 | AB40: 0 | AC40: 0.06 | AD40: 0 | AE40: 0.035 | AF40: 0 | AG40: 0 | AH40: =SUM(C40:AG40) -> 0.268 | AJ40: =+'Resumen RAE Anchoveta'!G15 -> 3.294
A41: Febrero | B41: =+AH41 -> 0.155 | C41: 0 | D41: 0 | E41: 0 | F41: 0 | G41: 0.07 | H41: 0 | I41: 0.055 | J41: 0 | K41: 0 | L41: 0 | M41: 0.03 | N41: 0 | O41: 0 | P41: 0 | Q41: 0 | R41: 0 | S41: 0 | T41: 0 | U41: 0 | V41: 0 | W41: 0 | X41: 0 | Y41: 0 | Z41: 0 | AA41: 0 | AB41: 0 | AC41: 0 | AD41: 0 | AH41: =SUM(C41:AG41) -> 0.155 | AJ41: =+AJ40/AJ39 -> 10.774309
A42: Marzo | B42: =+AH42 -> 2.306 | C42: 0 | D42: 0 | E42: 0 | F42: 0 | G42: 0 | H42: 0 | I42: 0 | J42: 0 | K42: 0 | L42: 0 | M42: 0 | N42: 0 | O42: 0 | P42: 0 | Q42: 0 | R42: 0.27 | S42: 0 | T42: 0.3 | U42: 0 | V42: 1.736 | W42: 0 | X42: 0 | Y42: 0 | Z42: 0 | AA42: 0 | AB42: 0 | AC42: 0 | AD42: 0 | AE42: 0 | AF42: 0 | AG42: 0 | AH42: =SUM(C42:AG42) -> 2.306
A43: Abril | B43: =+AH43 -> 3.377 | C43: 2.7 | D43: 0 | E43: 0 | F43: 0 | G43: 0 | H43: 0 | I43: 0 | J43: 0 | K43: 0 | L43: 0 | M43: 0 | N43: 0 | O43: 0 | P43: 0 | Q43: 0 | R43: 0 | S43: 0 | T43: 0 | U43: 0 | V43: 0 | W43: 0.28 | X43: 0.115 | Y43: 0 | Z43: 0 | AA43: 0 | AB43: 0 | AC43: 0 | AD43: 0 | AE43: 0 | AF43: 0.282 | AH43: =SUM(C43:AG43) -> 3.377
A44: Mayo | B44: =+AH44 -> 0.32 | C44: 0 | D44: 0.082 | E44: 0.123 | F44: 0 | G44: 0 | H44: 0.115 | I44: 0 | AH44: =SUM(C44:AG44) -> 0.32
A45: Junio | B45: =+AH45 -> 0 | AH45: =SUM(C45:AG45) -> 0
...

Sheet Anchoveta
A2: Anchoveta 2014
AI3: Promedio Consumo Anual Flota
F4: 79301.99 | AN4: RES 1893 22 07 2014
A5: XV y I Región, Arica e Iquique | AN5: XV Región IMPREVISTOS
A6: Mes | B6: Total mes | C6: 1 | D6: 2 | E6: 3 | F6: 4 | G6: 5 | H6: 6 | I6: 7 | J6: 8 | K6: 9 | L6: 10 | M6: 11 | N6: 12 | O6: 13 | P6: 14 | Q6: 15 | R6: 16 | S6: 17 | T6: 18 | U6: 19 | V6: 20 | W6: 21 | X6: 22 | Y6: 23 | Z6: 24 | AA6: 25 | AB6: 26 | AC6: 27 | AD6: 28 | AE6: 29 | AF6: 30 | AG6: 31 | AH6: TOTAL | AI6: Xc | AJ6: =(B19/COUNTIF($C$7:$AG$18,">0")) -> 801.833 | AL6: Suma global mas imprevistos | AN6: Mes | AO6: Total mes | AP6: 1 | AQ6: 2 | AR6: 3 | AS6: 4 | AT6: 5 | AU6: 6 | AV6: 7 | AW6: 8 | AX6: 9 | AY6: 10 | AZ6: 11 | BA6: 12 | BB6: 13 | BC6: 14 | BD6: 15 | BE6: 16 | BF6: 17 | BG6: 18 | BH6: 19 | BI6: 20 | BJ6: 21 | BK6: 22 | BL6: 23 | BM6: 24 | BN6: 25 | BO6: 26 | BP6: 27 | BQ6: 28 | BR6: 29 | BS6: 30 | BT6: 31 | BU6: TOTAL
A7: Enero | B7: =+AH7 -> 0 | C7: 0 | D7: 0 | E7: 0 | F7: 0 | G7: 0 | H7: 0 | I7: 0 | J7: 0 | K7: 0 | L7: 0 | M7: 0 | N7: 0 | O7: 0 | P7: 0 | Q7: 0 | R7: 0 | S7: 0 | T7: 0 | U7: 0 | V7: 0 | W7: 0 | X7: 0 | Y7: 0 | Z7: 0 | AA7: 0 | AB7: 0 | AC7: 0 | AD7: 0 | AE7: 0 | AF7: 0 | AG7: 0 | AH7: =SUM(C7:AG7) -> 0 | AJ7: =+'Res. Global'!J7 -> 41.322 | AL7: =+B7+AO7 -> 0 | AN7: Enero | AO7: =+BU7 -> 0 | BU7: =SUM(AP7:BT7) -> 0
A8: Febrero | B8: =+AH8 -> 5476.057 | C8: 0 | D8: 0 | E8: 0 | F8: 0 | G8: 0 | H8: 0 | I8: 0 | J8: 0 | K8: 0 | L8: 0 | M8: 865.35 | N8: 1669.385 | O8: 1803.79 | P8: 1024.092 | Q8: 113.44 | R8: 0 | S8: 0 | T8: 0 | U8: 0 | V8: 0 | W8: 0 | X8: 0 | Y8: 0 | Z8: 0 | AA8: 0 | AB8: 0 | AC8: 0 | AD8: 0 | AE8: - | AF8: - | AG8: - | AH8: =SUM(C8:AG8) -> 5476.057 | AJ8: =+AJ7/AJ6 -> 0.051534422 | AL8: =+B8+AO8 -> 5476.057 | AN8: Febrero | AO8: =+BU8 -> 0 | BU8: =SUM(AP8:BT8) -> 0
A9: Marzo | B9: =+AH9 -> 23235.61 | C9: 0 | D9: 0 | E9: 683.725 | F9: 2110.347 | G9: 1522.345 | H9: 1388.355 | I9: 540.665 | J9: 1070.354 | K9: 0 | L9: 2065.151 | M9: 997.196 | N9: 1407.911 | O9: 1606.53 | P9: 1004.979 | Q9: 488.58 | R9: 0 | S9: 0 | T9: 43.357 | U9: 386.734 | V9: 497.539 | W9: 203.312 | X9: 979.98 | Y9: 0 | Z9: 1001.331 | AA9: 1358.956 | AB9: 1628.798 | AC9: 327.011 | AD9: 1039.659 | AE9: 671.332 | AF9: 0 | AG9: 211.463 | AH9: =SUM(C9:AG9) -> 23235.61 | AL9: =+B9+AO9 -> 23235.61 | AN9: Marzo | AO9: =+BU9 -> 0 | BU9: =SUM(AP9:BT9) -> 0
A10: Abril | B10: =+AH10 -> 13636.963 | C10: 0 | D10: 0 | E10: 0 | F10: 0 | G10: 0 | H10: 0 | I10: 0 | J10: 0 | K10: 962.845 | L10: 66.415 | M10: 0 | N10: 0 | O10: 0 | P10: 1506.728 | Q10: 1146.245 | R10: 901.509 | S10: 345.533 | T10: 0 | U10: 0 | V10: 0 | W10: 1133.422 | X10: 296.778 | Y10: 729.212 | Z10: 1416.418 | AA10: 1368.25 | AB10: 0 | AC10: 0 | AD10: 212.862 | AE10: 1942.49 | AF10: 1608.256 | AG10: - | AH10: =SUM(C10:AG10) -> 13636.963 | AL10: =+B10+AO10 -> 13636.963 | AN10: Abril | AO10: =+BU10 -> 0 | BU10: =SUM(AP10:BT10) -> 0
A11: Mayo | B11: =+AH11 -> 20336.373 | C11: 0 | D11: 1727.028 | E11: 1437.48 | F11: 127.225 | G11: 305.33 | H11: 0 | I11: 0 | J11: 0 | K11: 0 | L11: 850.489 | M11: 32.715 | N11: 1575.642 | O11: 579.98 | P11: 528.137 | Q11: 29.72 | R11: 208.617 | S11: 1172.022 | T11: 13.98 | U11: 1723.523 | V11: 1845.976 | W11: 834.85 | X11: 1470.222 | Y11: 745.596 | Z11: 872.05 | AA11: 0 | AB11: 1553.87 | AC11: 211.955 | AD11: 736.039 | AE11: 512.732 | AF11: 623.785 | AG11: 617.41 | AH11: =SUM(C11:AG11) -> 20336.373 | AL11: =+B11+AO11 -> 20336.373 | AN11: Mayo | AO11: =+BU11 -> 0 | BU11: =SUM(AP11:BT11) -> 0
A12: Junio | B12: =+AH12 -> 15204.677 | C12: 0 | D12: 198.683 | E12: 1037.948 | F12: 901.204 | G12: 1240.481 | H12: 134.509 | I12: 0 | J12: 0 | K12: 949.724 | L12: 872.07 | M12: 1059.965 | N12: 701.715 | O12: 0 | P12: 330.46 | Q12: 46.22 | R12: 617.119 | S12: 275.747 | T12: 337.781 | U12: 543.185 | V12: 506.46 | W12: 42.215 | X12: 0 | Y12: 920.453 | Z12: 1181.518 | AA12: 893.68 | AB12: 1586.645 | AC12: 826.895 | AD12: 0 | AE12: 0 | AF12: 0 | AG12: - | AH12: =SUM(C12:AG12) -> 15204.677 | AL12: =+B12+AO12 -> 15204.677 | AN12: Junio | AO12: =+BU12 -> 0 | BU12: =SUM(AP12:BT12) -> 0
A13: Julio | B13: =+AH13 -> 3897.286 | C13: 365.694 | D13: 600.685 | E13: 573.86 | F13: 0 | G13: 0 | H13: 0 | I13: 0 | J13: 337.583 | K13: 353.491 | L13: 37.569 | M13: 35.991 | N13: 21.29 | O13: 0 | P13: 63.61 | Q13: 231.375 | R13: 0 | S13: 252.967 | T13: 1023.171 | U13: 0 | V13: 0 | W13: 0 | X13: 0 | Y13: 0 | Z13: 0 | AA13: 0 | AB13: 0 | AC13: 0 | AD13: 0 | AE13: 0 | AF13: 0 | AG13: 0 | AH13: =SUM(C13:AG13) -> 3897.286 | AI13: cierre 18 07 2014 | AL13: =+B13+AO13 -> 4766.329 | AN13: Julio | AO13: =+BU13 -> 869.043 | BK13: 0 | BL13: 443.785 | BM13: 96.625 | BN13: 153.218 | BO13: 0 | BP13: 0 | BQ13: 169.745 | BR13: 0 | BS13: 3.76 | BT13: 1.91 | BU13: =SUM(AP13:BT13) -> 869.043
A14: Agosto | B14: =+AH14 -> 0 | C14: 0 | D14: 0 | E14: 0 | F14: 0 | G14: 0 | H14: 0 | I14: 0 | J14: 0 | K14: 0 | L14: 0 | M14: 0 | N14: 0 | O14: 0 | P14: 0 | Q14: 0 | R14: 0 | S14: 0 | T14: 0 | U14: 0 | V14: 0 | W14: 0 | X14: 0 | Y14: 0 | Z14: 0 | AA14: 0 | AB14: 0 | AC14: 0 | AD14: 0 | AE14: 0 | AF14: 0 | AG14: 0 | AH14: =SUM(C14:AG14) -> 0 | AL14: =+B14+AO14 -> 2048.095 | AN14: Agosto | AO14: =+BU14 -> 2048.095 | AP14: 0 | AQ14: 0 | AR14: 0 | AS14: 1182.229 | AT14: 236.927 | AU14: 628.939 | AV14: 0 | AW14: 0 | AX14: 0 | AY14: 0 | BU14: =SUM(AP14:BT14) -> 2048.095
A15: Septiembre | B15: =+AH15 -> 0 | C15: 0 | D15: 0 | E15: 0 | F15: 0 | G15: 0 | H15: 0 | I15: 0 | J15: 0 | K15: 0 | L15: 0 | M15: 0 | N15: 0 | O15: 0 | P15: 0 | Q15: 0 | R15: 0 | S15: 0 | T15: 0 | U15: 0 | V15: 0 | W15: 0 | X15: 0 | Y15: 0 | Z15: 0 | AA15: 0 | AB15: 0 | AC15: 0 | AD15: 0 | AE15: 0 | AF15: 0 | AG15: - | AH15: =SUM(C15:AG15) -> 0 | AL15: =+B15+AO15 -> 2613.851 | AN15: Septiembre | AO15: =+BU15 -> 2613.851 | AP15: 0 | AQ15: 0 | AR15: 0 | AS15: 0 | AT15: 0 | AU15: 0 | AV15: 0 | AW15: 0 | AX15: 0 | AY15: 0 | AZ15: 0 | BA15: 0 | BB15: 0 | BC15: 0 | BD15: 0 | BE15: 0 | BF15: 0 | BG15: 0 | BH15: 0 | BI15: 0 | BJ15: 0 | BK15: 0 | BL15: 0 | BM15: 0 | BN15: 1238.755 | BO15: 1275.386 | BP15: 99.71 | BQ15: 0 | BU15: =SUM(AP15:BT15) -> 2613.851
A16: Octubre | B16: =+AH16 -> 0 | AH16: =SUM(C16:AG16) -> 0 | AL16: =+B16+AO16 -> 1882.723 | AN16: Octubre | AO16: =+BU16 -> 1882.723 | AP16: 0 | AQ16: 0 | AR16: 0 | AS16: 0 | AT16: 0 | AU16: 0 | AV16: 701.595 | AW16: 907.145 | AX16: 175.368 | AY16: 0 | AZ16: 98.615 | BU16: =SUM(AP16:BT16) -> 1882.723
A17: Noviembre | B17: =+AH17 -> 0 | C17: VEDA | D17: VEDA | E17: VEDA | F17: VEDA | G17: VEDA | H17: VEDA | I17: VEDA | J17: VEDA | K17: VEDA | L17: VEDA | M17: VEDA | N17: VEDA | O17: VEDA | P17: VEDA | Q17: VEDA | R17: VEDA | S17: VEDA | T17: VEDA | U17: VEDA | V17: VEDA | W17: VEDA | X17: VEDA | Y17: VEDA | Z17: VEDA | AA17: VEDA | AB17: VEDA | AC17: VEDA | AD17: VEDA | AE17: VEDA | AG17: VEDA | AH17: =SUM(C17:AG17) -> 0 | AL17: =+B17+AO17 -> 0 | AN17: Noviembre | AO17: =+BU17 -> 0 | AP17: VEDA | AQ17: VEDA | AR17: VEDA | AS17: VEDA | AT17: VEDA | AU17: VEDA | AV17: VEDA | AW17: VEDA | AX17: VEDA | AY17: VEDA | AZ17: VEDA | BA17: VEDA | BB17: VEDA | BC17: VEDA | BD17: VEDA | BE17: VEDA | BF17: VEDA | BG17: VEDA | BH17: VEDA | BI17: VEDA | BJ17: VEDA | BK17: VEDA | BL17: VEDA | BM17: VEDA | BN17: VEDA | BO17: VEDA | BP17: VEDA | BQ17: VEDA | BR17: VEDA | BS17: VEDA | BT17: VEDA | BU17: =SUM(AP17:BT17) -> 0
A18: Diciembre | B18: =+AH18 -> 0 | C18: VEDA | F18: VEDA | G18: VEDA | H18: VEDA | I18: VEDA | J18: VEDA | K18: VEDA | L18: VEDA | M18: VEDA | N18: VEDA | O18: VEDA | P18: VEDA | Q18: VEDA | R18: VEDA | S18: VEDA | T18: VEDA | U18: VEDA | V18: VEDA | W18: VEDA | X18: VEDA | Y18: VEDA | Z18: VEDA | AA18: VEDA | AB18: VEDA | AC18: VEDA | AD18: VEDA | AE18: VEDA | AF18: VEDA | AG18: VEDA | AH18: =SUM(C18:AG18) -> 0 | AL18: =+B18+AO18 -> 0 | AN18: Diciembre | AO18: =+BU18 -> 0 | AP18: VEDA | AQ18: VEDA | AR18: VEDA | AS18: VEDA | AT18: VEDA | AU18: VEDA | AV18: VEDA | AW18: VEDA | AX18: VEDA | AY18: VEDA | AZ18: VEDA | BA18: VEDA | BB18: VEDA | BC18: VEDA | BD18: VEDA | BE18: VEDA | BF18: VEDA | BG18: VEDA | BH18: VEDA | BI18: VEDA | BJ18: VEDA | BK18: VEDA | BL18: VEDA | BM18: VEDA | BN18: VEDA | BO18: VEDA | BP18: VEDA | BQ18: VEDA | BR18: VEDA | BS18: VEDA | BT18: VEDA | BU18: =SUM(AP18:BT18) -> 0
A19: TOTAL | B19: =SUM(B7:B18) -> 81786.966 | AH19: =SUM(AH7:AH18) -> 81786.966 | AL19: =+B19+AO19 -> 89200.678 | AN19: TOTAL | AO19: =SUM(AO7:AO18) -> 7413.712 | BU19: =SUM(BU7:BU18) -> 7413.712
F20: 89242 | AN20: cuota imprevistos | AO20: 7500 | AP20: por resol 1893 de 22 07 2014
A21: II Región, de Antofasta | AN21: saldo | AO21: =+AO20-AO19 -> 86.288
A22: Mes | B22: Total mes | C22: 1 | D22: 2 | E22: 3 | F22: 4 | G22: 5 | H22: 6 | I22: 7 | J22: 8 | K22: 9 | L22: 10 | M22: 11 | N22: 12 | O22: 13 | P22: 14 | Q22: 15 | R22: 16 | S22: 17 | T22: 18 | U22: 19 | V22: 20 | W22: 21 | X22: 22 | Y22: 23 | Z22: 24 | AA22: 25 | AB22: 26 | AC22: 27 | AD22: 28 | AE22: 29 | AF22: 30 | AG22: 31 | AH22: TOTAL | AI22: Xc | AJ22: =(B36/COUNTIF($C$23:$AG$34,">0")) -> 218.3504
AG23: 0.69 | AH23: =SUM(C23:AG23) -> 0.69 | AJ23: =+'Res. Global'!J9 -> 6685.456
A24: Enero | B24: =SUM(AH24) -> 0.69 | AG24: 0.69 | AH24: =SUM(C24:AG24) -> 0.69 | AJ24: =+AJ23/+AJ22 -> 30.618016
A25: Febrero | B25: =SUM(AH25) -> 0.39 | S25: 0.02 | AD25: 0.37 | AH25: =SUM(C25:AG25) -> 0.39
A26: Marzo | B26: =SUM(AH26) -> 3331.813 | E26: 219.24 | F26: 303.195 | G26: 75.45 | H26: 322.864 | I26: 281.393 | J26: 357.046 | L26: 54.435 | T26: 60.73 | W26: 0.3 | Z26: 75 | AA26: 340.585 | AB26: 248.205 | AC26: 164.9 | AD26: 345.965 | AE26: 266.55 | AF26: 144.265 | AG26: 71.69 | AH26: =SUM(C26:AG26) -> 3331.813
A27: Abril | B27: =SUM(AH27) -> 2053.37 | I27: 306.685 | J27: 190.075 | K27: 269.69 | L27: 234.807 | M27: 0.05 | N27: 256.195 | Y27: 5.285 | Z27: 40.86 | AA27: 223.705 | AB27: 49.492 | AC27: 232.166 | AD27: 79.905 | AE27: 144.805 | AF27: 19.65 | AH27: =SUM(C27:AG27) -> 2053.37
A28: Mayo | B28: =SUM(AH28) -> 1762.262 | E28: 0.03 | F28: 24.195 | G28: 115.11 | H28: 205.497 | I28: 74.945 | K28: 210.698 | S28: 0.02 | Y28: 574.3 | AA28: 107.922 | AC28: 67.305 | AE28: 290.505 | AG28: 91.735 | AH28: =SUM(C28:AG28) -> 1762.262 | AQ28: X|
A29: Junio | B29: =SUM(AH29) -> 355.372 | F29: 32.665 | G29: 15.31 | L29: 7.422 | N29: 56.295 | U29: 43.25 | W29: 69.995 | Y29: 45.085 | Z29: 85.35 | AH29: =SUM(C29:AG29) -> 355.372
A30: Julio | B30: =SUM(AH30) -> 283.021 | T30: 1.439 | U30: 104.49 | W30: 159.682 | AC30: 0.08 | AG30: 17.33 | AH30: =SUM(C30:AG30) -> 283.021
A31: Agosto | B31: =SUM(AH31) -> 0.02 | V31: 0.02 | AH31: =SUM(C31:AG31) -> 0.02
A32: Septiembre | B32: =SUM(AH32) -> 28.1 | G32: 0.01 | AB32: 24.635 | AC32: 3.055 | AF32: 0.4 | AH32: =SUM(C32:AG32) -> 28.1
A33: Octubre | B33: =SUM(AH33) -> 6174.975 | H33: 368.61 | I33: 354.205 | J33: 298.16 | K33: 249.7 | L33: 271.62 | M33: 256.83 | Q33: 273.65 | R33: 497.555 | S33: 374.965 | T33: 350.8 | U33: 468.547 | AA33: 0.04 | AC33: 507.27 | AD33: 540.833 | AE33: 395.25 | AF33: 403.49 | AG33: 563.45 | AH33: =SUM(C33:AG33) -> 6174.975
A34: Noviembre | B34: =SUM(AH34) -> 6845.26 | C34: 343.81 | D34: 310.175 | E34: 507.795 | F34: 37.76 | G34: 274.95 | H34: 274.335 | I34: 140.585 | L34: 16.755 | M34: 160.095 | N34: 380.785 | O34: 459.81 | P34: 408.3 | Q34: 384.78 | R34: 104.85 | S34: 228.405 | T34: 303.105 | U34: 313.98 | V34: 127.69 | W34: 314.665 | X34: 92.22 | Y34: 88.66 | Z34: 113.725 | AA34: 355.765 | AB34: 221.18 | AC34: 514.83 | AD34: 166.41 | AE34: 69.835 | AF34: 130.005 | AH34: =SUM(C34:AG34) -> 6845.26
A35: Diciembre | B35: =SUM(AH35) -> 3183.271 | C35: 186.02 | D35: 37.525 | E35: 259.21 | F35: 548.228 | G35: 313.577 | I35: 71.63 | J35: 294.631 | K35: 351.2 | L35: 129.79 | M35: 0.03 | N35: 37.405 | P35: 295.07 | Q35: 195.57 | R35: 215.445 | S35: 215.9 | T35: 6.585 | U35: 25.455 | AH35: =SUM(C35:AG35) -> 3183.271
A36: TOTAL | B36: =SUM(B23:B35) -> 24018.544 | C36: 0 | D36: 0 | E36: 0 | F36: 0 | G36: 0 | H36: 0 | I36: 0 | J36: 0 | K36: 0 | L36: 0 | M36: 0 | N36: 0 | O36: 0 | P36: 0 | Q36: 0 | R36: 0 | S36: 0 | T36: 0 | U36: 0 | V36: 0 | W36: 0 | X36: 0 | Y36: 0 | Z36: 0 | AA36: 0 | AB36: 0 | AC36: 0 | AD36: 0 | AE36: 0 | AF36: 0 | AG36: 0 | AH36: =SUM(AH24:AH35) -> 24018.544
A38: III Región, de Atacama
A39: Mes | B39: Total mes | C39: 1 | D39: 2 | E39: 3 | F39: 4 | G39: 5 | H39: 6 | I39: 7 | J39: 8 | K39: 9 | L39: 10 | M39: 11 | N39: 12 | O39: 13 | P39: 14 | Q39: 15 | R39: 16 | S39: 17 | T39: 18 | U39: 19 | V39: 20 | W39: 21 | X39: 22 | Y39: 23 | Z39: 24 | AA39: 25 | AB39: 26 | AC39: 27 | AD39: 28 | AE39: 29 | AF39: 30 | AG39: 31 | AH39: TOTAL | AI39: Xc | AJ39: =(B52/COUNTIF($C$40:$AG$51,">0")) -> 111.4973
A40: Enero | B40: =+AH40 -> 258.606 | C40: 0 | D40: 0 | E40: 0 | F40: 0 | G40: 0 | H40: 0 | I40: 0 | J40: 0 | K40: 0 | L40: 0 | M40: 0 | N40: 0 | O40: 0 | P40: 0 | Q40: 0 | R40: 0 | S40: 0 | T40: 0 | U40: 0 | V40: 0 | W40: 0 | X40: 0 | Y40: 22.381 | Z40: 25.365 | AA40: 0 | AB40: 0 | AC40: 0 | AD40: 0 | AE40: 0 | AF40: 14 | AG40: 196.86 | AH40: =SUM(C40:AG40) -> 258.606 | AJ40: =+'Res. Global'!J11 -> 5660.292
A41: Febrero | B41: =+AH41 -> 695.36 | C41: 7.765 | D41: 16.8 | E41: 0 | F41: 14.244 | G41: 0 | H41: 0 | I41: 0 | J41: 0 | K41: 0 | L41: 0 | M41: 0 | N41: 0 | O41: 0 | P41: 0 | Q41: 0 | R41: 0 | S41: 0 | T41: 0 | U41: 0 | V41: 0 | W41: 0 | X41: 0 | Y41: 74.13 | Z41: 233.106 | AA41: 210.285 | AB41: 0 | AC41: 94.08 | AD41: 44.95 | AH41: =SUM(C41:AG41) -> 695.36 | AJ41: =+AJ40/AJ39 -> 50.766182
A42: Marzo | B42: =+AH42 -> 4278.602 | C42: 240.81 | D42: 136.7 | E42: 146.743 | F42: 0 | G42: 0 | H42: 7.946 | I42: 0 | J42: 99.726 | K42: 551.981 | L42: 82.14 | M42: 0 | N42: 66.465 | O42: 175.506 | P42: 297.395 | Q42: 208.031 | R42: 0 | S42: 156.06 | T42: 148.307 | U42: 258.815 | V42: 13.745 | W42: 59.383 | X42: 33.36 | Y42: 5.04 | Z42: 0 | AA42: 39.765 | AB42: 30.975 | AC42: 640.435 | AD42: 538.795 | AE42: 204.954 | AF42: 50.35 | AG42: 85.175 | AH42: =SUM(C42:AG42) -> 4278.602
...

Sheet Resumen RAE S.Común
A2: Resumen RAE Sardina común 2014
A5: V Región, de Valparaíso
A7: Organización | B7: Periodo | C7: Cuota asignada (t) | D7: TRASPASOS | E7: Cuota efectiva (t) | F7: Desembarque (t) | G7: Saldo (t) | H7: Saldo % | I7: Fecha de Cierre
A8: A.G. Armadores Artesanales San Antonio R.A.G. 2510 | B8: Ene-Abr | C8: =4445+1540 -> 5985 | E8: =+C8+D8 -> 5985 | F8: =+SUM('RAE S.común'!B8:B11) -> 6061.911 | G8: =+E8-F8 -> -76.911 | H8: =+G8/E8 -> -0.012850627 | I8: 21 03 2014 / 07 04 2014 24-04-2014 02-05-2014
A9: Pescadores artesanales no afiliados | B9: Ene-Abr | C9: 1278 | E9: =+C9+D9 -> 1278 | F9: =+SUM('RAE S.común'!B24:B27) -> 1255.841 | G9: =+E9-F9 -> 22.159 | H9: =+G9/E9 -> 0.017338811
A10: Total | B10: Ene-Abr | C10: =SUM(C8:C9) -> 7263 | E10: =SUM(E8:E9) -> 7263 | F10: =SUM(F8:F9) -> 7317.752 | G10: =+E10-F10 -> -54.752
A12: Organización | B12: Periodo | C12: Cuota asignada (t) | E12: Cuota efectiva (t) | F12: Desembarque (t) | G12: Saldo (t) | H12: Saldo % | I12: Fecha de Cierre
A13: A.G. Armadores Artesanales San Antonio R.A.G. 2510 | B13: May-Ago | C13: =165+821 -> 986 | E13: =+C13+G8+D13 -> 909.089 | F13: =+SUM('RAE S.común'!B12:B15) -> 633.835 | G13: =+E13-F13 -> 275.254 | H13: =+G13/E13 -> 0.30278004 | I13: Apertura 23 05 2014 | J13: Apertura
A14: Pescadores artesanales no afiliados | B14: May-Ago | C14: =150+757 -> 907 | E14: =+C14+G9+D14 -> 929.159 | F14: =+SUM('RAE S.común'!B28:B31) -> 1807.874 | G14: =+E14-F14 -> -878.715 | H14: =+G14/E14 -> -0.94571005 | I14: 41771
A15: Total | B15: May-Ago | C15: =SUM(C13:C14) -> 1893 | E15: =+C15+G10 -> 1838.248 | F15: =SUM(F13:F14) -> 2441.709 | G15: =+E15-F15 -> -603.461
A17: Organización | B17: Periodo | C17: Cuota asignada (t) | E17: Cuota efectiva (t) | F17: Desembarque (t) | G17: Saldo (t) | H17: Saldo % | I17: 2
A18: A.G. Armadores Artesanales San Antonio R.A.G. 2510 | B18: Sep-Dic | C18: 83 | E18: =+C18+G13+D18 -> 358.254 | F18: =+SUM('RAE S.común'!B16:B19) -> 293.56 | G18: =+E18-F18 -> 64.694 | H18: =+G18/E18 -> 0.18058138 | K18: =+J18-135 -> -135
A19: Pescadores artesanales no afiliados | B19: Sep-Dic | C19: 75 | E19: =+C19+G14+D19 -> -803.715 | F19: =+SUM('RAE S.común'!B32:B35) -> 0 | G19: =+E19-F19 -> -803.715 | H19: =+G19/E19 -> 1
A20: Total | B20: Sep-Dic | C20: =SUM(C18:C19) -> 158 | E20: =+C20+G15 -> -445.461 | F20: =SUM(F18:F19) -> 293.56 | G20: =+E20-F20 -> -739.021
A22: VII Región, deL Maule
A24: Organización | B24: Periodo | C24: Cuota asignada (t) | D24: TRASPASOS | E24: Cuota efectiva (t) | F24: Desembarque (t) | G24: Saldo (t) | H24: Saldo % | I24: Fecha de Cierre
A25: STI:.de Pescadores "Pelágicos del Maule" Constitución, R.S.U. N° 07050150 | B25: Ene-Abr | C25: 1478.606 | E25: =+C25+D25 -> 1478.606 | F25: =+SUM('RAE S.común'!B41:B44) -> 1039.118 | G25: =+E25-F25 -> 439.488 | H25: =+G25/E25 -> 0.29723131
A26: STI. AGUA LIMPIA RSU. N° 07050118 | B26: Ene-Abr | C26: 17.143 | E26: =+C26+D26 -> 17.143 | F26: =+SUM('RAE S.común'!B57:B60) -> 0 | G26: =+E26-F26 -> 17.143 | H26: =+G26/E26 -> 1
A27: Cuota Residual | B27: Ene-Abr | C27: 91.251 | E27: =+C27 -> 91.251 | F27: =+SUM('RAE S.común'!B73:B76) -> 0 | G27: =+E27-F27 -> 91.251 | H27: =G27/E27 -> 1
A28: Total | B28: Ene-Abr | C28: =SUM(C25:C27) -> 1587 | E28: =SUM(E25:E27) -> 1587 | F28: =SUM(F25:F27) -> 1039.118 | G28: =+E28-F28 -> 547.882
A30: Organización | B30: Periodo | C30: Cuota asignada (t) | E30: Cuota efectiva (t) | F30: Desembarque (t) | G30: Saldo (t) | H30: Saldo % | I30: Fecha de Cierre
A31: STI:.de Pescadores "Pelágicos del Maule" Constitución, R.S.U. N° 07050150 | B31: May-Ago | C31: 211.254 | E31: =+C31+G25 -> 650.742 | F31: =+SUM('RAE S.común'!B45:B48) -> 311.153 | G31: =+E31-F31 -> 339.589 | H31: =+G31/E31 -> 0.5218489
A32: STI. AGUA LIMPIA RSU. N° 07050118 | B32: May-Ago | C32: 2.016 | E32: =+C32+G26 -> 19.159 | F32: =+SUM('RAE S.común'!B61:B64) -> 0 | G32: =+E32-F32 -> 19.159 | H32: =+G32/E32 -> 1
A33: Cuota Residual | B33: May-Ago | C33: 10.73 | E33: =+C33+G27 -> 101.981 | F33: =+SUM('RAE S.común'!B77:B80) -> 0 | G33: =+E33-F33 -> 101.981 | H33: =+G33/E33 -> 1
A34: Total | B34: May-Ago | C34: =SUM(C31:C33) -> 224 | E34: =+C34+G28 -> 771.882 | F34: =SUM(F31:F33) -> 311.153 | G34: =+E34-F34 -> 460.729
A36: Organización | B36: Periodo | C36: Cuota asignada (t) | E36: Cuota efectiva (t) | F36: Desembarque (t) | G36: Saldo (t) | H36: Saldo % | I36: Fecha de Cierre
A37: STI:.de Pescadores "Pelágicos del Maule" Constitución, R.S.U. N° 07050150 | B37: Sep-Dic | C37: 105.627 | E37: =+C37+G31 -> 445.216 | F37: =+SUM('RAE S.común'!B49:B52) -> 145.198 | G37: =+E37-F37 -> 300.018 | H37: =+G37/E37 -> 0.67387066
A38: STI. AGUA LIMPIA RSU. N° 07050118 | B38: Sep-Dic | C38: 1.008 | E38: =+C38+G32 -> 20.167 | F38: =+SUM('RAE S.común'!B65:B68) -> 0 | G38: =+E38-F38 -> 20.167 | H38: =+G38/E38 -> 1
A39: Cuota Residual | B39: Sep-Dic | C39: 5.365 | E39: =+C39+G33 -> 107.346 | F39: =+SUM('RAE S.común'!B81:B84) -> 207.631 | G39: =+E39-F39 -> -100.285 | H39: =+G39/E39 -> -0.93422205
A40: Total | B40: Sep-Dic | C40: =SUM(C37:C39) -> 112 | E40: =+C40+G34 -> 572.729 | F40: =SUM(F37:F39) -> 352.829 | G40: =+E40-F40 -> 219.9
K41: elemn
A42: VIII Región, del Bio Bio | L42: insertar aquí
A43: Organización | B43: Periodo | C43: Cuota asignada (t) | D43: traspaso | E43: Cuota efectiva (t) | F43: Desembarque (t) | G43: Saldo (t) | H43: Saldo % | I43: Fecha de Cierre | L43: desembarque
A44: Agrupación de Armadores y Pescadores Pelágicos de Caleta Tubul, Registro de Organización Comunitaria Funcional 478-2007 | B44: Ene-Ago | C44: 793 | E44: =+C44+D44 -> 793 | F44: =26.06+80.32+2.64+13.47+60.18+62.4+68.32+62.59-14.64+14.2+13.75+41.69+49.2+52.25+28.42+0.004+67.485+15.116+59.944 -> 703.399 | G44: =+E44-F44 -> 89.601 | H44: =+G44/E44 -> 0.11298991 | J44: 1 | K44: =+L44-F44 -> 0 | L44: 703.399
A45: ¿+¿ | B45: Ene-Ago | C45: 3232 | E45: =+C45+D45 -> 3232 | F45: =66.7+132.89+139.53+317.27+131.42+124.59+217.06+165.52+118.91+41.5+125.44+16.1+44.52+61.28+56.93+33.78+17.1+14.14+33.63+70.19+58.16+37.35+33.83+0.005+17.18+76.635+50.13+81.701+62.726+19.671+27.16+37.561 -> 2430.609 | G45: =+E45-F45 -> 801.391 | H45: =+G45/E45 -> 0.24795514 | J45: 2 | K45: =+L45-F45 -> 0 | L45: 2430.609
A46: Asociación de Armadores, Pescadores Artesanales y Actividades Afines de la Octava Región, Asociación Gremial ARPESCA A.G., R.A.G. 429-8 | B46: Ene-Ago | C46: 3211 | E46: =+C46+D46 -> 3211 | F46: =75.64+218.34+202+75.94+223.33+162.33+157.11+202.975+275.64+379.78+95.073+138.105+55.099+325.805+5.748+142.989+0.379-1015.993+79.555+94.191+59.899+4.333-224.423+63.395+185.77-262.72+55.967+137.515+42.334+80.024+58.545+75.33+52.45+73.89+46.163+12.33 -> 2354.838 | G46: =+E46-F46 -> 856.162 | H46: =+G46/E46 -> 0.26663407 | J46: 3 | K46: =+L46-F46 -> 0 | L46: 2354.838
A47: A.G. Armadores Artesanales Pelágico Coronel-Lota del Bío Bío, ARPES BIO BIO A.G., R.A.G. 445-8 | B47: Ene-Ago | C47: 12788 | E47: =+C47+D47 -> 12788 | F47: =549.765+380.877+1537.52+525.261+510.651+289.205+496.982+256.641+425.861+866.656+341.482+666.301+139.62+317.984+78.965+418.51+25.187+76.592+65.529+21.216+37.063+2.686+244.985+7.782+155.609+83.246+240.9+29.252+127.622+2.95+180.025+69.082+103.15+194.216+108.393+71.969+28.09+168.318+163.197+136.314+154.443+458.926+455.271+65.018+203.58+97.495+29.878 -> 11610.265 | G47: =+E47-F47 -> 1177.735 | H47: =+G47/E47 -> 0.092096888 | I47: 22 07 2014 | J47: 4 | K47: =+L47-F47 -> 0 | L47: 11610.265
A48: A.G. Armadores y Pescadores Artesanales, SIARPAR A.G., R.A.G. 448-8 | B48: Ene-Ago | C48: 0 | E48: =+C48+D48 -> 0 | G48: =+E48-F48 -> 0 | H48: =+G48/E48 -> #DIV/0! | J48: 5 | K48: =+L48-F48 -> 0 | L48: 0
A49: A.G. de Armadores Artesanales - ARMAR A.G., R.A.G. 384-8 | B49: Ene-Ago | C49: 9563 | E49: =+C49+D49 -> 9563 | F49: =533.136+193.789+1040.699+403.043+426.534+77.018+804.11+290.23+566.914+405.198+207.062+113.495+81.297+380.011+81.517+95.824+0.947+58.975+130.696+37.293+17.043+79.438+2.996+132.63+0.116+63.505+226.241+71.7+83.88+95.245+5.105+64.29+4.65+94.49+9.516+50.125+20.258+332.544+298.808+36.123+7.946+4.116+52.555 -> 7681.108 | G49: =+E49-F49 -> 1881.892 | H49: =+G49/E49 -> 0.19678887 | J49: 6 | K49: =+L49-F49 -> 0 | L49: 7681.108
A50: A.G. de Armadores Artesanales y Productores Pelágicos de la Caleta el Morro de Talcahuano - AGEMAPAR, R.A.G. 376-8 | B50: Ene-Ago | C50: 8995 | E50: =+C50+D50 -> 8995 | F50: =207.324+463.102+4.267+84.782+325.155+348.317+1195.332+150.691+272.8+213.507+245.91+323.319+229.24+503.062+201.693+249.909+69.525+5.323+89.005+106.881+3.524+127.225+9.382+148.281+76.531+5.359+105.073+12.723+167.449+31.771+103.691+37.063+3.992+15.667+86.135+1.34+3.388+65.08+108.174+312.633+95.822+143.301+35.013+53.003+81.272+40.641+100.941+191.937+142.441+204.046-29.415+95.767+304.369+139.064+42.352+41.185 -> 8395.364 | G50: =+E50-F50 -> 599.636 | H50: =+G50/E50 -> 0.066663257 | J50: 7 | K50: =+L50-F50 -> 0 | L50: 8395.364
...

Sheet RAE S.común
A2: RAE Sardina común 2014
A4: V región | AI4: Promedio Consumo Anual Flota
A6: V Región A.G. Armadores artesanales del Puerto de San Antonio R.A.G. N° 2510
A7: Mes | B7: Total mes | C7: 1 | D7: 2 | E7: 3 | F7: 4 | G7: 5 | H7: 6 | I7: 7 | J7: 8 | K7: 9 | L7: 10 | M7: 11 | N7: 12 | O7: 13 | P7: 14 | Q7: 15 | R7: 16 | S7: 17 | T7: 18 | U7: 19 | V7: 20 | W7: 21 | X7: 22 | Y7: 23 | Z7: 24 | AA7: 25 | AB7: 26 | AC7: 27 | AD7: 28 | AE7: 29 | AF7: 30 | AG7: 31 | AH7: TOTAL | AI7: Xc | AJ7: =(B20/COUNTIF($C$8:$AG$19,">0")) -> 225.46148
A8: Enero | B8: =+AH8 -> 0 | C8: VEDA | D8: VEDA | E8: VEDA | F8: VEDA | G8: VEDA | H8: VEDA | I8: VEDA | J8: VEDA | K8: VEDA | L8: VEDA | M8: VEDA | N8: VEDA | O8: VEDA | P8: VEDA | Q8: VEDA | R8: VEDA | S8: VEDA | T8: VEDA | U8: VEDA | V8: VEDA | W8: VEDA | X8: VEDA | Y8: VEDA | Z8: VEDA | AA8: VEDA | AB8: VEDA | AC8: VEDA | AD8: VEDA | AE8: VEDA | AF8: VEDA | AG8: VEDA | AH8: =SUM(C8:AG8) -> 0 | AJ8: =+'Resumen RAE S.Común'!G18 -> 64.694
A9: Febrero | B9: =+AH9 -> 0 | C9: VEDA | D9: VEDA | E9: VEDA | F9: VEDA | G9: VEDA | H9: VEDA | I9: VEDA | J9: VEDA | K9: VEDA | L9: VEDA | M9: VEDA | N9: VEDA | O9: VEDA | P9: VEDA | Q9: VEDA | R9: VEDA | S9: VEDA | T9: VEDA | U9: VEDA | V9: VEDA | W9: VEDA | X9: VEDA | Y9: VEDA | Z9: VEDA | AA9: VEDA | AB9: VEDA | AC9: VEDA | AD9: VEDA | AE9: VEDA | AF9: VEDA | AG9: VEDA | AH9: =SUM(C9:AG9) -> 0 | AJ9: =+AJ8/AJ7 -> 0.28694036
A10: Marzo | B10: =+AH10 -> 2657.14 | C10: VEDA | D10: VEDA | E10: VEDA | F10: VEDA | G10: VEDA | M10: 41.815 | N10: 265.124 | O10: 806.862 | Q10: 97.765 | R10: 42.358 | S10: 39.955 | T10: 286.196 | U10: 328.553 | V10: 443.523 | W10: 234.29 | AE10: 51.008 | AG10: 19.691 | AH10: =SUM(C10:AG10) -> 2657.14
A11: Abril | B11: =+AH11 -> 3404.771 | C11: 31.133 | D11: 0 | E11: 94.94 | F11: 178.438 | G11: 55.207 | H11: 185.173 | I11: 93.437 | J11: 0 | K11: 0 | L11: 0 | M11: 0 | N11: 0 | O11: 0 | P11: 0 | Q11: 0 | R11: 0 | S11: 0 | T11: 0 | U11: 0 | V11: 0 | W11: 19.693 | X11: 684.01 | Y11: 555.35 | Z11: 0 | AA11: 0 | AB11: 209.99 | AC11: 534.265 | AD11: 0 | AE11: 0 | AF11: 763.135 | AG11: 0 | AH11: =SUM(C11:AG11) -> 3404.771
A12: Mayo | B12: =+AH12 -> 633.835 | C12: 503.375 | D12: 130.46 | AH12: =SUM(C12:AG12) -> 633.835
A13: Junio | B13: =+AH13 -> 0 | AH13: =SUM(C13:AG13) -> 0
A14: Julio | B14: =+AH14 -> 0 | AF14: veda | AG14: veda | AH14: =SUM(C14:AG14) -> 0
A15: Agosto | B15: =+AH15 -> 0 | C15: veda | D15: veda | E15: veda | F15: veda | G15: veda | H15: veda | I15: veda | J15: veda | K15: veda | L15: veda | M15: veda | N15: veda | O15: veda | P15: veda | Q15: veda | R15: veda | S15: veda | T15: veda | U15: veda | V15: veda | W15: veda | X15: veda | Y15: veda | Z15: veda | AA15: veda | AB15: veda | AC15: veda | AD15: veda | AE15: veda | AF15: veda | AG15: veda | AH15: =SUM(C15:AG15) -> 0
A16: Septiembre | B16: =+AH16 -> 0 | C16: veda | D16: veda | E16: veda | F16: veda | G16: veda | H16: veda | I16: veda | J16: veda | K16: veda | L16: veda | M16: veda | N16: veda | O16: veda | P16: veda | Q16: veda | R16: veda | S16: veda | T16: veda | U16: veda | V16: veda | W16: veda | X16: veda | Y16: veda | Z16: veda | AA16: veda | AB16: veda | AC16: veda | AD16: veda | AE16: veda | AF16: veda | AG16: veda | AH16: =SUM(C16:AG16) -> 0
A17: Octubre | B17: =+AH17 -> 0 | C17: veda | D17: veda | E17: veda | F17: veda | G17: veda | H17: veda | I17: veda | J17: veda | K17: veda | L17: veda | M17: veda | N17: veda | O17: veda | P17: veda | Q17: veda | R17: veda | S17: veda | T17: veda | U17: veda | V17: veda | W17: veda | AH17: =SUM(C17:AG17) -> 0
