Workbook

Sheet Resumen
A2: Resumen Artesanal por unidad de pesquería, 2013
A3: 15 de enero 2014
A4: Recurso | B4: Unidad de pesquería | C4: Cuota Global (t) | D4: Desembarque total (t) | E4: Saldo total (t) | F4: % consumido 2013 | G4: % consumido 2012 | H4: % consumido 2011
A5: Jurel | B5: NACIONAL | C5: =+SUM(Global!C17+Global!C18+Global!C19+Global!C22+Global!C23+Global!C24+Global!C25) -> 9669 | D5: =+SUM(Global!D17+Global!D18+Global!D19+Global!D22+Global!D23+Global!D24+Global!D25) -> 7979.595 | E5: =+C5-D5 -> 1689.405 | F5: =+D5/C5 -> 0.82527614
B6: RAE | C6: =+(Global!C20+Global!C21+Global!C26+Global!C27) -> 7855.149 | D6: =+(Global!D20+Global!D21+Global!D26+Global!D27) -> 4306.038 | E6: =+C6-D6 -> 3549.111 | F6: =+D6/C6 -> 0.54818031
A7: Anchoveta | B7: NACIONAL | C7: =+SUM(Global!C6+Global!C7+Global!C8+Global!C11+Global!C14) -> 146751 | D7: =+SUM(Global!D6+Global!D7+Global!D8+Global!D11+Global!D14) -> 129237.75 | E7: =+C7-D7 -> 17513.251 | F7: =+D7/C7 -> 0.88066009
B8: RAE | C8: =+SUM(Global!C9+Global!C10+Global!C12+Global!C13+Global!C15+Global!C16) -> 72657 | D8: =+SUM(Global!D9+Global!D10+Global!D12+Global!D13+Global!D15+Global!D16) -> 39264.495 | E8: =+C8-D8 -> 33392.505 | F8: =+D8/C8 -> 0.54040898
A9: Sardina común | B9: NACIONAL | C9: =+SUM(Global!C32+Global!C35) -> 8293 | D9: =+SUM(Global!D32+Global!D35) -> 8139.576 | E9: =+C9-D9 -> 153.424 | F9: =+D9/C9 -> 0.98149958
B10: RAE | C10: =+SUM(Global!C31+Global!C33+Global!C34+Global!C36+Global!C37) -> 448730 | D10: =+SUM(Global!D31+Global!D33+Global!D34+Global!D36+Global!D37) -> 167086.37 | E10: =+C10-D10 -> 281643.64 | F10: =+D10/C10 -> 0.3723539
A11: Sardina española | B11: NACIONAL | C11: =+SUM(Global!C28:C30) -> 3105 | D11: =+SUM(Global!D28:D30) -> 58.008 | E11: =+C11-D11 -> 3046.992 | F11: =+D11/C11 -> 0.018682126
B12: RAE
A13: Sardina Austral | B13: NACIONAL | C13: =+SUM(Global!C38:C39) -> 28589.75 | D13: =+SUM(Global!D38:D39) -> 27636.639 | E13: =+C13-D13 -> 953.111 | F13: =+D13/C13 -> 0.96666249
B14: RAE

Sheet Global
A2: Resumen Global Cuotas Artesanales 2013
A3: 15 de enero 2014
A5: Recurso | B5: Unidad de pesquería | C5: Cuota Global (t) | D5: Desembarque total (t) | E5: Saldo total (t) | F5: % consumido 2013 | G5: % consumido 2012
A6: Anchoveta | B6: XV y I | C6: =+'Res. Global'!C7 -> 93183 | D6: =+'Res. Global'!H7 -> 92456.686 | E6: =+C6-D6 -> 726.314 | F6: =+D6/C6 -> 0.99220551
A7: Anchoveta | B7: II | C7: =+'Res. Global'!C9 -> 32183 | D7: =+'Res. Global'!H9 -> 19670.587 | E7: =+C7-D7 -> 12512.413 | F7: =+D7/C7 -> 0.61121048
A8: Anchoveta | B8: III | C8: =+'Res. Global'!C11 -> 20225 | D8: =+'Res. Global'!H11 -> 16881.181 | E8: =+C8-D8 -> 3343.819 | F8: =+D8/C8 -> 0.83466902
A9: Anchoveta | B9: IV RAE | C9: =+'Res. Global'!C13 -> 8669 | D9: =+'Res. Global'!H13 -> 7681.935 | E9: =+C9-D9 -> 987.065 | F9: =+D9/C9 -> 0.88613854
A10: Anchoveta | B10: V RAE | C10: =+'Res. Global'!C15 -> 5630 | D10: =+'Res. Global'!H15 -> 4449.991 | E10: =+C10-D10 -> 1180.009 | F10: =+D10/C10 -> 0.79040693
A11: Anchoveta | B11: VI | C11: =+'Res. Global'!C18 -> 36 | D11: =+'Res. Global'!H18 -> 0 | E11: =+C11-D11 -> 36 | F11: =+D11/C11 -> 0
A12: Anchoveta | B12: VII RAE | C12: =+'Res. Global'!C21 -> 602 | D12: =+'Res. Global'!H21 -> 812.188 | E12: =+C12-D12 -> -210.188 | F12: =+D12/C12 -> 1.3491495
A13: Anchoveta | B13: VIII RAE | C13: =+'Res. Global'!C24 -> 46810 | D13: =+'Res. Global'!H24 -> 22975.721 | E13: =+C13-D13 -> 23834.279 | F13: =+D13/C13 -> 0.49082933
A14: Anchoveta | B14: IX | C14: =+'Res. Global'!C26 -> 1124 | D14: =+'Res. Global'!H26 -> 229.295 | E14: =+C14-D14 -> 894.705 | F14: =+D14/C14 -> 0.20399911
A15: Anchoveta | B15: XIV RAE | C15: =+'Res. Global'!C29 -> 6773 | D15: =+'Res. Global'!H29 -> 2751.116 | E15: =+C15-D15 -> 4021.884 | F15: =+D15/C15 -> 0.40618869
A16: Anchoveta | B16: X RAE | C16: =+'Res. Global'!C32 -> 4173 | D16: =+'Res. Global'!H32 -> 593.544 | E16: =+C16-D16 -> 3579.456 | F16: =+D16/C16 -> 0.14223436
A17: Jurel | B17: XV y I | C17: =+'Res. Global'!C34 -> 916.5 | D17: =+'Res. Global'!H34 -> 7.148 | E17: =+C17-D17 -> 909.352 | F17: =+D17/C17 -> 0.0077992362
A18: Jurel | B18: II | C18: =+'Res. Global'!C36 -> 916.5 | D18: =+'Res. Global'!H36 -> 93.63 | E18: =+C18-D18 -> 822.87 | F18: =+D18/C18 -> 0.10216039
A19: Jurel | B19: III | C19: =+'Res. Global'!C38 -> 2282 | D19: =+'Res. Global'!H38 -> 2180.255 | E19: =+C19-D19 -> 101.745 | F19: =+D19/C19 -> 0.95541411
A20: Jurel | B20: IV RAE | C20: =+'Res. Global'!C40 -> 5443 | D20: =+'Res. Global'!H40 -> 3868.093 | E20: =+C20-D20 -> 1574.907 | F20: =+D20/C20 -> 0.7106546
A21: Jurel | B21: V RAE | C21: =+'Res. Global'!C42 -> 1358 | D21: =+'Res. Global'!H42 -> 72.689 | E21: =+C21-D21 -> 1285.311 | F21: =+D21/C21 -> 0.05352651
A22: Jurel | B22: VI | C22: =+'Res. Global'!C44 -> 10 | D22: =+'Res. Global'!H44 -> 0.789 | E22: =+C22-D22 -> 9.211 | F22: =+D22/C22 -> 0.0789
A23: Jurel | B23: VII | C23: =+'Res. Global'!C46 -> 82 | D23: =+'Res. Global'!H46 -> 54.193 | E23: =+C23-D23 -> 27.807 | F23: =+D23/C23 -> 0.66089024
A24: Jurel | B24: VIII | C24: =+'Res. Global'!C48 -> 5342 | D24: =+'Res. Global'!H48 -> 5643.58 | E24: =+C24-D24 -> -301.58 | F24: =+D24/C24 -> 1.0564545
A25: Jurel | B25: IX | C25: =+'Res. Global'!C50 -> 120 | D25: =+'Res. Global'!H50 -> 0 | E25: =+C25-D25 -> 120 | F25: =+D25/C25 -> 0
A26: Jurel | B26: XIV RAE | C26: =+'Res. Global'!C52 -> 252.15 | D26: =+'Res. Global'!H52 -> 15.411 | E26: =+C26-D26 -> 236.739 | F26: =+D26/C26 -> 0.061118382
A27: Jurel | B27: X RAE | C27: =+'Res. Global'!C54 -> 801.999 | D27: =+'Res. Global'!H54 -> 349.845 | E27: =+C27-D27 -> 452.154 | F27: =+D27/C27 -> 0.43621625
A28: Sardina española | B28: XV y I | C28: =+'Res. Global'!C56 -> 518 | D28: =+'Res. Global'!H56 -> 4.006 | E28: =+C28-D28 -> 513.994 | F28: =+D28/C28 -> 0.0077335907
A29: Sardina española | B29: II | C29: =+'Res. Global'!C58 -> 1962 | D29: =+'Res. Global'!H58 -> 53.085 | E29: =+C29-D29 -> 1908.915 | F29: =+D29/C29 -> 0.027056575
A30: Sardina española | B30: III - IV | C30: =+'Res. Global'!C60 -> 625 | D30: =+'Res. Global'!H60 -> 0.917 | E30: =+C30-D30 -> 624.083 | F30: =+D30/C30 -> 0.0014672
A31: Sardina común | B31: V RAE | C31: =+'Res. Global'!C62 -> 6457 | D31: =+'Res. Global'!H62 -> 5201.972 | E31: =+C31-D31 -> 1255.028 | F31: =+D31/C31 -> 0.80563296
A32: Sardina común | B32: VI | C32: =+'Res. Global'!C65 -> 152 | D32: =+'Res. Global'!H65 -> 0 | E32: =+C32-D32 -> 152 | F32: =+D32/C32 -> 0
A33: Sardina común | B33: VII RAE | C33: =+'Res. Global'!C68 -> 2334 | D33: =+'Res. Global'!H68 -> 1865.37 | E33: =+C33-D33 -> 468.63 | F33: =+D33/C33 -> 0.79921594
A34: Sardina común | B34: VIII RAE | C34: =+'Res. Global'!C71 -> 363385 | D34: =+'Res. Global'!H71 -> 117644.16 | E34: =+C34-D34 -> 245740.84 | F34: =+D34/C34 -> 0.32374522
A35: Sardina común | B35: IX | C35: =+'Res. Global'!C73 -> 8141 | D35: =+'Res. Global'!H73 -> 8139.576 | E35: =+C35-D35 -> 1.424 | F35: =+D35/C35 -> 0.99982508
A36: Sardina común | B36: XIV RAE | C36: =+'Res. Global'!C76 -> 51867 | D36: =+'Res. Global'!H76 -> 38323.261 | E36: =+C36-D36 -> 13543.739 | F36: =+D36/C36 -> 0.7388756
A37: Sardina común | B37: X RAE | C37: =+'Res. Global'!C79 -> 24687 | D37: =+'Res. Global'!H79 -> 4051.606 | E37: =+C37-D37 -> 20635.394 | F37: =+D37/C37 -> 0.16411901
A38: Sardina Austral | B38: X | C38: =+'Res. Global'!C81 -> 21669.75 | D38: =+'Res. Global'!H81 -> 21816.878 | E38: =+C38-D38 -> -147.128 | F38: =+D38/C38 -> 1.0067896
A39: Sardina Austral | B39: XI | C39: =+'Res. Global'!C83 -> 6920 | D39: =+'Res. Global'!H83 -> 5819.761 | E39: =+C39-D39 -> 1100.239 | F39: =+D39/C39 -> 0.84100592
C42: =SUM(C6:C39) -> 725649.9 | D42: =SUM(D6:D39) -> 383708.47 | E42: =SUM(E6:E39) -> 341941.43
B43: XI dif. Cuota real | D43: =+D42/C42 -> 0.52877905
B44: total: | C44: =SUM(C42:C43) -> 725649.9

Sheet Res. Global
A2: Resumen por Periodo Cuota Artesanal 2013
A3: 15 de enero 2014
E5: Cuota (t) | G5: Desembarque (t) | I5: Saldo (t) | K5: Saldo % | M5: Fecha de Cierre
A6: Recurso | B6: Unidad de Pesquería | C6: Cuota Global (t) | D6: Período | E6: Asignada | F6: Efectiva | G6: Período | H6: Global | I6: Período | J6: Global | K6: Período | L6: Global
A7: Anchoveta | B7: XV y I | C7: =SUM(E7:E8) -> 93183 | D7: Ene - Jun | E7: 74009 | F7: =+E7 -> 74009 | G7: =+SUM(Anchoveta!AJ7:AJ12) -> 65828.751 | H7: =SUM(G7:G8) -> 92456.686 | I7: =+F7-G7 -> 8180.249 | J7: =C7-H7 -> 726.314 | K7: =1-G7/F7 -> 0.11053046 | L7: =1-H7/C7 -> 0.0077944904 | M7: 41404 | N7: Llega redistribucion de cuota
D8: Jul - Dic | E8: =11124+8050 -> 19174 | F8: =+E8+I7 -> 27354.249 | G8: =+SUM(Anchoveta!AJ13:AJ18) -> 26627.935 | I8: =+F8-G8 -> 726.314 | K8: =1-G8/F8 -> 0.026552146 | M8: 41548
A9: Anchoveta | B9: II | C9: =SUM(E9:E10) -> 32183 | D9: Ene - Jun | E9: 24137 | F9: =+E9 -> 24137 | G9: =+SUM(Anchoveta!B23:B29) -> 8307.274 | H9: =SUM(G9:G10) -> 19670.587 | I9: =+F9-G9 -> 15829.726 | J9: =C9-H9 -> 12512.413 | K9: =1-G9/F9 -> 0.65582823 | L9: =1-H9/C9 -> 0.38878952
D10: Jul - Dic | E10: 8046 | F10: =+E10+I9 -> 23875.726 | G10: =+SUM(Anchoveta!B30:B35) -> 11363.313 | I10: =+F10-G10 -> 12512.413 | K10: =1-G10/F10 -> 0.52406419
A11: Anchoveta | B11: III | C11: =SUM(E11:E12) -> 20225 | D11: Ene - oct | E11: 19214 | F11: =+E11 -> 19214 | G11: =+SUM(Anchoveta!B40:B49) -> 16878.236 | H11: =SUM(G11:G12) -> 16881.181 | I11: =+F11-G11 -> 2335.764 | J11: =C11-H11 -> 3343.819 | K11: =1-G11/F11 -> 0.12156573 | L11: =1-H11/C11 -> 0.16533098
C12: =SUM(E12:E13) -> 9247 | D12: Nov - Dic | E12: 1011 | F12: =+E12+I11 -> 3346.764 | G12: =+SUM(Anchoveta!B50:B51) -> 2.945 | H12: =SUM(G12:G13) -> 7584.713 | I12: =+F12-G12 -> 3343.819 | J12: =+C12-H12 -> 1662.287 | K12: =1-G12/F12 -> 0.99912005
A13: Anchoveta | B13: IV (RAE por Org) | C13: =SUM(E13:E14) -> 8669 | D13: Ene - oct | E13: 8236 | F13: =+E13 -> 8236 | G13: =+'Resumen RAE Anchoveta'!F10 -> 7581.768 | H13: =SUM(G13:G14) -> 7681.935 | I13: =+F13-G13 -> 654.232 | J13: =C13-H13 -> 987.065 | K13: =1-G13/F13 -> 0.079435648 | L13: =1-H13/C13 -> 0.11386146
C14: =SUM(E14:E16) -> 5782 | D14: Nov - Dic | E14: 433 | F14: =+E14+I13 -> 1087.232 | G14: =+'Resumen RAE Anchoveta'!F16 -> 100.167 | H14: =SUM(G14:G16) -> 4550.158 | I14: =+F14-G14 -> 987.065 | J14: =+C14-H14 -> 1231.842 | K14: =1-G14/F14 -> 0.90786971
A15: Anchoveta | B15: V (RAE por Org) | C15: =SUM(E15:E17) -> 5630 | D15: Ene-Abr | E15: 4786 | F15: =+E15 -> 4786 | G15: =+SUM('Resumen RAE Anchoveta'!F23) -> 4139.884 | H15: =SUM(G15:G17) -> 4449.991 | I15: =+F15-G15 -> 646.116 | J15: =+C15-H15 -> 1180.009 | K15: =1-G15/F15 -> 0.13500125 | L15: =1-H15/C15 -> 0.20959307
D16: May-Ago | E16: 563 | F16: =+E16+I15 -> 1209.116 | G16: =+SUM('Resumen RAE Anchoveta'!F28) -> 310.107 | I16: =+F16-G16 -> 899.009 | K16: =1-G16/F16 -> 0.74352585
D17: Sep-Dic | E17: 281 | F17: =+E17+I16 -> 1180.009 | G17: =+SUM('Resumen RAE Anchoveta'!F33) -> 0 | I17: =+F17-G17 -> 1180.009 | K17: =1-G17/F17 -> 1
A18: Anchoveta | B18: VI | C18: =SUM(E18:E20) -> 36 | D18: Ene-Abr | E18: 30 | F18: =+E18 -> 30 | G18: =+SUM(Anchoveta!B89:B92) -> 0 | H18: =SUM(G18:G20) -> 0 | I18: =+F18-G18 -> 30 | J18: =+C18-H18 -> 36 | K18: =1-G18/F18 -> 1 | L18: =1-H18/C18 -> 1
D19: May-Ago | E19: 4 | F19: =+E19+I18 -> 34 | G19: =+SUM(Anchoveta!B93:B96) -> 0 | I19: =+F19-G19 -> 34 | K19: =1-G19/F19 -> 1
D20: Sep-Dic | E20: 2 | F20: =+E20+I19 -> 36 | G20: =+SUM(Anchoveta!B97:B100) -> 0 | I20: =+F20-G20 -> 36 | K20: =1-G20/F20 -> 1
A21: Anchoveta | B21: VII (RAE por Org) | C21: =SUM(E21:E23) -> 602 | D21: Ene-Abr | E21: 512 | F21: =+E21 -> 512 | G21: =+SUM('Resumen RAE Anchoveta'!F41) -> 812.153 | H21: =SUM(G21:G23) -> 812.188 | I21: =+F21-G21 -> -300.153 | J21: =+C21-H21 -> -210.188 | K21: =1-G21/F21 -> -0.58623633 | L21: =1-H21/C21 -> -0.3491495 | M21: 18 04 2013
D22: May-Ago | E22: 60 | F22: =+E22+I21 -> -240.153 | G22: =+SUM('Resumen RAE Anchoveta'!F47) -> 0.035 | I22: =+F22-G22 -> -240.188 | K22: =1-G22/F22 -> 1.0001457
D23: Sep-Dic | E23: 30 | F23: =+E23+I22 -> -210.188 | G23: =+SUM('Resumen RAE Anchoveta'!F53) -> 0 | I23: =+F23-G23 -> -210.188 | K23: =1-G23/F23 -> 1
A24: Anchoveta | B24: VIII (RAE por Org) | C24: =SUM(E24:E25) -> 46810 | D24: Ene- Ago | E24: =44546-80 -> 44466 | F24: =+E24 -> 44466 | G24: =+SUM('Resumen RAE Anchoveta'!F121) -> 22443.054 | H24: =SUM(G24:G25) -> 22975.721 | I24: =+F24-G24 -> 22022.946 | J24: =+C24-H24 -> 23834.279 | K24: =1-G24/F24 -> 0.49527608 | L24: =1-H24/C24 -> 0.50917067
D25: Sep - Dic | E25: 2344 | F25: =+E25+I24 -> 24366.946 | G25: =+SUM('Resumen RAE Anchoveta'!F187) -> 532.667 | I25: =+F25-G25 -> 23834.279 | K25: =1-G25/F25 -> 0.97813977
A26: Anchoveta | B26: IX | C26: =SUM(E26:E28) -> 1124 | D26: Ene-Abr | E26: 956 | F26: =+E26 -> 956 | G26: =+SUM(Anchoveta!B138:B141) -> 182.223 | H26: =SUM(G26:G28) -> 229.295 | I26: =+F26-G26 -> 773.777 | J26: =+C26-H26 -> 894.705 | K26: =1-G26/F26 -> 0.80939017 | L26: =1-H26/C26 -> 0.79600089
D27: May-Ago | E27: 112 | F27: =+E27+I26 -> 885.777 | G27: =+SUM(Anchoveta!B142:B145) -> 5.8 | I27: =+F27-G27 -> 879.977 | K27: =1-G27/F27 -> 0.99345208
D28: Sep-Dic | E28: 56 | F28: =+E28+I27 -> 935.977 | G28: =+SUM(Anchoveta!B146:B149) -> 41.272 | I28: =+F28-G28 -> 894.705 | K28: =1-G28/F28 -> 0.9559049
A29: Anchoveta | B29: XIV (RAE por ORG) | C29: =SUM(E29:E31) -> 6773 | D29: Ene-Abr | E29: 5757 | F29: =+E29 -> 5757 | G29: =+SUM('Resumen RAE Anchoveta'!F209) -> 708.532 | H29: =SUM(G29:G31) -> 2751.116 | I29: =+F29-G29 -> 5048.468 | J29: =+C29-H29 -> 4021.884 | K29: =1-G29/F29 -> 0.87692687 | L29: =1-H29/C29 -> 0.59381131
D30: May-Ago | E30: 677 | F30: =+E30+I29 -> 5725.468 | G30: =+SUM('Resumen RAE Anchoveta'!F229) -> 1472.055 | I30: =+F30-G30 -> 4253.413 | K30: =1-G30/F30 -> 0.74289351
D31: Sep-Dic | E31: 339 | F31: =+E31+I30 -> 4592.413 | G31: =+SUM('Resumen RAE Anchoveta'!F249) -> 570.529 | I31: =+F31-G31 -> 4021.884 | K31: =1-G31/F31 -> 0.87576705
A32: Anchoveta | B32: X (RAE por Org) | C32: =SUM(E32:E33) -> 4173 | D32: Ene-Jun | E32: 3338 | F32: =+E32 -> 3338 | G32: =+SUM('Resumen RAE Anchoveta'!F266) -> 96.713 | H32: =SUM(G32:G33) -> 593.544 | I32: =+F32-G32 -> 3241.287 | J32: =+C32-H32 -> 3579.456 | K32: =1-G32/F32 -> 0.97102666 | L32: =1-H32/C32 -> 0.85776564
D33: Jul-Dic | E33: 835 | F33: =+E33+I32 -> 4076.287 | G33: =+SUM('Resumen RAE Anchoveta'!F281) -> 496.831 | I33: =+F33-G33 -> 3579.456 | K33: =1-G33/F33 -> 0.87811678 | T33: Jurel Nacional Artesanal
A34: JUREL | B34: XV y I | C34: =SUM(E34:E35) -> 916.5 | D34: Ene - Sep | E34: 870.5 | F34: =+E34 -> 870.5 | G34: =+SUM(Jurel!B7:B15) -> 0.856 | H34: =SUM(G34:G35) -> 7.148 | I34: =+F34-G34 -> 869.644 | J34: =+C34-H34 -> 909.352 | K34: =1-G34/F34 -> 0.99901666 | L34: =1-H34/C34 -> 0.99220076 | O34: XV I | P34: =+G34+G35 -> 7.148 | R34: Cd_Region | S34: Cd_Especie | T34: SumaDeNr_Toneladas | U34: Cd_Estado | V34: AÑO | W34: Cd_Zona
C35: =SUM(E35:E36) -> 916.5 | D35: Oct-Dic | E35: 46 | F35: =+E35+I34 -> 915.644 | G35: =+SUM(Jurel!B16:B18) -> 6.292 | H35: =SUM(G35:G36) -> 95.913 | I35: =+F35-G35 -> 909.352 | J35: =+C35-H35 -> 820.587 | K35: =1-G35/F35 -> 0.99312833 | L35: =1-H35/C35 -> 0.89534861 | R35: 2 | S35: 234 | T35: 14.602 | U35: 2 | V35: 2013 | W35: 104 | X35: =+T35+T36+T37+T38 -> 122.408
A36: JUREL | B36: II | C36: =SUM(E36:E37) -> 916.5 | D36: Ene - Sep | E36: 870.5 | F36: =+E36 -> 870.5 | G36: =+SUM(Jurel!B23:B32) -> 89.621 | H36: =SUM(G36:G37) -> 93.63 | I36: =+F36-G36 -> 780.879 | J36: =+C36-H36 -> 822.87 | K36: =1-G36/F36 -> 0.89704652 | L36: =1-H36/C36 -> 0.89783961 | O36: II | P36: =+G36+G37 -> 93.63 | R36: 2 | S36: 234 | T36: 46.423 | U36: 2 | V36: 2013 | W36: 105
B37: II | C37: =SUM(E37:E38) -> 2214 | D37: Oct-Dic | E37: 46 | F37: =+E37+I36 -> 826.879 | G37: =+SUM(Jurel!B33:B34) -> 4.009 | H37: =SUM(G37:G38) -> 2161.984 | I37: =+F37-G37 -> 822.87 | J37: =+C37-H37 -> 52.016 | K37: =1-G37/F37 -> 0.99515165 | L37: =1-H37/C37 -> 0.023494128 | R37: 2 | S37: 234 | T37: 53.115 | U37: 2 | V37: 2013 | W37: 106
A38: JUREL | B38: III | C38: =SUM(E38:E39) -> 2282 | D38: Ene - Oct | E38: 2168 | F38: =+E38 -> 2168 | G38: =+SUM(Jurel!B39:B48) -> 2157.975 | H38: =SUM(G38:G39) -> 2180.255 | I38: =+F38-G38 -> 10.025 | J38: =+C38-H38 -> 101.745 | K38: =1-G38/F38 -> 0.0046240775 | L38: =1-H38/C38 -> 0.04458589 | M38: 09 05 2013 (luego habra aumento de cuota) | N38: cerro 05 09 2013 primer periodo | O38: III | P38: =+G38+G39+992+19.75 -> 3192.005 | R38: 2 | S38: 234 | T38: 8.268 | U38: 2 | V38: 2013 | W38: 109
D39: Nov - Dic | E39: 114 | F39: =+E39+I38 -> 124.025 | G39: =+SUM(Jurel!B49:B50) -> 22.28 | H39: =SUM(G39:G40) -> 2697.23 | I39: =+F39-G39 -> 101.745 | J39: =+C39-H39 -> -2697.23 | K39: =1-G39/F39 -> 0.8203588 | L39: =1-H39/C39 -> #DIV/0! | R39: 3 | S39: 234 | T39: 1054.377 | U39: 2 | V39: 2013 | W39: 107 | X39: =+T39+T40 -> 3137.771
A40: JUREL | B40: IV (RAE por Org) | C40: =SUM(E40:E41) -> 5443 | D40: Ene - Oct | E40: 5177 | F40: =+E40 -> 5177 | G40: =+('Resumen RAE Jurel'!F10) -> 2674.95 | H40: =SUM(G40:G41) -> 3868.093 | I40: =+F40-G40 -> 2502.05 | J40: =+C40-H40 -> 1574.907 | K40: =1-G40/F40 -> 0.48330114 | L40: =1-H40/C40 -> 0.2893454 | O40: IV | P40: =+G40+G41 -> 3868.093 | R40: 3 | S40: 234 | T40: 2083.394 | U40: 2 | V40: 2013 | W40: 108
C41: =SUM(E41:E42) -> 1498 | D41: Nov - Dic | E41: 266 | F41: =+E41+I40 -> 2768.05 | G41: =+'Resumen RAE Jurel'!F16 -> 1193.143 | H41: =SUM(G41:G42) -> 1253.126 | I41: =+F41-G41 -> 1574.907 | J41: =+C41-H41 -> 244.874 | K41: =1-G41/F41 -> 0.56895901 | L41: =1-H41/C41 -> 0.16346729 | R41: 4 | S41: 234 | T41: 3694.693 | U41: 2 | V41: 2013 | W41: 109 | X41: =+T41+T42 -> 3695.625
A42: Jurel | B42: V (RAE por Org) | C42: =SUM(E42:E43) -> 1358 | D42: Ene - Sep | E42: 1232 | F42: =+E42 -> 1232 | G42: =+'Resumen RAE Jurel'!F24 -> 59.983 | H42: =SUM(G42:G43) -> 72.689 | I42: =+F42-G42 -> 1172.017 | J42: =+C42-H42 -> 1285.311 | K42: =1-G42/F42 -> 0.9513125 | L42: =1-H42/C42 -> 0.94647349 | O42: V | P42: =+G42+G43 -> 72.689 | R42: 4 | S42: 234 | T42: 0.932 | U42: 2 | V42: 2013 | W42: 110
...

Sheet Resumen RAE Anchoveta
A2: Resumen RAE Anchoveta 2013
A4: IV Región, de Coquimbo
A6: Organización | B6: Periodo | C6: Cuota asignada (t) | D6: TRAPASOS | E6: Cuota efectiva (t) | F6: Desembarque (t) | G6: Saldo (t) | H6: % | I6: Fecha de Cierre
A7: A.G. de pescadores Art. Y Buzos Marisc. De Coquimbo IV Región | B7: Ene-Oct | C7: 60 | E7: =+C7 -> 60 | F7: =+SUM('RAE Anchoveta'!B8:B17) -> 0.2 | G7: =+E7-F7 -> 59.8 | H7: =+G7/E7 -> 0.99666667
A8: Cooperativa de Armadores Cerqueros IV Región | B8: Ene-Oct | C8: 8165 | E8: =+C8 -> 8165 | F8: =+SUM('RAE Anchoveta'!B24:B33) -> 7577.372 | G8: =+E8-F8 -> 587.628 | H8: =+G8/E8 -> 0.071969137 | L8: Atencion
A9: Cuota Residual - Bolson | B9: Ene-Oct | C9: 11 | E9: =+C9 -> 11 | F9: =+SUM('RAE Anchoveta'!B40:B49) -> 4.196 | G9: =+E9-F9 -> 6.804 | H9: =+G9/E9 -> 0.61854545
A10: Total | B10: Ene-Oct | C10: =SUM(C7:C9) -> 8236 | E10: =SUM(E7:E9) -> 8236 | F10: =SUM(F7:F9) -> 7581.768 | G10: =+E10-F10 -> 654.232
A12: Organización | B12: Periodo | C12: Cuota asignada (t) | D12: TRAPASOS | E12: Cuota efectiva (t) | F12: Desembarque (t) | G12: Saldo (t) | H12: % | I12: Fecha de Cierre
A13: A.G. de pescadores Art. Y Buzos Marisc. De Coquimbo IV Región | B13: Nov-Dic | C13: 3 | E13: =+C13+G7 -> 62.8 | F13: =+SUM('RAE Anchoveta'!B18:B19) -> 0 | G13: =+E13-F13 -> 62.8 | H13: =+G13/E13 -> 1
A14: Cooperativa de Armadores Cerqueros IV Región | B14: Nov-Dic | C14: 429 | E14: =+C14+G8 -> 1016.628 | F14: =+SUM('RAE Anchoveta'!B34:B35) -> 100.137 | G14: =+E14-F14 -> 916.491 | H14: =+G14/E14 -> 0.90150084
A15: Cuota Residual - Bolson | B15: Nov-Dic | C15: 1 | E15: =+C15+G9 -> 7.804 | F15: =+SUM('RAE Anchoveta'!B50:B51) -> 0.03 | G15: =+E15-F15 -> 7.774 | H15: =+G15/E15 -> 0.99615582
A16: Total | B16: Nov-Dic | C16: =SUM(C13:C15) -> 433 | E16: =+C16 -> 433 | F16: =SUM(F13:F15) -> 100.167 | G16: =+E16-F16 -> 332.833
A18: V Región, de Valparaíso
A20: Organización | B20: Periodo | C20: Cuota asignada (t) | D20: Traspasos | E20: Cuota efectiva (t) | F20: Desembarque (t) | G20: Saldo (t) | H20: % | I20: Fecha de Cierre
A21: A.G. Armadores Artesanales San Antonio R.A.G. 2510 | B21: Ene-Abr | C21: 4735 | E21: =+C21+D21 -> 4735 | F21: =+SUM('RAE Anchoveta'!B58:B61) -> 4108.784 | G21: =+E21-F21 -> 626.216 | H21: =+G21/E21 -> 0.13225259 | L21: Atencion
A22: Pescadores artesanales no afiliados | B22: Ene-Abr | C22: 51 | E22: =+C22+D22 -> 51 | F22: =+SUM('RAE Anchoveta'!B74:B77) -> 31.1 | G22: =+E22-F22 -> 19.9 | H22: =+G22/E22 -> 0.39019608 | L22: Atencion
A23: Total | B23: Ene-Abr | C23: =SUM(C21:C22) -> 4786 | E23: =SUM(E21:E22) -> 4786 | F23: =SUM(F21:F22) -> 4139.884 | G23: =+E23-F23 -> 646.116
A25: Organización | B25: Periodo | C25: Cuota asignada (t) | E25: Cuota efectiva (t) | F25: Desembarque (t) | G25: Saldo (t) | H25: % | I25: Fecha de Cierre
A26: A.G. Armadores Artesanales San Antonio R.A.G. 2510 | B26: May-Ago | C26: 557 | E26: =+C26+G21+D26 -> 1183.216 | F26: =+SUM('RAE Anchoveta'!B62:B65) -> 310.107 | G26: =+E26-F26 -> 873.109 | H26: =+G26/E26 -> 0.73791176
A27: Pescadores artesanales no afiliados | B27: May-Ago | C27: 6 | E27: =+C27+G22+D27 -> 25.9 | F27: =+SUM('RAE Anchoveta'!B78:B81) -> 0 | G27: =+E27-F27 -> 25.9 | H27: =+G27/E27 -> 1
A28: Total | B28: May-Ago | C28: =SUM(C26:C27) -> 563 | E28: =+C28+G23 -> 1209.116 | F28: =SUM(F26:F27) -> 310.107 | G28: =+E28-F28 -> 899.009
A30: Organización | B30: Periodo | C30: Cuota asignada (t) | E30: Cuota efectiva (t) | F30: Desembarque (t) | G30: Saldo (t) | H30: % | I30: Fecha de Cierre
A31: A.G. Armadores Artesanales San Antonio R.A.G. 2510 | B31: Sep-Dic | C31: 278 | E31: =+C31+G26+D31 -> 1151.109 | F31: =+SUM('RAE Anchoveta'!B66:B69) -> 0 | G31: =+E31-F31 -> 1151.109 | H31: =+G31/E31 -> 1
A32: Pescadores artesanales no afiliados | B32: Sep-Dic | C32: 3 | E32: =+C32+G27+D32 -> 28.9 | F32: =+SUM('RAE Anchoveta'!B82:B85) -> 0 | G32: =+E32-F32 -> 28.9 | H32: =+G32/E32 -> 1
A33: Total | B33: Sep-Dic | C33: =SUM(C31:C32) -> 281 | E33: =+C33+G28 -> 1180.009 | F33: =SUM(F31:F32) -> 0 | G33: =+E33-F33 -> 1180.009
A35: VII Región, deL Maule
A37: Organización | B37: Periodo | C37: Cuota asignada (t) | D37: TRASPASOS | E37: Cuota efectiva (t) | F37: Desembarque (t) | G37: Saldo (t) | H37: % | I37: Fecha de Cierre
A38: STI:.de Pescadores "Pelágicos del Maule" Constitución, R.S.U. N° 07050150 | B38: Ene-Abr | C38: 481.746 | E38: =+C38+D38 -> 481.746 | F38: =+SUM('RAE Anchoveta'!B91:B94) -> 673.229 | G38: =+E38-F38 -> -191.483 | H38: =+G38/E38 -> -0.39747709 | I38: 17 04 2013 | J38: anual
A39: STI. AGUA LIMPIA RSU. N° 07050118 | B39: Ene-Abr | C39: 4.597 | E39: =+C39+D39 -> 4.597 | F39: =+SUM('RAE Anchoveta'!B107:B110) -> 0 | G39: =+E39-F39 -> 4.597 | H39: =+G39/E39 -> 1
A40: Cuota Residual | B40: Ene-Abr | C40: 25.657 | E40: =+C40+D40 -> 25.657 | F40: =+SUM('RAE Anchoveta'!B123:B126) -> 138.924 | G40: =+E40-F40 -> -113.267 | H40: =+G40/E40 -> -4.4146627 | I40: 19 03 2013 | J40: anual
A41: Total | B41: Ene-Abr | C41: =SUM(C38:C40) -> 512 | E41: =SUM(E38:E40) -> 512 | F41: =SUM(F38:F40) -> 812.153 | G41: =+E41-F41 -> -300.153
A43: Organización | B43: Periodo | C43: Cuota asignada (t) | E43: Cuota efectiva (t) | F43: Desembarque (t) | G43: Saldo (t) | H43: % | I43: Fecha de Cierre
A44: STI:.de Pescadores "Pelágicos del Maule" Constitución, R.S.U. N° 07050150 | B44: May-Ago | C44: 56.455 | E44: =+C44+G38+D44 -> -135.028 | F44: =+SUM('RAE Anchoveta'!B95:B98) -> 0 | G44: =+E44-F44 -> -135.028 | H44: =+G44/E44 -> 1 | I44: 17 04 2013 | J44: anual
A45: STI. AGUA LIMPIA RSU. N° 07050118 | B45: May-Ago | C45: 0.539 | E45: =+C45+G39+D45 -> 5.136 | F45: =+SUM('RAE Anchoveta'!B111:B114) -> 0 | G45: =+E45-F45 -> 5.136 | H45: =+G45/E45 -> 1
A46: Cuota Residual | B46: May-Ago | C46: 3.007 | E46: =+C46+G40+D46 -> -110.26 | F46: =+SUM('RAE Anchoveta'!B127:B130) -> 0.035 | G46: =+E46-F46 -> -110.295 | H46: =+G46/E46 -> 1.0003174 | I46: 19 03 2013 | J46: anual
A47: Total | B47: May-Ago | C47: =SUM(C44:C46) -> 60.001 | E47: =+C47+G41 -> -240.152 | F47: =SUM(F44:F46) -> 0.035 | G47: =+E47-F47 -> -240.187
A49: Organización | B49: Periodo | C49: Cuota asignada (t) | E49: Cuota efectiva (t) | F49: Desembarque (t) | G49: Saldo (t) | H49: % | I49: Fecha de Cierre
A50: STI:.de Pescadores "Pelágicos del Maule" Constitución, R.S.U. N° 07050150 | B50: Sep-Dic | C50: 28.227 | E50: =+C50+G44+D50 -> -106.801 | F50: =+SUM('RAE Anchoveta'!B99:B102) -> 0 | G50: =+E50-F50 -> -106.801 | H50: =+G50/E50 -> 1 | I50: 17 04 2013 | J50: anual
A51: STI. AGUA LIMPIA RSU. N° 07050118 | B51: Sep-Dic | C51: 0.269 | E51: =+C51+G45+D51 -> 5.405 | F51: =+SUM('RAE Anchoveta'!B115:B118) -> 0 | G51: =+E51-F51 -> 5.405 | H51: =+G51/E51 -> 1
A52: Cuota Residual | B52: Sep-Dic | C52: 1.503 | E52: =+C52+G46+D52 -> -108.792 | F52: =+SUM('RAE Anchoveta'!B131:B134) -> 0 | G52: =+E52-F52 -> -108.792 | H52: =+G52/E52 -> 1 | I52: 19 03 2013 | J52: anual
...

Sheet RAE Anchoveta
A2: RAE Anchoveta 2013
A4: IV REGIÓN
A6: A.G. de pescadores Artesanales y Buzos Mariscadores de Coquimbo - IV Región
A7: Mes | B7: Total mes | C7: 1 | D7: 2 | E7: 3 | F7: 4 | G7: 5 | H7: 6 | I7: 7 | J7: 8 | K7: 9 | L7: 10 | M7: 11 | N7: 12 | O7: 13 | P7: 14 | Q7: 15 | R7: 16 | S7: 17 | T7: 18 | U7: 19 | V7: 20 | W7: 21 | X7: 22 | Y7: 23 | Z7: 24 | AA7: 25 | AB7: 26 | AC7: 27 | AD7: 28 | AE7: 29 | AF7: 30 | AG7: 31 | AH7: TOTAL
A8: Enero | B8: =+AH8 -> 0 | E8: 0 | F8: 0 | G8: 0 | AH8: =SUM(C8:AG8) -> 0
A9: Febrero | B9: =+AH9 -> 0 | AH9: =SUM(C9:AG9) -> 0
A10: Marzo | B10: =+AH10 -> 0 | AH10: =SUM(C10:AG10) -> 0
A11: Abril | B11: =+AH11 -> 0 | AH11: =SUM(C11:AG11) -> 0
A12: Mayo | B12: =+AH12 -> 0 | AH12: =SUM(C12:AG12) -> 0
A13: Junio | B13: =+AH13 -> 0.2 | J13: 0.2 | AH13: =SUM(C13:AG13) -> 0.2
A14: Julio | B14: =+AH14 -> 0 | AH14: =SUM(C14:AG14) -> 0
A15: Agosto | B15: =+AH15 -> 0 | AH15: =SUM(C15:AG15) -> 0
A16: Septiembre | B16: =+AH16 -> 0 | AH16: =SUM(C16:AG16) -> 0
A17: Octubre | B17: =+AH17 -> 0 | AH17: =SUM(C17:AG17) -> 0
A18: Noviembre | B18: =+AH18 -> 0 | AH18: =SUM(C18:AG18) -> 0
A19: Diciembre | B19: =+AH19 -> 0 | AH19: =SUM(C19:AG19) -> 0
A20: TOTAL | B20: =SUM(B8:B19) -> 0.2 | C20: =SUM(C8:C19) -> 0 | D20: =SUM(D8:D19) -> 0 | E20: =SUM(E8:E19) -> 0 | F20: =SUM(F8:F19) -> 0 | G20: =SUM(G8:G19) -> 0 | H20: =SUM(H8:H19) -> 0 | I20: =SUM(I8:I19) -> 0 | ... AH20: =SUM(AH8:AH19) -> 0.2
A22: Cooperativa de Armadores Cerqueros IV región
A23: Mes | B23: Total mes | C23: 1 | D23: 2 | E23: 3 | F23: 4 | G23: 5 | H23: 6 | I23: 7 | J23: 8 | K23: 9 | L23: 10 | M23: 11 | N23: 12 | O23: 13 | P23: 14 | Q23: 15 | R23: 16 | S23: 17 | T23: 18 | U23: 19 | V23: 20 | W23: 21 | X23: 22 | Y23: 23 | Z23: 24 | AA23: 25 | AB23: 26 | AC23: 27 | AD23: 28 | AE23: 29 | AF23: 30 | AG23: 31 | AH23: TOTAL
A24: Enero | B24: =+AH24 -> 13.49 | C24: 0 | D24: 0 | E24: 1.8 | F24: 10.19 | G24: 1.5 | H24: 0 | I24: 0 | J24: 0 | K24: 0 | L24: 0 | M24: 0 | N24: 0 | O24: 0 | P24: 0 | Q24: 0 | R24: 0 | S24: 0 | T24: 0 | U24: 0 | V24: 0 | W24: 0 | X24: 0 | Y24: 0 | Z24: 0 | AA24: 0 | AB24: 0 | AC24: 0 | AD24: 0 | AE24: 0 | AF24: 0 | AG24: 0 | AH24: =SUM(C24:AG24) -> 13.49
A25: Febrero | B25: =+AH25 -> 79.703 | C25: 0 | D25: 0 | E25: 0 | F25: 0 | G25: 0 | H25: 0 | I25: 0 | J25: 0 | K25: 0 | L25: 0 | M25: 31.561 | N25: 48.142 | O25: 0 | P25: 0 | Q25: 0 | R25: 0 | S25: 0 | T25: 0 | U25: 0 | V25: 0 | W25: 0 | X25: 0 | Y25: 0 | Z25: 0 | AA25: 0 | AB25: 0 | AC25: 0 | AD25: 0 | AH25: =SUM(C25:AG25) -> 79.703
A26: Marzo | B26: =+AH26 -> 946.993 | C26: 0 | D26: 0 | E26: 0 | F26: 13.129 | G26: 34.596 | H26: 72.534 | I26: 0 | J26: 0 | K26: 0 | L26: 0 | M26: 0 | N26: 91.167 | O26: 10.429 | P26: 118.57 | Q26: 0 | R26: 0 | S26: 0 | T26: 9.679 | U26: 89.859 | V26: 22.577 | W26: 5.337 | X26: 0 | Y26: 0 | Z26: 0 | AA26: 171.103 | AB26: 102.952 | AC26: 97.323 | AD26: 107.738 | AE26: 0 | AF26: 0 | AG26: 0 | AH26: =SUM(C26:AG26) -> 946.993
A27: Abril | B27: =+AH27 -> 1946.382 | C27: 172.602 | D27: 210.928 | E27: 36.793 | F27: 96.582 | G27: 10.31 | H27: 0 | I27: 0 | J27: 0 | K27: 59.195 | L27: 55.672 | M27: 4.351 | N27: 0 | O27: 0 | P27: 0 | Q27: 83.94 | R27: 334.723 | S27: 354.291 | T27: 287.643 | U27: 13.677 | V27: 0 | W27: 0 | X27: 57.307 | Y27: 2.774 | Z27: 0 | AA27: 0 | AB27: 0 | AC27: 0 | AD27: 0 | AE27: 141.563 | AF27: 24.031 | AH27: =SUM(C27:AG27) -> 1946.382
A28: Mayo | B28: =+AH28 -> 4495.067 | C28: 0 | D28: 140.977 | E28: 110.807 | F28: 0 | G28: 0 | H28: 55.745 | I28: 444.65 | J28: 327.764 | K28: 514.157 | L28: 519.226 | M28: 36.41 | N28: 0 | O28: 201.899 | P28: 303.959 | Q28: 0 | R28: 0 | S28: 89.914 | T28: 0 | U28: 0 | V28: 224.053 | W28: 0 | X28: 365.477 | Y28: 382.16 | Z28: 301.931 | AA28: 234.577 | AB28: 0 | AC28: 237.921 | AD28: 0 | AE28: 0 | AF28: 0 | AG28: 3.44 | AH28: =SUM(C28:AG28) -> 4495.067
A29: Junio | B29: =+AH29 -> 61.58 | C29: 0 | D29: 0 | E29: 0 | F29: 0 | G29: 0 | H29: 0 | I29: 0 | J29: 61.58 | AH29: =SUM(C29:AG29) -> 61.58
A30: Julio | B30: =+AH30 -> 34.157 | D30: 4.257 | AE30: 29.9 | AH30: =SUM(C30:AG30) -> 34.157
A31: Agosto | B31: =+AH31 -> 0
A32: Septiembre | B32: =+AH32 -> 0
A33: Octubre | B33: =+AH33 -> 0 | AH33: =SUM(C33:AG33) -> 0
A34: Noviembre | B34: =+AH34 -> 9.534 | M34: 9.534 | AH34: =SUM(C34:AG34) -> 9.534
A35: Diciembre | B35: =+AH35 -> 90.603 | C35: 0 | D35: 0 | E35: 0 | F35: 0 | G35: 0 | H35: 0 | I35: 0 | J35: 0 | K35: 0 | L35: 0 | M35: 0 | N35: 0 | O35: 2.365 | P35: 0 | Q35: 0 | R35: 0 | S35: 3.305 | T35: 0 | U35: 0 | V35: 0 | W35: 0 | X35: 0 | Y35: 0 | Z35: 0 | AA35: 0 | AB35: 0 | AC35: 21.564 | AD35: 28.905 | AE35: 0 | AF35: 34.464 | AG35: 0 | AH35: =SUM(C35:AG35) -> 90.603
A36: TOTAL | B36: =SUM(B24:B35) -> 7677.509 | C36: =SUM(C24:C35) -> 172.602 | D36: =SUM(D24:D35) -> 356.162 | E36: =SUM(E24:E35) -> 149.4 | F36: =SUM(F24:F35) -> 119.901 | G36: =SUM(G24:G35) -> 46.406 | H36: =SUM(H24:H35) -> 128.279 | I36: =SUM(I24:I35) -> 444.65 | ... AH36: =SUM(AH24:AH35) -> 7677.509
A38: Cuota residual - Bolson
A39: Mes | B39: Total mes | C39: 1 | D39: 2 | E39: 3 | F39: 4 | G39: 5 | H39: 6 | I39: 7 | J39: 8 | K39: 9 | L39: 10 | M39: 11 | N39: 12 | O39: 13 | P39: 14 | Q39: 15 | R39: 16 | S39: 17 | T39: 18 | U39: 19 | V39: 20 | W39: 21 | X39: 22 | Y39: 23 | Z39: 24 | AA39: 25 | AB39: 26 | AC39: 27 | AD39: 28 | AE39: 29 | AF39: 30 | AG39: 31 | AH39: TOTAL
A40: Enero | B40: =+AH40 -> 0.062 | C40: 0 | D40: 0 | E40: 0 | F40: 0 | G40: 0.03 | H40: 0 | I40: 0.012 | J40: 0 | K40: 0 | L40: 0 | M40: 0 | N40: 0 | O40: 0 | P40: 0 | Q40: 0 | R40: 0 | S40: 0 | T40: 0 | U40: 0 | V40: 0 | W40: 0 | X40: 0.01 | Y40: 0.01 | Z40: 0 | AA40: 0 | AB40: 0 | AC40: 0 | AD40: 0 | AE40: 0 | AF40: 0 | AG40: 0 | AH40: =SUM(C40:AG40) -> 0.062
A41: Febrero | B41: =+AH41 -> 0 | AH41: =SUM(C41:AG41) -> 0
A42: Marzo | B42: =+AH42 -> 3.04 | C42: 0 | D42: 0 | E42: 0 | F42: 0 | G42: 0 | H42: 0 | I42: 0 | J42: 0 | K42: 0 | L42: 0 | M42: 0 | N42: 0 | O42: 0 | P42: 0 | Q42: 0 | R42: 0 | S42: 0 | T42: 0 | U42: 0 | V42: 0 | W42: 0 | X42: 0 | Y42: 0 | Z42: 0 | AA42: 0 | AB42: 0 | AC42: 0 | AD42: 3.04 | AE42: 0 | AF42: 0 | AG42: 0 | AH42: =SUM(C42:AG42) -> 3.04
A43: Abril | B43: =+AH43 -> 0 | C43: 0 | D43: 0 | E43: 0 | F43: 0 | G43: 0 | H43: 0 | I43: 0 | J43: 0 | K43: 0 | L43: 0 | M43: 0 | N43: 0 | O43: 0 | P43: 0 | Q43: 0 | R43: 0 | S43: 0 | T43: 0 | U43: 0 | V43: 0 | W43: 0 | X43: 0 | Y43: 0 | Z43: 0 | AA43: 0 | AB43: 0 | AC43: 0 | AD43: 0 | AE43: 0 | AF43: 0 | AH43: =SUM(C43:AG43) -> 0
A44: Mayo | B44: =+AH44 -> 1 | C44: 0 | D44: 0 | E44: 0 | F44: 0 | G44: 0 | H44: 0 | I44: 0 | J44: 0 | K44: 0 | L44: 0 | M44: 0 | N44: 0 | O44: 0 | P44: 0 | Q44: 0 | R44: 0 | S44: 0 | T44: 0 | U44: 0 | V44: 1 | W44: 0 | X44: 0 | Y44: 0 | Z44: 0 | AA44: 0 | AB44: 0 | AC44: 0 | AD44: 0 | AE44: 0 | AF44: 0 | AG44: 0 | AH44: =SUM(C44:AG44) -> 1
A45: Junio | B45: =+AH45 -> 0 | C45: 0 | D45: 0 | E45: 0 | F45: 0 | G45: 0 | H45: 0 | I45: 0 | J45: 0 | K45: 0 | L45: 0 | M45: 0 | N45: 0 | O45: 0 | P45: 0 | Q45: 0 | R45: 0 | S45: 0 | AH45: =SUM(C45:AG45) -> 0
...

Sheet Anchoveta
A2: Anchoveta 2013
AM4: 41570
A5: XV y I Región, Arica e Iquique | AL5: XV Región IMPREVISTOS
A6: Mes | B6: Total mes | C6: 1 | D6: 2 | E6: 3 | F6: 4 | G6: 5 | H6: 6 | I6: 7 | J6: 8 | K6: 9 | L6: 10 | M6: 11 | N6: 12 | O6: 13 | P6: 14 | Q6: 15 | R6: 16 | S6: 17 | T6: 18 | U6: 19 | V6: 20 | W6: 21 | X6: 22 | Y6: 23 | Z6: 24 | AA6: 25 | AB6: 26 | AC6: 27 | AD6: 28 | AE6: 29 | AF6: 30 | AG6: 31 | AH6: TOTAL | AJ6: Suma global mas imprevistos | AL6: Mes | AM6: Total mes | AN6: 1 | AO6: 2 | AP6: 3 | AQ6: 4 | AR6: 5 | AS6: 6 | AT6: 7 | AU6: 8 | AV6: 9 | AW6: 10 | AX6: 11 | AY6: 12 | AZ6: 13 | BA6: 14 | BB6: 15 | BC6: 16 | BD6: 17 | BE6: 18 | BF6: 19 | BG6: 20 | BH6: 21 | BI6: 22 | BJ6: 23 | BK6: 24 | BL6: 25 | BM6: 26 | BN6: 27 | BO6: 28 | BP6: 29 | BQ6: 30 | BR6: 31 | BS6: TOTAL
A7: Enero | B7: =+AH7 -> 20380.568 | C7: 0 | D7: 646.965 | E7: 957.14 | F7: 850.96 | G7: 400.87 | H7: 0 | I7: 522.555 | J7: 93.62 | K7: 708.67 | L7: 55.57 | M7: 1166.795 | N7: 671.05 | O7: 0 | P7: 586.453 | Q7: 234.916 | R7: 828.628 | S7: 1198.609 | T7: 887.247 | U7: 210.869 | V7: 0 | W7: 1340.436 | X7: 1403.205 | Y7: 666.405 | Z7: 1298.15 | AA7: 1031.905 | AB7: 899.435 | AC7: 0 | AD7: 1489.455 | AE7: 574.665 | AF7: 775.01 | AG7: 880.985 | AH7: =SUM(C7:AG7) -> 20380.568 | AJ7: =+B7+AM7 -> 20380.568 | AL7: Enero | AM7: =+BS7 -> 0 | BS7: =SUM(AN7:BR7) -> 0
A8: Febrero | B8: =+AH8 -> 13834.984 | C8: 673.73 | D8: 539.43 | E8: 0 | F8: 894.29 | G8: 220.509 | H8: 320.33 | I8: 312.126 | J8: 1315.864 | K8: 426.601 | L8: 0 | M8: 789.797 | N8: 826.865 | O8: 677.47 | P8: 335.454 | Q8: 196.416 | R8: 513.429 | S8: 0 | T8: 1222.983 | U8: 369.275 | V8: 435.165 | W8: 174.255 | X8: 213.975 | Y8: 256.065 | Z8: 0 | AA8: 1216.815 | AB8: 691.36 | AC8: 670.795 | AD8: 541.985 | AE8: 0 | AF8: 0 | AG8: 0 | AH8: =SUM(C8:AG8) -> 13834.984 | AJ8: =+B8+AM8 -> 13834.984 | AL8: Febrero | AM8: =+BS8 -> 0 | BS8: =SUM(AN8:BR8) -> 0
A9: Marzo | B9: =+AH9 -> 8680.268 | C9: 359.275 | D9: 812.31 | E9: 0 | F9: 66.98 | G9: 333.975 | H9: 407.37 | I9: 164.025 | J9: 709.705 | K9: 0 | L9: 0 | M9: 1107.36 | N9: 652.58 | O9: 315.515 | P9: 24.21 | Q9: 178.82 | R9: 0 | S9: 0 | T9: 0 | U9: 405.64 | V9: 769.39 | W9: 397.388 | X9: 257.53 | Y9: 0 | Z9: 0 | AA9: 575.715 | AB9: 277.97 | AC9: 581.72 | AD9: 282.79 | AE9: 0 | AF9: 0 | AG9: 0 | AH9: =SUM(C9:AG9) -> 8680.268 | AJ9: =+B9+AM9 -> 8680.268 | AL9: Marzo | AM9: =+BS9 -> 0 | BS9: =SUM(AN9:BR9) -> 0
A10: Abril | B10: =+AH10 -> 14658.073 | C10: 1191.44 | D10: 0 | E10: 617.48 | F10: 998.805 | G10: 794.61 | H10: 230.805 | I10: 0 | J10: 1537.535 | K10: 1540.445 | L10: 0 | M10: 0 | N10: 1363.3 | O10: 0 | P10: 0 | Q10: 0 | R10: 1125.03 | S10: 1258.125 | T10: 0 | U10: 566.16 | V10: 75.865 | W10: 0 | X10: 0 | Y10: 1061.645 | Z10: 1092.783 | AA10: 270.64 | AB10: 367.89 | AC10: 0 | AD10: 0 | AE10: 565.515 | AF10: 0 | AG10: 0 | AH10: =SUM(C10:AG10) -> 14658.073 | AJ10: =+B10+AM10 -> 14658.073 | AL10: Abril | AM10: =+BS10 -> 0 | BS10: =SUM(AN10:BR10) -> 0
A11: Mayo | B11: =+AH11 -> 6739.338 | C11: 0 | D11: 248.978 | E11: 1039.015 | F11: 603.939 | G11: 270.03 | H11: 372.567 | I11: 264.97 | J11: 414.876 | K11: 801.02 | L11: 0 | M11: 379.1 | N11: 0 | O11: 226.965 | P11: 226.325 | Q11: 3.195 | R11: 0 | S11: 0 | T11: 100.12 | U11: 44.53 | V11: 514 | W11: 0 | X11: 0 | Y11: 0 | Z11: 0 | AA11: 0.5 | AB11: 0 | AC11: 874.214 | AD11: 0 | AE11: 354.994 | AF11: 0 | AG11: 0 | AH11: =SUM(C11:AG11) -> 6739.338 | AJ11: =+B11+AM11 -> 6739.338 | AL11: Mayo | AM11: =+BS11 -> 0 | BS11: =SUM(AN11:BR11) -> 0
A12: Junio | B12: =+AH12 -> 1535.52 | C12: 397.455 | D12: 0 | E12: 0 | F12: 2.423 | G12: 0 | H12: 0 | I12: 0 | J12: 0 | K12: 0 | L12: 261.85 | M12: 169.859 | N12: 97.4 | O12: 0 | P12: 26.713 | Q12: 0 | R12: 0 | S12: 0 | T12: 42.835 | U12: 192.786 | V12: 127.093 | W12: 109.575 | X12: 8.025 | Y12: 0 | Z12: 32.821 | AA12: 0 | AB12: 66.685 | AC12: 0 | AD12: 0 | AE12: 0 | AF12: 0 | AG12: 0 | AH12: =SUM(C12:AG12) -> 1535.52 | AJ12: =+B12+AM12 -> 1535.52 | AL12: Junio | AM12: =+BS12 -> 0 | BS12: =SUM(AN12:BR12) -> 0
A13: Julio | B13: =+AH13 -> 7906.17 | C13: 0 | D13: 0 | E13: 0 | F13: 2.423 | G13: 0 | H13: 0 | I13: 0 | J13: 0 | K13: 0 | L13: 0 | M13: 117.39 | N13: 344.801 | O13: 405.841 | P13: 109.654 | Q13: 95.74 | R13: 0 | S13: 65.709 | T13: 669.765 | U13: 384.072 | V13: 890.407 | W13: 377.665 | X13: 168.753 | Y13: 509.015 | Z13: 326.394 | AA13: 792.7 | AB13: 345.406 | AC13: 70.453 | AD13: 11.99 | AE13: 203.46 | AF13: 1056.665 | AG13: 957.867 | AH13: =SUM(C13:AG13) -> 7906.17 | AJ13: =+B13+AM13 -> 7906.17 | AL13: Julio | AM13: =+BS13 -> 0 | BS13: =SUM(AN13:BR13) -> 0
A14: Agosto | B14: =+AH14 -> 2495.039 | C14: 714.926 | D14: 619.623 | E14: 789.115 | F14: 371.375 | G14: 0 | H14: 0 | I14: 0 | J14: 0 | K14: 0 | L14: 0 | M14: 0 | N14: 0 | O14: 0 | P14: 0 | Q14: 0 | R14: 0 | S14: 0 | T14: 0 | U14: 0 | V14: 0 | W14: 0 | X14: 0 | Y14: 0 | Z14: 0 | AA14: 0 | AB14: 0 | AC14: 0 | AD14: 0 | AE14: 0 | AF14: 0 | AG14: 0 | AH14: =SUM(C14:AG14) -> 2495.039 | AJ14: =+B14+AM14 -> 2495.039 | AL14: Agosto | AM14: =+BS14 -> 0 | BS14: =SUM(AN14:BR14) -> 0
A15: Septiembre | B15: =+AH15 -> 7536.52 | C15: 0 | D15: 0 | E15: 0 | F15: 0 | G15: 0 | H15: 0 | I15: 0 | J15: 0 | K15: 0 | L15: 0 | M15: 0 | N15: 0 | O15: 0 | P15: 0 | Q15: 0 | R15: 0 | S15: 0 | T15: 0 | U15: 0 | V15: 0 | W15: 0 | X15: 0 | Y15: 0 | Z15: 841.425 | AA15: 1296.985 | AB15: 1196.205 | AC15: 1372.895 | AD15: 1265.555 | AE15: 0 | AF15: 1563.455 | AG15: 0 | AH15: =SUM(C15:AG15) -> 7536.52 | AJ15: =+B15+AM15 -> 7536.52 | AL15: Septiembre | AM15: =+BS15 -> 0 | BS15: =SUM(AN15:BR15) -> 0
A16: Octubre | B16: =+AH16 -> 236.23 | C16: 236.23 | D16: 0 | E16: 0 | F16: 0 | K16: 0 | L16: 0 | M16: 0 | N16: 0 | O16: 0 | P16: 0 | Q16: 0 | R16: 0 | S16: 0 | T16: 0 | U16: 0 | V16: 0 | W16: 0 | X16: 0 | Y16: 0 | Z16: 0 | AA16: 0 | AB16: 0 | AC16: 0 | AD16: 0 | AE16: 0 | AF16: 0 | AG16: 0 | AH16: =SUM(C16:AG16) -> 236.23 | AJ16: =+B16+AM16 -> 7563.085 | AL16: Octubre | AM16: =+BS16 -> 7326.855 | AN16: 236.23 | AO16: 0 | AP16: 0 | AQ16: 0 | AR16: 1613.945 | AS16: 557.365 | AT16: 1414.44 | AU16: 1173.215 | AV16: 1283.7 | AW16: 1047.96 | AY16: 0 | AZ16: 0 | BA16: 0 | BB16: 0 | BC16: 0 | BD16: 0 | BE16: 0 | BF16: 0 | BG16: 0 | BH16: 0 | BI16: 0 | BJ16: 0 | BK16: 0 | BL16: 0 | BM16: 0 | BN16: 0 | BO16: 0 | BP16: 0 | BQ16: 0 | BR16: 0 | BS16: =SUM(AN16:BR16) -> 7326.855
A17: Noviembre | B17: =+AH17 -> 253.665 | C17: VEDA | D17: VEDA | E17: VEDA | F17: VEDA | G17: VEDA | H17: VEDA | I17: VEDA | J17: VEDA | K17: VEDA | L17: VEDA | M17: VEDA | N17: VEDA | O17: VEDA | P17: VEDA | Q17: VEDA | R17: VEDA | S17: VEDA | T17: VEDA | U17: VEDA | V17: VEDA | W17: VEDA | X17: VEDA | Y17: VEDA | Z17: VEDA | AA17: VEDA | AB17: VEDA | AC17: VEDA | AD17: VEDA | AE17: VEDA | AF17: 253.665 | AG17: VEDA | AH17: =SUM(C17:AG17) -> 253.665 | AJ17: =+B17+AM17 -> 253.665 | AL17: Noviembre | AM17: =+BS17 -> 0 | AN17: VEDA | AO17: VEDA | AP17: VEDA | AQ17: VEDA | AR17: VEDA | AS17: VEDA | AT17: VEDA | AU17: VEDA | AV17: VEDA | AW17: VEDA | AX17: VEDA | AY17: VEDA | AZ17: VEDA | BA17: VEDA | BB17: VEDA | BC17: VEDA | BD17: VEDA | BE17: VEDA | BF17: VEDA | BG17: VEDA | BH17: VEDA | BI17: VEDA | BJ17: VEDA | BK17: VEDA | BL17: VEDA | BM17: VEDA | BN17: VEDA | BO17: VEDA | BP17: VEDA | BQ17: VEDA | BR17: VEDA | BS17: =SUM(AN17:BR17) -> 0
A18: Diciembre | B18: =+AH18 -> 873.456 | C18: VEDA | D18: 34.55 | E18: 491.616 | F18: 268.6 | G18: VEDA | H18: VEDA | I18: VEDA | J18: VEDA | K18: 74.65 | L18: 3.92 | M18: VEDA | N18: VEDA | O18: VEDA | P18: VEDA | Q18: VEDA | R18: VEDA | S18: 0.12 | T18: VEDA | U18: VEDA | W18: VEDA | X18: VEDA | Y18: VEDA | Z18: VEDA | AA18: VEDA | AB18: VEDA | AC18: VEDA | AD18: VEDA | AE18: VEDA | AF18: VEDA | AG18: VEDA | AH18: =SUM(C18:AG18) -> 873.456 | AJ18: =+B18+AM18 -> 873.456 | AL18: Diciembre | AM18: =+BS18 -> 0 | AN18: VEDA | AO18: VEDA | AP18: VEDA | AQ18: VEDA | AR18: VEDA | AS18: VEDA | AT18: VEDA | AU18: VEDA | AV18: VEDA | AW18: VEDA | AX18: VEDA | AY18: VEDA | AZ18: VEDA | BA18: VEDA | BB18: VEDA | BC18: VEDA | BD18: VEDA | BE18: VEDA | BF18: VEDA | BG18: VEDA | BH18: VEDA | BI18: VEDA | BJ18: VEDA | BK18: VEDA | BL18: VEDA | BM18: VEDA | BN18: VEDA | BO18: VEDA | BP18: VEDA | BQ18: VEDA | BR18: VEDA | BS18: =SUM(AN18:BR18) -> 0
A19: TOTAL | B19: =SUM(B7:B18) -> 85129.831 | AH19: =SUM(AH7:AH18) -> 85129.831 | AJ19: =+B19+AM19 -> 92456.686 | AL19: TOTAL | AM19: =SUM(AM7:AM18) -> 7326.855 | BS19: =SUM(BS7:BS18) -> 7326.855
AL20: cuota imprevistos | AM20: 8050
A21: II Región, de Antofasta | AL21: saldo | AM21: =+AM20-AM19 -> 723.145
A22: Mes | B22: Total mes | C22: 1 | D22: 2 | E22: 3 | F22: 4 | G22: 5 | H22: 6 | I22: 7 | J22: 8 | K22: 9 | L22: 10 | M22: 11 | N22: 12 | O22: 13 | P22: 14 | Q22: 15 | R22: 16 | S22: 17 | T22: 18 | U22: 19 | V22: 20 | W22: 21 | X22: 22 | Y22: 23 | Z22: 24 | AA22: 25 | AB22: 26 | AC22: 27 | AD22: 28 | AE22: 29 | AF22: 30 | AG22: 31 | AH22: TOTAL
AH23: =SUM(C23:AG23) -> 0
A24: Enero | B24: =SUM(AH24) -> 3742.385 | J24: 133.71 | K24: 113.4 | L24: 86.135 | M24: 436.655 | N24: 242.565 | Q24: 295.335 | R24: 217.675 | S24: 338.965 | T24: 134.17 | U24: 384.455 | V24: 78.345 | W24: 237.805 | X24: 255.32 | Y24: 184.49 | Z24: 439.085 | AA24: 138.35 | AB24: 0.1 | AE24: 0.3 | AG24: 25.525 | AH24: =SUM(C24:AG24) -> 3742.385
A25: Febrero | B25: =SUM(AH25) -> 242.651 | D25: 0.01 | H25: 86.18 | I25: 150.746 | J25: 3.035 | K25: 0.03 | R25: 0.1 | X25: 0.09 | Y25: 0.3 | AB25: 0.02 | AD25: 2.14 | AH25: =SUM(C25:AG25) -> 242.651
A26: Marzo | B26: =SUM(AH26) -> 932.725 | G26: 124.16 | H26: 147.455 | I26: 174.685 | J26: 60.92 | O26: 164.81 | P26: 138.955 | Q26: 62.07 | U26: 56.91 | AA26: 0.02 | AD26: 0.4 | AG26: 2.34 | AH26: =SUM(C26:AG26) -> 932.725
A27: Abril | B27: =SUM(AH27) -> 4.626 | M27: 1.5 | V27: 0.1 | Z27: 0.01 | AB27: 0.018 | AC27: 0.25 | AF27: 2.748 | AH27: =SUM(C27:AG27) -> 4.626
A28: Mayo | B28: =SUM(AH28) -> 2608.617 | F28: 103.665 | I28: 60.415 | J28: 237.265 | K28: 157.98 | L28: 435.505 | M28: 223.385 | O28: 125.72 | P28: 80.69 | Q28: 236.41 | R28: 202.53 | S28: 154.52 | T28: 49.5 | U28: 148.935 | V28: 282.125 | W28: 88.15 | X28: 0.03 | AC28: 19.362 | AF28: 0.26 | AG28: 2.17 | AH28: =SUM(C28:AG28) -> 2608.617
A29: Junio | B29: =SUM(AH29) -> 776.27 | D29: 79.825 | E29: 141.13 | F29: 87.76 | G29: 288.17 | I29: 102.48 | L29: 2.1 | P29: 74.735 | Y29: 0.01 | AF29: 0.06 | AH29: =SUM(C29:AG29) -> 776.27
A30: Julio | B30: =SUM(AH30) -> 0.64 | AG30: 0.64 | AH30: =SUM(C30:AG30) -> 0.64
A31: Agosto | B31: =SUM(AH31) -> 2.28 | K31: 2.2 | AG31: 0.08 | AH31: =SUM(C31:AG31) -> 2.28
A32: Septiembre | B32: =SUM(AH32) -> 1179.415 | K32: 0.02 | N32: 2,8 | Z32: 44.86 | AA32: 320 | AB32: 223.525 | AC32: 205.115 | AD32: 238.955 | AE32: 146.71 | AF32: 0.23 | AH32: =SUM(C32:AG32) -> 1179.415
A33: Octubre | B33: =SUM(AH33) -> 4371.783 | C33: 16.005 | D33: 0,3 | E33: 23.85 | F33: 222.505 | G33: 125.17 | I33: 88.81 | Q33: 356.95 | R33: 319.085 | S33: 249.035 | T33: 281.34 | U33: 133.57 | V33: 241.48 | W33: 143.845 | X33: 137.865 | Y33: 162.845 | Z33: 97.02 | AA33: 154.83 | AB33: 262.48 | AC33: 237.625 | AD33: 397.785 | AE33: 358.223 | AF33: 361.17 | AG33: 0.295 | AH33: =SUM(C33:AG33) -> 4371.783
A34: Noviembre | B34: =SUM(AH34) -> 5809.195 | F34: 353.13 | G34: 430.915 | H34: 298.54 | I34: 211.21 | J34: 703.915 | K34: 199.9 | L34: 310.83 | M34: 85.96 | Q34: 356.475 | R34: 130.225 | V34: 80.16 | W34: 489.595 | X34: 450.385 | AA34: 323.47 | AB34: 504.23 | AC34: 332.545 | AD34: 547.71 | AH34: =SUM(C34:AG34) -> 5809.195
A35: Diciembre | B35: =SUM(AH35) -> 0 | C35: VEDA | D35: VEDA | E35: VEDA | F35: VEDA | G35: VEDA | H35: VEDA | I35: VEDA | J35: VEDA | K35: VEDA | L35: VEDA | M35: VEDA | N35: VEDA | O35: VEDA | P35: VEDA | Q35: VEDA | R35: VEDA | S35: VEDA | T35: VEDA | U35: VEDA | V35: VEDA | W35: VEDA | X35: VEDA | Y35: VEDA | Z35: VEDA | AA35: VEDA | AB35: VEDA | AC35: VEDA | AD35: VEDA | AE35: VEDA | AF35: VEDA | AG35: VEDA | AH35: =SUM(C35:AG35) -> 0
A36: TOTAL | B36: =SUM(B23:B35) -> 19670.587 | C36: 0 | D36: 0 | E36: 0 | F36: 0 | G36: 0 | H36: 0 | I36: 0 | J36: 0 | K36: 0 | L36: 0 | M36: 0 | N36: 0 | O36: 0 | P36: 0 | Q36: 0 | R36: 0 | S36: 0 | T36: 0 | U36: 0 | V36: 0 | W36: 0 | X36: 0 | Y36: 0 | Z36: 0 | AA36: 0 | AB36: 0 | AC36: 0 | AD36: 0 | AE36: 0 | AF36: 0 | AG36: 0 | AH36: =SUM(AH24:AH35) -> 19670.587
A38: III Región, de Atacama
A39: Mes | B39: Total mes | C39: 1 | D39: 2 | E39: 3 | F39: 4 | G39: 5 | H39: 6 | I39: 7 | J39: 8 | K39: 9 | L39: 10 | M39: 11 | N39: 12 | O39: 13 | P39: 14 | Q39: 15 | R39: 16 | S39: 17 | T39: 18 | U39: 19 | V39: 20 | W39: 21 | X39: 22 | Y39: 23 | Z39: 24 | AA39: 25 | AB39: 26 | AC39: 27 | AD39: 28 | AE39: 29 | AF39: 30 | AG39: 31 | AH39: TOTAL
A40: Enero | B40: =+AH40 -> 3198.13 | C40: 0 | D40: 0 | E40: 259.067 | F40: 174.481 | G40: 29.681 | H40: 139.133 | I40: 371.75 | J40: 299.484 | K40: 154.613 | L40: 187.694 | M40: 180.053 | N40: 272.775 | O40: 339.7 | P40: 228.441 | Q40: 0 | R40: 0 | S40: 7.22 | T40: 0 | U40: 0 | V40: 0 | W40: 0 | X40: 0 | Y40: 186.112 | Z40: 40.941 | AA40: 67.061 | AB40: 24.218 | AC40: 68.75 | AD40: 104.059 | AE40: 62.897 | AF40: 0 | AG40: 0 | AH40: =SUM(C40:AG40) -> 3198.13
A41: Febrero | B41: =+AH41 -> 511.801 | C41: 0 | D41: 0 | E41: 0 | F41: 0 | G41: 0 | H41: 0 | I41: 0 | J41: 0 | K41: 0 | L41: 0 | M41: 0 | N41: 0 | O41: 0 | P41: 1.016 | Q41: 0 | R41: 73.725 | S41: 72.355 | T41: 91.38 | U41: 147.16 | V41: 53.48 | W41: 36.28 | X41: 0 | Y41: 0 | Z41: 0 | AA41: 3.955 | AB41: 0 | AC41: 0 | AD41: 32.45 | AH41: =SUM(C41:AG41) -> 511.801
A42: Marzo | B42: =+AH42 -> 5845.859 | C42: 139.17 | D42: 39.735 | E42: 89.73 | F42: 171.82 | G42: 443.92 | H42: 382.72 | I42: 451.924 | J42: 500.57 | K42: 46.94 | L42: 193.915 | M42: 142.215 | N42: 103.425 | O42: 136.195 | P42: 83.3 | Q42: 297.84 | R42: 159.81 | S42: 20.3 | T42: 68.56 | U42: 359.4 | V42: 112.89 | W42: 404.22 | X42: 371.665 | Y42: 518.1 | Z42: 180.115 | AA42: 23.865 | AB42: 0 | AC42: 185.92 | AD42: 133.4 | AE42: 0 | AF42: 29.85 | AG42: 54.345 | AH42: =SUM(C42:AG42) -> 5845.859
A43: Abril | B43: =+AH43 -> 6203.369 | C43: 257.205 | D43: 402.475 | E43: 501.62 | F43: 0 | G43: 326.1 | H43: 565.505 | I43: 782.975 | J43: 463.41 | K43: 221.12 | L43: 399.04 | M43: 0 | N43: 0 | O43: 0 | P43: 0 | Q43: 0 | R43: 0 | S43: 0 | T43: 0 | U43: 131.58 | V43: 529.481 | W43: 414.406 | X43: 444.655 | Y43: 425.34 | Z43: 68.445 | AA43: 107.445 | AB43: 0 | AC43: 0 | AD43: 0 | AE43: 67.76 | AF43: 94.807 | AH43: =SUM(C43:AG43) -> 6203.369
...

Sheet Resumen RAE S.Común
A2: Resumen RAE Sardina común 2013
A5: V Región, de Valparaíso
A7: Organización | B7: Periodo | C7: Cuota asignada (t) | D7: TRASPASOS | E7: Cuota efectiva (t) | F7: Desembarque (t) | G7: Saldo (t) | H7: Saldo % | I7: Fecha de Cierre
A8: A.G. Armadores Artesanales San Antonio R.A.G. 2510 | B8: Ene-Abr | C8: 4147 | E8: =+C8+D8 -> 4147 | F8: =+SUM('RAE S.común'!B8:B11) -> 3674.573 | G8: =+E8-F8 -> 472.427 | H8: =+G8/E8 -> 0.11392018 | J8: atencion
A9: Pescadores artesanales no afiliados | B9: Ene-Abr | C9: 1341 | E9: =+C9+D9 -> 1341 | F9: =+SUM('RAE S.común'!B24:B27) -> 928.769 | G9: =+E9-F9 -> 412.231 | H9: =+G9/E9 -> 0.30740567
A10: Total | B10: Ene-Abr | C10: =SUM(C8:C9) -> 5488 | E10: =SUM(E8:E9) -> 5488 | F10: =SUM(F8:F9) -> 4603.342 | G10: =+E10-F10 -> 884.658
A12: Organización | B12: Periodo | C12: Cuota asignada (t) | E12: Cuota efectiva (t) | F12: Desembarque (t) | G12: Saldo (t) | H12: Saldo % | I12: Fecha de Cierre
A13: A.G. Armadores Artesanales San Antonio R.A.G. 2510 | B13: May-Ago | C13: 488 | E13: =+C13+G8+D13 -> 960.427 | F13: =+SUM('RAE S.común'!B12:B15) -> 436.503 | G13: =+E13-F13 -> 523.924 | H13: =+G13/E13 -> 0.54551153
A14: Pescadores artesanales no afiliados | B14: May-Ago | C14: 158 | E14: =+C14+G9+D14 -> 570.231 | F14: =+SUM('RAE S.común'!B28:B31) -> 121.546 | G14: =+E14-F14 -> 448.685 | H14: =+G14/E14 -> 0.78684779
A15: Total | B15: May-Ago | C15: =SUM(C13:C14) -> 646 | E15: =+C15+G10 -> 1530.658 | F15: =SUM(F13:F14) -> 558.049 | G15: =+E15-F15 -> 972.609
A17: Organización | B17: Periodo | C17: Cuota asignada (t) | E17: Cuota efectiva (t) | F17: Desembarque (t) | G17: Saldo (t) | H17: Saldo % | I17: 2
A18: A.G. Armadores Artesanales San Antonio R.A.G. 2510 | B18: Sep-Dic | C18: 244 | E18: =+C18+G13+D18 -> 767.924 | F18: =+SUM('RAE S.común'!B16:B19) -> 0 | G18: =+E18-F18 -> 767.924 | H18: =+G18/E18 -> 1
A19: Pescadores artesanales no afiliados | B19: Sep-Dic | C19: 79 | E19: =+C19+G14+D19 -> 527.685 | F19: =+SUM('RAE S.común'!B32:B35) -> 40.581 | G19: =+E19-F19 -> 487.104 | H19: =+G19/E19 -> 0.92309617
A20: Total | B20: Sep-Dic | C20: =SUM(C18:C19) -> 323 | E20: =+C20+G15 -> 1295.609 | F20: =SUM(F18:F19) -> 40.581 | G20: =+E20-F20 -> 1255.028
A22: VII Región, deL Maule
A24: Organización | B24: Periodo | C24: Cuota asignada (t) | D24: TRASPASOS | E24: Cuota efectiva (t) | F24: Desembarque (t) | G24: Saldo (t) | H24: Saldo % | I24: Fecha de Cierre
A25: STI:.de Pescadores "Pelágicos del Maule" Constitución, R.S.U. N° 07050150 | B25: Ene-Abr | C25: 1866.765 | E25: =+C25+D25 -> 1866.765 | F25: =+SUM('RAE S.común'!B41:B44) -> 1266.368 | G25: =+E25-F25 -> 600.397 | H25: =+G25/E25 -> 0.32162431
A26: STI. AGUA LIMPIA RSU. N° 07050118 | B26: Ene-Abr | C26: 17.812 | E26: =+C26+D26 -> 17.812 | F26: =+SUM('RAE S.común'!B57:B60) -> 0 | G26: =+E26-F26 -> 17.812 | H26: =+G26/E26 -> 1
A27: Cuota Residual | B27: Ene-Abr | C27: 99.422 | E27: =+C27 -> 99.422 | F27: =+SUM('RAE S.común'!B73:B76) -> 258.181 | G27: =+E27-F27 -> -158.759 | H27: =G27/E27 -> -1.5968196 | I27: 19 03 2013 | J27: anual
A28: Total | B28: Ene-Abr | C28: =SUM(C25:C27) -> 1983.999 | E28: =SUM(E25:E27) -> 1983.999 | F28: =SUM(F25:F27) -> 1524.549 | G28: =+E28-F28 -> 459.45
A30: Organización | B30: Periodo | C30: Cuota asignada (t) | E30: Cuota efectiva (t) | F30: Desembarque (t) | G30: Saldo (t) | H30: Saldo % | I30: Fecha de Cierre
A31: STI:.de Pescadores "Pelágicos del Maule" Constitución, R.S.U. N° 07050150 | B31: May-Ago | C31: 219.232 | E31: =+C31+G25 -> 819.629 | F31: =+SUM('RAE S.común'!B45:B48) -> 337.931 | G31: =+E31-F31 -> 481.698 | H31: =+G31/E31 -> 0.58770248
A32: STI. AGUA LIMPIA RSU. N° 07050118 | B32: May-Ago | C32: 2.092 | E32: =+C32+G26 -> 19.904 | F32: =+SUM('RAE S.común'!B61:B64) -> 0 | G32: =+E32-F32 -> 19.904 | H32: =+G32/E32 -> 1
A33: Cuota Residual | B33: May-Ago | C33: 11.676 | E33: =+C33+G27 -> -147.083 | F33: =+SUM('RAE S.común'!B77:B80) -> 0.1 | G33: =+E33-F33 -> -147.183 | H33: =+G33/E33 -> 1.0006799 | I33: 19 03 2013 | J33: anual
A34: Total | B34: May-Ago | C34: =SUM(C31:C33) -> 233 | E34: =+C34+G28 -> 692.45 | F34: =SUM(F31:F33) -> 338.031 | G34: =+E34-F34 -> 354.419
A36: Organización | B36: Periodo | C36: Cuota asignada (t) | E36: Cuota efectiva (t) | F36: Desembarque (t) | G36: Saldo (t) | H36: Saldo % | I36: Fecha de Cierre
A37: STI:.de Pescadores "Pelágicos del Maule" Constitución, R.S.U. N° 07050150 | B37: Sep-Dic | C37: 110.086 | E37: =+C37+G31 -> 591.784 | F37: =+SUM('RAE S.común'!B49:B52) -> 2.79 | G37: =+E37-F37 -> 588.994 | H37: =+G37/E37 -> 0.99528544
A38: STI. AGUA LIMPIA RSU. N° 07050118 | B38: Sep-Dic | C38: 1.05 | E38: =+C38+G32 -> 20.954 | F38: =+SUM('RAE S.común'!B65:B68) -> 0 | G38: =+E38-F38 -> 20.954 | H38: =+G38/E38 -> 1
A39: Cuota Residual | B39: Sep-Dic | C39: 5.863 | E39: =+C39+G33 -> -141.32 | F39: =+SUM('RAE S.común'!B81:B84) -> 0 | G39: =+E39-F39 -> -141.32 | H39: =+G39/E39 -> 1 | I39: 19 03 2013 | J39: anual
A40: Total | B40: Sep-Dic | C40: =SUM(C37:C39) -> 116.999 | E40: =+C40+G34 -> 471.418 | F40: =SUM(F37:F39) -> 2.79 | G40: =+E40-F40 -> 468.628
N41: E.Norero C.
A42: VIII Región, del Bio Bio | L42: insertar aquí | N42: 22-10-2013 se hicieron unos ajustes antes de la apertura
A43: Organización | B43: Periodo | C43: Cuota asignada (t) | D43: traspaso | E43: Cuota efectiva (t) | F43: Desembarque (t) | G43: Saldo (t) | H43: Saldo % | I43: Fecha de Cierre | L43: desembarque
A44: Agrupación de Armadores y Pescadores Pelágicos de Caleta Tubul, Registro de Organización Comunitaria Funcional 478-2007 | B44: Ene-Ago | C44: 1070 | E44: =+C44+D44 -> 1070 | F44: =18.167+9.52+1.74+23.44+1.64+55.25+19.71+0.26+1.72+0.52+0.15 -> 132.117 | G44: =+E44-F44 -> 937.883 | H44: =+G44/E44 -> 0.87652617 | K44: =+(L44-F44) -> -0.002 | L44: 132.115 | N44: =+C44+C110 -> 1126 | O44: =+F44+F110 -> 142.133 | P44: =+N44-O44 -> 983.867
A45: Agrupación Gremial de Productores Pelágicos, Armadores Artesanales de Talcahuano, Región del Bío Bío AGREPAR BIO BIO A.G., R.A.G. N° 468-8 | B45: Ene-Ago | C45: 2782 | E45: =+C45+D45 -> 2782 | F45: =70.33+97.19+6.04+30.83+87.19+93.54+3.12+53.6+26.81+65.85+37.77+37.15+8.41+12.04+2.41+61.96+157.23+29.53+40.23+52.2+8.1 -> 981.53 | G45: =+E45-F45 -> 1800.47 | H45: =+G45/E45 -> 0.64718548 | K45: =+(L45-F45) -> -0.004 | L45: 981.526 | N45: =+C45+C111 -> 2907 | O45: =+F45+F111 -> 1202.884 | P45: =+N45-O45 -> 1704.116
A46: Asociación de Armadores, Pescadores Artesanales y Actividades Afines de la Octava Región, Asociación Gremial ARPESCA A.G., R.A.G. 429-8 | B46: Ene-Ago | C46: 17 | E46: =+C46+D46 -> 17 | F46: 9.47 | G46: =+E46-F46 -> 7.53 | H46: =+G46/E46 -> 0.44294118 | K46: =+(L46-F46) -> 0.002 | L46: 9.472 | N46: =+C46+C112 -> 29 | O46: =+F46+F112 -> 16.712 | P46: =+N46-O46 -> 12.288
A47: A.G. Armadores Artesanales Pelágico Coronel-Lota del Bío Bío, ARPES BIO BIO A.G., R.A.G. 445-8 | B47: Ene-Ago | C47: 13248 | E47: =+C47+D47 -> 13248 | F47: =5.05+618.37+411.79+48.81+73.68+44.03+20.97+4.03+68.13+48.291+62.04+15.178+165.492+62.31+39.431+1.047+17.355+68.055+133.864+79.254+0.231+58.318+13.24+24.823+13.328+5.204+0.377+180.833+79.305+158.42+116.07+78.2+21.928+36.791+120.884+18.871+45.104+77.41+402.34+709.823+328.21+490.444+55.209 -> 5022.54 | G47: =+E47-F47 -> 8225.46 | H47: =+G47/E47 -> 0.62088315 | K47: =+(L47-F47) -> 0 | L47: 5022.54 | N47: =+C47+C113 -> 13945 | O47: =+F47+F113 -> 5876.549 | P47: =+N47-O47 -> 8068.451
A48: A.G. Armadores y Pescadores Artesanales, SIARPAR A.G., R.A.G. 448-8 | B48: Ene-Ago | C48: 161 | E48: =+C48+D48 -> 161 | F48: 0 | G48: =+E48-F48 -> 161 | H48: =+G48/E48 -> 1 | K48: =+(L48-F48) -> 0 | L48: 0 | N48: =+C48+C114 -> 169 | O48: =+F48+F114 -> 0 | P48: =+N48-O48 -> 169
A49: A.G. de Armadores Artesanales - ARMAR A.G., R.A.G. 384-8 | B49: Ene-Ago | C49: 10014 | E49: =+C49+D49 -> 10014 | F49: =425.47+229.94+96.17+25.33+58.78+105.25+11.24+13.7+146.015+12.862+28.175+0.57+6.238+47.706+0.323+1.679+0.996+5.968+24.212+3+33.853+2.002+61.87+342.823+211.58+97.068+41.33+15.487 -> 2049.637 | G49: =+E49-F49 -> 7964.363 | H49: =+G49/E49 -> 0.79532285 | K49: =+(L49-F49) -> 4.5474735e-13 | L49: 2049.637 | N49: =+C49+C115 -> 10541 | O49: =+F49+F115 -> 2545.264 | P49: =+N49-O49 -> 7995.736
A50: A.G. de Armadores Artesanales y Productores Pelágicos de la Caleta el Morro de Talcahuano - AGEMAPAR, R.A.G. 376-8 | B50: Ene-Ago | C50: 10467 | E50: =+C50+D50 -> 10467 | F50: =159.377+124.79+8.41+0.52+149.03+122.14+48.23+52.16+115.92+107.06+107.89+254.33+33.92+16.2+141.98+95.72+37.9+30.25+106.68+19.38+13.54+13.64+41.08+17.18+21.56+32.1+40.54+91.25+17.88+44.5+2.91+14.48+57.57+49.06+76.13+125.06+25.69+39.32+18.2+17.78+13.68+18.55+431.215+78.232+57.932+14.825 -> 3105.791 | G50: =+E50-F50 -> 7361.209 | H50: =+G50/E50 -> 0.70327783 | K50: =+(L50-F50) -> 0 | L50: 3105.791 | N50: =+C50+C116 -> 11018 | O50: =+F50+F116 -> 3402.564 | P50: =+N50-O50 -> 7615.436
...

Sheet RAE S.común
A2: RAE Sardina común 2013
A4: V región
A6: V Región A.G. Armadores artesanales del Puerto de San Antonio R.A.G. N° 2510
A7: Mes | B7: Total mes | C7: 1 | D7: 2 | E7: 3 | F7: 4 | G7: 5 | H7: 6 | I7: 7 | J7: 8 | K7: 9 | L7: 10 | M7: 11 | N7: 12 | O7: 13 | P7: 14 | Q7: 15 | R7: 16 | S7: 17 | T7: 18 | U7: 19 | V7: 20 | W7: 21 | X7: 22 | Y7: 23 | Z7: 24 | AA7: 25 | AB7: 26 | AC7: 27 | AD7: 28 | AE7: 29 | AF7: 30 | AG7: 31 | AH7: TOTAL
A8: Enero | B8: =+AH8 -> 0 | C8: VEDA | D8: VEDA | E8: VEDA | F8: VEDA | G8: VEDA | H8: VEDA | I8: VEDA | J8: VEDA | K8: VEDA | L8: VEDA | M8: VEDA | N8: VEDA | O8: VEDA | P8: VEDA | Q8: VEDA | R8: VEDA | S8: VEDA | T8: VEDA | U8: VEDA | V8: VEDA | W8: VEDA | X8: VEDA | Y8: VEDA | Z8: VEDA | AA8: VEDA | AB8: VEDA | AC8: VEDA | AD8: VEDA | AE8: VEDA | AF8: VEDA | AG8: VEDA | AH8: =SUM(C8:AG8) -> 0
A9: Febrero | B9: =+AH9 -> 0 | C9: VEDA | D9: VEDA | E9: VEDA | F9: VEDA | G9: VEDA | H9: VEDA | I9: VEDA | J9: VEDA | K9: VEDA | L9: VEDA | M9: VEDA | N9: VEDA | O9: VEDA | P9: VEDA | Q9: VEDA | R9: VEDA | S9: VEDA | T9: VEDA | U9: VEDA | V9: VEDA | W9: VEDA | X9: VEDA | Y9: VEDA | Z9: VEDA | AA9: VEDA | AB9: VEDA | AC9: VEDA | AD9: VEDA | AE9: VEDA | AF9: VEDA | AG9: VEDA | AH9: =SUM(C9:AG9) -> 0
A10: Marzo | B10: =+AH10 -> 2001.286 | C10: VEDA | D10: VEDA | E10: VEDA | F10: VEDA | G10: VEDA | H10: 366.74 | I10: 177.465 | J10: 223.156 | K10: 0 | L10: 0 | M10: 111.11 | N10: 172.355 | O10: 123.595 | P10: 0 | Q10: 0 | R10: 144.39 | S10: 77.38 | T10: 143.41 | U10: 48.145 | V10: 5.08 | W10: 35.915 | X10: 0 | Y10: 103.16 | Z10: 1.4 | AA10: 0 | AB10: 75.88 | AC10: 100.19 | AD10: 91.915 | AE10: 0 | AF10: 0 | AG10: 0 | AH10: =SUM(C10:AG10) -> 2001.286
A11: Abril | B11: =+AH11 -> 1673.287 | C11: 77.14 | D11: 85.095 | E11: 104.09 | F11: 90.575 | G11: 124.942 | H11: 103.325 | I11: 0 | J11: 87.435 | K11: 139.175 | L11: 127.58 | M11: 51.85 | N11: 0 | O11: 0 | P11: 177.105 | Q11: 107.93 | R11: 127.475 | S11: 0 | T11: 140.56 | U11: 76.52 | V11: 0 | W11: 44.01 | X11: 0 | Y11: 0 | Z11: 0 | AA11: 4.31 | AB11: 4.17 | AC11: 0 | AD11: 0 | AE11: 0 | AF11: 0 | AG11: 0 | AH11: =SUM(C11:AG11) -> 1673.287
A12: Mayo | B12: =+AH12 -> 436.503 | C12: 0 | D12: 0 | E12: 0 | F12: 0 | G12: 0 | H12: 0 | I12: 104.93 | J12: 95.31 | K12: 0 | L12: 11.955 | M12: 0 | N12: 0 | O12: 0 | P12: 0 | Q12: 0 | R12: 0 | S12: 139.318 | T12: 53.705 | U12: 0 | V12: 0 | W12: 0 | X12: 0 | Y12: 21.34 | Z12: 9.945 | AA12: 0 | AB12: 0 | AC12: 0 | AD12: 0 | AE12: 0 | AF12: 0 | AG12: 0 | AH12: =SUM(C12:AG12) -> 436.503
A13: Junio | B13: =+AH13 -> 0 | AH13: =SUM(C13:AG13) -> 0
A14: Julio | B14: =+AH14 -> 0 | AF14: veda | AG14: veda | AH14: =SUM(C14:AG14) -> 0
A15: Agosto | B15: =+AH15 -> 0 | C15: veda | D15: veda | E15: veda | F15: veda | G15: veda | H15: veda | I15: veda | J15: veda | K15: veda | L15: veda | M15: veda | N15: veda | O15: veda | P15: veda | Q15: veda | R15: veda | S15: veda | T15: veda | U15: veda | V15: veda | W15: veda | X15: veda | Y15: veda | Z15: veda | AA15: veda | AB15: veda | AC15: veda | AD15: veda | AE15: veda | AF15: veda | AG15: veda | AH15: =SUM(C15:AG15) -> 0
A16: Septiembre | B16: =+AH16 -> 0 | C16: veda | D16: veda | E16: veda | F16: veda | G16: veda | H16: veda | I16: veda | J16: veda | K16: veda | L16: veda | M16: veda | N16: veda | O16: veda | P16: veda | Q16: veda | R16: veda | S16: veda | T16: veda | U16: veda | V16: veda | W16: veda | X16: veda | Y16: veda | Z16: veda | AA16: veda | AB16: veda | AC16: veda | AD16: veda | AE16: veda | AF16: veda | AG16: veda | AH16: =SUM(C16:AG16) -> 0
A17: Octubre | B17: =+AH17 -> 0 | C17: veda | D17: veda | E17: veda | F17: veda | G17: veda | H17: veda | I17: veda | J17: veda | K17: veda | L17: veda | M17: veda | N17: veda | O17: veda | P17: veda | Q17: veda | R17: veda | S17: veda | T17: veda | U17: veda | V17: veda | W17: veda | AH17: =SUM(C17:AG17) -> 0
A18: Noviembre | B18: =+AH18 -> 0 | AH18: =SUM(C18:AG18) -> 0
A19: Diciembre | B19: =+AH19 -> 0 | P19: VEDA | Q19: VEDA | R19: VEDA | S19: VEDA | T19: VEDA | U19: VEDA | V19: VEDA | W19: VEDA | X19: VEDA | Y19: VEDA | Z19: VEDA | AA19: VEDA | AB19: VEDA | AC19: VEDA | AD19: VEDA | AE19: VEDA | AF19: VEDA | AG19: VEDA | AH19: =SUM(C19:AG19) -> 0
A20: Total | B20: =SUM(B8:B19) -> 4111.076 | C20: =SUM(C8:C18) -> 77.14 | D20: =SUM(D8:D18) -> 85.095 | E20: 0 | F20: =SUM(F8:F18) -> 90.575 | G20: =SUM(G8:G18) -> 124.942 | H20: =SUM(H8:H18) -> 470.065 | I20: =SUM(I8:I18) -> 282.395 | J20: =SUM(J8:J18) -> 405.901 | K20: =SUM(K8:K18) -> 139.175 | L20: =SUM(L8:L18) -> 139.535 | M20: =SUM(M8:M18) -> 162.96 | ... AC20: =SUM(AC8:AC18) -> 100.19 | AD20: 0 | AE20: =SUM(AE8:AE18) -> 0 | AF20: =SUM(AF8:AF18) -> 0 | AG20: =SUM(AG8:AG18) -> 0 | AH20: =SUM(AH8:AH18) -> 4111.076
A22: Cuota bolsón o residual
