Workbook

Sheet Resumen
A2: Resumen Artesanal por unidad de pesquería, 2012
A3: Al 24 ENERO de 2013
A4: Recurso | B4: Unidad de pesquería | C4: Cuota Global (t) | D4: Desembarque total (t) | E4: Saldo total (t) | F4: % consumido 2012 | G4: % consumido 2011
A5: Jurel | B5: III | C5: =+Global!C29 -> 1141 | D5: =+Global!D29 -> 1116.061 | E5: =+C5-D5 -> 24.939 | F5: =+D5/C5 -> 0.97814286
B6: IV | C6: =+Global!C30 -> 2662 | D6: =+Global!D30 -> 2464.378 | E6: =+C6-D6 -> 197.622 | F6: =+D6/C6 -> 0.92576183
B7: V (RAE por Org) | C7: =+Global!C31 -> 1253 | D7: =+Global!D31 -> 395.985 | E7: =+C7-D7 -> 857.015 | F7: =+D7/C7 -> 0.31602953
B8: VIII | C8: =+Global!C34 -> 2671 | D8: =+Global!D34 -> 2670.063 | E8: =+C8-D8 -> 0.937 | F8: =+D8/C8 -> 0.9996492
B9: Otras regiones (XV,I, II, VI, VII, IX, XIV y X) | C9: =+Global!C27+Global!C28+Global!C32+Global!C33+Global!C35+Global!C36+Global!C37 -> 4258 | D9: =+Global!D27+Global!D28+Global!D32+Global!D33+Global!D35+Global!D36+Global!D37 -> 740.049 | E9: =+C9-D9 -> 3517.951 | F9: =+D9/C9 -> 0.17380202
A10: Jibia | B10: XV- XII regs. | C10: =+SUM(Global!C38) -> 138240 | D10: =+SUM(Global!D38) -> 100599.54 | E10: =+C10-D10 -> 37640.461 | F10: =+D10/C10 -> 0.72771657
A11: Anchoveta | B11: V (RAE por Org) | C11: =+Global!C10 -> 2410 | D11: =+Global!D10 -> 2409.701 | E11: =+C11-D11 -> 0.299 | F11: =+D11/C11 -> 0.99987593
B12: VI | C12: =+Global!C11 -> 15 | D12: =+Global!D11 -> 0 | E12: =+C12-D12 -> 15 | F12: =+D12/C12 -> 0
B13: VII | C13: =+Global!C12 -> 258 | D13: =+Global!D12 -> 580.084 | E13: =+C13-D13 -> -322.084 | F13: =+D13/C13 -> 2.2483876
B14: VIII (RAE por Org) | C14: =+Global!C13 -> 30884 | D14: =+Global!D13 -> 44144.653 | E14: =+C14-D14 -> -13260.653 | F14: =+D14/C14 -> 1.4293697
B15: XIV (RAE por Org) | C15: =+Global!C15 -> 2900 | D15: =+Global!D15 -> 751.229 | E15: =+C15-D15 -> 2148.771 | F15: =+D15/C15 -> 0.25904448
B16: X (RAE por Org) | C16: =+Global!C16 -> 1787 | D16: =+Global!D16 -> 98.712 | E16: =+C16-D16 -> 1688.288 | F16: =+D16/C16 -> 0.055238948
B17: Otras regiones (XV a IV, VI, VII y IX) | C17: =+Global!C6+Global!C7+Global!C8+Global!C9+Global!C11+Global!C12+Global!C14 -> 126151 | D17: =+Global!D6+Global!D7+Global!D8+Global!D9+Global!D11+Global!D12+Global!D14 -> 122066.11 | E17: =+C17-D17 -> 4084.891 | F17: =+D17/C17 -> 0.96761904
A18: Sardina común | B18: V (RAE por Org) | C18: =+Global!C57 -> 10352 | D18: =+Global!D57 -> 9712.112 | E18: =+C18-D18 -> 639.888 | F18: =+D18/C18 -> 0.93818702
B19: VIII (RAE por Org) | C19: =+Global!C60 -> 588550.23 | D19: =+Global!D60 -> 475542.87 | E19: =+C19-D19 -> 113007.36 | F19: =+D19/C19 -> 0.80799028
B20: XIV (RAE por Org) | C20: =+Global!C62 -> 88434.014 | D20: =+Global!D62 -> 88025.842 | E20: =+C20-D20 -> 408.172 | F20: =+D20/C20 -> 0.99538445
B21: X (RAE por Org) | C21: =+Global!C63 -> 39582 | D21: =+Global!D63 -> 17754.391 | E21: =+C21-D21 -> 21827.609 | F21: =+D21/C21 -> 0.44854709
B22: Otras regiones (VI, VII y IX) | C22: =+Global!C58+Global!C59+Global!C61 -> 12627 | D22: =+Global!D58+Global!D59+Global!D61 -> 10573.352 | E22: =+C22-D22 -> 2053.648 | F22: =+D22/C22 -> 0.83736058
A23: Merluza común | B23: V | C23: =+Global!C45 -> 4024.331 | D23: =+Global!D45 -> 3475.033 | E23: =+C23-D23 -> 549.298 | F23: =+D23/C23 -> 0.86350576
B24: VII | C24: =+Global!C47 -> 5408.818 | D24: =+Global!D47 -> 4698.305 | E24: =+C24-D24 -> 710.513 | F24: =+D24/C24 -> 0.86863803
B25: VIII (RAE por Org) | C25: =+Global!C48 -> 4867.214 | D25: =+Global!D48 -> 3372.11 | E25: =+C25-D25 -> 1495.104 | F25: =+D25/C25 -> 0.6928214
B26: Otras regiones (IV, VI, IX, XIV y X) | C26: =+Global!C44+Global!C46+Global!C49+Global!C50 -> 1808.992 | D26: =+Global!D44+Global!D46+Global!D49+Global!D50 -> 1486.91 | E26: =+C26-D26 -> 322.082 | F26: =+D26/C26 -> 0.82195499
A27: Merluza del sur | B27: X | C27: =+Global!C51 -> 6000 | D27: =+Global!D51 -> 4089.0716 | E27: =+C27-D27 -> 1910.9284 | F27: =+D27/C27 -> 0.68151193
B28: XI | C28: =+Global!C52 -> 3298.824 | D28: =+Global!D52 -> 1954.593 | E28: =+C28-D28 -> 1344.231 | F28: =+D28/C28 -> 0.59251206
B29: XII | C29: =+Global!C53 -> 1664 | D29: =+Global!D53 -> 1369.8015 | E29: =+C29-D29 -> 294.19851 | F29: =+D29/C29 -> 0.82319801
A30: Camarón nailon | B30: IV | C30: =+Global!C19 -> 430 | D30: =+Global!D19 -> 437.99 | E30: =+C30-D30 -> -7.99 | F30: =+D30/C30 -> 1.0185814
B31: V | C31: =+Global!C20 -> 430 | D31: =+Global!D20 -> 432.292 | E31: =+C31-D31 -> -2.292 | F31: =+D31/C31 -> 1.0053302
B32: Otras regiones (II, III, VI a VIII) | C32: =+Global!C17+Global!C18+Global!C21+Global!C22+Global!C23 -> 129 | D32: =+Global!D17+Global!D18+Global!D21+Global!D22+Global!D23 -> 1.083 | E32: =+C32-D32 -> 127.917 | F32: =+D32/C32 -> 0.0083953488
A33: Congrio dorado | B33: X - XII | C33: =+Global!C24+Global!C25+Global!C26 -> 405 | D33: =+Global!D24+Global!D25+Global!D26 -> 410.69119 | E33: =+C33-D33 -> -5.6911944 | F33: =+D33/C33 -> 1.0140523
A34: Langostino amarillo | B34: III | C34: =+Global!C39 -> 196 | D34: =+Global!D39 -> 13.638 | E34: =+C34-D34 -> 182.362 | F34: =+D34/C34 -> 0.069581633
B35: IV | C35: =+Global!C40 -> 781 | D35: =+Global!D40 -> 817.722 | E35: =+C35-D35 -> -36.722 | F35: =+D35/C35 -> 1.0470192
A36: Langostino colorado | B36: II | C36: =+Global!C41 -> 20 | D36: =+Global!D41 -> 0 | E36: =+C36-D36 -> 20 | F36: =+D36/C36 -> 0
B37: III | C37: =+Global!C42 -> 150 | D37: =+Global!D42 -> 0 | E37: =+C37-D37 -> 150 | F37: =+D37/C37 -> 0
B38: IV | C38: =+Global!C43 -> 515 | D38: =+Global!D43 -> 516.566 | E38: =+C38-D38 -> -1.566 | F38: =+D38/C38 -> 1.0030408
A39: Sardina española | B39: XV y I | C39: =+Global!C54 -> 525 | D39: =+Global!D54 -> 12.128 | E39: =+C39-D39 -> 512.872 | F39: =+D39/C39 -> 0.023100952
B40: II | C40: =+Global!C55 -> 1975 | D40: =+Global!D55 -> 172.922 | E40: =+C40-D40 -> 1802.078 | F40: =+D40/C40 -> 0.087555443
B41: III - IV | C41: =+Global!C56 -> 625 | D41: =+Global!D56 -> 8.426 | E41: =+C41-D41 -> 616.574 | F41: =+D41/C41 -> 0.0134816
...

Sheet Global
A2: Resumen Global Cuotas Artesanales 2012
A3: Al 24 ENERO de 2013
A5: Recurso | B5: Unidad de pesquería | C5: Cuota Global (t) | D5: Desembarque total (t) | E5: Saldo total (t) | F5: % consumido 2012 | G5: % consumido 2011
A6: Anchoveta | B6: XV y I | C6: =+'Res. Global'!E7+'Res. Global'!E8 -> 73879 | D6: =+SUM('Res. Global'!G7:G8) -> 73839.434 | E6: =+C6-D6 -> 39.566 | F6: =+D6/C6 -> 0.99946445 | G6: 1.0004208
A7: Anchoveta | B7: II | C7: =+SUM('Res. Global'!E9:E10) -> 22068 | D7: =+SUM('Res. Global'!G9:G10) -> 20013.479 | E7: =+C7-D7 -> 2054.521 | F7: =+D7/C7 -> 0.90690044 | G7: 0.72571316
A8: Anchoveta | B8: III | C8: =+SUM('Res. Global'!E11:E12) -> 20615 | D8: =+SUM('Res. Global'!G11:G12) -> 19012.21 | E8: =+C8-D8 -> 1602.79 | F8: =+D8/C8 -> 0.92225127 | G8: 1.011722
A9: Anchoveta | B9: IV | C9: =+SUM('Res. Global'!E13:E14) -> 8835 | D9: =+SUM('Res. Global'!G13:G14) -> 8530.777 | E9: =+C9-D9 -> 304.223 | F9: =+D9/C9 -> 0.96556616 | G9: 0.9212029
A10: Anchoveta | B10: V (RAE por Org) | C10: =+SUM('Res. Global'!E15:E17) -> 2410 | D10: =+SUM('Res. Global'!G15:G17) -> 2409.701 | E10: =+C10-D10 -> 0.299 | F10: =+D10/C10 -> 0.99987593 | G10: 1.0024192
A11: Anchoveta | B11: VI | C11: =+SUM('Res. Global'!E18:E20) -> 15 | D11: =+SUM('Res. Global'!G18:G20) -> 0 | E11: =+C11-D11 -> 15 | F11: =+D11/C11 -> 0 | G11: 0
A12: Anchoveta | B12: VII | C12: =+SUM('Res. Global'!E21:E23) -> 258 | D12: =+SUM('Res. Global'!G21:G23) -> 580.084 | E12: =+C12-D12 -> -322.084 | F12: =+D12/C12 -> 2.2483876 | G12: 2.3895703
A13: Anchoveta | B13: VIII (RAE por Org) | C13: =+SUM('Res. Global'!E24:E25) -> 30884 | D13: =+SUM('Res. Global'!G24:G25) -> 44144.653 | E13: =+C13-D13 -> -13260.653 | F13: =+D13/C13 -> 1.4293697 | G13: 2.6155879
A14: Anchoveta | B14: IX | C14: =+SUM('Res. Global'!E26:E28) -> 481 | D14: =+SUM('Res. Global'!G26:G28) -> 90.125 | E14: =+C14-D14 -> 390.875 | F14: =+D14/C14 -> 0.18737006 | G14: 0.13915665
A15: Anchoveta | B15: XIV (RAE por Org) | C15: =+SUM('Res. Global'!E29:E31) -> 2900 | D15: =+SUM('Res. Global'!G29:G31) -> 751.229 | E15: =+C15-D15 -> 2148.771 | F15: =+D15/C15 -> 0.25904448 | G15: 0.15908861
A16: Anchoveta | B16: X (RAE por Org) | C16: =+SUM('Res. Global'!E32:E33) -> 1787 | D16: =+SUM('Res. Global'!G32:G33) -> 98.712 | E16: =+C16-D16 -> 1688.288 | F16: =+D16/C16 -> 0.055238948 | G16: 0.75441022
A17: Camarón nailon | B17: II | C17: =+SUM('Res. Global'!E34:E36) -> 15 | D17: =+SUM('Res. Global'!G34:G36) -> 0 | E17: =+C17-D17 -> 15 | F17: =+D17/C17 -> 0 | G17: 0
A18: Camarón nailon | B18: III | C18: =+SUM('Res. Global'!E37:E39) -> 90 | D18: =+SUM('Res. Global'!G37:G39) -> 1.083 | E18: =+C18-D18 -> 88.917 | F18: =+D18/C18 -> 0.012033333 | G18: 0.36196667
A19: Camarón nailon | B19: IV | C19: =+SUM('Res. Global'!E40:E42) -> 430 | D19: =+SUM('Res. Global'!G40:G42) -> 437.99 | E19: =+C19-D19 -> -7.99 | F19: =+D19/C19 -> 1.0185814 | G19: 1.017014
A20: Camarón nailon | B20: V | C20: =+SUM('Res. Global'!E43:E45) -> 430 | D20: =+SUM('Res. Global'!G43:G45) -> 432.292 | E20: =+C20-D20 -> -2.292 | F20: =+D20/C20 -> 1.0053302 | G20: 0.99819488
A21: Camarón nailon | B21: VI | C21: =+SUM('Res. Global'!E46:E48) -> 8 | D21: =+SUM('Res. Global'!G46:G48) -> 0 | E21: =+C21-D21 -> 8 | F21: =+D21/C21 -> 0 | G21: 0
A22: Camarón nailon | B22: VII | C22: =+SUM('Res. Global'!E49:E51) -> 8 | D22: =+SUM('Res. Global'!G49:G51) -> 0 | E22: =+C22-D22 -> 8 | F22: =+D22/C22 -> 0 | G22: 0
A23: Camarón nailon | B23: VIII | C23: =+SUM('Res. Global'!E52:E54) -> 8 | D23: =+SUM('Res. Global'!G52:G54) -> 0 | E23: =+C23-D23 -> 8 | F23: =+D23/C23 -> 0 | G23: 0
A24: Congrio dorado | B24: X | C24: =+SUM('Res. Global'!E55:E56) -> 259 | D24: =+SUM('Res. Global'!G55:G56) -> 261.83689 | E24: =+C24-D24 -> -2.8368944 | F24: =+D24/C24 -> 1.0109533 | G24: 1.0958585
A25: Congrio dorado | B25: XI | C25: =+SUM('Res. Global'!E57:E58) -> 85 | D25: =+SUM('Res. Global'!G57:G58) -> 86.108 | E25: =+C25-D25 -> -1.108 | F25: =+D25/C25 -> 1.0130353 | G25: 0.83410703
A26: Congrio dorado | B26: XII | C26: =+SUM('Res. Global'!E59:E60) -> 61 | D26: =+SUM('Res. Global'!G59:G60) -> 62.7463 | E26: =+C26-D26 -> -1.7463 | F26: =+D26/C26 -> 1.0286279 | G26: 1.0086484
A27: Jurel | B27: XV y I | C27: =+SUM('Res. Global'!E61:E62) -> 875 | D27: =+SUM('Res. Global'!G61:G62) -> 8.449 | E27: =+C27-D27 -> 866.551 | F27: =+D27/C27 -> 0.009656 | G27: 0.0065688073
A28: Jurel | B28: II | C28: =+SUM('Res. Global'!E63:E64) -> 875 | D28: =+SUM('Res. Global'!G63:G64) -> 107.57 | E28: =+C28-D28 -> 767.43 | F28: =+D28/C28 -> 0.12293714 | G28: 0.1650581
A29: Jurel | B29: III | C29: =+SUM('Res. Global'!E65:E66) -> 1141 | D29: =+SUM('Res. Global'!G65:G66) -> 1116.061 | E29: =+C29-D29 -> 24.939 | F29: =+D29/C29 -> 0.97814286 | G29: 1.0173142
A30: Jurel | B30: IV | C30: =+SUM('Res. Global'!E67:E68) -> 2662 | D30: =+SUM('Res. Global'!G67:G68) -> 2464.378 | E30: =+C30-D30 -> 197.622 | F30: =+D30/C30 -> 0.92576183 | G30: 0.89670094
A31: Jurel | B31: V (RAE por Org) | C31: =+SUM('Res. Global'!E69:E70) -> 1253 | D31: =+SUM('Res. Global'!G69:G70) -> 395.985 | E31: =+C31-D31 -> 857.015 | F31: =+D31/C31 -> 0.31602953 | G31: 0.13618447
A32: Jurel | B32: VI | C32: =+SUM('Res. Global'!E71:E72) -> 5 | D32: =+SUM('Res. Global'!G71:G72) -> 0.463 | E32: =+C32-D32 -> 4.537 | F32: =+D32/C32 -> 0.0926 | G32: 0.014
A33: Jurel | B33: VII | C33: =+SUM('Res. Global'!E73:E74) -> 41 | D33: =+SUM('Res. Global'!G73:G74) -> 14.818 | E33: =+C33-D33 -> 26.182 | F33: =+D33/C33 -> 0.36141463 | G33: 0.65481395
A34: Jurel | B34: VIII | C34: =+SUM('Res. Global'!E75:E76) -> 2671 | D34: =+SUM('Res. Global'!G75:G76) -> 2670.063 | E34: =+C34-D34 -> 0.937 | F34: =+D34/C34 -> 0.9996492 | G34: 0.89481054
A35: Jurel | B35: IX | C35: =+SUM('Res. Global'!E77:E78) -> 60 | D35: =+SUM('Res. Global'!G77:G78) -> 0 | E35: =+C35-D35 -> 60 | F35: =+D35/C35 -> 0 | G35: 0
A36: Jurel | B36: XIV (RAE por Org) | C36: =+SUM('Res. Global'!E79:E80) -> 312 | D36: =+SUM('Res. Global'!G79:G80) -> 0.528 | E36: =+C36-D36 -> 311.472 | F36: =+D36/C36 -> 0.0016923077 | G36: 0
A37: Jurel | B37: X (RAE por Org) | C37: =+SUM('Res. Global'!E81:E82) -> 2090 | D37: =+SUM('Res. Global'!G81:G82) -> 608.221 | E37: =+C37-D37 -> 1481.779 | F37: =+D37/C37 -> 0.29101483 | G37: 0
A38: Jibia | B38: XV- XII regs. | C38: =+SUM('Res. Global'!C83) -> 138240 | D38: =+SUM('Res. Global'!G83) -> 100599.54 | E38: =+C38-D38 -> 37640.461 | F38: =+D38/C38 -> 0.72771657 | G38: 0
A39: Langostino amarillo | B39: III | C39: =+SUM('Res. Global'!E84:E86) -> 196 | D39: =+SUM('Res. Global'!G84:G86) -> 13.638 | E39: =+C39-D39 -> 182.362 | F39: =+D39/C39 -> 0.069581633 | G39: 0.56482133
A40: Langostino amarillo | B40: IV | C40: =+SUM('Res. Global'!E87:E89) -> 781 | D40: =+SUM('Res. Global'!G87:G89) -> 817.722 | E40: =+C40-D40 -> -36.722 | F40: =+D40/C40 -> 1.0470192 | G40: 1.0077206
A41: Langostino colorado | B41: II | C41: =+SUM('Res. Global'!E90:E92) -> 20 | D41: =+SUM('Res. Global'!G90:G92) -> 0 | E41: =+C41-D41 -> 20 | F41: =+D41/C41 -> 0 | G41: 0
A42: Langostino colorado | B42: III | C42: =+SUM('Res. Global'!E93:E95) -> 150 | D42: =+SUM('Res. Global'!G93:G95) -> 0 | E42: =+C42-D42 -> 150 | F42: =+D42/C42 -> 0 | G42: 8.2352941e-05
...

Sheet Res. Global
A2: Resumen por Periodo Cuota Artesanal 2012
A3: Al 24 ENERO 2013
E5: Cuota (t) | G5: Desembarque (t) | I5: Saldo (t) | K5: Saldo % | M5: Fecha de Cierre
A6: Recurso | B6: Unidad de Pesquería | C6: Cuota Global (t) | D6: Período | E6: Asignada | F6: Efectiva | G6: Período | H6: Global | I6: Período | J6: Global | K6: Período | L6: Global | O6: Datos Access
A7: Anchoveta | B7: XV y I | C7: =SUM(E7:E8) -> 73879 | D7: Ene - Jun | E7: 54045 | F7: =+E7 -> 54045 | G7: =+SUM(Anchoveta!B7:B12) -> 61617.402 | H7: =SUM(G7:G8) -> 73839.434 | I7: =+F7-G7 -> -7572.402 | J7: =+C7-H7 -> 39.566 | K7: =1-G7/F7 -> -0.14011291 | L7: =1-H7/C7 -> 0.00053555137 | M7: 41054 | N7: Desmbarque XV-I incluye cesiones | O7: 135764.65
D8: Jul - Dic | E8: 19834 | F8: =+E8+I7 -> 12261.598 | G8: =+SUM(Anchoveta!B13:B18) -> 12222.032 | I8: =+F8-G8 -> 39.566 | K8: =1-G8/F8 -> 0.0032268225 | M8: 41123
A9: Anchoveta | B9: II | C9: =SUM(E9:E10) -> 22068 | D9: Ene - Jun | E9: 16144 | F9: =+E9 -> 16144 | G9: =+SUM(Anchoveta!B23:B28) -> 11195.23 | H9: =SUM(G9:G10) -> 20013.479 | I9: =+F9-G9 -> 4948.77 | J9: =+C9-H9 -> 2054.521 | K9: =1-G9/F9 -> 0.30653927 | L9: =1-H9/C9 -> 0.093099556 | N9: Desmbarque II incluye cesiones | O9: 20451.727
D10: Jul - Dic | E10: 5924 | F10: =+E10+I9 -> 10872.77 | G10: =+SUM(Anchoveta!B29:B34) -> 8818.249 | I10: =+F10-G10 -> 2054.521 | K10: =1-G10/F10 -> 0.18896022
A11: Anchoveta | B11: III | C11: =SUM(E11:E12) -> 20615 | D11: Ene - Oct | E11: 19584 | F11: =+E11 -> 19584 | G11: =+SUM(Anchoveta!B39:B48) -> 16350.21 | H11: =SUM(G11:G12) -> 19012.21 | I11: =+F11-G11 -> 3233.79 | J11: =+C11-H11 -> 1602.79 | K11: =1-G11/F11 -> 0.16512408 | L11: =1-H11/C11 -> 0.077748727
D12: Nov - Dic | E12: 1031 | F12: =+E12+I11 -> 4264.79 | G12: =+SUM(Anchoveta!B49:B50) -> 2662 | I12: =+F12-G12 -> 1602.79 | K12: =1-G12/F12 -> 0.37581921
A13: Anchoveta | B13: IV | C13: =SUM(E13:E14) -> 8835 | D13: Ene - Oct | E13: =+'Resumen RAE Anchoveta'!C10 -> 8393 | F13: =+E13 -> 8393 | G13: =+SUM('Resumen RAE Anchoveta'!F10) -> 8483.687 | H13: =SUM(G13:G14) -> 8530.777 | I13: =+F13-G13 -> -90.687 | J13: =+C13-H13 -> 304.223 | K13: =1-G13/F13 -> -0.010805076 | L13: =1-H13/C13 -> 0.034433843
D14: Nov - Dic | E14: =+'Resumen RAE Anchoveta'!C16 -> 442 | F14: =+E14+I13 -> 351.313 | G14: =+SUM('Resumen RAE Anchoveta'!F16) -> 47.09 | I14: =+F14-G14 -> 304.223 | K14: =1-G14/F14 -> 0.86595998
A15: Anchoveta | B15: V (RAE por Org) | C15: =SUM(E15:E17) -> 2410 | D15: Ene-Abr | E15: =+SUM('Resumen RAE Anchoveta'!C23) -> 2049 | F15: =+E15 -> 2049 | G15: =+'Resumen RAE Anchoveta'!F23 -> 742.536 | H15: =SUM(G15:G17) -> 2409.701 | I15: =+F15-G15 -> 1306.464 | J15: =+C15-H15 -> 0.299 | K15: =1-G15/F15 -> 0.63761054 | L15: =1-H15/C15 -> 0.00012406639
D16: May-Ago | E16: =+SUM('Resumen RAE Anchoveta'!C28) -> 241 | F16: =+E16+I15 -> 1547.464 | G16: =+'Resumen RAE Anchoveta'!F28 -> 865.055 | I16: =+F16-G16 -> 682.409 | K16: =1-G16/F16 -> 0.44098538
D17: Sep-Dic | E17: =+SUM('Resumen RAE Anchoveta'!C33) -> 120 | F17: =+E17+I16 -> 802.409 | G17: =+'Resumen RAE Anchoveta'!F33 -> 802.11 | I17: =+F17-G17 -> 0.299 | K17: =1-G17/F17 -> 0.00037262792
A18: Anchoveta | B18: VI | C18: =SUM(E18:E20) -> 15 | D18: Ene-Abr | E18: 12 | F18: =+E18 -> 12 | G18: =+SUM(Anchoveta!B55:B58) -> 0 | H18: =SUM(G18:G20) -> 0 | I18: =+F18-G18 -> 12 | J18: =+C18-H18 -> 15 | K18: =1-G18/F18 -> 1 | L18: =1-H18/C18 -> 1
D19: May-Ago | E19: 2 | F19: =+E19+I18 -> 14 | G19: =+SUM(Anchoveta!B59:B62) -> 0 | I19: =+F19-G19 -> 14 | K19: =1-G19/F19 -> 1
D20: Sep-Dic | E20: 1 | F20: =+E20+I19 -> 15 | G20: =+SUM(Anchoveta!B63:B66) -> 0 | I20: =+F20-G20 -> 15 | K20: =1-G20/F20 -> 1
A21: Anchoveta | B21: VII | C21: =SUM(E21:E23) -> 258 | D21: Ene-Abr | E21: 219 | F21: =+E21 -> 219 | G21: =+SUM('Resumen RAE Anchoveta'!F40) -> 453.152 | H21: =SUM(G21:G23) -> 580.084 | I21: =+F21-G21 -> -234.152 | J21: =+C21-H21 -> -322.084 | K21: =1-G21/F21 -> -1.0691872 | L21: =1-H21/C21 -> -1.2483876 | M21: 41031
D22: May-Ago | E22: 26 | F22: =+E22+I21 -> -208.152 | G22: =+SUM('Resumen RAE Anchoveta'!F45+'Resumen RAE Anchoveta'!F45) -> 126.932 | I22: =+F22-G22 -> -335.084 | K22: 0
D23: Sep-Dic | E23: 13 | F23: =+E23+I22 -> -322.084 | G23: =+SUM('Resumen RAE Anchoveta'!F50) -> 0 | I23: =+F23-G23 -> -322.084 | K23: 0
A24: Anchoveta | B24: VIII (RAE por Org) | C24: =SUM(E24:E25) -> 30884 | D24: Ene- Ago | E24: 29340 | F24: =+E24 -> 29340 | G24: =SUM('Resumen RAE Anchoveta'!F116)+-SUM('Resumen RAE Anchoveta'!D116) -> 42783.287 | H24: =SUM(G24:G25) -> 44144.653 | I24: =+F24-G24 -> -13443.287 | J24: =+C24-H24 -> -13260.653 | K24: =1-G24/F24 -> -0.45818974 | L24: =1-H24/C24 -> -0.42936967 | M24: 41031
D25: Sep - Dic | E25: 1544 | F25: =+E25+I24 -> -11899.287 | G25: =+SUM('Resumen RAE Anchoveta'!F180)+-SUM('Resumen RAE Anchoveta'!D180) -> 1361.366 | I25: =+F25-G25 -> -13260.653 | K25: =1-G25/F25 -> 1.1144074
A26: Anchoveta | B26: IX | C26: =SUM(E26:E28) -> 481 | D26: Ene-Abr | E26: 409 | F26: =+E26 -> 409 | G26: =+SUM(Anchoveta!B72:B75) -> 7.864 | H26: =SUM(G26:G28) -> 90.125 | I26: =+F26-G26 -> 401.136 | J26: =+C26-H26 -> 390.875 | K26: =1-G26/F26 -> 0.98077262 | L26: =1-H26/C26 -> 0.81262994 | M26: 41014
D27: May-Ago | E27: 48 | F27: =+E27+I26 -> 449.136 | G27: =+SUM(Anchoveta!B76:B79) -> 82.261 | I27: =+F27-G27 -> 366.875 | K27: =1-G27/F27 -> 0.81684612
D28: Sep-Dic | E28: 24 | F28: =+E28+I27 -> 390.875 | G28: =+SUM(Anchoveta!B80:B83) -> 0 | I28: =+F28-G28 -> 390.875 | K28: =1-G28/F28 -> 1
A29: Anchoveta | B29: XIV (RAE por Org) | C29: =SUM(E29:E31) -> 2900 | D29: Ene-Abr | E29: 2465 | F29: =+E29 -> 2465 | G29: =+'Resumen RAE Anchoveta'!F202 -> 280.681 | H29: =SUM(G29:G31) -> 751.229 | I29: =+F29-G29 -> 2184.319 | J29: =+C29-H29 -> 2148.771 | K29: =1-G29/F29 -> 0.88613347 | L29: =1-H29/C29 -> 0.74095552
D30: May-Ago | E30: 290 | F30: =+E30+I29 -> 2474.319 | G30: =+'Resumen RAE Anchoveta'!F222 -> 143.832 | I30: =+F30-G30 -> 2330.487 | K30: =1-G30/F30 -> 0.94187007
D31: Sep-Dic | E31: 145 | F31: =+E31+I30 -> 2475.487 | G31: =+'Resumen RAE Anchoveta'!F242 -> 326.716 | I31: =+F31-G31 -> 2148.771 | K31: =1-G31/F31 -> 0.8680195
A32: Anchoveta | B32: X (RAE por Org) | C32: =SUM(E32:E33) -> 1787 | D32: Ene-Jun | E32: 1430 | F32: =+E32 -> 1430 | G32: =+SUM('Resumen RAE Anchoveta'!F257) -> 97.512 | H32: =SUM(G32:G33) -> 98.712 | I32: =+F32-G32 -> 1332.488 | J32: =+C32-H32 -> 1688.288 | K32: =1-G32/F32 -> 0.93180979 | L32: =1-H32/C32 -> 0.94476105
D33: Jul-Dic | E33: 357 | F33: =+E33+I32 -> 1689.488 | G33: =+'Resumen RAE Anchoveta'!F270 -> 1.2 | I33: =+F33-G33 -> 1688.288 | K33: =1-G33/F33 -> 0.99928973
A34: Camarón nailon | B34: II | C34: =SUM(E34:E36) -> 15 | D34: Ene - Mar | E34: 6 | F34: =+E34 -> 6 | G34: =+SUM(C.Nailon!B7:B9) -> 0 | H34: =SUM(G34:G36) -> 0 | I34: =+F34-G34 -> 6 | J34: =+C34-H34 -> 15 | K34: =1-G34/F34 -> 1 | L34: =1-H34/C34 -> 1
D35: Abr - Ago | E35: 4 | F35: =+E35+I34 -> 10 | G35: =+SUM(C.Nailon!B10:B14) -> 0 | I35: =+F35-G35 -> 10 | K35: =1-G35/F35 -> 1
D36: Sep - Dic | E36: 5 | F36: =+E36+I35 -> 15 | G36: =+SUM(C.Nailon!B15:B18) -> 0 | I36: =+F36-G36 -> 15 | K36: =1-G36/F36 -> 1
A37: Camarón nailon | B37: III | C37: =SUM(E37:E39) -> 90 | D37: Ene - Mar | E37: 41 | F37: =+E37 -> 41 | G37: =+SUM(C.Nailon!B23:B25) -> 0 | H37: =SUM(G37:G39) -> 1.083 | I37: =+F37-G37 -> 41 | J37: =+C37-H37 -> 88.917 | K37: =1-G37/F37 -> 1 | L37: =1-H37/C37 -> 0.98796667
D38: Abr - Ago | E38: 23 | F38: =+E38+I37 -> 64 | G38: =+SUM(C.Nailon!B26:B30) -> 0 | I38: =+F38-G38 -> 64 | K38: =1-G38/F38 -> 1
D39: Sep - Dic | E39: 26 | F39: =+E39+I38 -> 90 | G39: =+SUM(C.Nailon!B31:B34) -> 1.083 | I39: =+F39-G39 -> 88.917 | K39: =1-G39/F39 -> 0.98796667
A40: Camarón nailon | B40: IV | C40: =SUM(E40:E42) -> 430 | D40: Ene - Mar | E40: 193 | F40: =+E40 -> 193 | G40: =+SUM(C.Nailon!B39:B41) -> 203.868 | H40: =SUM(G40:G42) -> 437.99 | I40: =+F40-G40 -> -10.868 | J40: =+C40-H40 -> -7.99 | K40: =1-G40/F40 -> -0.056310881 | L40: =1-H40/C40 -> -0.018581395 | M40: 40980
D41: Abr - Ago | E41: 107 | F41: =+E41+I40 -> 96.132 | G41: =+SUM(C.Nailon!B42:B46) -> 103.271 | I41: =+F41-G41 -> -7.139 | K41: =1-G41/F41 -> -0.074262472 | M41: 41081
D42: Sep - Dic | E42: 130 | F42: =+E42+I41 -> 122.861 | G42: =+SUM(C.Nailon!B47:B50) -> 130.851 | I42: =+F42-G42 -> -7.99 | K42: =1-G42/F42 -> -0.065032842 | M42: 41225
...

Sheet Resumen RAE Anchoveta
A2: Resumen RAE Anchoveta 2012
A4: IV Región, de Coquimbo
A6: Organización | B6: Periodo | C6: Cuota asignada (t) | D6: TRAPASOS | E6: Cuota efectiva (t) | F6: Desembarque (t) | G6: Saldo (t) | H6: % | I6: Fecha de Cierre
A7: Cooperativa de Armadores Cerqueros IV Región | B7: Ene-Oct | C7: 8321 | E7: =+C7 -> 8321 | F7: =+SUM('RAE Anchoveta'!B8:B17) -> 8387.066 | G7: =+E7-F7 -> -66.066 | H7: =+G7/E7 -> -0.0079396707 | I7: 41207
A8: A.G. de pescadores Art. Y Buzos Marisc. De Coquimbo IV Región | B8: Ene-Oct | C8: 56 | E8: =+C8 -> 56 | F8: =+SUM('RAE Anchoveta'!B24:B33) -> 2.92 | G8: =+E8-F8 -> 53.08 | H8: =+G8/E8 -> 0.94785714
A9: Cuota Residual - Bolson | B9: Ene-Oct | C9: 16 | E9: =+C9 -> 16 | F9: =+SUM('RAE Anchoveta'!B40:B49) -> 93.701 | G9: =+E9-F9 -> -77.701 | H9: =+G9/E9 -> -4.8563125 | I9: 41033
A10: Total | B10: Ene-Oct | C10: =SUM(C7:C9) -> 8393 | E10: =SUM(E7:E9) -> 8393 | F10: =SUM(F7:F9) -> 8483.687 | G10: =+E10-F10 -> -90.687
A12: Organización | B12: Periodo | C12: Cuota asignada (t) | E12: Cuota efectiva (t) | F12: Desembarque (t) | G12: Saldo (t) | H12: % | I12: Fecha de Cierre
A13: Cooperativa de Armadores Cerqueros IV Región | B13: Nov-Dic | C13: 438 | E13: =+C13+G7 -> 371.934 | F13: =+SUM('RAE Anchoveta'!B18:B19) -> 45.09 | G13: =+E13-F13 -> 326.844 | H13: =+G13/E13 -> 0.87876881
A14: A.G. de pescadores Art. Y Buzos Marisc. De Coquimbo IV Región | B14: Nov-Dic | C14: 3 | E14: =+C14+G8 -> 56.08 | F14: =+SUM('RAE Anchoveta'!B34:B35) -> 2 | G14: =+E14-F14 -> 54.08 | H14: =+G14/E14 -> 0.96433666
A15: Cuota Residual - Bolson | B15: Nov-Dic | C15: 1 | E15: =+C15+G9 -> -76.701 | F15: =+SUM('RAE Anchoveta'!B50:B51) -> 0 | G15: =+E15-F15 -> -76.701 | H15: =+G15/E15 -> 1 | I15: 41218
A16: Total | B16: Nov-Dic | C16: =SUM(C13:C15) -> 442 | E16: =+C16+G10 -> 351.313 | F16: =SUM(F13:F15) -> 47.09 | G16: =+E16-F16 -> 304.223
A18: V Región, de Valparaíso
A20: Organización | B20: Periodo | C20: Cuota asignada (t) | E20: Cuota efectiva (t) | F20: Desembarque (t) | G20: Saldo (t) | H20: % | I20: Fecha de Cierre
A21: A.G. Armadores Artesanales San Antonio R.A.G. 2510 | B21: Ene-Abr | C21: 2026 | E21: =+C21 -> 2026 | F21: =+SUM('RAE Anchoveta'!B58:B61) -> 706.441 | G21: =+E21-F21 -> 1319.559 | H21: =+G21/E21 -> 0.65131244
A22: Pescadores artesanales no afiliados | B22: Ene-Abr | C22: 23 | E22: =+C22 -> 23 | F22: =+SUM('RAE Anchoveta'!B74:B77) -> 36.095 | G22: =+E22-F22 -> -13.095 | H22: =+G22/E22 -> -0.56934783 | I22: 41031
A23: Total | B23: Ene-Abr | C23: =SUM(C21:C22) -> 2049 | E23: =SUM(E21:E22) -> 2049 | F23: =SUM(F21:F22) -> 742.536 | G23: =+E23-F23 -> 1306.464
A25: Organización | B25: Periodo | C25: Cuota asignada (t) | E25: Cuota efectiva (t) | F25: Desembarque (t) | G25: Saldo (t) | H25: % | I25: Fecha de Cierre
A26: A.G. Armadores Artesanales San Antonio R.A.G. 2510 | B26: May-Ago | C26: 238 | E26: =+C26+G21 -> 1557.559 | F26: =+SUM('RAE Anchoveta'!B62:B65) -> 865.055 | G26: =+E26-F26 -> 692.504 | H26: =+G26/E26 -> 0.44460852
A27: Pescadores artesanales no afiliados | B27: May-Ago | C27: 3 | E27: =+C27+G22 -> -10.095 | F27: =+SUM('RAE Anchoveta'!B78:B81) -> 0 | G27: =+E27-F27 -> -10.095 | H27: 0 | I27: 41031
A28: Total | B28: May-Ago | C28: =SUM(C26:C27) -> 241 | E28: =+C28+G23 -> 1547.464 | F28: =SUM(F26:F27) -> 865.055 | G28: =+E28-F28 -> 682.409
A30: Organización | B30: Periodo | C30: Cuota asignada (t) | E30: Cuota efectiva (t) | F30: Desembarque (t) | G30: Saldo (t) | H30: % | I30: Fecha de Cierre
A31: A.G. Armadores Artesanales San Antonio R.A.G. 2510 | B31: Sep-Dic | C31: 119 | E31: =+C31+G26 -> 811.504 | F31: =+SUM('RAE Anchoveta'!B66:B69) -> 802.11 | G31: =+E31-F31 -> 9.394 | H31: =+G31/E31 -> 0.011576037 | J31: atención
A32: Pescadores artesanales no afiliados | B32: Sep-Dic | C32: 1 | E32: =+C32+G27 -> -9.095 | F32: =+SUM('RAE Anchoveta'!B82:B85) -> 0 | G32: =+E32-F32 -> -9.095 | H32: 0 | I32: 41031
A33: Total | B33: Sep-Dic | C33: =SUM(C31:C32) -> 120 | E33: =+C33+G28 -> 802.409 | F33: =SUM(F31:F32) -> 802.11 | G33: =+E33-F33 -> 0.299
C34: =+C21+C26+C31 -> 2383 | E34: =+C34 -> 2383 | F34: =+F21+F26+F31 -> 2373.606 | G34: =+C34-F34 -> 9.394 | H34: =+G34/E34 -> 0.0039420898
A35: VII Región, deL Maule
A37: Organización | B37: Periodo | C37: Cuota asignada (t) | D37: TRASPASOS | E37: Cuota efectiva (t) | F37: Desembarque (t) | G37: Saldo (t) | H37: % | I37: Fecha de Cierre
A38: STI:.de Pescadores "Pelágicos del Maule" Constitución, R.S.U. N° 07050150 | B38: Ene-Abr | C38: 206.1 | E38: =+C38 -> 206.1 | F38: =+SUM('RAE Anchoveta'!B91:B94) -> 333.606 | G38: =+E38-F38 -> -127.506 | H38: =+G38/E38 -> -0.61866084 | I38: 41029
A39: Cuota Residual | B39: Ene-Abr | C39: 12.9 | E39: =+C39 -> 12.9 | F39: =+SUM('RAE Anchoveta'!B107:B110) -> 119.546 | G39: =+E39-F39 -> -106.646 | H39: =+G39/E39 -> -8.2671318 | I39: 41031
A40: Total | B40: Ene-Abr | C40: =SUM(C38:C39) -> 219 | E40: =SUM(E38:E39) -> 219 | F40: =SUM(F38:F39) -> 453.152 | G40: =+E40-F40 -> -234.152
A42: Organización | B42: Periodo | C42: Cuota asignada (t) | E42: Cuota efectiva (t) | F42: Desembarque (t) | G42: Saldo (t) | H42: % | I42: Fecha de Cierre
A43: STI:.de Pescadores "Pelágicos del Maule" Constitución, R.S.U. N° 07050150 | B43: May-Ago | C43: 24.5 | E43: =+C43+G38 -> -103.006 | F43: =+SUM('RAE Anchoveta'!B95:B98) -> 61.3 | G43: =+E43-F43 -> -164.306 | H43: 0 | I43: 41029
A44: Cuota Residual | B44: May-Ago | C44: 1.5 | E44: =+C44+G39 -> -105.146 | F44: =+SUM('RAE Anchoveta'!B111:B114) -> 2.166 | G44: =+E44-F44 -> -107.312 | H44: 0 | I44: 41031
A45: Total | B45: May-Ago | C45: =SUM(C43:C44) -> 26 | E45: =+C45+G40 -> -208.152 | F45: =SUM(F43:F44) -> 63.466 | G45: =+E45-F45 -> -271.618
A47: Organización | B47: Periodo | C47: Cuota asignada (t) | E47: Cuota efectiva (t) | F47: Desembarque (t) | G47: Saldo (t) | H47: % | I47: Fecha de Cierre
A48: STI:.de Pescadores "Pelágicos del Maule" Constitución, R.S.U. N° 07050150 | B48: Sep-Dic | C48: 12.2 | E48: =+C48+G43 -> -152.106 | F48: =+SUM('RAE Anchoveta'!B99:B102) -> 0 | G48: =+E48-F48 -> -152.106 | H48: 0 | I48: 41029
A49: Cuota Residual | B49: Sep-Dic | C49: 0.8 | E49: =+C49+G44 -> -106.512 | F49: =+SUM('RAE Anchoveta'!B115:B118) -> 0 | G49: =+E49-F49 -> -106.512 | H49: 0 | I49: 41031
A50: Total | B50: Sep-Dic | C50: =SUM(C48:C49) -> 13 | E50: =+C50+G45 -> -258.618 | F50: =SUM(F48:F49) -> 0 | G50: =+E50-F50 -> -258.618
A52: VIII Región, del Bio Bio | G52: 41011
...

Sheet Resumen RAE S.Común
A2: Resumen RAE Sardina común 2012
A5: V Región, de Valparaíso
A7: Organización | B7: Periodo | C7: Cuota asignada (t) | D7: TRASPASOS | E7: Cuota efectiva (t) | F7: Desembarque (t) | G7: Saldo (t) | H7: Saldo % | I7: Fecha de Cierre
A8: A.G. Armadores Artesanales San Antonio R.A.G. 2510 | B8: Ene-Abr | C8: 6561 | E8: =+C8 -> 6561 | F8: =+SUM('RAE S.común'!B8:B11) -> 2409.39 | G8: =+E8-F8 -> 4151.61 | H8: =+G8/E8 -> 0.63277092
A9: Pescadores artesanales no afiliados | B9: Ene-Abr | C9: 2239 | E9: =+C9 -> 2239 | F9: =+SUM('RAE S.común'!B24:B27) -> 657.93 | G9: =+E9-F9 -> 1581.07 | H9: =+G9/E9 -> 0.70615007
A10: Total | B10: Ene-Abr | C10: =SUM(C8:C9) -> 8800 | E10: =SUM(E8:E9) -> 8800 | F10: =SUM(F8:F9) -> 3067.32 | G10: =+E10-F10 -> 5732.68
A12: Organización | B12: Periodo | C12: Cuota asignada (t) | E12: Cuota efectiva (t) | F12: Desembarque (t) | G12: Saldo (t) | H12: Saldo % | I12: Fecha de Cierre
A13: A.G. Armadores Artesanales San Antonio R.A.G. 2510 | B13: May-Ago | C13: 772 | E13: =+C13+G8 -> 4923.61 | F13: =+SUM('RAE S.común'!B12:B15) -> 2975.781 | G13: =+E13-F13 -> 1947.829 | H13: =+G13/E13 -> 0.39560993
A14: Pescadores artesanales no afiliados | B14: May-Ago | C14: 263 | E14: =+C14+G9 -> 1844.07 | F14: =+SUM('RAE S.común'!B28:B31) -> 932.071 | G14: =+E14-F14 -> 911.999 | H14: =+G14/E14 -> 0.49455769
A15: Total | B15: May-Ago | C15: =SUM(C13:C14) -> 1035 | E15: =+C15+G10 -> 6767.68 | F15: =SUM(F13:F14) -> 3907.852 | G15: =+E15-F15 -> 2859.828
A17: Organización | B17: Periodo | C17: Cuota asignada (t) | E17: Cuota efectiva (t) | F17: Desembarque (t) | G17: Saldo (t) | H17: Saldo % | I17: 2
A18: A.G. Armadores Artesanales San Antonio R.A.G. 2510 | B18: Sep-Dic | C18: 385 | E18: =+C18+G13 -> 2332.829 | F18: =+SUM('RAE S.común'!B16:B19) -> 2329.965 | G18: =+E18-F18 -> 2.864 | H18: =+G18/E18 -> 0.0012276939 | I18: 41240
A19: Pescadores artesanales no afiliados | B19: Sep-Dic | C19: 132 | E19: =+C19+G14 -> 1043.999 | F19: =+SUM('RAE S.común'!B32:B35) -> 406.975 | G19: =+E19-F19 -> 637.024 | H19: =+G19/E19 -> 0.61017683
A20: Total | B20: Sep-Dic | C20: =SUM(C18:C19) -> 517 | E20: =+C20+G15 -> 3376.828 | F20: =SUM(F18:F19) -> 2736.94 | G20: =+E20-F20 -> 639.888
A22: VII Región, deL Maule
A24: Organización | B24: Periodo | C24: Cuota asignada (t) | D24: TRASPASOS | E24: Cuota efectiva (t) | F24: Desembarque (t) | G24: Saldo (t) | H24: Saldo % | I24: Fecha de Cierre
A25: STI:.de Pescadores "Pelágicos del Maule" Constitución, R.S.U. N° 07050150 | B25: Ene-Abr | C25: 2994 | D25: -303 | E25: =+C25+D25 -> 2691 | F25: 961.5 | G25: =+E25-F25 -> 1729.5 | H25: =+G25/E25 -> 0.64269788
A26: Cuota Residual | B26: Ene-Abr | C26: 188 | E26: =+C26 -> 188 | F26: =+SUM('RAE S.común'!B57:B60) -> 390.361 | G26: =+E26-F26 -> -202.361 | H26: =G26/E26 -> -1.0763883 | I26: 41031
A27: Total | B27: Ene-Abr | C27: =SUM(C25:C26) -> 3182 | E27: =SUM(E25:E26) -> 2879 | F27: =SUM(F25:F26) -> 1351.861 | G27: =+E27-F27 -> 1527.139
A29: Organización | B29: Periodo | C29: Cuota asignada (t) | E29: Cuota efectiva (t) | F29: Desembarque (t) | G29: Saldo (t) | H29: Saldo % | I29: Fecha de Cierre
A30: STI:.de Pescadores "Pelágicos del Maule" Constitución, R.S.U. N° 07050150 | B30: May-Ago | C30: 352 | E30: =+C30+G25 -> 2081.5 | F30: =+SUM('RAE S.común'!B45:B48) -> 435.957 | G30: =+E30-F30 -> 1645.543 | H30: =+G30/E30 -> 0.79055633
A31: Cuota Residual | B31: May-Ago | C31: 22 | E31: =+C31+G26 -> -180.361 | F31: =+SUM('RAE S.común'!B61:B64) -> 0 | G31: =+E31-F31 -> -180.361 | H31: =+F31/E31 -> 0 | I31: 41031
A32: Total | B32: May-Ago | C32: =SUM(C30:C31) -> 374 | E32: =+C32+G27 -> 1901.139 | F32: =SUM(F30:F31) -> 435.957 | G32: =+E32-F32 -> 1465.182
A34: Organización | B34: Periodo | C34: Cuota asignada (t) | E34: Cuota efectiva (t) | F34: Desembarque (t) | G34: Saldo (t) | H34: Saldo % | I34: Fecha de Cierre
A35: STI:.de Pescadores "Pelágicos del Maule" Constitución, R.S.U. N° 07050150 | B35: Sep-Dic | C35: 176 | E35: =+C35+G30 -> 1821.543 | F35: =+SUM('RAE S.común'!B49:B52) -> 120.17 | G35: =+E35-F35 -> 1701.373 | H35: =+G35/E35 -> 0.93402846
A36: Cuota Residual | B36: Sep-Dic | C36: 11 | E36: =+C36+G31 -> -169.361 | F36: =+SUM('RAE S.común'!B65:B68) -> 0 | G36: =+E36-F36 -> -169.361 | H36: =+F36/E36 -> 0 | I36: 41031
A37: Total | B37: Sep-Dic | C37: =SUM(C35:C36) -> 187 | E37: =+C37+G32 -> 1652.182 | F37: =SUM(F35:F36) -> 120.17 | G37: =+E37-F37 -> 1532.012
A38: VIII Región, del Bio Bio | G38: 40995
A40: Organización | B40: Periodo | C40: Cuota asignada (t) | D40: traspaso | E40: Cuota efectiva (t) | F40: Desembarque (t) | G40: Saldo (t) | H40: Saldo % | I40: Fecha de Cierre
A41: Caleta Tubul.R.O.Comunitaria Funcional 478-2007 | B41: Ene-Ago | C41: 1736 | D41: -481.8 | E41: =+C41+D41 -> 1254.2 | F41: 558.151 | G41: =+E41-F41 -> 696.049 | H41: =+G41/E41 -> 0.55497449
A42: AGREPAR BIO BIO A.G 468-8 | B42: Ene-Ago | C42: 3848 | E42: =+C42 -> 3848 | F42: 3456.179 | G42: =+E42-F42 -> 391.821 | H42: =+G42/E42 -> 0.10182458
A43: ARPESCA.R.A.G. 429-8 | B43: Ene-Ago | C43: =8752-1000-500-500-1000-500 -> 5252 | E43: =+C43 -> 5252 | F43: 2328.675 | G43: =+E43-F43 -> 2923.325 | H43: =+G43/E43 -> 0.55661177
A44: ARPES BIO BIO R.A.G.445-8 | B44: Ene-Ago | C44: 21488 | E44: =+C44 -> 21488 | F44: 15504.651 | G44: =+E44-F44 -> 5983.349 | H44: =+G44/E44 -> 0.27845072
A45: SIARPAR R.A.G.448-8 | B45: Ene-Ago | C45: =1555+700 -> 2255 | E45: =+C45 -> 2255 | F45: 1449.176 | G45: =+E45-F45 -> 805.824 | H45: =+G45/E45 -> 0.35734989
A46: ARMAR R.A.G. 384-8 | B46: Ene-Ago | C46: 16244 | E46: =+C46 -> 16244 | F46: 9716.54 | G46: =+E46-F46 -> 6527.46 | H46: =+G46/E46 -> 0.40183822
A47: AGEMAPAR R.A.G.376-8 | B47: Ene-Ago | C47: 16977 | E47: =+C47 -> 16977 | F47: 12364.192 | G47: =+E47-F47 -> 4612.808 | H47: =+G47/E47 -> 0.27170925
A48: ARPROPELAR R.A.G.353-8 | B48: Ene-Ago | C48: =13291+500+500 -> 14291 | E48: =+C48 -> 14291 | F48: 11245.472 | G48: =+E48-F48 -> 3045.528 | H48: =+G48/E48 -> 0.21310811
A49: ITALMAR R.A.G.392-8 | B49: Ene-Ago | C49: 5176 | E49: =+C49 -> 5176 | F49: 3875.912 | G49: =+E49-F49 -> 1300.088 | H49: =+G49/E49 -> 0.2511762
A50: A.G. Pescadores Artesanales de Coronel R.A.G.5-8 | B50: Ene-Ago | C50: =47781+180 -> 47961 | E50: =+C50 -> 47961 | F50: 36640.021 | G50: =+E50-F50 -> 11320.979 | H50: =+G50/E50 -> 0.23604552
A51: A.G.APESCA R.A.G. 428-8 | B51: Ene-Ago | C51: 2905 | E51: =+C51 -> 2905 | F51: 2609.005 | G51: =+E51-F51 -> 295.995 | H51: =+G51/E51 -> 0.10189157
...

Sheet RAE Anchoveta
A2: RAE Anchoveta 2012
A4: IV REGIÓN
A6: Cooperativa de Armadores Cerqueros IV región | K6: ok¡
A7: Mes | B7: Total mes | C7: 1 | D7: 2 | E7: 3 | F7: 4 | G7: 5 | H7: 6 | I7: 7 | J7: 8 | K7: 9 | L7: 10 | M7: 11 | N7: 12 | O7: 13 | P7: 14 | Q7: 15 | R7: 16 | S7: 17 | T7: 18 | U7: 19 | V7: 20 | W7: 21 | X7: 22 | Y7: 23 | Z7: 24 | AA7: 25 | AB7: 26 | AC7: 27 | AD7: 28 | AE7: 29 | AF7: 30 | AG7: 31 | AH7: TOTAL
A8: Enero | B8: =+AH8 -> 947.513 | C8: 0 | D8: 85.807 | E8: 335.518 | F8: 156.985 | G8: 111.137 | H8: 35.574 | I8: 120.214 | J8: 0 | K8: 0 | L8: 0 | M8: 0 | N8: 0 | O8: 0 | P8: 25.44 | Q8: 0 | R8: 0 | S8: 0 | T8: 22.165 | U8: 27.163 | V8: 4.81 | W8: 7.2 | X8: 0 | Y8: 5.35 | Z8: 3.75 | AA8: 5.35 | AB8: 1.05 | AC8: 0 | AD8: 0 | AE8: 0 | AF8: 0 | AG8: 0 | AH8: =SUM(C8:AG8) -> 947.513
A9: Febrero | B9: =+AH9 -> 1186.794 | C9: 0 | D9: 0 | E9: 0 | F9: 1.01 | G9: 0 | H9: 89.771 | I9: 147.764 | J9: 121.628 | K9: 6.98 | L9: 3.639 | M9: 2.74 | N9: 0 | O9: 57.453 | P9: 9.565 | Q9: 93.379 | R9: 0.95 | S9: 2.8 | T9: 5.31 | U9: 0 | V9: 43.687 | W9: 141.54 | X9: 148.991 | Y9: 23.959 | Z9: 57.662 | AA9: 56.49 | AB9: 0 | AC9: 50.218 | AD9: 107.907 | AE9: 13.351 | AH9: =SUM(C9:AG9) -> 1186.794
A10: Marzo | B10: =+AH10 -> 3499.127 | C10: 0 | D10: 101.2 | E10: 1.3 | F10: 0 | G10: 304.271 | H10: 149.917 | I10: 0 | J10: 0 | K10: 27.448 | L10: 3.6 | M10: 0 | N10: 0 | O10: 369.442 | P10: 159.574 | Q10: 167.656 | R10: 0 | S10: 3.995 | T10: 0 | U10: 0 | V10: 19.296 | W10: 2.82 | X10: 21.81 | Y10: 546.182 | Z10: 241.327 | AA10: 0 | AB10: 290.917 | AC10: 0 | AD10: 441.28 | AE10: 573.188 | AF10: 69.982 | AG10: 3.922 | AH10: =SUM(C10:AG10) -> 3499.127
A11: Abril | B11: =+AH11 -> 560.978 | C11: 0 | D11: 249.825 | E11: 73.562 | F11: 0 | G11: 0 | H11: 0 | I11: 0 | J11: 0 | K11: 60.207 | L11: 0 | M11: 43.513 | N11: 0 | O11: 42.788 | P11: 0 | Q11: 0 | R11: 0 | S11: 28.053 | T11: 0 | U11: 0 | V11: 0 | W11: 0 | X11: 0 | Y11: 0 | Z11: 58.03 | AA11: 5 | AB11: 0 | AC11: 0 | AD11: 0 | AE11: 0 | AF11: 0 | AH11: =SUM(C11:AG11) -> 560.978
A12: Mayo | B12: =+AH12 -> 106.122 | C12: 0 | D12: 0 | E12: 0 | F12: 0 | G12: 0 | H12: 0 | I12: 0 | J12: 0 | K12: 0 | L12: 0 | M12: 0 | N12: 0 | O12: 0 | P12: 0 | Q12: 0 | R12: 0 | S12: 0 | T12: 0 | U12: 0 | V12: 0 | W12: 0 | X12: 0 | Y12: 0 | Z12: 0 | AA12: 0.587 | AB12: 0 | AC12: 0 | AD12: 0 | AE12: 0 | AF12: 0 | AG12: 105.535 | AH12: =SUM(C12:AG12) -> 106.122
A13: Junio | B13: =+AH13 -> 1269.159 | C13: 5.104 | D13: 68.215 | E13: 0 | F13: 70.753 | G13: 9.162 | H13: 194.52 | I13: 0 | J13: 0 | K13: 97.01 | L13: 0 | M13: 65.742 | N13: 106.972 | O13: 62.65 | P13: 61.676 | Q13: 60.506 | R13: 8.174 | S13: 0 | T13: 3.7 | U13: 6.7 | V13: 9.1 | W13: 1.1 | X13: 0 | Y13: 0 | Z13: 0 | AA13: 13.352 | AB13: 144.572 | AC13: 135.616 | AD13: 134.96 | AE13: 1.513 | AF13: 8.062 | AH13: =SUM(C13:AG13) -> 1269.159
A14: Julio | B14: =+AH14 -> 54.93 | C14: 0 | D14: 0 | E14: 0 | F14: 0 | G14: 0 | H14: 0 | I14: 0 | J14: 0 | K14: 3.8 | L14: 21.83 | M14: 0 | N14: 0.85 | O14: 0 | P14: 0 | Q14: 0 | R14: 0 | S14: 2.54 | T14: 12.01 | U14: 3.83 | V14: 5.2 | W14: 1.3 | X14: 0 | Y14: 0 | Z14: 3.57 | AA14: 0 | AB14: 0 | AC14: 0 | AD14: 0 | AE14: 0 | AF14: 0 | AH14: =SUM(C14:AG14) -> 54.93
A15: Agosto | B15: =+AH15 -> 13.79 | C15: 0 | D15: 0 | E15: 0 | F15: 0 | G15: 0 | H15: 0 | I15: 3.03 | J15: 3.04 | K15: 0 | L15: 0 | M15: 2.4 | N15: 0 | O15: 0 | P15: 0 | Q15: 0 | R15: 0 | S15: 0 | T15: 5.32 | U15: 0 | V15: 0 | W15: 0 | X15: 0 | Y15: 0 | Z15: 0 | AA15: veda | AB15: veda | AC15: veda | AD15: veda | AE15: veda | AF15: veda | AG15: veda | AH15: =SUM(C15:AG15) -> 13.79
A16: Septiembre | B16: =+AH16 -> 352.492 | C16: veda | D16: veda | E16: veda | F16: veda | G16: veda | H16: veda | I16: veda | J16: veda | K16: veda | L16: veda | M16: veda | N16: veda | O16: veda | P16: veda | Q16: veda | R16: veda | S16: veda | T16: veda | U16: veda | V16: veda | W16: veda | X16: veda | Y16: veda | Z16: 37.92 | AA16: 114.594 | AB16: 151.845 | AC16: 48.133 | AD16: 0 | AE16: 0 | AF16: 0 | AH16: =SUM(C16:AG16) -> 352.492
A17: Octubre | B17: =+AH17 -> 396.161 | C17: 0 | D17: 5.08 | E17: 0 | F17: 0 | G17: 0 | H17: 0 | I17: 0 | J17: 0 | K17: 0 | L17: 0 | M17: 0 | N17: 0 | O17: 0 | P17: 0 | Q17: 0 | R17: 0 | S17: 0 | T17: 0 | U17: 164.997 | V17: 56.543 | W17: 65.425 | X17: 88.666 | Y17: 15.45 | Z17: 0 | AA17: 0 | AB17: 0 | AH17: =SUM(C17:AG17) -> 396.161
A18: Noviembre | B18: =+AH18 -> 40.45 | C18: 0 | D18: 0 | E18: 0 | F18: 0 | G18: 0 | H18: 0 | I18: 0 | J18: 0 | K18: 0 | L18: 0 | M18: 0 | N18: 0 | O18: 0 | P18: 0 | Q18: 37.35 | R18: 0 | S18: 0.7 | T18: 0 | U18: 1.2 | V18: 0 | W18: 1.2 | X18: 0 | Y18: 0 | Z18: 0 | AA18: 0 | AB18: 0 | AC18: 0 | AD18: 0 | AE18: 0 | AF18: 0 | AH18: =SUM(C18:AG18) -> 40.45
A19: Diciembre | B19: =+AH19 -> 4.64 | C19: 0 | D19: 0 | E19: 0 | F19: 0 | G19: 4.64 | H19: 0 | I19: 0 | J19: 0 | K19: 0 | L19: 0 | M19: 0 | N19: 0 | O19: 0 | P19: 0 | Q19: 0 | R19: 0 | S19: 0 | T19: 0 | U19: 0 | V19: 0 | W19: 0 | X19: 0 | Y19: 0 | Z19: 0 | AA19: 0 | AB19: 0 | AC19: 0 | AD19: 0 | AE19: 0 | AF19: 0 | AG19: 0 | AH19: =SUM(C19:AG19) -> 4.64
A20: TOTAL | B20: =SUM(B8:B19) -> 8432.156 | C20: =SUM(C8:C19) -> 5.104 | D20: =SUM(D8:D19) -> 510.127 | E20: =SUM(E8:E19) -> 410.38 | F20: =SUM(F8:F19) -> 228.748 | G20: =SUM(G8:G19) -> 429.21 | H20: =SUM(H8:H19) -> 469.782 | I20: =SUM(I8:I19) -> 271.008 | ... AH20: =SUM(AH8:AH19) -> 8432.156
A22: A.G. de pescadores Artesanales y Buzos Mariscadores de Coquimbo - IV Región
A23: Mes | B23: Total mes | C23: 1 | D23: 2 | E23: 3 | F23: 4 | G23: 5 | H23: 6 | I23: 7 | J23: 8 | K23: 9 | L23: 10 | M23: 11 | N23: 12 | O23: 13 | P23: 14 | Q23: 15 | R23: 16 | S23: 17 | T23: 18 | U23: 19 | V23: 20 | W23: 21 | X23: 22 | Y23: 23 | Z23: 24 | AA23: 25 | AB23: 26 | AC23: 27 | AD23: 28 | AE23: 29 | AF23: 30 | AG23: 31 | AH23: TOTAL
A24: Enero | B24: =+AH24 -> 0 | C24: 0 | D24: 0 | E24: 0 | F24: 0 | G24: 0 | H24: 0 | I24: 0 | J24: 0 | K24: 0 | L24: 0 | M24: 0 | N24: 0 | O24: 0 | P24: 0 | Q24: 0 | R24: 0 | S24: 0 | T24: 0 | U24: 0 | V24: 0 | W24: 0 | X24: 0 | Y24: 0 | Z24: 0 | AA24: 0 | AB24: 0 | AC24: 0 | AD24: 0 | AE24: 0 | AF24: 0 | AG24: 0 | AH24: =SUM(C24:AG24) -> 0
A25: Febrero | B25: =+AH25 -> 0 | C25: 0 | D25: 0 | E25: 0 | F25: 0 | G25: 0 | H25: 0 | I25: 0 | J25: 0 | K25: 0 | L25: 0 | M25: 0 | N25: 0 | O25: 0 | P25: 0 | Q25: 0 | R25: 0 | S25: 0 | T25: 0 | U25: 0 | V25: 0 | W25: 0 | X25: 0 | Y25: 0 | Z25: 0 | AA25: 0 | AB25: 0 | AC25: 0 | AD25: 0 | AE25: 0 | AH25: =SUM(C25:AG25) -> 0
A26: Marzo | B26: =+AH26 -> 0 | C26: 0 | D26: 0 | E26: 0 | F26: 0 | G26: 0 | H26: 0 | I26: 0 | J26: 0 | K26: 0 | L26: 0 | M26: 0 | N26: 0 | O26: 0 | P26: 0 | Q26: 0 | R26: 0 | S26: 0 | T26: 0 | U26: 0 | V26: 0 | W26: 0 | X26: 0 | Y26: 0 | Z26: 0 | AA26: 0 | AB26: 0 | AC26: 0 | AD26: 0 | AE26: 0 | AF26: 0 | AG26: 0 | AH26: =SUM(C26:AG26) -> 0
A27: Abril | B27: =+AH27 -> 0.1 | C27: 0 | D27: 0 | E27: 0 | F27: 0 | G27: 0 | H27: 0 | I27: 0 | J27: 0 | K27: 0 | L27: 0 | M27: 0 | N27: 0 | O27: 0 | P27: 0 | Q27: 0 | R27: 0 | S27: 0 | T27: 0 | U27: 0 | V27: 0 | W27: 0 | X27: 0 | Y27: 0 | Z27: 0 | AA27: 0 | AB27: 0 | AC27: 0 | AD27: 0.1 | AE27: 0 | AF27: 0 | AH27: =SUM(C27:AG27) -> 0.1
A28: Mayo | B28: =+AH28 -> 0.37 | C28: 0 | D28: 0 | E28: 0 | F28: 0 | G28: 0 | H28: 0 | I28: 0 | J28: 0 | K28: 0 | L28: 0 | M28: 0 | N28: 0 | O28: 0 | P28: 0 | Q28: 0 | R28: 0 | S28: 0 | T28: 0 | U28: 0 | V28: 0 | W28: 0 | X28: 0 | Y28: 0 | Z28: 0 | AA28: 0 | AB28: 0 | AC28: 0 | AD28: 0 | AE28: 0 | AF28: 0.37 | AG28: 0 | AH28: =SUM(C28:AG28) -> 0.37
A29: Junio | B29: =+AH29 -> 2.45 | C29: 0 | D29: 0 | E29: 0 | F29: 0 | G29: 0 | H29: 0 | I29: 0.45 | J29: 1.2 | K29: 0.8 | L29: 0 | M29: 0 | N29: 0 | O29: 0 | P29: 0 | Q29: 0 | R29: 0 | S29: 0 | T29: 0 | U29: 0 | V29: 0 | W29: 0 | X29: 0 | Y29: 0 | Z29: 0 | AA29: 0 | AB29: 0 | AC29: 0 | AD29: 0 | AE29: 0 | AF29: 0 | AH29: =SUM(C29:AG29) -> 2.45
A30: Julio | B30: =+AH30 -> 0 | AH30: =SUM(C30:AG30) -> 0
A31: Agosto | B31: =+AH31 -> 0
A32: Septiembre | B32: =+AH32 -> 0 | C32: veda | D32: veda | E32: veda | F32: veda | G32: veda | H32: veda | I32: veda | J32: veda | K32: veda | L32: veda | M32: veda | N32: veda | O32: veda | P32: veda | Q32: veda | R32: veda | S32: veda | T32: veda | U32: veda | V32: veda | W32: veda | X32: veda | Y32: veda
A33: Octubre | B33: =+AH33 -> 0 | C33: 0 | D33: 0 | E33: 0 | F33: 0 | G33: 0 | H33: 0 | I33: 0 | J33: 0 | K33: 0 | L33: 0 | M33: 0 | N33: 0 | O33: 0 | P33: 0 | Q33: 0 | R33: 0 | S33: 0 | T33: 0 | U33: 0 | V33: 0 | W33: 0 | X33: 0 | Y33: 0 | Z33: 0 | AA33: 0 | AB33: 0 | AC33: 0 | AD33: 0 | AE33: 0 | AF33: 0 | AG33: 0 | AH33: =SUM(C33:AG33) -> 0
A34: Noviembre | B34: =+AH34 -> 0 | C34: 0 | D34: 0 | E34: 0 | F34: 0 | G34: 0 | H34: 0 | I34: 0 | J34: 0 | K34: 0 | L34: 0 | M34: 0 | N34: 0 | O34: 0 | P34: 0 | Q34: 0 | R34: 0 | S34: 0 | T34: 0 | U34: 0 | V34: 0 | W34: 0 | X34: 0 | Y34: 0 | Z34: 0 | AA34: 0 | AB34: 0 | AC34: 0 | AD34: 0 | AE34: 0 | AF34: 0 | AH34: =SUM(C34:AG34) -> 0
A35: Diciembre | B35: =+AH35 -> 2 | C35: 0 | D35: 0 | E35: 0 | F35: 0 | G35: 0 | H35: 0 | I35: 2 | J35: 0 | K35: 0 | L35: 0 | M35: 0 | N35: 0 | O35: 0 | P35: 0 | Q35: 0 | R35: 0 | S35: 0 | T35: 0 | U35: 0 | V35: 0 | W35: 0 | X35: 0 | Y35: 0 | Z35: 0 | AA35: 0 | AB35: 0 | AC35: 0 | AD35: 0 | AE35: 0 | AF35: 0 | AG35: 0 | AH35: =SUM(C35:AG35) -> 2
A36: TOTAL | B36: =SUM(B24:B35) -> 4.92 | C36: =SUM(C24:C35) -> 0 | D36: =SUM(D24:D35) -> 0 | E36: =SUM(E24:E35) -> 0 | F36: =SUM(F24:F35) -> 0 | G36: =SUM(G24:G35) -> 0 | H36: =SUM(H24:H35) -> 0 | I36: =SUM(I24:I35) -> 2.45 | ... AH36: =SUM(AH24:AH35) -> 4.92
A38: Cuota residual - Bolson
A39: Mes | B39: Total mes | C39: 1 | D39: 2 | E39: 3 | F39: 4 | G39: 5 | H39: 6 | I39: 7 | J39: 8 | K39: 9 | L39: 10 | M39: 11 | N39: 12 | O39: 13 | P39: 14 | Q39: 15 | R39: 16 | S39: 17 | T39: 18 | U39: 19 | V39: 20 | W39: 21 | X39: 22 | Y39: 23 | Z39: 24 | AA39: 25 | AB39: 26 | AC39: 27 | AD39: 28 | AE39: 29 | AF39: 30 | AG39: 31 | AH39: TOTAL
A40: Enero | B40: =+AH40 -> 3.12 | C40: 0 | D40: 0 | E40: 3.02 | F40: 0 | G40: 0 | H40: 0 | I40: 0 | J40: 0 | K40: 0.1 | L40: 0 | M40: 0 | N40: 0 | O40: 0 | P40: 0 | Q40: 0 | R40: 0 | S40: 0 | T40: 0 | U40: 0 | V40: 0 | W40: 0 | X40: 0 | Y40: 0 | Z40: 0 | AA40: 0 | AB40: 0 | AC40: 0 | AD40: 0 | AE40: 0 | AF40: 0 | AG40: 0 | AH40: =SUM(C40:AG40) -> 3.12
A41: Febrero | B41: =+AH41 -> 0 | C41: 0 | D41: 0 | E41: 0 | F41: 0 | G41: 0 | H41: 0 | I41: 0 | J41: 0 | K41: 0 | L41: 0 | M41: 0 | N41: 0 | O41: 0 | P41: 0 | Q41: 0 | R41: 0 | S41: 0 | T41: 0 | U41: 0 | V41: 0 | W41: 0 | X41: 0 | Y41: 0 | Z41: 0 | AA41: 0 | AB41: 0 | AC41: 0 | AD41: 0 | AE41: 0 | AH41: =SUM(C41:AG41) -> 0
A42: Marzo | B42: =+AH42 -> 0.3 | C42: 0 | D42: 0 | E42: 0 | F42: 0 | G42: 0 | H42: 0 | I42: 0 | J42: 0 | K42: 0 | L42: 0 | M42: 0 | N42: 0 | O42: 0 | P42: 0 | Q42: 0 | R42: 0.3 | S42: 0 | T42: 0 | U42: 0 | V42: 0 | W42: 0 | X42: 0 | Y42: 0 | Z42: 0 | AA42: 0 | AB42: 0 | AC42: 0 | AD42: 0 | AE42: 0 | AF42: 0 | AG42: 0 | AH42: =SUM(C42:AG42) -> 0.3
A43: Abril | B43: =+AH43 -> 12.48 | C43: 0 | D43: 0 | E43: 0 | F43: 0 | G43: 0 | H43: 0 | I43: 0 | J43: 0 | K43: 0.019 | L43: 0 | M43: 0 | N43: 0 | O43: 0.026 | P43: 0 | Q43: 0 | R43: 0 | S43: 0 | T43: 0 | U43: 0 | V43: 0 | W43: 0 | X43: 0 | Y43: 0.03 | Z43: 0 | AA43: 0 | AB43: 0 | AC43: 12.405 | AD43: 0 | AE43: 0 | AF43: 0 | AH43: =SUM(C43:AG43) -> 12.48
A44: Mayo | B44: =+AH44 -> 0.013 | C44: 0 | D44: 0.013 | E44: 0 | F44: 0 | G44: 0 | H44: 0 | I44: 0 | J44: 0 | K44: 0 | L44: 0 | M44: 0 | N44: 0 | O44: 0 | P44: 0 | Q44: 0 | R44: 0 | S44: 0 | T44: 0 | U44: 0 | V44: 0 | W44: 0 | X44: 0 | Y44: 0 | Z44: 0 | AA44: 0 | AB44: 0 | AC44: 0 | AD44: 0 | AE44: 0 | AF44: 0 | AG44: 0 | AH44: =SUM(C44:AG44) -> 0.013
A45: Junio | B45: =+AH45 -> 77.476 | C45: 0 | D45: 0 | E45: 0 | F45: 0 | G45: 0 | H45: 0 | I45: 22.13 | J45: 5.225 | K45: 23.546 | L45: 0 | M45: 0 | N45: 0.01 | O45: 0 | P45: 0 | Q45: 0 | R45: 0 | S45: 0 | T45: 0.025 | U45: 0 | V45: 0 | W45: 0 | X45: 0 | Y45: 0 | Z45: 0 | AA45: 0 | AB45: 0 | AC45: 26.54 | AD45: 0 | AE45: 0 | AF45: 0 | AH45: =SUM(C45:AG45) -> 77.476
...

Sheet Anchoveta
A2: Anchoveta 2012
A5: XV y I Región, Arica e Iquique
A6: Mes | B6: Total mes | C6: 1 | D6: 2 | E6: 3 | F6: 4 | G6: 5 | H6: 6 | I6: 7 | J6: 8 | K6: 9 | L6: 10 | M6: 11 | N6: 12 | O6: 13 | P6: 14 | Q6: 15 | R6: 16 | S6: 17 | T6: 18 | U6: 19 | V6: 20 | W6: 21 | X6: 22 | Y6: 23 | Z6: 24 | AA6: 25 | AB6: 26 | AC6: 27 | AD6: 28 | AE6: 29 | AF6: 30 | AG6: 31 | AH6: TOTAL
A7: Enero | B7: =+AH7 -> 1544.695 | AF7: 1073.91 | AG7: 470.785 | AH7: =SUM(C7:AG7) -> 1544.695
A8: Febrero | B8: =+AH8 -> 11241.526 | C8: 516.4 | D8: 893.625 | E8: 631.695 | F8: 264.525 | H8: 823.493 | I8: 450.095 | J8: 585.83 | K8: 375.055 | L8: 304.375 | M8: 72.24 | O8: 80.05 | P8: 541.025 | Q8: 231.585 | R8: 102.97 | S8: 839.878 | T8: 7.41 | V8: 325.655 | W8: 419.785 | X8: 384.675 | Y8: 362.014 | Z8: 304.513 | AA8: 512.777 | AC8: 456.496 | AD8: 930.226 | AE8: 825.134 | AH8: =SUM(C8:AG8) -> 11241.526
A9: Marzo | B9: =+AH9 -> 19300.05 | C9: 785.221 | D9: 870.064 | E9: 870.505 | G9: 1327.445 | H9: 989.355 | I9: 410 | J9: 775.912 | K9: 36.817 | L9: 917.3 | N9: 1549.513 | O9: 202.895 | P9: 727.93 | Q9: 661.997 | R9: 863.34 | U9: 1344.19 | V9: 1145.971 | W9: 1433.695 | X9: 1797.045 | Y9: 135.07 | Z9: 170.505 | AB9: 1139.07 | AC9: 385.515 | AD9: 513.445 | AF9: 4.07 | AG9: 243.18 | AH9: =SUM(C9:AG9) -> 19300.05
A10: Abril | B10: =+AH10 -> 14562.886 | D10: 18.34 | E10: 323.25 | F10: 461.55 | G10: 1239.49 | K10: 1452.015 | L10: 1060.53 | M10: 1517.385 | N10: 1334.03 | O10: 1398.051 | P10: 838.555 | R10: 18.03 | S10: 1297.69 | T10: 28.645 | U10: 377.515 | V10: 558.095 | Y10: 251 | Z10: 875.88 | AA10: 659.855 | AB10: 280.71 | AC10: 316.425 | AD10: 255.845 | AH10: =SUM(C10:AG10) -> 14562.886
A11: Mayo | B11: =+AH11 -> 14968.245 | D11: 1369.18 | E11: 510.605 | I11: 1506.08 | J11: 1298.33 | K11: 796.165 | L11: 1125.4 | M11: 1853.24 | N11: 1059.185 | P11: 1512.955 | Q11: 1504.645 | R11: 898.265 | S11: 97.48 | T11: 84.31 | X11: 103.41 | Y11: 828.855 | Z11: 399.5 | AD11: 20.64 | AH11: =SUM(C11:AG11) -> 14968.245
A12: Junio | B12: =+AH12 -> 0 | AH12: =SUM(C12:AG12) -> 0
A13: Julio | B13: =+AH13 -> 9433.058 | E13: 19.94 | F13: 199.484 | K13: 1430.97 | L13: 1003.52 | M13: 1256.123 | N13: 925.621 | O13: 787.008 | P13: 351.533 | T13: 260.775 | U13: 658.155 | V13: 4.46 | Y13: 773.005 | Z13: 259.891 | AA13: 378.5 | AB13: 83.25 | AC13: 21.11 | AD13: 417.77 | AF13: 572.503 | AG13: 29.44 | AH13: =SUM(C13:AG13) -> 9433.058
A14: Agosto | B14: =+AH14 -> 330.261 | C14: 176.946 | D14: 93.734 | F14: 54.56 | AE14: 5.021 | AH14: =SUM(C14:AG14) -> 330.261 | AI14: 116.94TON DE DESEMBARQUE DE DIA 25/11, SE IMPUTA A FRACCION ARTESANAL POR SOBREPASE DE CUOTA DE TRASPASO RES. EX. Nº 2883/2012.
A15: Septiembre | B15: =+AH15 -> 3.812 | C15: veda | D15: veda | E15: veda | F15: veda | G15: veda | H15: veda | I15: veda | J15: veda | K15: veda | L15: 3.812 | M15: veda | N15: veda | O15: veda | P15: veda | Q15: veda | R15: veda | S15: veda | T15: veda | U15: veda | V15: veda | W15: veda | X15: veda | Y15: veda | Z15: 0 | AA15: 0 | AB15: 0 | AC15: 0 | AD15: 0 | AE15: 0 | AF15: 0 | AG15: 0 | AH15: =SUM(C15:AG15) -> 3.812 | AI15: 564.18 TON DE DESEMBARQUE DE DIA 27/11, SE IMPUTA A FRACCION ARTESANAL POR SOBREPASE DE CUOTA DE TRASPASO RES. EX. Nº 2883/2012.
A16: Octubre | B16: =+AH16 -> 0 | AH16: =SUM(C16:AG16) -> 0 | AI16: 855.15 TON DE DESEMBARQUE DE DIA 28/11, SE IMPUTA A FRACCION ARTESANAL POR SOBREPASE DE CUOTA DE TRASPASO RES. EX. Nº 2883/2012.
A17: Noviembre | B17: =+AH17 -> 1540.102 | M17: 3.832 | N17: 0 | O17: 0 | AA17: 116.94 | AC17: 564.18 | AD17: 855.15 | AH17: =SUM(C17:AG17) -> 1540.102 | AI17: 341.434 TON DE DESEMBARQUE DE DIA 06/12, SE IMPUTA A FRACCION ARTESANAL
A18: Diciembre | B18: =+AH18 -> 914.799 | C18: 0 | D18: 0 | E18: 0 | F18: 0 | G18: 1 | H18: 341.434 | I18: 168.97 | J18: 0 | K18: 0 | L18: 398.215 | M18: 0 | N18: 0 | O18: 0 | P18: 0 | Q18: 0 | R18: 0 | S18: 0 | T18: 1.53 | U18: 0 | V18: 0 | W18: 0 | X18: 0 | Y18: 0 | Z18: 0 | AA18: 0 | AD18: 1.65 | AG18: 2 | AH18: =SUM(C18:AG18) -> 914.799 | AI18: 168.97 TON DE DESEMBARQUE DE DIA 07/12, SE IMPUTA A FRACCION ARTESANAL
A19: TOTAL | B19: =SUM(B7:B18) -> 73839.434 | C19: 0 | D19: 0 | E19: 0 | F19: 0 | G19: 0 | H19: 0 | I19: 0 | J19: 0 | K19: 0 | L19: 0 | M19: 0 | N19: 0 | O19: 0 | P19: 0 | Q19: 0 | R19: 0 | S19: 0 | T19: 0 | U19: 0 | V19: 0 | W19: 0 | X19: 0 | Y19: 0 | Z19: 0 | AA19: 0 | AB19: 0 | AC19: 0 | AD19: 0 | AE19: 0 | AF19: 0 | AG19: 0 | AH19: =SUM(AH7:AH18) -> 73839.434 | AI19: 398.215 TON DE DESEMBARQUE DE DIA 10/12, SE IMPUTA A FRACCION ARTESANAL
A21: II Región, de Antofasta | I21: ok
A22: Mes | B22: Total mes | C22: 1 | D22: 2 | E22: 3 | F22: 4 | G22: 5 | H22: 6 | I22: 7 | J22: 8 | K22: 9 | L22: 10 | M22: 11 | N22: 12 | O22: 13 | P22: 14 | Q22: 15 | R22: 16 | S22: 17 | T22: 18 | U22: 19 | V22: 20 | W22: 21 | X22: 22 | Y22: 23 | Z22: 24 | AA22: 25 | AB22: 26 | AC22: 27 | AD22: 28 | AE22: 29 | AF22: 30 | AG22: 31 | AH22: TOTAL
A23: Enero | B23: =+AH23 -> 0.5 | C23: veda | D23: veda | E23: veda | F23: veda | G23: veda | H23: veda | I23: veda | J23: veda | K23: veda | L23: veda | M23: veda | N23: veda | O23: veda | P23: veda | Q23: veda | R23: veda | S23: veda | T23: veda | U23: veda | V23: 0.5 | W23: veda | X23: veda | Y23: veda | Z23: veda | AA23: veda | AB23: veda | AC23: veda | AD23: veda | AE23: veda | AH23: =+V23 -> 0.5
A24: Febrero | B24: =SUM(AH24) -> 1449.015 | T24: 336.29 | U24: 101.73 | V24: 150.5 | W24: 50.785 | X24: 22.47 | Y24: 134.555 | Z24: 306.14 | AA24: 107.495 | AB24: 239.05 | AH24: =SUM(C24:AG24) -> 1449.015
A25: Marzo | B25: =SUM(AH25) -> 3734.9 | D25: 217.33 | E25: 162.425 | G25: 127.31 | H25: 227.81 | I25: 250.24 | J25: 8.365 | K25: 256.995 | L25: 225.025 | P25: 330.035 | Q25: 344.085 | R25: 111.895 | S25: 121.365 | T25: 375.935 | U25: 329.15 | V25: 179.68 | W25: 297.71 | X25: 15.635 | Y25: 15.635 | AB25: 29.39 | AC25: 11.12 | AE25: 97.765 | AH25: =SUM(C25:AG25) -> 3734.9
A26: Abril | B26: =SUM(AH26) -> 2182.99 | N26: 95.645 | O26: 8.79 | P26: 256.365 | Q26: 381.75 | R26: 291.995 | T26: 2.13 | V26: 325.175 | W26: 425.41 | X26: 116.475 | Y26: 77.51 | AB26: 80.205 | AD26: 121.54 | AH26: =SUM(C26:AG26) -> 2182.99
A27: Mayo | B27: =SUM(AH27) -> 1558.13 | E27: 207.27 | F27: 107.145 | G27: 93.995 | K27: 110.45 | L27: 27.055 | R27: 203.43 | T27: 457.455 | Z27: 120.155 | AA27: 85.06 | AB27: 38.75 | AC27: 107.065 | AE27: 0.3 | AH27: =SUM(C27:AG27) -> 1558.13
A28: Junio | B28: =SUM(AH28) -> 2269.695 | D28: 1 | G28: 182.82 | H28: 81.44 | I28: 104.18 | N28: 106.64 | O28: 168.455 | P28: 118.815 | Q28: 142.685 | R28: 83.71 | T28: 22.325 | U28: 251.215 | V28: 95.2 | W28: 171.21 | X28: 143.225 | Y28: 191.305 | Z28: 250.205 | AA28: 27.9 | AC28: 91.52 | AD28: 35.845 | AH28: =SUM(C28:AG28) -> 2269.695
A29: Julio | B29: =SUM(AH29) -> 1522.288 | G29: 104.685 | H29: 69.29 | K29: 0.023 | O29: 56.705 | S29: 214.7 | T29: 342.215 | U29: 203.385 | V29: 116.94 | X29: 161.95 | Z29: 197.465 | AE29: 54.93 | AH29: =SUM(C29:AG29) -> 1522.288
A30: Agosto | B30: =SUM(AH30) -> 849.08 | J30: 0.04 | S30: 157.125 | T30: 182.155 | U30: 101.075 | V30: 140.465 | W30: 107.92 | X30: 160 | AE30: 0.3 | AH30: =SUM(C30:AG30) -> 849.08
A31: Septiembre | B31: =SUM(AH31) -> 0.3 | C31: veda | D31: veda | E31: veda | F31: veda | G31: veda | H31: veda | I31: veda | J31: veda | K31: veda | L31: veda | M31: veda | N31: veda | O31: veda | P31: veda | Q31: veda | R31: veda | S31: veda | T31: veda | U31: veda | V31: veda | W31: veda | X31: veda | Y31: veda | AD31: 0.3 | AH31: =SUM(C31:AG31) -> 0.3
A32: Octubre | B32: =SUM(AH32) -> 744.636 | D32: 199.155 | J32: 0.15 | L32: 0.2 | T32: 0.11 | Y32: 183.335 | AA32: 143.52 | AC32: 108.9 | AE32: 57.88 | AF32: 28.39 | AG32: 22.996 | AH32: =SUM(C32:AG32) -> 744.636
A33: Noviembre | B33: =SUM(AH33) -> 2144.73 | I33: 221.34 | J33: 111.455 | K33: 188.165 | L33: 11.865 | N33: 189.57 | O33: 240.57 | P33: 110.53 | Q33: 241.285 | R33: 177.885 | S33: 139.15 | U33: 238.68 | V33: 106.385 | W33: 62.085 | X33: 70.245 | Y33: 34.3 | Z33: 1.2 | AB33: 0.02 | AH33: =SUM(C33:AG33) -> 2144.73
A34: Diciembre | B34: =SUM(AH34) -> 3557.215 | F34: 275.465 | G34: 137.68 | H34: 400.56 | L34: 286.79 | M34: 227.89 | N34: 360.845 | O34: 148.335 | P34: 245.17 | Q34: 268.375 | R34: 196.8 | T34: 35.88 | U34: 160.465 | V34: 290.375 | X34: 0.5 | Y34: 0.3 | AB34: 182.535 | AC34: 178.32 | AD34: 160.93 | AH34: =SUM(C34:AG34) -> 3557.215
A35: TOTAL | B35: =SUM(B23:B34) -> 20013.479 | AH35: =SUM(AH23:AH34) -> 20013.479
A37: III Región, de Atacama
A38: Mes | B38: Total mes | C38: 1 | D38: 2 | E38: 3 | F38: 4 | G38: 5 | H38: 6 | I38: 7 | J38: 8 | K38: 9 | L38: 10 | M38: 11 | N38: 12 | O38: 13 | P38: 14 | Q38: 15 | R38: 16 | S38: 17 | T38: 18 | U38: 19 | V38: 20 | W38: 21 | X38: 22 | Y38: 23 | Z38: 24 | AA38: 25 | AB38: 26 | AC38: 27 | AD38: 28 | AE38: 29 | AF38: 30 | AG38: 31 | AH38: TOTAL
A39: Enero | B39: =+AH39 -> 252 | G39: 120 | H39: 55 | I39: 6 | J39: 0 | K39: 0 | L39: 0 | M39: 14 | N39: 0 | O39: 0 | P39: 3 | Q39: 26 | R39: 15 | S39: 0 | T39: 0 | U39: 0 | V39: 0 | W39: 0 | X39: 0 | Y39: 0 | Z39: 0 | AA39: 0 | AB39: 0 | AC39: 0 | AD39: 0 | AE39: 0 | AF39: 0 | AG39: 13 | AH39: =SUM(C39:AG39) -> 252
A40: Febrero | B40: =+AH40 -> 1331 | C40: 0 | D40: 0 | E40: 0 | F40: 0 | G40: 0 | H40: 0 | I40: 0 | J40: 0 | K40: 0 | L40: 18 | O40: 2 | P40: 35 | Q40: 155 | R40: 137 | S40: 15 | T40: 79 | U40: 10 | V40: 148 | W40: 512 | X40: 62 | Y40: 51 | Z40: 2 | AA40: 22 | AD40: 75 | AE40: 8 | AH40: =SUM(C40:AG40) -> 1331
A41: Marzo | B41: =+AH41 -> 300 | D41: 1 | E41: 3 | I41: 16 | J41: 4 | N41: 2 | P41: 16 | R41: 23 | S41: 13 | X41: 22 | Y41: 14 | AE41: 94 | AF41: 27 | AG41: 65 | AH41: =SUM(C41:AG41) -> 300
A42: Abril | B42: =+AH42 -> 4981 | C42: 34 | D42: 38 | E42: 128 | F42: 436 | G42: 189 | K42: 132 | L42: 466 | M42: 142 | N42: 89 | O42: 23 | P42: 6 | R42: 61 | S42: 20 | T42: 438 | U42: 51 | V42: 519 | W42: 242 | X42: 619 | Y42: 469 | Z42: 216 | AA42: 257 | AB42: 238 | AC42: 31 | AD42: 137 | AH42: =SUM(C42:AG42) -> 4981
A43: Mayo | B43: =+AH43 -> 6233 | E43: 419 | F43: 188 | G43: 360 | H43: 145 | I43: 686 | J43: 1450 | K43: 324 | L43: 79 | M43: 58 | N43: 5 | O43: 0 | P43: 308 | Q43: 177 | R43: 231 | S43: 132 | T43: 24 | Z43: 467 | AA43: 316 | AB43: 216 | AC43: 345 | AD43: 138 | AG43: 165 | AH43: =SUM(C43:AG43) -> 6233
A44: Junio | B44: =+AH44 -> 1558 | C44: 96 | D44: 167 | E44: 2 | F44: 8 | I44: 126 | J44: 236 | K44: 126 | L44: 232 | M44: 435 | N44: 48 | O44: 25 | P44: 0 | Q44: 0 | R44: 0 | S44: 0 | T44: 0 | U44: 0 | V44: 0 | W44: 0 | X44: 0 | Y44: 0 | Z44: 0 | AA44: 0 | AC44: 57 | AH44: =SUM(C44:AG44) -> 1558
A45: Julio | B45: =+AH45 -> 0.21 | AC45: 0.21 | AH45: =SUM(C45:AG45) -> 0.21
...

Sheet RAE S.común
A2: RAE Sardina común 2012
A4: V región
A6: V Región A.G. Armadores artesanales del Puerto de San Antonio R.A.G. N° 2510
A7: Mes | B7: Total mes | C7: 1 | D7: 2 | E7: 3 | F7: 4 | G7: 5 | H7: 6 | I7: 7 | J7: 8 | K7: 9 | L7: 10 | M7: 11 | N7: 12 | O7: 13 | P7: 14 | Q7: 15 | R7: 16 | S7: 17 | T7: 18 | U7: 19 | V7: 20 | W7: 21 | X7: 22 | Y7: 23 | Z7: 24 | AA7: 25 | AB7: 26 | AC7: 27 | AD7: 28 | AE7: 29 | AF7: 30 | AG7: 31 | AH7: TOTAL
A8: Enero | B8: =+AH8 -> 0 | C8: VEDA | D8: VEDA | E8: VEDA | F8: VEDA | G8: VEDA | H8: VEDA | I8: VEDA | J8: VEDA | K8: VEDA | L8: VEDA | M8: VEDA | N8: VEDA | O8: VEDA | P8: VEDA | Q8: VEDA | R8: VEDA | S8: VEDA | T8: VEDA | U8: VEDA | V8: VEDA | W8: VEDA | X8: VEDA | Y8: VEDA | Z8: VEDA | AA8: VEDA | AB8: VEDA | AC8: VEDA | AD8: VEDA | AE8: VEDA | AF8: VEDA | AG8: VEDA | AH8: =SUM(C8:AG8) -> 0
A9: Febrero | B9: =+AH9 -> 0 | C9: VEDA | D9: VEDA | E9: VEDA | F9: VEDA | G9: VEDA | H9: VEDA | I9: VEDA | J9: VEDA | K9: VEDA | L9: VEDA | M9: VEDA | N9: VEDA | O9: VEDA | P9: VEDA | Q9: VEDA | R9: VEDA | S9: VEDA | T9: VEDA | U9: VEDA | V9: VEDA | W9: VEDA | X9: VEDA | Y9: VEDA | Z9: VEDA | AA9: VEDA | AB9: VEDA | AC9: VEDA | AD9: VEDA | AE9: VEDA | AF9: VEDA | AG9: VEDA | AH9: =SUM(C9:AG9) -> 0
A10: Marzo | B10: =+AH10 -> 23.855 | C10: VEDA | D10: VEDA | E10: VEDA | F10: VEDA | G10: VEDA | L10: 0 | M10: 0 | N10: 0 | O10: 0 | P10: 0 | Q10: 23.855 | R10: 0 | S10: 0 | T10: 0 | U10: 0 | V10: 0 | W10: 0 | X10: 0 | Y10: 0 | Z10: 0 | AA10: 0 | AB10: 0 | AC10: 0 | AD10: 0 | AE10: 0 | AF10: 0 | AG10: 0 | AH10: =SUM(C10:AG10) -> 23.855
A11: Abril | B11: =+AH11 -> 2385.535 | C11: VEDA | D11: VEDA | E11: VEDA | F11: VEDA | G11: VEDA | H11: VEDA | I11: VEDA | J11: VEDA | K11: VEDA | L11: 184.625 | M11: 39.055 | N11: 0 | O11: 117.92 | P11: 109.12 | Q11: 60.555 | R11: 168.815 | S11: 0 | T11: 129.52 | U11: 44.025 | V11: 213.12 | W11: 185.565 | X11: 110.745 | Y11: 192.06 | Z11: 141 | AA11: 177.1 | AB11: 0 | AC11: 81.745 | AD11: 179.27 | AE11: 86.5 | AF11: 164.795 | AG11: 0 | AH11: =SUM(C11:AG11) -> 2385.535
A12: Mayo | B12: =+AH12 -> 1896.845 | C12: 0 | D12: 0 | E12: 46.2 | F12: 176.77 | G12: 158.88 | H12: 0 | I12: 200.865 | J12: 132.995 | K12: 68.77 | L12: 212.575 | M12: 0 | N12: 147.4 | O12: 97.435 | P12: 66.2 | Q12: 156.18 | R12: 132.8 | S12: 14.82 | T12: 45.98 | U12: 0 | V12: 0 | W12: 0 | X12: 58.62 | Y12: 124.285 | Z12: 38.695 | AA12: 0 | AB12: 0 | AC12: 0 | AD12: 0 | AE12: 17.375 | AF12: 0 | AG12: 0 | AH12: =SUM(C12:AG12) -> 1896.845
