Workbook

Sheet Resumen LTP-PEP
C2: Informe
C3: Resumen Cuotas LTP 2016
C4: actualizado al 27-01-2017
C6: Unidad de Pesquería | D6: Zona | E6: D.Ex. Establece cuota | F6: D.Ex. Modifica cuota | G6: Cuota Asignada Sector Industrial | H6: Cuota LTP Asignada con sus Modificaciones | I6: Transferencias de Cuotas | J6: Cuota Efectiva | K6: Desembarque total (t) | L6: Aguas internacionales | M6: Saldo total (t) | N6: % consumido 2016
B7: Peces Pelágicos | C7: Anchoveta | D7: XV- I - II | E7: 1185/22-12-15 | G7: 636926 | H7: =SUM('Pelagicos LTP '!E6:E11) -> 636926 | I7: =SUM('Pelagicos LTP '!F6:F11) -> -4530.964 | J7: =H7+I7 -> 632395.04 | K7: =SUM('Pelagicos LTP '!H6:H11) -> 152165.06 | M7: =J7-K7 -> 480229.97 | N7: =K7/J7 -> 0.24061711
C8: Anchoveta | D8: III - IV | E8: 1184/22-12-15 | F8: 474/17-06-16 | G8: 12790 | H8: =SUM('Pelagicos LTP '!E14:E29) -> 17265 | I8: =SUM('Pelagicos LTP '!F14:F31) -> -12467.402 | J8: =H8+I8 -> 4797.598 | K8: =SUM('Pelagicos LTP '!H14:H31) -> 0 | M8: =J8-K8 -> 4797.598 | N8: =K8/J8 -> 0
C9: Anchoveta | D9: V - X | E9: 943/11-11-15 | F9: 346/09-05-16 | G9: 7388 | H9: =SUM('Pelagicos LTP '!E34:E93) -> 8573.998 | I9: =SUM('Pelagicos LTP '!F34:F93) -> -2138.553 | J9: =H9+I9 -> 6435.445 | K9: =SUM('Pelagicos LTP '!H34:H93) -> 5288.222 | M9: =J9-K9 -> 1147.223 | N9: =K9/J9 -> 0.8217337
C10: Sardina común | D10: V -X | E10: 943/11-11-15 | F10: 346/09-05-16 | G10: 61191.025 | H10: =SUM('Pelagicos LTP '!E99:E179) -> 70750.021 | I10: =SUM('Pelagicos LTP '!F99:F179) -> 15645.432 | J10: =H10+I10 -> 86395.453 | K10: =SUM('Pelagicos LTP '!H99:H179) -> 84377.544 | M10: =J10-K10 -> 2017.909 | N10: =K10/J10 -> 0.97664334 | Q10: IAN TAYLOR CHILE S.A. | R10: 2236.305
C11: Jurel | D11: XV - I - II | E11: 1142/18-12-15 | F11: 121/03-03-16 | G11: 43245.005 | H11: =SUM('Pelagicos LTP '!E183:E190) -> 41430.004 | I11: =SUM('Pelagicos LTP '!F183:F188) -> -15327.317 | J11: =H11+I11 -> 26102.687 | K11: =SUM('Pelagicos LTP '!H183:H188) -> 24199.027 | M11: =J11-K11 -> 1903.66 | N11: =K11/J11 -> 0.92707034
C12: Jurel | D12: III - IV | E12: 1142/18-12-15 | F12: 121/03-03-16 | G12: 9139 | H12: =SUM('Pelagicos LTP '!E193:E220) -> 8743.999 | I12: =SUM('Pelagicos LTP '!F193:F220) -> 2490.803 | J12: =H12+I12 -> 11234.802 | K12: =SUM('Pelagicos LTP '!H193:H220) -> 11038.451 | L12: =400+145 -> 545 | M12: =J12-K12 -> 196.351 | N12: =K12/J12 -> 0.98252297 | Q12: Rótulos de fila | R12: Suma de SumaDeSumaDeNr_Toneladas
C13: Jurel | D13: V - IX | E13: 1142/18-12-15 | F13: 121/03-03-16 | G13: 195598 | H13: =SUM('Pelagicos LTP '!E223:E288) -> 187555.01 | I13: =SUM('Pelagicos LTP '!F223:F288) -> 14063.417 | J13: =H13+I13 -> 201618.43 | K13: =SUM('Pelagicos LTP '!H223:H288) -> 200066.04 | L13: =467.273 -> 467.273 | M13: =J13-K13 -> 1552.384 | N13: =K13/J13 -> 0.99230039 | Q13: ALIMENTOS MARINOS S.A. | R13: 2191.783
C14: Jurel | D14: XIV - X | E14: 1142/18-12-15 | F14: 121/03-03-16 | G14: 27421.995 | H14: =SUM('Pelagicos LTP '!E291:E340) -> 26117.998 | I14: =SUM('Pelagicos LTP '!F291:F340) -> -2334.346 | J14: =H14+I14 -> 23783.652 | K14: =SUM('Pelagicos LTP '!H291:H340) -> 23260.74 | L14: 2146.783 | M14: =J14-K14 -> 522.912 | N14: =K14/J14 -> 0.97801381 | Q14: CAMANCHACA PESCA SUR S.A. | R14: 281.698
C15: Sardina española | D15: XV- I - II | E15: 1185/22-12-15 | G15: 742 | H15: =SUM('Pelagicos LTP '!E343:E348) -> 742 | I15: =SUM('Pelagicos LTP '!F343:F348) -> 0 | J15: =H15+I15 -> 742 | K15: =SUM('Pelagicos LTP '!H343:H348) -> 0 | M15: =J15-K15 -> 742 | N15: =K15/J15 -> 0 | Q15: Total general | R15: 4709.786
C16: Sardina española | D16: III - IV | E16: 1184/22-12-15 | G16: 875.002 | H16: =SUM('Pelagicos LTP '!E351:E368) -> 875.002 | I16: =SUM('Pelagicos LTP '!F351:F368) -> -100 | J16: =H16+I16 -> 775.002 | K16: =SUM('Pelagicos LTP '!H351:H366) -> 0 | M16: =J16-K16 -> 775.002 | N16: =K16/J16 -> 0
B17: Peces Demersales | C17: Congrio dorado | D17: paralelo 41° 28,6’ - 47° L.S. | E17: 1186/22-12-15 | G17: 418.501 | H17: =SUM('Demersales LTP '!E7:E16) -> 418.501 | I17: =SUM('Demersales LTP '!F7:F16) -> -33.432 | J17: =H17+I17 -> 385.069 | K17: =SUM('Demersales LTP '!H7:H16) -> 371.505 | M17: =J17-K17 -> 13.564 | N17: =K17/J17 -> 0.96477514
C18: Congrio dorado | D18: paralelo 47° - 57° L.S. | E18: 1186/22-12-15 | G18: 238 | H18: =SUM('Demersales LTP '!E21:E30) -> 238 | I18: =SUM('Demersales LTP '!F21:F30) -> 0 | J18: =H18+I18 -> 238 | K18: =SUM('Demersales LTP '!H21:H30) -> 226.948 | M18: =J18-K18 -> 11.052 | N18: =K18/J18 -> 0.95356303
C19: Merluza del sur | D19: paralelo 41° 28,6’ - 47° L.S. | E19: 1186/22-12-15 | F19: 645/25-08-16 | G19: 3937.961 | H19: =SUM('Demersales LTP '!E33:E48) -> 4313.001 | I19: =SUM('Demersales LTP '!F33:F48) -> 3591.581 | J19: =H19+I19 -> 7904.582 | K19: =SUM('Demersales LTP '!H33:H48) -> 7501.967 | M19: =J19-K19 -> 402.615 | N19: =K19/J19 -> 0.94906562
C20: Merluza del sur | D20: paralelo 47° - 57° L.S. | E20: 1186/22-12-15 | F20: 645/25-08-16 | G20: 2518 | H20: =SUM('Demersales LTP '!E51:E60) -> 2758.001 | I20: =SUM('Demersales LTP '!F51:F60) -> -14.013 | J20: =H20+I20 -> 2743.988 | K20: =SUM('Demersales LTP '!H51:H60) -> 2427.755 | M20: =J20-K20 -> 316.233 | N20: =K20/J20 -> 0.88475423
C21: Merluza de tres aletas | D21: paralelo 41º28,6´ - XII | E21: 1186/22-12-15 | G21: 11516 | H21: =SUM('Demersales LTP '!E63:E70) -> 11516 | I21: =SUM('Demersales LTP '!F63:F70) -> 0 | J21: =H21+I21 -> 11516 | K21: =SUM('Demersales LTP '!H63:H70) -> 8270.994 | M21: =J21-K21 -> 3245.006 | N21: =K21/J21 -> 0.71821761
C22: Merluza de cola | D22: V -X | E22: 1140/18-12-15 | G22: 24132.998 | H22: =SUM('Demersales LTP '!E73:E120) -> 24132.998 | I22: =SUM('Demersales LTP '!F73:F120) -> -8138.485 | J22: =H22+I22 -> 15994.513 | K22: =SUM('Demersales LTP '!H73:H116) -> 9407.792 | M22: =J22-K22 -> 6586.721 | N22: =K22/J22 -> 0.58818871
C23: Merluza de cola | D23: XI -XII | E23: 1140/18-12-15 | G23: 16088 | H23: =SUM('Demersales LTP '!E125:E136) -> 16087.423 | I23: =SUM('Demersales LTP '!F125:F136) -> 8138.081 | J23: =H23+I23 -> 24225.504 | K23: =SUM('Demersales LTP '!H125:H134) -> 18670.551 | M23: =J23-K23 -> 5554.953 | N23: =K23/J23 -> 0.77069815
C24: Merluza común | D24: IV- 41º 28, 6 | E24: 1186/22-12-15 | G24: 13542 | H24: =SUM('Demersales LTP '!E141:E194) -> 13542 | I24: =SUM('Demersales LTP '!F141:F194) -> 107.55371 | J24: =H24+I24 -> 13649.554 | K24: =SUM('Demersales LTP '!H141:H194) -> 13445.023 | M24: =J24-K24 -> 204.53071 | N24: =K24/J24 -> 0.98501557
B25: Crustáceos | C25: Camarón nailon | D25: II-VIII | E25: 945/11-11-15 | G25: 4405 | H25: 4405 | I25: =+'Crustaceos LTP'!AV52 -> 287.23528 | J25: =H25+I25 -> 4692.2353 | K25: =+'Crustaceos LTP'!AX52 -> 3855.7171 | M25: =J25-K25 -> 836.51822 | N25: =K25/J25 -> 0.82172287
C26: Langostino amarillo | D26: III-IV | E26: 945/11-11-15 | G26: 1482.004 | H26: 1482.004 | I26: =+'Crustaceos LTP'!X82 -> 467.3 | J26: =H26+I26 -> 1949.304 | K26: =+'Crustaceos LTP'!Z82 -> 1829.24 | M26: =J26-K26 -> 120.064 | N26: =K26/J26 -> 0.93840673
C27: Langostino colorado | D27: XV-IV | E27: 945/11-11-15 | F27: 147/15-03-16 | G27: 91.004 | H27: 169 | I27: =+'Crustaceos LTP'!X100 -> 129.99 | J27: =H27+I27 -> 298.99 | K27: =+'Crustaceos LTP'!Z100 -> 256.63 | M27: =J27-K27 -> 42.36 | N27: =K27/J27 -> 0.85832302
I29: =33.39-33.432 -> -0.042
C31: Nota: El desembarque de aguas internacionales (columna G) Jurel desde III a X regiones, esta incorporado en la columna de desembarque total. Solo se incorpora el dato en la columna G para tenerlo de referencia
C34: Informe
C35: Resumen Cuotas PEP 2016
C38: Unidad de Pesquería | D38: Zona | E38: D.Ex. Establece cuota | F38: D.Ex. Modifica cuota | G38: Cuota PEP Asignada | H38: Cuota PEP Asignada con sus Modificaciones | I38: Cuota PEP Adjudicada | J38: Transferencias de Cuotas | K38: Cuota Efectiva | L38: Desembarque total (t) | M38: Saldo total (t) | N38: % consumido 2016
C39: Langostino amarillo | D39: V-VIII | E39: 944/11-11-15 | G39: 1830 | H39: =+'Cuotas Licitadas '!D13 -> 1830 | I39: =+'Cuotas Licitadas '!E39 -> 1830 | J39: ='Cuotas Licitadas '!F39 -> 818.08746 | K39: ='Cuotas Licitadas '!H39 -> 1830.0007 | L39: ='Cuotas Licitadas '!I39 -> 1785.373 | M39: =K39-L39 -> 44.627668 | N39: =L39/K39 -> 0.97561331
C40: Langostino colorado | D40: V-VIII | E40: 944/11-11-15 | F40: 148/15-03-16 | G40: 3130 | H40: ='Cuotas Licitadas '!D50 -> 4618 | I40: =+'Cuotas Licitadas '!E78 -> 4502.5501 | J40: =+'Cuotas Licitadas '!F78 -> 2104.0325 | K40: =+'Cuotas Licitadas '!H78 -> 4502.5501 | L40: =+'Cuotas Licitadas '!I78 -> 4428.684 | M40: =K40-L40 -> 73.866139 | N40: =L40/K40 -> 0.9835946
C41: Bacalao licitado | D41: 47° L.S. al 57° L.S. | E41: 946/11-11-15 | G41: 1636 | H41: =+'Cuotas Licitadas '!E87 -> 1636 | I41: =+'Cuotas Licitadas '!E116 -> 1635.9999 | J41: =+'Cuotas Licitadas '!F116 -> 89.595 | K41: =+'Cuotas Licitadas '!H116 -> 1635.9999 | L41: =+'Cuotas Licitadas '!I116 -> 1615.093 | M41: =K41-L41 -> 20.906889 | N41: =L41/K41 -> 0.98722073

Sheet Pelagicos LTP 
A1: Cuotas LTP Recursos Pelágicos Año 2016 actualizado al 27-01-2017
C4: Periodo | E4: CUOTA (TONELADAS) | H4: OPERACIÓN | K4: RESUMEN ANUAL
A5: Unidad de pesquería | B5: Titular de cuota LTP | C5: Inicial | D5: Final | E5: Cuota Asignada por R. Ex N°3520-15 y Mod | F5: Traspaso, Cesion, Arriendo, etc) | G5: Cuota Efectiva | H5: captura (t) | I5: Saldo (t) | J5: % consumido | K5: Cuota asignada (t) | L5: Traspaso, Cesion, Arriendo, etc) | M5: Cuota Efectiva | N5: Captura (t) | O5: Saldo (t) | P5: % consumido
A6: Anchoveta XV - I - II | B6: ARICA SEAFOOD PRODUCER S.A. | C6: 42005 | D6: 42185 | E6: 3398.22 | G6: =E6+F6 -> 3398.22 | I6: =G6-H6 -> 3398.22 | J6: =H6/G6 -> 0 | K6: =E6+E7 -> 4530.965 | L6: =F6+F7 -> -4530.964 | M6: =K6+L6 -> 0.001 | N6: =H6+H7 -> 0 | O6: =M6-N6 -> 0.001 | P6: =N6/M6 -> 0
C7: 42186 | D7: 42369 | E7: 1132.745 | F7: =-4530.964 -> -4530.964 | G7: =E7+F7+I6 -> 0.001 | I7: =G7-H7 -> 0.001 | J7: =H7/G7 -> 0
B8: CAMANCHACA S.A. CIA. PESQ | C8: 42005 | D8: 42185 | E8: 94287.815 | G8: =+E8+F8 -> 94287.815 | H8: 16244.86 | I8: =G8-H8 -> 78042.955 | J8: =H8/G8 -> 0.17229013 | K8: =E8+E9 -> 125717.22 | L8: =F8+F9 -> 0 | M8: =K8+L8 -> 125717.22 | N8: =H8+H9 -> 29997.803 | O8: =M8-N8 -> 95719.415 | P8: =N8/M8 -> 0.23861332
C9: 42186 | D9: 42369 | E9: 31429.403 | G9: =E9+F9+I8 -> 109472.36 | H9: 13752.943 | I9: =G9-H9 -> 95719.415 | J9: =H9/G9 -> 0.12562937
B10: CORPESCA S.A | C10: 42005 | D10: 42185 | E10: 380007.97 | G10: =E10+F10 -> 380007.97 | H10: 89313.017 | I10: =G10-H10 -> 290694.95 | J10: =H10/G10 -> 0.23502933 | K10: =E10+E11 -> 506677.82 | L10: =F10+F11 -> 0 | M10: =K10+L10 -> 506677.82 | N10: =H10+H11 -> 122167.26 | O10: =M10-N10 -> 384510.56 | P10: =N10/M10 -> 0.24111429
C11: 42186 | D11: 42369 | E11: 126669.85 | G11: =E11+F11+I10 -> 417364.8 | H11: 32854.243 | I11: =G11-H11 -> 384510.56 | J11: =H11/G11 -> 0.078718289
K12: =SUM(K6:K11) -> 636926 | L12: =SUM(L6:L11) -> -4530.964 | M12: =SUM(M6:M11) -> 632395.04 | N12: =SUM(N6:N11) -> 152165.06 | O12: =SUM(O6:O11) -> 480229.97 | P12: =+N12/M12 -> 0.24061711
A14: Anchoveta III - IV. | B14: ALIMENTOS MARINOS S.A. | C14: 42005 | D14: 42308 | E14: 1080.547 | G14: =E14+F14 -> 1080.547 | I14: =G14-H14 -> 1080.547 | J14: =H14/G14 -> 0 | K14: =E14+E15 -> 1137.401 | L14: =F14+F15 -> 0 | M14: =K14+L14 -> 1137.401 | N14: =H14+H15 -> 0 | O14: =M14-N14 -> 1137.401 | P14: =N14/M14 -> 0
C15: 42309 | D15: 42369 | E15: 56.854 | G15: =E15+F15+I14 -> 1137.401 | I15: =G15-H15 -> 1137.401 | J15: =H15/G15 -> 0
B16: BAHIA CALDERA S.A. PESQ. | C16: 42005 | D16: 42308 | E16: 8055.856 | F16: =-3554.512-2147.89 -> -5702.402 | G16: =E16+F16 -> 2353.454 | I16: =G16-H16 -> 2353.454 | J16: =H16/G16 -> 0 | K16: =E16+E17 -> 8479.719 | L16: =F16+F17 -> -5702.402 | M16: =K16+L16 -> 2777.317 | N16: =H16+H17 -> 0 | O16: =M16-N16 -> 2777.317 | P16: =N16/M16 -> 0
C17: 42309 | D17: 42369 | E17: 423.863 | G17: =E17+F17+I16 -> 2777.317 | I17: =G17-H17 -> 2777.317 | J17: =H17/G17 -> 0
B18: BLUMAR S.A. | C18: 42005 | D18: 42308 | E18: 62.332 | F18: =-2727.319+2727.319 -> 0 | G18: =E18+F18 -> 62.332 | I18: =G18-H18 -> 62.332 | J18: =H18/G18 -> 0 | K18: =E18+E19 -> 65.612 | L18: =F18+F19 -> 0 | M18: =K18+L18 -> 65.612 | N18: =H18+H19 -> 0 | O18: =M18-N18 -> 65.612 | P18: =N18/M18 -> 0
C19: 42309 | D19: 42369 | E19: 3.28 | G19: =E19+F19+I18 -> 65.612 | I19: =G19-H19 -> 65.612 | J19: =H19/G19 -> 0
B20: CAMANCHACA S.A. CIA. PESQ | C20: 42005 | D20: 42308 | E20: 14.926 | G20: =E20+F20 -> 14.926 | I20: =G20-H20 -> 14.926 | J20: =H20/G20 -> 0 | K20: =E20+E21 -> 15.711 | L20: =F20+F21 -> 0 | M20: =K20+L20 -> 15.711 | N20: =H20+H21 -> 0 | O20: =M20-N20 -> 15.711 | P20: =N20/M20 -> 0
C21: 42309 | D21: 42369 | E21: 0.785 | G21: =E21+F21+I20 -> 15.711 | I21: =G21-H21 -> 15.711 | J21: =H21/G21 -> 0
B22: INVERSIONES PESQUERAS SpA | C22: 42005 | D22: 42308 | E22: 187.406 | F22: -187.403 | G22: =E22+F22 -> 0.003 | I22: =G22-H22 -> 0.003 | J22: =H22/G22 -> 0 | K22: =E22+E23 -> 197.266 | L22: =F22+F23 -> -187.403 | M22: =K22+L22 -> 9.863 | N22: =H22+H23 -> 0 | O22: =M22-N22 -> 9.863 | P22: =N22/M22 -> 0
C23: 42309 | D23: 42369 | E23: 9.86 | G23: =E23+F23+I22 -> 9.863 | I23: =G23-H23 -> 9.863 | J23: =H23/G23 -> 0
B24: ORIZON S.A | C24: 42005 | D24: 42308 | E24: 6949.604 | F24: -6765 | G24: =E24+F24 -> 184.604 | I24: =G24-H24 -> 184.604 | J24: =H24/G24 -> 0 | K24: =E24+E25 -> 7315.261 | L24: =F24+F25 -> -6765 | M24: =K24+L24 -> 550.261 | N24: =H24+H25 -> 0 | O24: =M24-N24 -> 550.261 | P24: =N24/M24 -> 0
C25: 42309 | D25: 42369 | E25: 365.657 | G25: =E25+F25+I24 -> 550.261 | I25: =G25-H25 -> 550.261 | J25: =H25/G25 -> 0
B26: CAMANCHACA PESCA SUR S.A. | C26: 42005 | D26: 42308 | E26: 49.526 | G26: =E26+F26 -> 49.526 | I26: =G26-H26 -> 49.526 | J26: =H26/G26 -> 0 | K26: =E26+E27 -> 52.132 | L26: =F26+F27 -> 0 | M26: =K26+L26 -> 52.132 | N26: =H26+H27 -> 0 | O26: =M26-N26 -> 52.132 | P26: =N26/M26 -> 0
C27: 42309 | D27: 42369 | E27: 2.606 | G27: =E27+F27+I26 -> 52.132 | I27: =G27-H27 -> 52.132 | J27: =H27/G27 -> 0
B28: LANDES S.A. SOC. PESQ. | C28: 42005 | D28: 42308 | E28: 1.803 | G28: =E28+F28 -> 1.803 | I28: =G28-H28 -> 1.803 | J28: =H28/G28 -> 0 | K28: =E28+E29 -> 1.898 | L28: =F28+F29 -> 0 | M28: =K28+L28 -> 1.898 | N28: =H28+H29 -> 0 | O28: =M28-N28 -> 1.898 | P28: =N28/M28 -> 0
C29: 42309 | D29: 42369 | E29: 0.095 | G29: =E29+F29+I28 -> 1.898 | I29: =G29-H29 -> 1.898 | J29: =H29/G29 -> 0
B30: PESQUERA LITORAL SpA | C30: 42005 | D30: 42308 | E30: 0 | F30: 187.403 | G30: =E30+F30 -> 187.403 | I30: =G30-H30 -> 187.403 | J30: =H30/G30 -> 0 | K30: =E30+E31 -> 0 | L30: =F30+F31 -> 187.403 | M30: =K30+L30 -> 187.403 | N30: =H30+H31 -> 0 | O30: =M30-N30 -> 187.403 | P30: =N30/M30 -> 0
C31: 42309 | D31: 42369 | E31: 0 | F31: 0 | G31: =E31+F31+I30 -> 187.403 | I31: =G31-H31 -> 187.403 | J31: =H31/G31 -> 0
K32: =SUM(K14:K29) -> 17265 | L32: =SUM(L14:L31) -> -12467.402 | M32: =SUM(M14:M31) -> 4797.598 | N32: =SUM(N14:N29) -> 0 | O32: =SUM(O14:O29) -> 4610.195 | P32: =+N32/M32 -> 0
M33: =+L32-M32 -> -17265
A34: Anchoveta V-X | B34: ALIMENTOS MARINOS S.A. | C34: 42005 | D34: 42124 | E34: 1362.899 | F34: =-469.505+44.339+35.36+71.045+196.135-411.22-157 -> -690.846 | G34: =E34+F34 -> 672.053 | I34: =G34-H34 -> 672.053 | J34: =H34/G34 -> 0 | K34: =E34+E35+E36 -> 1603.389 | L34: =F34+F35+F36 -> -690.846 | M34: =K34+L34 -> 912.543 | N34: =H34+H35+H36 -> 730.633 | O34: =M34-N34 -> 181.91 | P34: =N34/M34 -> 0.80065597
C35: 42125 | D35: 42247 | E35: 160.264 | G35: =E35+F35+I34 -> 832.317 | H35: 78.325 | I35: =G35-H35 -> 753.992 | J35: =H35/G35 -> 0.09410477
C36: 42248 | D36: 42369 | E36: 80.226 | G36: =E36+F36+I35 -> 834.218 | H36: 652.308 | I36: =G36-H36 -> 181.91 | J36: =H36/G36 -> 0.78193949
B37: BERTA ELENA LTDA. SOC. PESQ. | C37: 42005 | D37: 42124 | E37: 0 | F37: 0 | G37: =E37+F37 -> 0 | I37: =G37-H37 -> 0 | J37: =H37/G37 -> #DIV/0! | K37: =E37+E38+E39 -> 0 | L37: =F37+F38+F39 -> 0 | M37: =K37+L37 -> 0 | N37: =H37+H38+H39 -> 0 | O37: =M37-N37 -> 0 | P37: =N37/M37 -> #DIV/0!
C38: 42125 | D38: 42247 | E38: 0 | F38: 0 | G38: =E38+F38+I37 -> 0 | I38: =G38-H38 -> 0 | J38: =H38/G38 -> #DIV/0!
C39: 42248 | D39: 42369 | E39: 0 | F39: 0 | G39: =E39+F39+I38 -> 0 | I39: =G39-H39 -> 0 | J39: =H39/G39 -> #DIV/0!
B40: BLUMAR S.A. | C40: 42005 | D40: 42124 | E40: 1713.557 | F40: =-85-10-1100 -> -1195 | G40: =E40+F40 -> 518.557 | H40: 61.974 | I40: =G40-H40 -> 456.583 | J40: =H40/G40 -> 0.11951242 | K40: =E40+E41+E42 -> 2015.922 | L40: =F40+F41+F42 -> -1195 | M40: =K40+L40 -> 820.922 | N40: =H40+H41+H42 -> 567.191 | O40: =M40-N40 -> 253.731 | P40: =N40/M40 -> 0.69091948
C41: 42125 | D41: 42247 | E41: 201.498 | G41: =E41+F41+I40 -> 658.081 | H41: 147.945 | I41: =G41-H41 -> 510.136 | J41: =H41/G41 -> 0.22481275
C42: 42248 | D42: 42369 | E42: 100.867 | G42: =E42+F42+I41 -> 611.003 | H42: 357.272 | I42: =G42-H42 -> 253.731 | J42: =H42/G42 -> 0.58473035
B43: CAMANCHACA PESCA SUR S.A. | C43: 42005 | D43: 42124 | E43: 1128.256 | F43: =-35+34+85.98 -> 84.98 | G43: =E43+F43 -> 1213.236 | H43: 609.719 | I43: =G43-H43 -> 603.517 | J43: =H43/G43 -> 0.50255597 | K43: =E43+E44+E45 -> 1327.342 | L43: =F43+F44+F45 -> 84.98 | M43: =K43+L43 -> 1412.322 | N43: =H43+H44+H45 -> 1361.678 | O43: =M43-N43 -> 50.644 | P43: =N43/M43 -> 0.96414132
...

Sheet Demersales LTP 
A2: Cuotas LTP Recursos Demersales Año 2016 actualizado al 27-01-2017
C5: Periodo | E5: Cuota (t) | H5: Operación | K5: Resumen anual
A6: Unidad de pesquería | B6: Armador | C6: Inicial | D6: Final | E6: Cuota Asignada | F6: Traspaso, Cesion, Arriendo, etc) | G6: Cuota Efectiva | H6: Desembarque (t) | I6: Saldo (t) | J6: % consumido | K6: Cuota Total | L6: Traspaso, Cesion, Arriendo, etc) | M6: Cuota Efectiva | N6: Desembarque (t) | O6: Saldo (t) | P6: % consumido
A7: Congrio dorado NE H/F (41º28,6 LS hasta 47º) | B7: Emdepes S.A. | C7: 42005 | D7: 42063 | E7: 0.529 | G7: =E7+F7 -> 0.529 | I7: =G7-H7 -> 0.529 | J7: =H7/G7 -> 0 | K7: =E7+E8 -> 1.059 | L7: =F7+F8 -> 0 | M7: =K7+L7 -> 1.059 | N7: =H7+H8 -> 1.001 | O7: =M7-N7 -> 0.058 | P7: =N7/M7 -> 0.94523135
C8: 42064 | D8: 42369 | E8: 0.53 | G8: =E8+F8+I7 -> 1.059 | H8: 1.001 | I8: =G8-H8 -> 0.058 | J8: =H8/G8 -> 0.94523135
B9: Grimar S.A.Pesq. | C9: 42005 | D9: 42063 | E9: 7.714 | G9: =E9+F9 -> 7.714 | H9: 1.984 | I9: =G9-H9 -> 5.73 | J9: =H9/G9 -> 0.25719471 | K9: =E9+E10 -> 15.447 | L9: =F9+F10 -> 0 | M9: =K9+L9 -> 15.447 | N9: =H9+H10 -> 14.367 | O9: =M9-N9 -> 1.08 | P9: =N9/M9 -> 0.93008351
C10: 42064 | D10: 42369 | E10: 7.733 | G10: =E10+F10+I9 -> 13.463 | H10: 12.383 | I10: =G10-H10 -> 1.08 | J10: =H10/G10 -> 0.91978014
B11: Deris S.A. | C11: 42005 | D11: 42063 | E11: 145.187 | F11: =-33.39+60.001+23.728 -> 50.339 | G11: =E11+F11 -> 195.526 | H11: 53.215 | I11: =G11-H11 -> 142.311 | J11: =H11/G11 -> 0.27216329 | K11: =E11+E12 -> 290.721 | L11: =F11+F12 -> 50.339 | M11: =K11+L11 -> 341.06 | N11: =H11+H12 -> 336.726 | O11: =M11-N11 -> 4.334 | P11: =N11/M11 -> 0.98729256
C12: 42064 | D12: 42369 | E12: 145.534 | G12: =E12+F12+I11 -> 287.845 | H12: 283.511 | I12: =G12-H12 -> 4.334 | J12: =H12/G12 -> 0.98494329
B13: Pesca Cisne S.A. Pesq. | C13: 42005 | D13: 42063 | E13: 12.385 | F13: =-0.042-23.728 -> -23.77 | G13: =E13+F13 -> -11.385 | I13: =G13-H13 -> -11.385 | J13: =H13/G13 -> 0 | K13: =E13+E14 -> 24.799 | L13: =F13+F14 -> -23.77 | M13: =K13+L13 -> 1.029 | N13: =H13+H14 -> 0 | O13: =M13-N13 -> 1.029 | P13: =N13/M13 -> 0
C14: 42064 | D14: 42369 | E14: 12.414 | G14: =E14+F14+I13 -> 1.029 | I14: =G14-H14 -> 1.029 | J14: =H14/G14 -> 0
B15: Sur Austral S.A. Pesq. | C15: 42005 | D15: 42063 | E15: 43.186 | F15: -60.001 | G15: =E15+F15 -> -16.815 | I15: =G15-H15 -> -16.815 | J15: =H15/G15 -> 0 | K15: =E15+E16 -> 86.475 | L15: =F15+F16 -> -60.001 | M15: =K15+L15 -> 26.474 | N15: =H15+H16 -> 19.411 | O15: =M15-N15 -> 7.063 | P15: =N15/M15 -> 0.73320994
C16: 42064 | D16: 42369 | E16: 43.289 | G16: =E16+F16+I15 -> 26.474 | H16: 19.411 | I16: =G16-H16 -> 7.063 | J16: =H16/G16 -> 0.73320994
B17: Alimentos Marinos S.A. | C17: 42005 | D17: 42063 | E17: 0 | F17: 0.042 | G17: =E17+F17 -> 0.042 | I17: =G17-H17 -> 0.042 | J17: =H17/G17 -> 0 | K17: =E17+E18 -> 0 | L17: =F17+F18 -> 0.042 | M17: =K17+L17 -> 0.042 | N17: =H17+H18 -> 0 | O17: =M17-N17 -> 0.042 | P17: =N17/M17 -> 0
C18: 42064 | D18: 42369 | E18: 0 | G18: =E18+F18+I17 -> 0.042 | I18: =G18-H18 -> 0.042 | J18: =H18/G18 -> 0
K19: =SUM(K7:K16) -> 418.501 | L19: =SUM(L7:L16) -> -33.432 | M19: =SUM(M7:M16) -> 385.069 | N19: =SUM(N7:N16) -> 371.505 | O19: =SUM(O7:O16) -> 13.564 | P19: =+N19/M19 -> 0.96477514
L20: 33.39
A21: Congrio dorado SE (47º hasta 57º) | B21: Emdepes S.A., | C21: 42005 | D21: 42063 | E21: 20.665 | G21: =E21+F21 -> 20.665 | I21: =G21-H21 -> 20.665 | J21: =H21/G21 -> 0 | K21: =E21+E22 -> 41.33 | L21: =F21+F22 -> 0 | M21: =K21+L21 -> 41.33 | N21: =H21+H22 -> 41.071 | O21: =M21-N21 -> 0.259 | P21: =N21/M21 -> 0.99373337
C22: 42064 | D22: 42369 | E22: 20.665 | G22: =E22+F22+I21 -> 41.33 | H22: 41.071 | I22: =G22-H22 -> 0.259 | J22: =H22/G22 -> 0.99373337
B23: Grimar S.A.Pesq. | C23: 42005 | D23: 42063 | E23: 0.062 | G23: =E23+F23 -> 0.062 | I23: =G23-H23 -> 0.062 | J23: =H23/G23 -> 0 | K23: =E23+E24 -> 0.124 | L23: =F23+F24 -> 0 | M23: =K23+L23 -> 0.124 | N23: =H23+H24 -> 0 | O23: =M23-N23 -> 0.124 | P23: =N23/M23 -> 0
C24: 42064 | D24: 42369 | E24: 0.062 | G24: =E24+F24+I23 -> 0.124 | I24: =G24-H24 -> 0.124 | J24: =H24/G24 -> 0
B25: Deris S.A. | C25: 42005 | D25: 42063 | E25: 70.758 | F25: =-23.7 -> -23.7 | G25: =E25+F25 -> 47.058 | H25: 4.937 | I25: =G25-H25 -> 42.121 | J25: =H25/G25 -> 0.10491309 | K25: =E25+E26 -> 141.516 | L25: =F25+F26 -> -23.7 | M25: =K25+L25 -> 117.816 | N25: =H25+H26 -> 111.844 | O25: =M25-N25 -> 5.972 | P25: =N25/M25 -> 0.94931079
C26: 42064 | D26: 42369 | E26: 70.758 | G26: =E26+F26+I25 -> 112.879 | H26: 106.907 | I26: =G26-H26 -> 5.972 | J26: =H26/G26 -> 0.94709379
B27: Pesca Cisne S.A | C27: 42005 | D27: 42063 | E27: 27.485 | F27: =23.7 -> 23.7 | G27: =E27+F27 -> 51.185 | H27: 74.033 | I27: =G27-H27 -> -22.848 | J27: =H27/G27 -> 1.4463808 | K27: =E27+E28 -> 54.97 | L27: =F27+F28 -> 23.7 | M27: =K27+L27 -> 78.67 | N27: =H27+H28 -> 74.033 | O27: =M27-N27 -> 4.637 | P27: =N27/M27 -> 0.94105758
C28: 42064 | D28: 42369 | E28: 27.485 | G28: =E28+F28+I27 -> 4.637 | I28: =G28-H28 -> 4.637 | J28: =H28/G28 -> 0
B29: Sur Austral S.A. Pesq. | C29: 42005 | D29: 42063 | E29: 0.03 | G29: =E29+F29 -> 0.03 | I29: =G29-H29 -> 0.03 | J29: =H29/G29 -> 0 | K29: =E29+E30 -> 0.06 | L29: =F29+F30 -> 0 | M29: =K29+L29 -> 0.06 | N29: =H29+H30 -> 0 | O29: =M29-N29 -> 0.06 | P29: =N29/M29 -> 0
C30: 42064 | D30: 42369 | E30: 0.03 | G30: =E30+F30+I29 -> 0.06 | I30: =G30-H30 -> 0.06 | J30: =H30/G30 -> 0
H31: =SUM(H7:H30) -> 598.453 | K31: =SUM(K21:K30) -> 238 | L31: =SUM(L21:L30) -> 0 | M31: =SUM(M21:M30) -> 238 | N31: =SUM(N21:N30) -> 226.948 | O31: =SUM(O21:O30) -> 11.052 | P31: =+N31/M31 -> 0.95356303
A33: Merluza del sur NE F/H (41º28,6 LS al 47º LS) | B33: Emdepes S.A. | C33: 42005 | D33: 42035 | E33: 192.551 | F33: =73.003+134.435+55.338+500+5.6+140+5.008+55.613-55.613 -> 913.384 | G33: =E33+F33 -> 1105.935 | I33: =G33-H33 -> 1105.935 | J33: =H33/G33 -> 0 | K33: =E33+E34 -> 549.981 | L33: =F33+F34 -> 913.384 | M33: =K33+L33 -> 1463.365 | N33: =H33+H34 -> 1457.811 | O33: =M33-N33 -> 5.554 | P33: =N33/M33 -> 0.99620464
C34: 42036 | D34: 42369 | E34: 357.43 | G34: =E34+F34+I33 -> 1463.365 | H34: 1457.811 | I34: =G34-H34 -> 5.554 | J34: =H34/G34 -> 0.99620464
B35: Grimar S.A. Pesq. | C35: 42005 | D35: 42035 | E35: 44.713 | F35: =140.465+163.676+58.764+946.461+11.815+79.944+370+10.43+8.737 -> 1790.292 | G35: =E35+F35 -> 1835.005 | H35: 50.073 | I35: =G35-H35 -> 1784.932 | J35: =H35/G35 -> 0.027287664 | K35: =E35+E36 -> 127.714 | L35: =F35+F36 -> 1790.292 | M35: =K35+L35 -> 1918.006 | N35: =H35+H36 -> 1543.442 | O35: =M35-N35 -> 374.564 | P35: =N35/M35 -> 0.80471177
C36: 42036 | D36: 42369 | E36: 83.001 | G36: =E36+F36+I35 -> 1867.933 | H36: 1493.369 | I36: =G36-H36 -> 374.564 | J36: =H36/G36 -> 0.79947675
B37: Pesca Cisne S.A. | C37: 42005 | D37: 42035 | E37: 44.838 | F37: -128 | G37: =E37+F37 -> -83.162 | I37: =G37-H37 -> -83.162 | J37: =H37/G37 -> 0 | K37: =E37+E38 -> 128.071 | L37: =F37+F38 -> -128 | M37: =K37+L37 -> 0.071 | N37: =H37+H38 -> 0 | O37: =M37-N37 -> 0.071 | P37: =N37/M37 -> 0
C38: 42036 | D38: 42369 | E38: 83.233 | G38: =E38+F38+I37 -> 0.071 | I38: =G38-H38 -> 0.071 | J38: =H38/G38 -> 0
B39: Sur Austral S.A. Pesq. | C39: 42005 | D39: 42035 | E39: 528.373 | F39: =64.108+18.6+71.024+6.667+7.506-100-21+11 -> 57.905 | G39: =E39+F39 -> 586.278 | H39: 33.625 | I39: =G39-H39 -> 552.653 | J39: =H39/G39 -> 0.057353337 | K39: =E39+E40 -> 1509.188 | L39: =F39+F40 -> 57.905 | M39: =K39+L39 -> 1567.093 | N39: =H39+H40 -> 1601.998 | O39: =M39-N39 -> -34.905 | P39: =N39/M39 -> 1.0222737
C40: 42036 | D40: 42369 | E40: 980.815 | G40: =E40+F40+I39 -> 1533.468 | H40: 1568.373 | I40: =G40-H40 -> -34.905 | J40: =H40/G40 -> 1.0227621
B41: Deris S.A. | C41: 42005 | D41: 42035 | E41: 699.389 | F41: =700+138+130+90-100+21-21 -> 958 | G41: =E41+F41 -> 1657.389 | I41: =G41-H41 -> 1657.389 | J41: =H41/G41 -> 0 | K41: =E41+E42 -> 1997.659 | L41: =F41+F42 -> 958 | M41: =K41+L41 -> 2955.659 | N41: =H41+H42 -> 2898.684 | O41: =M41-N41 -> 56.975 | P41: =N41/M41 -> 0.98072342
C42: 42036 | D42: 42369 | E42: 1298.27 | G42: =E42+F42+I41 -> 2955.659 | H42: 2898.684 | I42: =G42-H42 -> 56.975 | J42: =H42/G42 -> 0.98072342
B43: Congelados del Pacífico S.A. | C43: 42005 | D43: 42035 | E43: 0 | F43: 0.17252 | G43: =E43+F43 -> 0.17252 | I43: =G43-H43 -> 0.17252 | J43: =H43/G43 -> 0 | K43: =E43+E44 -> 0 | L43: =F43+F44 -> 0.17252 | M43: =K43+L43 -> 0.17252 | N43: =H43+H44 -> 0.032 | O43: =M43-N43 -> 0.14052 | P43: =N43/M43 -> 0.18548574
C44: 42036 | D44: 42369 | E44: 0 | G44: =E44+F44+I43 -> 0.17252 | H44: 0.032 | I44: =G44-H44 -> 0.14052 | J44: =H44/G44 -> 0.18548574
...

Sheet DATOS BIO BIO EXCESOS
A2: Merluza comun LTP | B2: Periodo | D2: Cuota (t) | G2: Operación | J2: Resumen anual
A3: Armador | B3: Inicial | C3: Final | D3: Cuota Asignada | E3: Traspaso, Cesion, Arriendo, etc) | F3: Cuota Efectiva | G3: Desembarque (t) | H3: Saldo (t) | I3: % consumido | J3: Cuota Total | K3: Traspaso, Cesion, Arriendo, etc) | L3: Cuota Efectiva | M3: Desembarque (t) | N3: Saldo (t) | O3: % consumido
A4: Bio Bio S.A. Merluza comun LTP | B4: 42005 | C4: 42216 | D4: 3750.94 | E4: =-2574.906+32.514+107.937 -> -2434.455 | F4: =D4+E4 -> 1316.485 | G4: 1360.591 | H4: =F4-G4 -> -44.106 | I4: =G4/F4 -> 1.0335029 | J4: =D4+D5 -> 5001.253 | K4: =E4+E5 -> -4971.988 | L4: =J4+K4 -> 29.265 | M4: =G4+G5 -> 1488.978 | N4: =L4-M4 -> -1459.713 | O4: =M4/L4 -> 50.879139
B5: 42217 | C5: 42369 | D5: 1250.313 | E5: -2537.533 | F5: =D5+E5+H4 -> -1331.326 | G5: 128.387 | H5: =F5-G5 -> -1459.713 | I5: =G5/F5 -> -0.096435434
A8: DETALLES MOVIMIENTOS TRASLATICIOS Y NO TRASLATICIOS:
A10: TRASLATICIOS
A11: Fecha Resolución | B11: Resolución | C11: TIPO | D11: UNIDAD DE PESQUERÍA | E11: PARTE 1 | F11: PARTE 2 | G11: COEFICIENTE | H11: Cuota 2016 | I11: Toneladas (según cuotas 2016
A12: 42179 | B12: 2012 | C12: Compra/Venta | D12: 011 Merluza común, IV región al paralelo 41° 28,6’ L.S. | E12: GRIMAR S.A. PESQ. | F12: BIO BIO S.A. PESQ. | G12: 0.0738853 | H12: 13542 | I12: 1000.554
A13: 42389 | B13: 104 | C13: Compra/Venta | D13: 011 Merluza común, IV región al paralelo 41° 28,6’ L.S. | E13: SUR AUSTRAL S.A. PESQ. | F13: BIO BIO S.A. PESQ. | G13: 0.002401 | H13: 13542 | I13: 32.514
A14: 42389 | B14: 106 | C14: Compra/Venta | D14: 011 Merluza común, IV región al paralelo 41° 28,6’ L.S. | E14: GRIMAR S.A. PESQ. | F14: BIO BIO S.A. PESQ. | G14: 0.0079705 | H14: 13542 | I14: 107.937
A15: 42389 | B15: 107 | C15: Modifica RES.N°.2144-13 | D15: 011 Merluza común, IV región al paralelo 41° 28,6’ L.S. | E15: GRIMAR S.A. PESQ. | F15: BIO BIO S.A. PESQ. | G15: 0.0082805 | H15: 13542 | I15: 112.135
A17: TRASLATICIOS
A18: Fecha Resolución | B18: Resolución | C18: TIPO | D18: UNIDAD DE PESQUERÍA | E18: PARTE 1 | F18: PARTE 2 | G18: COEFICIENTE | H18: Cuota 2016 | I18: Toneladas (según 2016)
A19: 42212 | B19: 2013 | C19: Compra/Venta | D19: 011 Merluza común, IV región al paralelo 41° 28,6’ L.S. | E19: BIO BIO S.A. PESQ. | F19: GRIMAR S.A. PESQ. | G19: 0.0970434 | H19: 13542 | I19: 1314.162
A22: Negocios No traslaticios
A23: Fecha | B23: Nº Certificado | C23: Negocio Juridico | D23: Recurso | E23: 1 UNIDAD PESQUERIA | F23: 1 CEDENTE | G23: 2 RECEPTOR | H23: 2 UNIDAD PESQUERIA | I23: Tons.Traspaso | J23: Coeficiente | K23: Cuota 2016 | L23: Tons traspaso según valor cuota 2016 modificada | M23: Desde
A24: 41662 | B24: 156 | C24: Comodato | D24: Merluza Comun | E24: 011 MERLUZA COMÚN, IV REGIÓN AL PARALELO 41° 28,6’ L.S. | F24: BIO BIO S.A. PESQ | G24: CONGELADOS PACIFICO S.A. | I24: total cuota | M24: 41662
A25: 41675 | B25: 163 | C25: Comodato | D25: Merluza Comun | E25: 011 MERLUZA COMÚN, IV REGIÓN AL PARALELO 41° 28,6’ L.S. | F25: BIO BIO S.A. PESQ | G25: CONGELADOS PACIFICO S.A. | H25: 011 MERLUZA COMÚN, IV REGIÓN AL PARALELO 41° 28,6’ L.S. | I25: 3298.995 | J25: 0.29545 | K25: 13542 | L25: 4000.984 | M25: 41675
A26: 42405 | B26: 17 | C26: Modifica N°163-2014 en el la vigencia del comodato | D26: Merluza Comun | E26: 011 MERLUZA COMÚN, IV REGIÓN AL PARALELO 41° 28,6’ L.S. | F26: BIO BIO S.A. PESQ | G26: CONGELADOS PACIFICO S.A. | H26: 011 MERLUZA COMÚN, IV REGIÓN AL PARALELO 41° 28,6’ L.S. | M26: 42405
A27: 42492 | B27: 73 | C27: Modifica N°163-2014 modificado por cert N° 17-2016, en el sentido de resciliación parcial quedando vigente sólo comodato de 2574,906 | D27: Merluza Comun | E27: 011 MERLUZA COMÚN, IV REGIÓN AL PARALELO 41° 28,6’ L.S. | F27: BIO BIO S.A. PESQ | G27: CONGELADOS PACIFICO S.A. | H27: 011 MERLUZA COMÚN, IV REGIÓN AL PARALELO 41° 28,6’ L.S. | I27: 2574.906 | M27: 42492
A28: 42655 | B28: 120 | C28: Comodato | D28: Merluza Comun | E28: 011 MERLUZA COMÚN, IV REGIÓN AL PARALELO 41° 28,6’ L.S. | F28: BIO BIO S.A. PESQ | G28: CONGELADOS PACIFICO S.A. | H28: 011 MERLUZA COMÚN, IV REGIÓN AL PARALELO 41° 28,6’ L.S. | I28: 2537.533 | J28: 0.1873824 | K28: 13542 | L28: 2537.532 | M28: 42655
A31: Cuota Merluza Bio BIO 4001,142
A32: Documentos Respaldo | B32: Datos BIO BIO SA | C32: Datos SERNAPESCA | D32: NOTAS
A33: R. Ex. N° 2012, 27-07-2015 | B33: 1000.111 | D33: No corresponde incluir negicio 2015, se incluye en la asignación de cuota 2016
A34: R. Ex. N° 104, 20-01-2016 | B34: 3.2514 | C34: 32.514 | D34: Diferencia, ya que el Cert N°73 deja vigente coef. 0,002401 equivalente a 32,514 ton.
A35: R. Ex. N° 106, 20-01-2016 | B35: 107.937 | C35: 107.937 | D35: ok
A36: Cert.N° 73, 02-05-2016 | B36: -1426.078 | C36: -2574.906 | D36: Diferencia, ya que el Cert N°73 deja vigente coef. 0,1901422 equivalente a 2574,906 ton.
A37: Cert.N° 120, 12-10-2016 | B37: -2537.533 | C37: -2537.533 | D37: ok
B38: =SUM(B33:B37) -> -2852.3116 | C38: =SUM(C33:C37) -> -4971.988
A42: VALOR CUOTA | B42: 13542 | C42: MONTOS MOVIMIENTOS | D42: TIPO NEGOCIO
A43: R. Ex. N° 2012, 27-jul-2015 | B43: 0.07385255 | C43: =+B42*B43 -> 1000.1112 | D43: Compra a GRIMAR 2015
A44: R. Ex. N° 104, 20-01-2016 | B44: 0.002401 | C44: =+B42*B44 -> 32.514342 | D44: Compra a SUR AUSTRAL 2016
A45: R. Ex. N° 106, 20-01-2016 | B45: 0.0079705 | C45: =+B42*B45 -> 107.93651 | D45: Compra a GRIMAR 2016
A46: R. Ex. N° 107, 20-01-2016 | D46: Modifica Resol inicial por Compra-Venta-OK
A47: Cert.N° 73, 02-05-2016 | B47: -0.1901422 | C47: =+B42*B47 -> -2574.9057 | D47: Comodato parcial a CONGELADOS (resciliación Comodato N° 163-14)
A48: Cert.N° 120, 12-10-2016 | B48: -0.1873824 | C48: =+B42*B48 -> -2537.5325 | D48: Comodato a CONGELADOS
C49: =SUM(C44:C48) -> -4971.9873
A51: Merluza cola V-X LTP | B51: Periodo | D51: Cuota (t) | G51: Operación | J51: Resumen anual
A52: Armador | B52: Inicial | C52: Final | D52: Cuota Asignada | E52: Traspaso, Cesion, Arriendo, etc) | F52: Cuota Efectiva | G52: Desembarque (t) | H52: Saldo (t) | I52: % consumido | J52: Cuota Total | K52: Traspaso, Cesion, Arriendo, etc) | L52: Cuota Efectiva | M52: Desembarque (t) | N52: Saldo (t) | O52: % consumido
A53: Bio Bio S.A.Pesq. | B53: 42005 | C53: 42094 | D53: 302.58 | E53: =0.483-0.241+6.088-0.72399-755.742+949.506-949.505 -> -750.13499 | F53: =D53+E53 -> -447.55499 | G53: 61.821 | H53: =F53-G53 -> -509.37599 | I53: =G53/F53 -> -0.13813051 | J53: =D53+D54 -> 756.466 | K53: =E53+E54 -> -750.13499 | L53: =J53+K53 -> 6.33101 | M53: =G53+G54 -> 67.795 | N53: =L53-M53 -> -61.46399 | O53: =M53/L53 -> 10.708402
...

Sheet Crustaceos  LTP
A1: Cuotas LTP Recursos Crustáceos Año 2016 actualizado al 27-01-2017
R2: =+R14+X14+Z14:AD15 -> #VALUE! | AP2: 0
AV3: * registra la sumatoria de los traspasos en todas las regiones
C4: Periodo | E4: Cuota II-III Región (t) | H4: Operación II y III región | K4: Cuota IV Región (t) | N4: Operación IV Región | Q4: Cuota V Región (t) | T4: Operación V Región | W4: Cuota VI Región (t) | Z4: Operación VI Región | AC4: Cuota VII Región (t) | AF4: Operación VII Región | AI4: Cuota VIII Región (t) | AL4: Operación VIII Región | AO4: Cuota y Operación Camaron Nailon II-VIII | AU4: Resumen Global Anual II-VIII
A5: Unidad de pesquería | B5: Armador | C5: Inicial | D5: Final | E5: Cuota Asignada | F5: Traspaso, Cesion, Arriendo, etc) | G5: Cuota Efectiva | H5: Desembarque (t) | I5: Saldo (t) | J5: Cuota Total | K5: Cuota Asignada | L5: Traspaso, Cesion, Arriendo, etc) | M5: Cuota Efectiva | N5: Desembarque (t) | O5: Saldo (t) | P5: Cuota Total efectiva | Q5: Cuota Asignada | R5: Traspaso, Cesion, Arriendo, etc) | S5: Cuota Efectiva | T5: Desembarque (t) | U5: Saldo (t) | V5: Cuota Total | W5: Cuota Asignada | X5: Traspaso, Cesion, Arriendo, etc) | Y5: Cuota Efectiva | Z5: Desembarque (t) | AA5: Saldo (t) | AB5: Cuota Total | AC5: Cuota Asignada | AD5: Traspaso, Cesion, Arriendo, etc) | AE5: Cuota Efectiva | AF5: Desembarque (t) | AG5: Saldo (t) | AH5: Cuota Total | AI5: Cuota Asignada | AJ5: Traspaso, Cesion, Arriendo, etc) | AK5: Cuota Efectiva | AL5: Desembarque (t) | AM5: Saldo (t) | AN5: Cuota Total | AO5: Cuota Asignada II-VIII | AP5: * Traspaso, Cesion, Arriendo, etc) | AQ5: Cuota Efectiva | AR5: Desembarque (t) II-VIII | AS5: Saldo (t) | AT5: % consumido | AU5: Cuota Total | AV5: * Traspaso, Cesion, Arriendo, etc) | AW5: Cuota Efectiva | AX5: Desembarque (t) | AY5: Saldo (t) | AZ5: % consumido
A6: Camarón nailon II-VIII | B6: ANTARTIC SEAFOOD S.A. | C6: 42005 | D6: 42216 | E6: =7.278+0.588 -> 7.866 | F6: =1.7136955+0.2145 -> 1.9281955 | G6: =E6+F6 -> 9.7941955 | I6: =G6-H6 -> 9.7941955 | J6: =E6+E7+F6+F7 -> 10.757195 | K6: =66.839+5.4 -> 72.239 | L6: =15.57905+1.95 -> 17.52905 | M6: =K6+L6 -> 89.76805 | N6: 17.59 | O6: =M6-N6 -> 72.17805 | P6: =K6+K7+L6+L7 -> 97.79505 | Q6: =97.586+7.884 -> 105.47 | R6: =22.745413+2.847 -> 25.592413 | S6: =Q6+R6 -> 131.06241 | T6: 90.05 | U6: =S6-T6 -> 41.012413 | V6: =Q6+Q7+R6+R7 -> 142.78141 | W6: =139.026+11.232 -> 150.258 | X6: =32.404424+4.056 -> 36.460424 | Y6: =W6+X6 -> 186.71842 | Z6: 98.081 | AA6: =Y6-Z6 -> 88.637424 | AB6: =W6+W7+X6+X7 -> 203.41342 | AC6: =139.026+11.232 -> 150.258 | AD6: =32.404424+4.056 -> 36.460424 | AE6: =AC6+AD6 -> 186.71842 | AF6: 191.022 | AG6: =AE6-AF6 -> -4.303576 | AH6: =AC6+AC7+AD6+AD7 -> 203.41342 | AI6: =139.159724+11.2428 -> 150.40252 | AJ6: =32.4355821+4.0599 -> 36.495482 | AK6: =AI6+AJ6 -> 186.89801 | AL6: 193.325 | AM6: =AK6-AL6 -> -6.4269939 | AN6: =AI6+AI7+AJ6+AJ7 -> 203.6094 | AO6: =E6+K6+Q6+W6+AC6+AI6 -> 636.49352 | AP6: =F6+L6+R6+X6+AD6+AJ6 -> 154.46599 | AQ6: =AO6+AP6 -> 790.95951 | AR6: =H6+N6+T6+Z6+AF6+AL6 -> 590.068 | AS6: =AQ6-AR6 -> 200.89151 | AT6: =AR6/AQ6 -> 0.74601543 | AU6: =AO6+AO7 -> 707.30392 | AV6: =AP6+AP7 -> 154.46599 | AW6: =AU6+AV6 -> 861.7699 | AX6: =AR6+AR7 -> 807.551 | AY6: =AW6-AX6 -> 54.218904 | AZ6: =AX6/AW6 -> 0.93708424
C7: 42278 | D7: 42369 | E7: =0.891+0.072 -> 0.963 | G7: =E7+F7+I6 -> 10.757195 | H7: 0.208 | I7: =G7-H7 -> 10.549195 | K7: =7.427+0.6 -> 8.027 | M7: =K7+L7+O6 -> 80.20505 | N7: 60.145 | O7: =M7-N7 -> 20.06005 | Q7: =10.843+0.876 -> 11.719 | S7: =Q7+R7+U6 -> 52.731413 | T7: 49.666 | U7: =S7-T7 -> 3.065413 | W7: =15.447+1.248 -> 16.695 | Y7: =W7+X7+AA6 -> 105.33242 | Z7: 94.979 | AA7: =Y7-Z7 -> 10.353424 | AC7: =15.447+1.248 -> 16.695 | AE7: =AC7+AD7+AG6 -> 12.391424 | AF7: 7.458 | AG7: =AE7-AF7 -> 4.933424 | AI7: =15.4621916+1.2492 -> 16.711392 | AK7: =AI7+AJ7+AM6 -> 10.284398 | AL7: 5.027 | AM7: =AK7-AL7 -> 5.2573977 | AO7: =E7+K7+Q7+W7+AC7+AI7 -> 70.810392 | AP7: =F7+L7+R7+X7+AD7+AJ7 -> 0 | AQ7: =AO7+AP7+AS6 -> 271.7019 | AR7: =H7+N7+T7+Z7+AF7+AL7 -> 217.483 | AS7: =AQ7-AR7 -> 54.218904 | AT7: =AR7/AQ7 -> 0.8004471
B8: BAYCIC BAYCIC MARIA | C8: 41640 | D8: 42216 | E8: 2.775 | F8: =-3.1134455 -> -3.1134455 | G8: =E8+F8 -> -0.3384455 | I8: =G8-H8 -> -0.3384455 | J8: =E8+E9+F8+F9 -> 0.0015545 | K8: 25.487 | L8: =-28.30405 -> -28.30405 | M8: =K8+L8 -> -2.81705 | O8: =M8-N8 -> -2.81705 | P8: =K8+K9+L8+L9 -> 0.01495 | Q8: 37.211 | R8: =-41.323913 -> -41.323913 | S8: =Q8+R8 -> -4.112913 | U8: =S8-T8 -> -4.112913 | V8: =Q8+Q9+R8+R9 -> 0.022087 | W8: 53.013 | X8: =-58.872424 -> -58.872424 | Y8: =W8+X8 -> -5.859424 | AA8: =Y8-Z8 -> -5.859424 | AB8: =W8+W9+X8+X9 -> 0.030576 | AC8: 53.013 | AD8: =-58.872424 -> -58.872424 | AE8: =AC8+AD8 -> -5.859424 | AG8: =AE8-AF8 -> -5.859424 | AH8: =AC8+AC9+AD8+AD9 -> 0.030576 | AI8: 53.064236 | AJ8: =-58.9290321 -> -58.929032 | AK8: =AI8+AJ8 -> -5.8647962 | AM8: =AK8-AL8 -> -5.8647962 | AN8: =AI8+AI9+AJ8+AJ9 -> 0.03123001 | AO8: =E8+K8+Q8+W8+AC8+AI8 -> 224.56324 | AP8: =F8+L8+R8+X8+AD8+AJ8 -> -249.41529 | AQ8: =AO8+AP8 -> -24.852053 | AR8: =H8+N8+T8+Z8+AF8+AL8 -> 0 | AS8: =AQ8-AR8 -> -24.852053 | AT8: =AR8/AQ8 -> 0 | AU8: =AO8+AO9 -> 249.54626 | AV8: =AP8+AP9 -> -249.41529 | AW8: =AU8+AV8 -> 0.13097351 | AX8: =AR8+AR9 -> 0 | AY8: =AW8-AX8 -> 0.13097351 | AZ8: =AX8/AW8 -> 0
C9: 42278 | D9: 42369 | E9: 0.34 | G9: =E9+F9+I8 -> 0.0015545 | I9: =G9-H9 -> 0.0015545 | K9: 2.832 | M9: =K9+L9+O8 -> 0.01495 | O9: =M9-N9 -> 0.01495 | Q9: 4.135 | S9: =Q9+R9+U8 -> 0.022087 | U9: =S9-T9 -> 0.022087 | W9: 5.89 | Y9: =W9+X9+AA8 -> 0.030576 | AA9: =Y9-Z9 -> 0.030576 | AC9: 5.89 | AE9: =AC9+AD9+AG8 -> 0.030576 | AG9: =AE9-AF9 -> 0.030576 | AI9: 5.8960262 | AK9: =AI9+AJ9+AM8 -> 0.03123001 | AM9: =AK9-AL9 -> 0.03123001 | AO9: =E9+K9+Q9+W9+AC9+AI9 -> 24.983026 | AP9: =F9+L9+R9+X9+AD9+AJ9 -> 0 | AQ9: =AO9+AP9+AS8 -> 0.13097351 | AR9: =H9+N9+T9+Z9+AF9+AL9 -> 0 | AS9: =AQ9-AR9 -> 0.13097351 | AT9: =AR9/AQ9 -> 0
B10: BLUMAR S.A. | C10: 41640 | D10: 42216 | E10: 0.889 | F10: =-0.0044-0.9552455 -> -0.9596455 | G10: =E10+F10 -> -0.0706455 | I10: =G10-H10 -> -0.0706455 | J10: =E10+E11+F10+F11 -> 0.0383545 | K10: 8.167 | L10: =-0.0441-0.044-8.68405 -> -8.77215 | M10: =K10+L10 -> -0.60515 | O10: =M10-N10 -> -0.60515 | P10: =K10+K11+L10+L11 -> 0.30185 | Q10: 11.924 | R10: =-0.0441-0.0584-12.678713 -> -12.781213 | S10: =Q10+R10 -> -0.857213 | U10: =S10-T10 -> -0.857213 | V10: =Q10+Q11+R10+R11 -> 0.467787 | W10: 16.987 | X10: =-0.0441-0.0832-18.062824 -> -18.190124 | Y10: =W10+X10 -> -1.203124 | AA10: =Y10-Z10 -> -1.203124 | AB10: =W10+W11+X10+X11 -> 0.683876 | AC10: 16.987 | AD10: =-0.0441-0.0832-18.062824 -> -18.190124 | AE10: =AC10+AD10 -> -1.203124 | AG10: =AE10-AF10 -> -1.203124 | AH10: =AC10+AC11+AD10+AD11 -> 0.683876 | AI10: 17.00333 | AJ10: =-0.0441-0.08328-18.0801921 -> -18.207572 | AK10: =AI10+AJ10 -> -1.2042424 | AM10: =AK10-AL10 -> -1.2042424 | AN10: =AI10+AI11+AJ10+AJ11 -> 0.68501645 | AO10: =E10+K10+Q10+W10+AC10+AI10 -> 71.95733 | AP10: =F10+L10+R10+X10+AD10+AJ10-0.66106-2.20353 -> -79.965419 | AQ10: =AO10+AP10 -> -8.0080889 | AR10: =H10+N10+T10+Z10+AF10+AL10 -> 0 | AS10: =AQ10-AR10 -> -8.0080889 | AT10: =AR10/AQ10 -> 0 | AU10: =AO10+AO11 -> 79.961589 | AV10: =AP10+AP11 -> -79.965419 | AW10: =AU10+AV10 -> -0.00383005 | AX10: =AR10+AR11 -> 0 | AY10: =AW10-AX10 -> -0.00383005 | AZ10: =AX10/AW10 -> 0
C11: 42278 | D11: 42369 | E11: 0.109 | G11: =E11+F11+I10 -> 0.0383545 | I11: =G11-H11 -> 0.0383545 | K11: 0.907 | M11: =K11+L11+O10 -> 0.30185 | O11: =M11-N11 -> 0.30185 | Q11: 1.325 | S11: =Q11+R11+U10 -> 0.467787 | U11: =S11-T11 -> 0.467787 | W11: 1.887 | Y11: =W11+X11+AA10 -> 0.683876 | AA11: =Y11-Z11 -> 0.683876 | AC11: 1.887 | AE11: =AC11+AD11+AG10 -> 0.683876 | AG11: =AE11-AF11 -> 0.683876 | AI11: 1.8892589 | AK11: =AI11+AJ11+AM10 -> 0.68501645 | AM11: =AK11-AL11 -> 0.68501645 | AO11: =E11+K11+Q11+W11+AC11+AI11 -> 8.0042588 | AP11: =F11+L11+R11+X11+AD11+AJ11 -> 0 | AQ11: =AO11+AP11+AS10 -> -0.00383005 | AR11: =H11+N11+T11+Z11+AF11+AL11 -> 0 | AS11: =AQ11-AR11 -> -0.00383005 | AT11: =AR11/AQ11 -> 0
B12: BRACPESCA S.A. | C12: 41640 | D12: 42216 | E12: =7.147+0.442 -> 7.589 | F12: =0.9552455+0.37125 -> 1.3264955 | G12: =E12+F12 -> 8.9154955 | I12: =G12-H12 -> 8.9154955 | J12: =E12+E13+F12+F13 -> 9.8444955 | K12: =65.634+4.05 -> 69.684 | L12: =21.17-59.82+8.68405+3.375 -> -26.59095 | M12: =K12+L12 -> 43.09305 | N12: 10.776 | O12: =M12-N12 -> 32.31705 | P12: =K12+K13+L12+L13 -> 50.83605 | Q12: =95.826+5.914 -> 101.74 | R12: =12.678713+4.9275 -> 17.606213 | S12: =Q12+R12 -> 119.34621 | T12: 73.648 | U12: =S12-T12 -> 45.698213 | V12: =Q12+Q13+R12+R13 -> 130.65121 | W12: =136.519+8.424 -> 144.943 | X12: =18.062824+7.02 -> 25.082824 | Y12: =W12+X12 -> 170.02582 | Z12: 59.869 | AA12: =Y12-Z12 -> 110.15682 | AB12: =W12+W13+X12+X13 -> 186.13082 | AC12: =136.519+8.424 -> 144.943 | AD12: =18.062824+7.02 -> 25.082824 | AE12: =AC12+AD12 -> 170.02582 | AF12: 135.719 | AG12: =AE12-AF12 -> 34.306824 | AH12: =AC12+AC13+AD12+AD13 -> 186.13082 | AI12: =136.65005+8.4321 -> 145.08215 | AJ12: =18.0801921+7.02675 -> 25.106942 | AK12: =AI12+AJ12 -> 170.18909 | AL12: 133.38 | AM12: =AK12-AL12 -> 36.809092 | AN12: =AI12+AI13+AJ12+AJ13 -> 186.30933 | AO12: =E12+K12+Q12+W12+AC12+AI12 -> 613.98115 | AP12: =F12+L12+R12+X12+AD12+AJ12 -> 67.614349 | AQ12: =AO12+AP12 -> 681.5955 | AR12: =H12+N12+T12+Z12+AF12+AL12 -> 413.392 | AS12: =AQ12-AR12 -> 268.2035 | AT12: =AR12/AQ12 -> 0.60650635 | AU12: =AO12+AO13 -> 682.28839 | AV12: =AP12+AP13 -> 67.614349 | AW12: =AU12+AV12 -> 749.90274 | AX12: =AR12+AR13 -> 481.66 | AY12: =AW12-AX12 -> 268.24274 | AZ12: =AX12/AW12 -> 0.64229663
C13: 42278 | D13: 42369 | E13: =0.875+0.054 -> 0.929 | G13: =E13+F13+I12 -> 9.8444955 | I13: =G13-H13 -> 9.8444955 | K13: =7.293+0.45 -> 7.743 | M13: =K13+L13+O12 -> 40.06005 | N13: 1.106 | O13: =M13-N13 -> 38.95405 | Q13: =10.647+0.658 -> 11.305 | S13: =Q13+R13+U12 -> 57.003213 | U13: =S13-T13 -> 57.003213 | W13: =15.169+0.936 -> 16.105 | Y13: =W13+X13+AA12 -> 126.26182 | Z13: 9.157 | AA13: =Y13-Z13 -> 117.10482 | AC13: =15.169+0.936 -> 16.105 | AE13: =AC13+AD13+AG12 -> 50.411824 | AF13: 41.517 | AG13: =AE13-AF13 -> 8.894824 | AI13: =15.1833389+0.9369 -> 16.120239 | AK13: =AI13+AJ13+AM12 -> 52.929331 | AL13: 16.488 | AM13: =AK13-AL13 -> 36.441331 | AO13: =E13+K13+Q13+W13+AC13+AI13 -> 68.307239 | AP13: =F13+L13+R13+X13+AD13+AJ13 -> 0 | AQ13: =AO13+AP13+AS12 -> 336.51074 | AR13: =H13+N13+T13+Z13+AF13+AL13 -> 68.268 | AS13: =AQ13-AR13 -> 268.24274 | AT13: =AR13/AQ13 -> 0.2028702
B14: CAMANCHACA PESCA SUR S.A. | C14: 41640 | D14: 42216 | E14: =0.037+0.221 -> 0.258 | F14: =-0.0000404*55 -> -0.002222 | G14: =E14+F14 -> 0.255778 | I14: =G14-H14 -> 0.255778 | J14: =E14+E15+F14+F15 -> 0.287778 | K14: =0.341+2.025 -> 2.366 | L14: =-0.0000404*500 -> -0.0202 | M14: =K14+L14 -> 2.3458 | O14: =M14-N14 -> 2.3458 | P14: =K14+K15+L14+L15 -> 2.6088 | Q14: =0.497+2.957 -> 3.454 | R14: =-0.04445-0.0295 -> -0.07395 | S14: =Q14+R14 -> 3.38005 | U14: =S14-T14 -> 3.38005 | V14: =Q14+Q15+R14+R15 -> 3.76405 | W14: =0.708+4.212 -> 4.92 | X14: =-0.04445-0.042 -> -0.08645 | Y14: =W14+X14 -> 4.83355 | AA14: =Y14-Z14 -> 4.83355 | AB14: =W14+W15+X14+X15 -> 5.38055 | AC14: =0.708+4.212 -> 4.92 | AD14: =-0.04445-0.042 -> -0.08645 | AE14: =AC14+AD14 -> 4.83355 | AF14: 1.951 | AG14: =AE14-AF14 -> 2.88255 | AH14: =AC14+AC15+AD14+AD15 -> 5.38055 | AI14: =0.70904592+4.21605 -> 4.9250959 | AJ14: =-0.04445-0.0421 -> -0.08655 | AK14: =AI14+AJ14 -> 4.8385459 | AL14: 2.765 | AM14: =AK14-AL14 -> 2.0735459 | AN14: =AI14+AI15+AJ14+AJ15 -> 5.3857788 | AO14: =E14+K14+Q14+W14+AC14+AI14 -> 20.843096 | AP14: =F14+L14+R14+X14+AD14+AJ14 -> -0.355822 | AQ14: =AO14+AP14 -> 20.487274 | AR14: =H14+N14+T14+Z14+AF14+AL14 -> 4.716 | AS14: =AQ14-AR14 -> 15.771274 | AT14: =AR14/AQ14 -> 0.23019168 | AU14: =AO14+AO15 -> 23.163329 | AV14: =AP14+AP15 -> -0.355822 | AW14: =AU14+AV14 -> 22.807507 | AX14: =AR14+AR15 -> 5.045 | AY14: =AW14-AX14 -> 17.762507 | AZ14: =AX14/AW14 -> 0.2211991
C15: 42278 | D15: 42369 | E15: =0.005+0.027 -> 0.032 | G15: =E15+F15+I14 -> 0.287778 | I15: =G15-H15 -> 0.287778 | K15: =0.038+0.225 -> 0.263 | M15: =K15+L15+O14 -> 2.6088 | O15: =M15-N15 -> 2.6088 | Q15: =0.055+0.329 -> 0.384 | S15: =Q15+R15+U14 -> 3.76405 | U15: =S15-T15 -> 3.76405 | W15: =0.079+0.468 -> 0.547 | Y15: =W15+X15+AA14 -> 5.38055 | AA15: =Y15-Z15 -> 5.38055 | AC15: =0.079+0.468 -> 0.547 | AE15: =AC15+AD15+AG14 -> 3.42955 | AF15: 0.094 | AG15: =AE15-AF15 -> 3.33555 | AI15: =0.07878288+0.46845 -> 0.54723288 | AK15: =AI15+AJ15+AM14 -> 2.6207788 | AL15: 0.235 | AM15: =AK15-AL15 -> 2.3857788 | AO15: =E15+K15+Q15+W15+AC15+AI15 -> 2.3202329 | AP15: =F15+L15+R15+X15+AD15+AJ15 -> 0 | AQ15: =AO15+AP15+AS14 -> 18.091507 | AR15: =H15+N15+T15+Z15+AF15+AL15 -> 0.329 | AS15: =AQ15-AR15 -> 17.762507 | AT15: =AR15/AQ15 -> 0.018185329
B16: COSTA BRAVA LTDA. PESQ. | C16: 41640 | D16: 42216 | E16: 1.015 | F16: =-1.1389785 -> -1.1389785 | G16: =E16+F16 -> -0.1239785 | I16: =G16-H16 -> -0.1239785 | J16: =E16+E17+F16+F17 -> 2.15e-05 | K16: 9.319 | L16: =-10.35435 -> -10.35435 | M16: =K16+L16 -> -1.03535 | O16: =M16-N16 -> -1.03535 | P16: =K16+K17+L16+L17 -> -0.00035 | Q16: 13.606 | R16: =-15.117351 -> -15.117351 | S16: =Q16+R16 -> -1.511351 | U16: =S16-T16 -> -1.511351 | V16: =Q16+Q17+R16+R17 -> 0.000649 | W16: 19.383 | X16: =-21.537048 -> -21.537048 | Y16: =W16+X16 -> -2.154048 | AA16: =Y16-Z16 -> -2.154048 | AB16: =W16+W17+X16+X17 -> -4.8e-05 | AC16: 19.383 | AD16: =-21.537048 -> -21.537048 | AE16: =AC16+AD16 -> -2.154048 | AG16: =AE16-AF16 -> -2.154048 | AH16: =AC16+AC17+AD16+AD17 -> -4.8e-05 | AI16: 19.401981 | AJ16: =-21.5577567 -> -21.557757 | AK16: =AI16+AJ16 -> -2.1557757 | AM16: =AK16-AL16 -> -2.1557757 | AN16: =AI16+AI17+AJ16+AJ17 -> -2.9999999e-08 | AO16: =E16+K16+Q16+W16+AC16+AI16 -> 82.107981 | AP16: =F16+L16+R16+X16+AD16+AJ16 -> -91.242532 | AQ16: =AO16+AP16 -> -9.1345512 | AR16: =H16+N16+T16+Z16+AF16+AL16 -> 0 | AS16: =AQ16-AR16 -> -9.1345512 | AT16: =AR16/AQ16 -> 0 | AU16: =AO16+AO17 -> 91.242757 | AV16: =AP16+AP17 -> -91.242532 | AW16: =AU16+AV16 -> 0.00022447 | AX16: =AR16+AR17 -> 0 | AY16: =AW16-AX16 -> 0.00022447 | AZ16: =AX16/AW16 -> 0
C17: 42278 | D17: 42369 | E17: 0.124 | G17: =E17+F17+I16 -> 2.15e-05 | I17: =G17-H17 -> 2.15e-05 | K17: 1.035 | M17: =K17+L17+O16 -> -0.00035 | O17: =M17-N17 -> -0.00035 | Q17: 1.512 | S17: =Q17+R17+U16 -> 0.000649 | U17: =S17-T17 -> 0.000649 | W17: 2.154 | Y17: =W17+X17+AA16 -> -4.8e-05 | AA17: =Y17-Z17 -> -4.8e-05 | AC17: 2.154 | AE17: =AC17+AD17+AG16 -> -4.8e-05 | AG17: =AE17-AF17 -> -4.8e-05 | AI17: 2.1557757 | AK17: =AI17+AJ17+AM16 -> -2.9999999e-08 | AM17: =AK17-AL17 -> -2.9999999e-08 | AO17: =E17+K17+Q17+W17+AC17+AI17 -> 9.1347757 | AP17: =F17+L17+R17+X17+AD17+AJ17 -> 0 | AQ17: =AO17+AP17+AS16 -> 0.00022447 | AR17: =H17+N17+T17+Z17+AF17+AL17 -> 0 | AS17: =AQ17-AR17 -> 0.00022447 | AT17: =AR17/AQ17 -> 0
B18: GRIMAR S.A. PESQ. | C18: 41640 | D18: 42216 | E18: 0.139 | G18: =E18+F18 -> 0.139 | I18: =G18-H18 -> 0.139 | J18: =E18+E19+F18+F19 -> 0.156 | K18: 1.278 | M18: =K18+L18 -> 1.278 | O18: =M18-N18 -> 1.278 | P18: =K18+K19+L18+L19 -> 1.42 | Q18: 1.865 | S18: =Q18+R18 -> 1.865 | U18: =S18-T18 -> 1.865 | V18: =Q18+Q19+R18+R19 -> 2.072 | W18: 2.657 | Y18: =W18+X18 -> 2.657 | AA18: =Y18-Z18 -> 2.657 | AB18: =W18+W19+X18+X19 -> 2.952 | AC18: 2.657 | AE18: =AC18+AD18 -> 2.657 | AG18: =AE18-AF18 -> 2.657 | AH18: =AC18+AC19+AD18+AD19 -> 2.952 | AI18: 2.6598591 | AK18: =AI18+AJ18 -> 2.6598591 | AM18: =AK18-AL18 -> 2.6598591 | AN18: =AI18+AI19+AJ18+AJ19 -> 2.955399 | AO18: =E18+K18+Q18+W18+AC18+AI18 -> 11.255859 | AP18: =F18+L18+R18+X18+AD18+AJ18 -> 0 | AQ18: =AO18+AP18 -> 11.255859 | AR18: =H18+N18+T18+Z18+AF18+AL18 -> 0 | AS18: =AQ18-AR18 -> 11.255859 | AT18: =AR18/AQ18 -> 0 | AU18: =AO18+AO19 -> 12.507399 | AV18: =AP18+AP19 -> 0 | AW18: =AU18+AV18 -> 12.507399 | AX18: =AR18+AR19 -> 0 | AY18: =AW18-AX18 -> 12.507399 | AZ18: =AX18/AW18 -> 0
C19: 42278 | D19: 42369 | E19: 0.017 | G19: =E19+F19+I18 -> 0.156 | I19: =G19-H19 -> 0.156 | K19: 0.142 | M19: =K19+L19+O18 -> 1.42 | O19: =M19-N19 -> 1.42 | Q19: 0.207 | S19: =Q19+R19+U18 -> 2.072 | U19: =S19-T19 -> 2.072 | W19: 0.295 | Y19: =W19+X19+AA18 -> 2.952 | AA19: =Y19-Z19 -> 2.952 | AC19: 0.295 | AE19: =AC19+AD19+AG18 -> 2.952 | AG19: =AE19-AF19 -> 2.952 | AI19: 0.2955399 | AK19: =AI19+AJ19+AM18 -> 2.955399 | AM19: =AK19-AL19 -> 2.955399 | AO19: =E19+K19+Q19+W19+AC19+AI19 -> 1.2515399 | AP19: =F19+L19+R19+X19+AD19+AJ19 -> 0 | AQ19: =AO19+AP19+AS18 -> 12.507399 | AR19: =H19+N19+T19+Z19+AF19+AL19 -> 0 | AS19: =AQ19-AR19 -> 12.507399 | AT19: =AR19/AQ19 -> 0
B20: ISLADAMAS S.A. PESQ. | C20: 41640 | D20: 42216 | E20: =6.423+0.368 -> 6.791 | F20: =0.0998855+0.561+0.14025+2.5047+1.1389785+2.0301215+0.2475+0.2475+0.12925 -> 7.0991855 | G20: =E20+F20 -> 13.890185 | I20: =G20-H20 -> 13.890185 | J20: =E20+E21+F20+F21 -> 14.721186 | K20: =58.987+3.375 -> 62.362 | L20: =0.90805+5.1+1.275+22.77+10.35435+18.45565+2.25+2.25+1.175 -> 64.53805 | M20: =K20+L20 -> 126.90005 | N20: 13.864 | O20: =M20-N20 -> 113.03605 | P20: =K20+K21+L20+L21 -> 133.82905 | Q20: =86.121+4.928 -> 91.049 | R20: =1.325753+7.446+1.8615+33.2442+15.117351+26.945249+3.285+3.285+1.7155 -> 94.225553 | S20: =Q20+R20 -> 185.27455 | T20: =82.975+3.583 -> 86.558 | U20: =S20-T20 -> 98.716553 | V20: =Q20+Q21+X20+R21 -> 235.40514 | W20: =122.693+7.02 -> 129.713 | X20: =1.888744+10.608+2.652+47.3616+21.537048+38.387752+4.68+4.68+2.444 -> 134.23914 | Y20: =W20+X20 -> 263.95214 | Z20: =82.781+2.723 -> 85.504 | AA20: =Y20-Z20 -> 178.44814 | AB20: =W20+W21+X20+X21 -> 278.36514 | AC20: =122.693+7.02 -> 129.713 | AD20: =1.888744+10.608+2.652+47.3616+21.537048+38.387752+4.68+4.68+2.444 -> 134.23914 | AE20: =AC20+AD20 -> 263.95214 | AF20: =171.553+36.502 -> 208.055 | AG20: =AE20-AF20 -> 55.897144 | AH20: =AC20+AC21+AD20+AD21 -> 278.36514 | AI20: =122.811007+7.02675 -> 129.83776 | AJ20: =1.8905601+10.6182+2.65455+47.40714+21.5577567+38.4246633+4.6845+4.6845+2.44635 -> 134.36822 | AK20: =AI20+AJ20 -> 264.20598 | AL20: =75.292+13.687 -> 88.979 | AM20: =AK20-AL20 -> 175.22698 | AN20: =AI20+AI21+AJ20+AJ21 -> 278.63239 | AO20: =E20+K20+Q20+W20+AC20+AI20 -> 549.46576 | AP20: =F20+L20+R20+X20+AD20+AJ20 -> 568.7093 | AQ20: =AO20+AP20 -> 1118.1751 | AR20: =H20+N20+T20+Z20+AF20+AL20 -> 482.96 | AS20: =AQ20-AR20 -> 635.21505 | AT20: =AR20/AQ20 -> 0.43191806 | AU20: =AO20+AO21 -> 610.59517 | AV20: =AP20+AP21 -> 568.7093 | AW20: =AU20+AV20 -> 1179.3045 | AX20: =AR20+AR21 -> 856.434 | AY20: =AW20-AX20 -> 322.87047 | AZ20: =AX20/AW20 -> 0.72621958
C21: 42278 | D21: 42369 | E21: =0.786+0.045 -> 0.831 | G21: =E21+F21+I20 -> 14.721185 | I21: =G21-H21 -> 14.721185 | K21: =6.554+0.375 -> 6.929 | M21: =K21+L21+O20 -> 119.96505 | N21: =20.92+5.079 -> 25.999 | O21: =M21-N21 -> 93.96605 | Q21: =9.569+0.548 -> 10.117 | S21: =Q21+R21+U20 -> 108.83355 | T21: 73.955 | U21: =S21-T21 -> 34.878553 | W21: =13.633+0.78 -> 14.413 | Y21: =W21+X21+AA20 -> 192.86114 | Z21: 35.686 | AA21: =Y21-Z21 -> 157.17514 | AC21: =13.633+0.78 -> 14.413 | AE21: =AC21+AD21+AG20 -> 70.310144 | AF21: 66.251 | AG21: =AE21-AF21 -> 4.059144 | AI21: =13.6456674+0.78075 -> 14.426417 | AK21: =AI21+AJ21+AM20 -> 189.65339 | AL21: 171.583 | AM21: =AK21-AL21 -> 18.070395 | AO21: =E21+K21+Q21+W21+AC21+AI21 -> 61.129417 | AP21: =F21+L21+R21+X21+AD21+AJ21 -> 0 | AQ21: =AO21+AP21+AS20 -> 696.34447 | AR21: =H21+N21+T21+Z21+AF21+AL21 -> 373.474 | AS21: =AQ21-AR21 -> 322.87047 | AT21: =AR21/AQ21 -> 0.53633513
B22: LANDES S.A. SOC. PESQ. | C22: 41640 | D22: 42216 | E22: 0.076 | G22: =E22+F22 -> 0.076 | I22: =G22-H22 -> 0.076 | J22: =E22+E23+F22+F23 -> 0.085 | K22: 0.697 | M22: =K22+L22 -> 0.697 | O22: =M22-N22 -> 0.697 | P22: =K22+K23+L22+L23 -> 0.774 | Q22: 1.018 | S22: =Q22+R22 -> 1.018 | U22: =S22-T22 -> 1.018 | V22: =Q22+Q23+R22+R23 -> 1.131 | W22: 1.451 | Y22: =W22+X22 -> 1.451 | AA22: =Y22-Z22 -> 1.451 | AB22: =W22+W23+X22+X23 -> 1.612 | AC22: 1.451 | AE22: =AC22+AD22 -> 1.451 | AG22: =AE22-AF22 -> 1.451 | AH22: =AC22+AC23+AD22+AD23 -> 1.612 | AI22: 1.4519139 | AK22: =AI22+AJ22 -> 1.4519139 | AM22: =AK22-AL22 -> 1.4519139 | AN22: =AI22+AI23+AJ22+AJ23 -> 1.6132377 | AO22: =E22+K22+Q22+W22+AC22+AI22 -> 6.1449139 | AP22: =F22+L22+R22+X22+AD22+AJ22 -> 0 | AQ22: =AO22+AP22 -> 6.1449139 | AR22: =H22+N22+T22+Z22+AF22+AL22 -> 0 | AS22: =AQ22-AR22 -> 6.1449139 | AT22: =AR22/AQ22 -> 0 | AU22: =AO22+AO23 -> 6.8272377 | AV22: =AP22+AP23 -> 0 | AW22: =AU22+AV22 -> 6.8272377 | AX22: =AR22+AR23 -> 0 | AY22: =AW22-AX22 -> 6.8272377 | AZ22: =AX22/AW22 -> 0
C23: 42278 | D23: 42369 | E23: 0.009 | G23: =E23+F23+I22 -> 0.085 | I23: =G23-H23 -> 0.085 | K23: 0.077 | M23: =K23+L23+O22 -> 0.774 | O23: =M23-N23 -> 0.774 | Q23: 0.113 | S23: =Q23+R23+U22 -> 1.131 | U23: =S23-T23 -> 1.131 | W23: 0.161 | Y23: =W23+X23+AA22 -> 1.612 | AA23: =Y23-Z23 -> 1.612 | AC23: 0.161 | AE23: =AC23+AD23+AG22 -> 1.612 | AG23: =AE23-AF23 -> 1.612 | AI23: 0.16132377 | AK23: =AI23+AJ23+AM22 -> 1.6132377 | AM23: =AK23-AL23 -> 1.6132377 | AO23: =E23+K23+Q23+W23+AC23+AI23 -> 0.68232377 | AP23: =F23+L23+R23+X23+AD23+AJ23 -> 0 | AQ23: =AO23+AP23+AS22 -> 6.8272377 | AR23: =H23+N23+T23+Z23+AF23+AL23 -> 0 | AS23: =AQ23-AR23 -> 6.8272377 | AT23: =AR23/AQ23 -> 0
B24: MOROZIN BAYCIC MARIA ANA | C24: 41640 | D24: 42216 | E24: 1.592 | F24: =-1.7850635 -> -1.7850635 | G24: =E24+F24 -> -0.1930635 | I24: =G24-H24 -> -0.1930635 | J24: =E24+E25+F24+F25 -> 0.0019365 | K24: 14.619 | L24: =-16.22785 -> -16.22785 | M24: =K24+L24 -> -1.60885 | O24: =M24-N24 -> -1.60885 | P24: =K24+K25+L24+L25 -> 0.01515 | Q24: 21.343 | R24: =-23.692661 -> -23.692661 | S24: =Q24+R24 -> -2.349661 | U24: =S24-T24 -> -2.349661 | V24: =Q24+Q25+R24+R25 -> 0.021339 | W24: 30.407 | X24: =-33.753928 -> -33.753928 | Y24: =W24+X24 -> -3.346928 | AA24: =Y24-Z24 -> -3.346928 | AB24: =W24+W25+X24+X25 -> 0.032072 | AC24: 30.407 | AD24: =-33.753928 -> -33.753928 | AE24: =AC24+AD24 -> -3.346928 | AG24: =AE24-AF24 -> -3.346928 | AH24: =AC24+AC25+AD24+AD25 -> 0.032072 | AI24: 30.435852 | AJ24: =-33.7863837 -> -33.786384 | AK24: =AI24+AJ24 -> -3.3505314 | AM24: =AK24-AL24 -> -3.3505314 | AN24: =AI24+AI25+AJ24+AJ25 -> 0.03122997 | AO24: =E24+K24+Q24+W24+AC24+AI24 -> 128.80385 | AP24: =F24+L24+R24+X24+AD24+AJ24 -> -142.99981 | AQ24: =AO24+AP24 -> -14.195962 | AR24: =H24+N24+T24+Z24+AF24+AL24 -> 0 | AS24: =AQ24-AR24 -> -14.195962 | AT24: =AR24/AQ24 -> 0 | AU24: =AO24+AO25 -> 143.13361 | AV24: =AP24+AP25 -> -142.99981 | AW24: =AU24+AV24 -> 0.13379947 | AX24: =AR24+AR25 -> 0 | AY24: =AW24-AX24 -> 0.13379947 | AZ24: =AX24/AW24 -> 0
C25: 42278 | D25: 42369 | E25: 0.195 | G25: =E25+F25+I24 -> 0.0019365 | I25: =G25-H25 -> 0.0019365 | K25: 1.624 | M25: =K25+L25+O24 -> 0.01515 | O25: =M25-N25 -> 0.01515 | Q25: 2.371 | S25: =Q25+R25+U24 -> 0.021339 | U25: =S25-T25 -> 0.021339 | W25: 3.379 | Y25: =W25+X25+AA24 -> 0.032072 | AA25: =Y25-Z25 -> 0.032072 | AC25: 3.379 | AE25: =AC25+AD25+AG24 -> 0.032072 | AG25: =AE25-AF25 -> 0.032072 | AI25: 3.3817614 | AK25: =AI25+AJ25+AM24 -> 0.03122997 | AM25: =AK25-AL25 -> 0.03122997 | AO25: =E25+K25+Q25+W25+AC25+AI25 -> 14.329761 | AP25: =F25+L25+R25+X25+AD25+AJ25 -> 0 | AQ25: =AO25+AP25+AS24 -> 0.13379947 | AR25: =H25+N25+T25+Z25+AF25+AL25 -> 0 | AS25: =AQ25-AR25 -> 0.13379947 | AT25: =AR25/AQ25 -> 0
B26: MOROZIN YURECIC MARIO | C26: 41640 | D26: 42216 | E26: 3.59 | F26: =-4.0280295 -> -4.0280295 | G26: =E26+F26 -> -0.4380295 | I26: =G26-H26 -> -0.4380295 | J26: =E26+E27+F26+F27 -> 0.0019705 | K26: 32.97 | L26: =-36.61845 -> -36.61845 | M26: =K26+L26 -> -3.64845 | O26: =M26-N26 -> -3.64845 | P26: =K26+K27+L26+L27 -> 0.01455 | Q26: 48.136 | R26: =-53.462937 -> -53.462937 | S26: =Q26+R26 -> -5.326937 | U26: =S26-T26 -> -5.326937 | V26: =Q26+Q27+R26+R27 -> 0.021063 | W26: 68.5778 | X26: =-76.166376 -> -76.166376 | Y26: =W26+X26 -> -7.588576 | AA26: =Y26-Z26 -> -7.588576 | AB26: =W26+W27+X26+X27 -> 0.031424 | AC26: 68.578 | AD26: =-76.166376 -> -76.166376 | AE26: =AC26+AD26 -> -7.588376 | AG26: =AE26-AF26 -> -7.588376 | AH26: =AC26+AC27+AD26+AD27 -> 0.031624 | AI26: 68.643759 | AJ26: =-76.2396129 -> -76.239613 | AK26: =AI26+AJ26 -> -7.5958543 | AM26: =AK26-AL26 -> -7.5958543 | AN26: =AI26+AI27+AJ26+AJ27 -> 0.03122999 | AO26: =E26+K26+Q26+W26+AC26+AI26 -> 290.49556 | AP26: =F26+L26+R26+X26+AD26+AJ26 -> -322.68178 | AQ26: =AO26+AP26 -> -32.186223 | AR26: =H26+N26+T26+Z26+AF26+AL26 -> 0 | AS26: =AQ26-AR26 -> -32.186223 | AT26: =AR26/AQ26 -> 0 | AU26: =AO26+AO27 -> 322.81364 | AV26: =AP26+AP27 -> -322.68178 | AW26: =AU26+AV26 -> 0.13186149 | AX26: =AR26+AR27 -> 0 | AY26: =AW26-AX26 -> 0.13186149 | AZ26: =AX26/AW26 -> 0
C27: 42278 | D27: 42369 | E27: 0.44 | G27: =E27+F27+I26 -> 0.0019705 | I27: =G27-H27 -> 0.0019705 | K27: 3.663 | M27: =K27+L27+O26 -> 0.01455 | O27: =M27-N27 -> 0.01455 | Q27: 5.348 | S27: =Q27+R27+U26 -> 0.021063 | U27: =S27-T27 -> 0.021063 | W27: 7.62 | Y27: =W27+X27+AA26 -> 0.031424 | AA27: =Y27-Z27 -> 0.031424 | AC27: 7.62 | AE27: =AC27+AD27+AG26 -> 0.031624 | AG27: =AE27-AF27 -> 0.031624 | AI27: 7.6270843 | AK27: =AI27+AJ27+AM26 -> 0.03122999 | AM27: =AK27-AL27 -> 0.03122999 | AO27: =E27+K27+Q27+W27+AC27+AI27 -> 32.318084 | AP27: =F27+L27+R27+X27+AD27+AJ27 -> 0 | AQ27: =AO27+AP27+AS26 -> 0.13186149 | AR27: =H27+N27+T27+Z27+AF27+AL27 -> 0 | AS27: =AQ27-AR27 -> 0.13186149 | AT27: =AR27/AQ27 -> 0
B28: QUINTERO LTDA. SOC. PESQ. | C28: 41640 | D28: 42216 | E28: 0.859 | F28: =-0.9636165 -> -0.9636165 | G28: =E28+F28 -> -0.1046165 | I28: =G28-H28 -> -0.1046165 | J28: =E28+E29+F28+F29 -> 0.0003835 | K28: 7.893 | L28: =-8.76015 -> -8.76015 | M28: =K28+L28 -> -0.86715 | O28: =M28-N28 -> -0.86715 | P28: =K28+K29+L28+L29 -> 0.00985 | Q28: 11.524 | R28: =-12.789819 -> -12.789819 | S28: =Q28+R28 -> -1.265819 | U28: =S28-T28 -> -1.265819 | V28: =Q28+Q29+R28+R29 -> 0.014181 | W28: 16.418 | X28: =-18.221112 -> -18.221112 | Y28: =W28+X28 -> -1.803112 | Z28: 0.105 | AA28: =Y28-Z28 -> -1.908112 | AB28: =W28+W29+X28+X29 -> 0.020888 | AC28: 16.418 | AD28: =-18.221112 -> -18.221112 | AE28: =AC28+AD28 -> -1.803112 | AG28: =AE28-AF28 -> -1.803112 | AH28: =AC28+AC29+AD28+AD29 -> 0.020888 | AI28: 16.433507 | AJ28: =-18.2386323 -> -18.238632 | AK28: =AI28+AJ28 -> -1.8051252 | AM28: =AK28-AL28 -> -1.8051252 | AN28: =AI28+AI29+AJ28+AJ29 -> 0.02082003 | AO28: =E28+K28+Q28+W28+AC28+AI28 -> 69.545507 | AP28: =F28+L28+R28+X28+AD28+AJ28 -> -77.194442 | AQ28: =AO28+AP28 -> -7.6489347 | AR28: =H28+N28+T28+Z28+AF28+AL28 -> 0.105 | AS28: =AQ28-AR28 -> -7.7539347 | AT28: =AR28/AQ28 -> -0.013727402 | AU28: =AO28+AO29 -> 77.281452 | AV28: =AP28+AP29 -> -77.194442 | AW28: =AU28+AV28 -> 0.08701053 | AX28: =AR28+AR29 -> 0.105 | AY28: =AW28-AX28 -> -0.01798947 | AZ28: =AX28/AW28 -> 1.2067505
C29: 42278 | D29: 42369 | E29: 0.105 | G29: =E29+F29+I28 -> 0.0003835 | I29: =G29-H29 -> 0.0003835 | K29: 0.877 | M29: =K29+L29+O28 -> 0.00985 | O29: =M29-N29 -> 0.00985 | Q29: 1.28 | S29: =Q29+R29+U28 -> 0.014181 | U29: =S29-T29 -> 0.014181 | W29: 1.824 | Y29: =W29+X29+AA28 -> -0.084112 | AA29: =Y29-Z29 -> -0.084112 | AC29: 1.824 | AE29: =AC29+AD29+AG28 -> 0.020888 | AG29: =AE29-AF29 -> 0.020888 | AI29: 1.8259452 | AK29: =AI29+AJ29+AM28 -> 0.02082003 | AM29: =AK29-AL29 -> 0.02082003 | AO29: =E29+K29+Q29+W29+AC29+AI29 -> 7.7359452 | AP29: =F29+L29+R29+X29+AD29+AJ29 -> 0 | AQ29: =AO29+AP29+AS28 -> -0.01798947 | AR29: =H29+N29+T29+Z29+AF29+AL29 -> 0 | AS29: =AQ29-AR29 -> -0.01798947 | AT29: =AR29/AQ29 -> 0
