Workbook

Sheet Resumen LTP
A2: Informe
A3: Resumen LTP 2015
A4: Al 31 de diciembre de 2015
A5: Unidad de Pesquería | B5: Zona | C5: Cuota LTP R.Ex Nº 3510 | D5: Arriendos u otro | E5: Cuota Final | F5: Desembarque total (t) | G5: Aguas internacionales | H5: Saldo total (t) | I5: % consumido 2015
A6: Anchoveta | B6: XV- I - II | C6: =SUM('Pelagicos LTP '!E6:E11) -> 521962 | D6: =SUM('Pelagicos LTP '!F6:F11) -> -31713.134 | E6: =C6+D6 -> 490248.87 | F6: =SUM('Pelagicos LTP '!H6:H11) -> 343447.74 | H6: =E6-F6 -> 146801.13 | I6: =F6/E6 -> 0.70055794
A7: Anchoveta | B7: III - IV | C7: =SUM('Pelagicos LTP '!E14:E31) -> 14664.999 | D7: =SUM('Pelagicos LTP '!F14:F31) -> -13322.349 | E7: =C7+D7 -> 1342.65 | F7: =SUM('Pelagicos LTP '!H14:H31) -> 0 | H7: =E7-F7 -> 1342.65 | I7: =F7/E7 -> 0
A8: Anchoveta | B8: V - X | C8: =SUM('Pelagicos LTP '!E34:E90) -> 7380 | D8: =SUM('Pelagicos LTP '!F34:F90) -> -2509.409 | E8: =C8+D8 -> 4870.591 | F8: =SUM('Pelagicos LTP '!H34:H90) -> 4082.495 | H8: =E8-F8 -> 788.096 | I8: =F8/E8 -> 0.83819294
A9: Camarón nailon | B9: II-VIII | C9: =SUM('Crustaceos LTP'!AU6:AU41) -> 4026.004 | D9: =SUM('Crustaceos LTP'!AV6:AV41) -> 95.489311 | E9: =C9+D9 -> 4121.4933 | F9: =SUM('Crustaceos LTP'!AX6:AX41) -> 3198.195 | H9: =E9-F9 -> 923.29831 | I9: =F9/E9 -> 0.77597967
A10: Congrio dorado | B10: NE F + H | C10: =SUM('Demersales LTP '!E7:E16) -> 416.499 | D10: =SUM('Demersales LTP '!F7:F16) -> 0 | E10: =C10+D10 -> 416.499 | F10: =SUM('Demersales LTP '!H7:H16) -> 326.756 | H10: =E10-F10 -> 89.743 | I10: =F10/E10 -> 0.78453009
A11: Congrio dorado | B11: SE | C11: =SUM('Demersales LTP '!E18:E27) -> 236 | D11: =SUM('Demersales LTP '!F18:F27) -> 0 | E11: =C11+D11 -> 236 | F11: =SUM('Demersales LTP '!H18:H27) -> 202.405 | H11: =E11-F11 -> 33.595 | I11: =F11/E11 -> 0.85764831
A12: Jurel | B12: XV - I - II | C12: =SUM('Pelagicos LTP '!E93:E98) -> 41448.004 | D12: =SUM('Pelagicos LTP '!F93:F98) -> -2000 | E12: =C12+D12 -> 39448.004 | F12: =SUM('Pelagicos LTP '!H93:H98) -> 34552.018 | H12: =E12-F12 -> 4895.986 | I12: =F12/E12 -> 0.87588761
A13: Jurel | B13: III - IV | C13: =SUM('Pelagicos LTP '!E101:E126) -> 8758.999 | D13: =SUM('Pelagicos LTP '!F101:F126) -> 10916.367 | E13: =C13+D13 -> 19675.366 | F13: =SUM('Pelagicos LTP '!H101:H126) -> 19246.318 | G13: 10817.393 | H13: =E13-F13 -> 429.048 | I13: =F13/E13 -> 0.97819365
A14: Jurel | B14: V - IX | C14: =SUM('Pelagicos LTP '!E129:E192) -> 187467 | D14: =SUM('Pelagicos LTP '!F129:F192) -> -18812.762 | E14: =C14+D14 -> 168654.23 | F14: =SUM('Pelagicos LTP '!H129:H192) -> 166902.08 | G14: 30546.078 | H14: =E14-F14 -> 1752.158 | I14: =F14/E14 -> 0.98961095
A15: Jurel | B15: XIV - X | C15: =SUM('Pelagicos LTP '!E195:E246) -> 26281.998 | D15: =SUM('Pelagicos LTP '!F195:F246) -> 1569.772 | E15: =C15+D15 -> 27851.77 | F15: =SUM('Pelagicos LTP '!H195:H246) -> 27333.01 | G15: 14939.449 | H15: =E15-F15 -> 518.76 | I15: =F15/E15 -> 0.98137425
A16: Langostino amarillo | B16: III-IV | C16: =SUM('Crustaceos LTP'!Q54:Q75) -> 1779.999 | D16: =SUM('Crustaceos LTP'!R54:R75) -> 136.4822 | E16: =C16+D16 -> 1916.4812 | F16: =SUM('Crustaceos LTP'!Z54:Z75) -> 1645.675 | H16: =E16-F16 -> 270.8062 | I16: =F16/E16 -> 0.85869614
A17: Langostino colorado | B17: I -IV | C17: =SUM('Crustaceos LTP'!W82:W95) -> 66.001 | D17: =SUM('Crustaceos LTP'!X82:X95) -> 91.64944 | E17: =C17+D17 -> 157.65044 | F17: =SUM('Crustaceos LTP'!AF82:AF95) -> 43.833 | H17: =E17-F17 -> 113.81744 | I17: =F17/E17 -> 0.27803919
A18: Merluza común | B18: IV- 41º 28, 6 | C18: =SUM('Demersales LTP '!E132:E203) -> 13542.001 | D18: =SUM('Demersales LTP '!F132:F203) -> 27.340383 | E18: =C18+D18 -> 13569.341 | F18: =SUM('Demersales LTP '!H132:H203) -> 11853.182 | H18: =E18-F18 -> 1716.1594 | I18: =F18/E18 -> 0.8735267
A19: Merluza de cola | B19: V -X | C19: =SUM('Demersales LTP '!E64:E111) -> 24102.999 | D19: =SUM('Demersales LTP '!F64:F111) -> -11045.804 | E19: =C19+D19 -> 13057.195 | F19: =SUM('Demersales LTP '!H64:H111) -> 12247.079 | H19: =E19-F19 -> 810.11583 | I19: =F19/E19 -> 0.93795637
A20: Merluza de cola | B20: XI -XII | C20: =SUM('Demersales LTP '!E115:E130) -> 16067.926 | D20: =SUM('Demersales LTP '!F115:F130) -> 11045.768 | E20: =C20+D20 -> 27113.694 | F20: =SUM('Demersales LTP '!H115:H130) -> 23899.017 | H20: =E20-F20 -> 3214.6773 | I20: =F20/E20 -> 0.88143713
A21: Merluza de tres aletas | B21: 41º28,6 - XII | C21: =SUM('Demersales LTP '!E53:E62) -> 13770 | D21: =SUM('Demersales LTP '!F53:F62) -> 0 | E21: =C21+D21 -> 13770 | F21: =SUM('Demersales LTP '!H53:H62) -> 7117.143 | H21: =E21-F21 -> 6652.857 | I21: =F21/E21 -> 0.51685861
A22: Merluza del sur | B22: NE F + H | C22: =SUM('Demersales LTP '!E29:E38) -> 3898.001 | D22: =SUM('Demersales LTP '!F29:F38) -> 2527.3077 | E22: =C22+D22 -> 6425.3087 | F22: =SUM('Demersales LTP '!H29:H38) -> 6326.556 | H22: =E22-F22 -> 98.752718 | I22: =F22/E22 -> 0.98463067
A23: Merluza del sur | B23: SE | C23: =SUM('Demersales LTP '!E42:E51) -> 2492.999 | D23: =SUM('Demersales LTP '!F42:F51) -> -382.92242 | E23: =C23+D23 -> 2110.0766 | F23: =SUM('Demersales LTP '!H42:H51) -> 1706.025 | H23: =E23-F23 -> 404.05158 | I23: =F23/E23 -> 0.80851331
A24: Sardina común | B24: V -X | C24: =SUM('Pelagicos LTP '!E249:E317) -> 103024 | D24: =SUM('Pelagicos LTP '!F249:F317) -> -21833.554 | E24: =C24+D24 -> 81190.444 | F24: =SUM('Pelagicos LTP '!H249:H317) -> 78031.757 | H24: =E24-F24 -> 3158.687 | I24: =F24/E24 -> 0.96109534
A25: Sardina española | B25: XV- I - II | C25: =SUM('Pelagicos LTP '!E320:E327) -> 735 | D25: =SUM('Pelagicos LTP '!F320:F327) -> 0 | E25: =C25+D25 -> 735 | F25: =SUM('Pelagicos LTP '!H320:H327) -> 2.236 | H25: =E25-F25 -> 732.764 | I25: =F25/E25 -> 0.0030421769
A26: Sardina española | B26: III - IV | C26: =SUM('Pelagicos LTP '!E330:E349) -> 875.002 | D26: =SUM('Pelagicos LTP '!F330:F349) -> -193.4 | E26: =C26+D26 -> 681.602 | F26: =SUM('Pelagicos LTP '!H330:H349) -> 0 | H26: =E26-F26 -> 681.602 | I26: =F26/E26 -> 0
A28: Nota: El desembarque de aguas internacionales (columna G) Jurel desde III a X regiones, esta incorporado en la columna de desembarque total. Solo se incorpora el dato en la columna G para tenerlo de referencia

Sheet Pelagicos LTP 
B1: 2015. CUOTAS LTP Y SU CONSUMO DE RECURSOS PELÁGICOS al 31 de diciembre de 2015
C4: Periodo | E4: CUOTA (TONELADAS) | H4: OPERACIÓN | K4: RESUMEN ANUAL
A5: Unidad de pesquería | B5: Titular de cuota LTP | C5: Inicial | D5: Final | E5: Cuota Asignada por Res N° 3510 mod por Res N° 908 | F5: Traspaso, Cesion, Arriendo, etc) | G5: Cuota Efectiva | H5: Desembarque (t) | I5: Saldo (t) | J5: % consumido | K5: Cuota asignada (t) | L5: Traspaso, Cesion, Arriendo, etc) | M5: Cuota Efectiva | N5: Desembarque (t) | O5: Saldo (t) | P5: % consumido
A6: Anchoveta XV - I - II | B6: Arica Seafood Producer S.A. | C6: 42005 | D6: 42185 | E6: 2784.854 | F6: =-2784.854 -> -2784.854 | G6: =E6+F6 -> 0 | I6: =G6-H6 -> 0 | J6: =H6/G6 -> #DIV/0! | K6: =E6+E7 -> 3713.134 | L6: =F6+F7 -> -3713.134 | M6: =K6+L6 -> 0 | N6: =H6+H7 -> 0 | O6: =M6-N6 -> 0 | P6: =N6/M6 -> #DIV/0!
C7: 42186 | D7: 42369 | E7: 928.28 | F7: =-928.28 -> -928.28 | G7: =E7+F7+I6 -> 0 | I7: =G7-H7 -> 0 | J7: =H7/G7 -> #DIV/0!
B8: Camanchaca S.A. Cia. Pesq. | C8: 42005 | D8: 42185 | E8: 77269.213 | G8: =+E8+F8 -> 77269.213 | H8: 28288.036 | I8: =G8-H8 -> 48981.177 | J8: =H8/G8 -> 0.36609712 | K8: =E8+E9 -> 103025.49 | L8: =F8+F9 -> 0 | M8: =K8+L8 -> 103025.49 | N8: =H8+H9 -> 66618.994 | O8: =M8-N8 -> 36406.492 | P8: =N8/M8 -> 0.64662635
C9: 42186 | D9: 42369 | E9: 25756.273 | G9: =E9+F9+I8 -> 74737.45 | H9: 38330.958 | I9: =G9-H9 -> 36406.492 | J9: =H9/G9 -> 0.51287484
B10: Corpesca S.A. | C10: 42005 | D10: 42185 | E10: 311417.93 | G10: =E10+F10 -> 311417.93 | H10: 108923.8 | I10: =G10-H10 -> 202494.13 | J10: =H10/G10 -> 0.34976729 | K10: =E10+E11 -> 415223.38 | L10: =F10+F11 -> -28000 | M10: =K10+L10 -> 387223.38 | N10: =H10+H11 -> 276828.74 | O10: =M10-N10 -> 110394.64 | P10: =N10/M10 -> 0.7149071
C11: 42186 | D11: 42369 | E11: 103805.45 | F11: =-10000-4000-10000-4000 -> -28000 | G11: =E11+F11+I10 -> 278299.58 | H11: 167904.94 | I11: =G11-H11 -> 110394.64 | J11: =H11/G11 -> 0.60332445
A14: Anchoveta III - IV | B14: Alimentos Marinos S.A., | C14: 42005 | D14: 42308 | E14: 917.826 | F14: =-2.05 -> -2.05 | G14: =E14+F14 -> 915.776 | I14: =G14-H14 -> 915.776 | J14: =H14/G14 -> 0 | K14: =E14+E15 -> 966.115 | L14: =F14+F15 -> -2.05 | M14: =K14+L14 -> 964.065 | N14: =H14+H15 -> 0 | O14: =M14-N14 -> 964.065 | P14: =N14/M14 -> 0
C15: 42309 | D15: 42369 | E15: 48.289 | G15: =E15+F15+I14 -> 964.065 | I15: =G15-H15 -> 964.065 | J15: =H15/G15 -> 0
B16: Bahia Caldera S.A. Pesq. | C16: 42005 | D16: 42308 | E16: 3871.888 | F16: =-3871.888 -> -3871.888 | G16: =E16+F16 -> 0 | I16: =G16-H16 -> 0 | J16: =H16/G16 -> #DIV/0! | K16: =E16+E17 -> 4075.598 | L16: =F16+F17 -> -4075.598 | M16: =K16+L16 -> 0 | N16: =H16+H17 -> 0 | O16: =M16-N16 -> 0 | P16: =N16/M16 -> #DIV/0!
C17: 42309 | D17: 42369 | E17: 203.71 | F17: =-203.71 -> -203.71 | G17: =E17+F17+I16 -> 0 | I17: =G17-H17 -> 0 | J17: =H17/G17 -> #DIV/0!
B18: Blumar S.A. | C18: 42005 | D18: 42308 | E18: 3025.302 | F18: =-3025.302 -> -3025.302 | G18: =E18+F18 -> 0 | I18: =G18-H18 -> 0 | J18: =H18/G18 -> #DIV/0! | K18: =E18+E19 -> 3184.471 | L18: =F18+F19 -> -3133.151 | M18: =K18+L18 -> 51.32 | N18: =H18+H19 -> 0 | O18: =M18-N18 -> 51.32 | P18: =N18/M18 -> 0
C19: 42309 | D19: 42369 | E19: 159.169 | F19: =-107.849 -> -107.849 | G19: =E19+F19+I18 -> 51.32 | I19: =G19-H19 -> 51.32 | J19: =H19/G19 -> 0
B20: Camanchaca S.A. Cia. Pesq. | C20: 42005 | D20: 42308 | E20: 12.678 | G20: =E20+F20 -> 12.678 | I20: =G20-H20 -> 12.678 | J20: =H20/G20 -> 0 | K20: =E20+E21 -> 13.345 | L20: =F20+F21 -> 0 | M20: =K20+L20 -> 13.345 | N20: =H20+H21 -> 0 | O20: =M20-N20 -> 13.345 | P20: =N20/M20 -> 0
C21: 42309 | D21: 42369 | E21: 0.667 | G21: =E21+F21+I20 -> 13.345 | I21: =G21-H21 -> 13.345 | J21: =H21/G21 -> 0
B22: Inversiones Pesqueras S.p.A | C22: 42005 | D22: 42308 | E22: 159.184 | F22: =-83.737 -> -83.737 | G22: =E22+F22 -> 75.447 | I22: =G22-H22 -> 75.447 | J22: =H22/G22 -> 0 | K22: =E22+E23 -> 167.559 | L22: =F22+F23 -> -83.737 | M22: =K22+L22 -> 83.822 | N22: =H22+H23 -> 0 | O22: =M22-N22 -> 83.822 | P22: =N22/M22 -> 0
C23: 42309 | D23: 42369 | E23: 8.375 | G23: =E23+F23+I22 -> 83.822 | I23: =G23-H23 -> 83.822 | J23: =H23/G23 -> 0
B24: Orizón S.A. | C24: 42005 | D24: 42308 | E24: 5903.054 | F24: =-5903.054 -> -5903.054 | G24: =E24+F24 -> 0 | I24: =G24-H24 -> 0 | J24: =H24/G24 -> #DIV/0! | K24: =E24+E25 -> 6213.63 | L24: =F24+F25 -> -6113.6 | M24: =K24+L24 -> 100.03 | N24: =H24+H25 -> 0 | O24: =M24-N24 -> 100.03 | P24: =N24/M24 -> 0
C25: 42309 | D25: 42369 | E25: 310.576 | F25: -210.546 | G25: =E25+F25+I24 -> 100.03 | I25: =G25-H25 -> 100.03 | J25: =H25/G25 -> 0
B26: Camanchaca Pesca Sur S.A. | C26: 42005 | D26: 42308 | E26: 42.068 | G26: =E26+F26 -> 42.068 | I26: =G26-H26 -> 42.068 | J26: =H26/G26 -> 0 | K26: =E26+E27 -> 44.281 | L26: =F26+F27 -> 0 | M26: =K26+L26 -> 44.281 | N26: =H26+H27 -> 0 | O26: =M26-N26 -> 44.281 | P26: =N26/M26 -> 0
C27: 42309 | D27: 42369 | E27: 2.213 | G27: =E27+F27+I26 -> 44.281 | I27: =G27-H27 -> 44.281 | J27: =H27/G27 -> 0
B28: Centro Sur SpA. Pesq. | C28: 42005 | D28: 42308 | E28: 0 | F28: =83.737 -> 83.737 | G28: =E28+F28 -> 83.737 | I28: =G28-H28 -> 83.737 | J28: =H28/G28 -> 0 | K28: =E28+E29 -> 0 | L28: =F28+F29 -> 83.737 | M28: =K28+L28 -> 83.737 | N28: =H28+H29 -> 0 | O28: =M28-N28 -> 83.737 | P28: =N28/M28 -> 0
C29: 42309 | D29: 42369 | E29: 0 | G29: =E29+F29+I28 -> 83.737 | I29: =G29-H29 -> 83.737 | J29: =H29/G29 -> 0
B30: Foodcorp S.A. | C30: 42005 | D30: 42308 | E30: 0 | F30: =2.05 -> 2.05 | G30: =E30+F30 -> 2.05 | I30: =G30-H30 -> 2.05 | J30: =H30/G30 -> 0 | K30: =E30+E31 -> 0 | L30: =F30+F31 -> 2.05 | M30: =K30+L30 -> 2.05 | N30: =H30+H31 -> 0 | O30: =M30-N30 -> 2.05 | P30: =N30/M30 -> 0
C31: 42309 | D31: 42369 | E31: 0 | G31: =E31+F31+I30 -> 2.05 | I31: =G31-H31 -> 2.05 | J31: =H31/G31 -> 0
A34: Anchoveta V-X | B34: Alimentos Marinos S.A. | C34: 42005 | D34: 42124 | E34: 1173.088 | F34: =-209.025-111.48-350-350 -> -1020.505 | G34: =E34+F34 -> 152.583 | H34: 24.487 | I34: =G34-H34 -> 128.096 | J34: =H34/G34 -> 0.16048315 | K34: =E34+E35+E36 -> 1380.103 | L34: =F34+F35+F36 -> -1353.405 | M34: =K34+L34 -> 26.698 | N34: =H34+H35+H36 -> 24.487 | O34: =M34-N34 -> 2.211 | P34: =N34/M34 -> 0.91718481
C35: 42125 | D35: 42247 | E35: 138.01 | F35: =-332.9 -> -332.9 | G35: =E35+F35+I34 -> -66.794 | I35: =G35-H35 -> -66.794 | J35: =H35/G35 -> 0
C36: 42248 | D36: 42369 | E36: 69.005 | G36: =E36+F36+I35 -> 2.211 | I36: =G36-H36 -> 2.211 | J36: =H36/G36 -> 0
B37: Berta Elena Ltda. Soc. Pesq. | C37: 42005 | D37: 42124 | E37: 21.98 | F37: =-21.98 -> -21.98 | G37: =E37+F37 -> 0 | I37: =G37-H37 -> 0 | J37: =H37/G37 -> #DIV/0! | K37: =E37+E38+E39 -> 25.859 | L37: =F37+F38+F39 -> -25.859 | M37: =K37+L37 -> 0 | N37: =H37+H38+H39 -> 0 | O37: =M37-N37 -> 0 | P37: =N37/M37 -> #DIV/0!
C38: 42125 | D38: 42247 | E38: 2.586 | F38: =-2.586 -> -2.586 | G38: =E38+F38+I37 -> 0 | I38: =G38-H38 -> 0 | J38: =H38/G38 -> #DIV/0!
C39: 42248 | D39: 42369 | E39: 1.293 | F39: =-1.293 -> -1.293 | G39: =E39+F39+I38 -> 0 | I39: =G39-H39 -> 0 | J39: =H39/G39 -> #DIV/0!
B40: Blumar S.A. | C40: 42005 | D40: 42124 | E40: 1474.91 | F40: =-660 -> -660 | G40: =E40+F40 -> 814.91 | H40: 183.551 | I40: =G40-H40 -> 631.359 | J40: =H40/G40 -> 0.22524082 | K40: =E40+E41+E42 -> 1735.188 | L40: =F40+F41+F42 -> -680 | M40: =K40+L40 -> 1055.188 | N40: =H40+H41+H42 -> 832.744 | O40: =M40-N40 -> 222.444 | P40: =N40/M40 -> 0.78919017
C41: 42125 | D41: 42247 | E41: 173.519 | F41: =-20 -> -20 | G41: =E41+F41+I40 -> 784.878 | I41: =G41-H41 -> 784.878 | J41: =H41/G41 -> 0
C42: 42248 | D42: 42369 | E42: 86.759 | G42: =E42+F42+I41 -> 871.637 | H42: 649.193 | I42: =G42-H42 -> 222.444 | J42: =H42/G42 -> 0.74479743
B43: Camanchaca Pesca Sur S.A. | C43: 42005 | D43: 42124 | E43: 971.124 | F43: =-21 -> -21 | G43: =E43+F43 -> 950.124 | H43: 437.43 | I43: =G43-H43 -> 512.694 | J43: =H43/G43 -> 0.46039254 | K43: =E43+E44+E45 -> 1142.499 | L43: =F43+F44+F45 -> -230 | M43: =K43+L43 -> 912.499 | N43: =H43+H44+H45 -> 878.06 | O43: =M43-N43 -> 34.439 | P43: =N43/M43 -> 0.96225859
C44: 42125 | D44: 42247 | E44: 114.25 | G44: =E44+F44+I43 -> 626.944 | H44: 7.4 | I44: =G44-H44 -> 619.544 | J44: =H44/G44 -> 0.011803287
C45: 42248 | D45: 42369 | E45: 57.125 | F45: =-9-200 -> -209 | G45: =E45+F45+I44 -> 467.669 | H45: 433.23 | I45: =G45-H45 -> 34.439 | J45: =H45/G45 -> 0.92636031
B46: Camanchaca S.A. Cia. Pesq. | C46: 42005 | D46: 42124 | E46: 48.678 | G46: =E46+F46 -> 48.678 | I46: =G46-H46 -> 48.678 | J46: =H46/G46 -> 0 | K46: =E46+E47+E48 -> 57.268 | L46: =F46+F47+F48 -> 0 | M46: =K46+L46 -> 57.268 | N46: =H46+H47+H48 -> 0 | O46: =M46-N46 -> 57.268 | P46: =N46/M46 -> 0
...

Sheet Demersales LTP 
B2: 2015. CUOTAS LTP Y SU CONSUMO DE RECURSOS PECES DEMERSALES al 31 de diciembre de 2015.
C5: Periodo | E5: Cuota (t) | H5: Operación | K5: Resumen anual
A6: Unidad de pesquería | B6: Armador | C6: Inicial | D6: Final | E6: Cuota Asignada | F6: Traspaso, Cesion, Arriendo, etc) | G6: Cuota Efectiva | H6: Desembarque (t) | I6: Saldo (t) | J6: % consumido | K6: Cuota Total | L6: Traspaso, Cesion, Arriendo, etc) | M6: Cuota Efectiva | N6: Desembarque (t) | O6: Saldo (t) | P6: % consumido
A7: Congrio dorado NE H/F (41º28,6 LS hasta 47º) | B7: Emdepes S.A. | C7: 42005 | D7: 42063 | E7: 0.526 | G7: =E7+F7 -> 0.526 | I7: =G7-H7 -> 0.526 | J7: =H7/G7 -> 0 | K7: =E7+E8 -> 1.054 | L7: =F7+F8 -> 0 | M7: =K7+L7 -> 1.054 | N7: =H7+H8 -> 0.198 | O7: =M7-N7 -> 0.856 | P7: =N7/M7 -> 0.18785579
C8: 42064 | D8: 42369 | E8: 0.528 | G8: =E8+F8+I7 -> 1.054 | H8: 0.198 | I8: =G8-H8 -> 0.856 | J8: =H8/G8 -> 0.18785579
B9: Grimar S.A.Pesq. | C9: 42005 | D9: 42063 | E9: 7.677 | G9: =E9+F9 -> 7.677 | H9: 2.361 | I9: =G9-H9 -> 5.316 | J9: =H9/G9 -> 0.30754201 | K9: =E9+E10 -> 15.373 | L9: =F9+F10 -> 0 | M9: =K9+L9 -> 15.373 | N9: =H9+H10 -> 15.373 | O9: =M9-N9 -> 0 | P9: =N9/M9 -> 1
C10: 42064 | D10: 42369 | E10: 7.696 | G10: =E10+F10+I9 -> 13.012 | H10: 13.012 | I10: =G10-H10 -> 0 | J10: =H10/G10 -> 1
B11: Deris S.A. | C11: 42005 | D11: 42063 | E11: 144.492 | G11: =E11+F11 -> 144.492 | H11: 3.111 | I11: =G11-H11 -> 141.381 | J11: =H11/G11 -> 0.021530604 | K11: =E11+E12 -> 289.331 | L11: =F11+F12 -> 0 | M11: =K11+L11 -> 289.331 | N11: =H11+H12 -> 236.759 | O11: =M11-N11 -> 52.572 | P11: =N11/M11 -> 0.81829807
C12: 42064 | D12: 42369 | E12: 144.839 | G12: =E12+F12+I11 -> 286.22 | H12: 233.648 | I12: =G12-H12 -> 52.572 | J12: =H12/G12 -> 0.81632311
B13: Pesca Cisne S.A. Pesq. | C13: 42005 | D13: 42063 | E13: 12.325 | G13: =E13+F13 -> 12.325 | I13: =G13-H13 -> 12.325 | J13: =H13/G13 -> 0 | K13: =E13+E14 -> 24.68 | L13: =F13+F14 -> 0 | M13: =K13+L13 -> 24.68 | N13: =H13+H14 -> 0 | O13: =M13-N13 -> 24.68 | P13: =N13/M13 -> 0
C14: 42064 | D14: 42369 | E14: 12.355 | G14: =E14+F14+I13 -> 24.68 | I14: =G14-H14 -> 24.68 | J14: =H14/G14 -> 0
B15: Sur Austral S.A. Pesq. | C15: 42005 | D15: 42063 | E15: 42.979 | G15: =E15+F15 -> 42.979 | H15: 0.407 | I15: =G15-H15 -> 42.572 | J15: =H15/G15 -> 0.009469741 | K15: =E15+E16 -> 86.061 | L15: =F15+F16 -> 0 | M15: =K15+L15 -> 86.061 | N15: =H15+H16 -> 74.426 | O15: =M15-N15 -> 11.635 | P15: =N15/M15 -> 0.8648052
C16: 42064 | D16: 42369 | E16: 43.082 | G16: =E16+F16+I15 -> 85.654 | H16: 74.019 | I16: =G16-H16 -> 11.635 | J16: =H16/G16 -> 0.86416279
A18: Congrio dorado SE (47º hasta 57º) | B18: Emdepes S.A., | C18: 42005 | D18: 42063 | E18: 20.491 | G18: =E18+F18 -> 20.491 | I18: =G18-H18 -> 20.491 | J18: =H18/G18 -> 0 | K18: =E18+E19 -> 40.982 | L18: =F18+F19 -> 0 | M18: =K18+L18 -> 40.982 | N18: =H18+H19 -> 32.265 | O18: =M18-N18 -> 8.717 | P18: =N18/M18 -> 0.78729686
C19: 42064 | D19: 42369 | E19: 20.491 | G19: =E19+F19+I18 -> 40.982 | H19: 32.265 | I19: =G19-H19 -> 8.717 | J19: =H19/G19 -> 0.78729686
B20: Grimar S.A.Pesq. | C20: 42005 | D20: 42063 | E20: 0.061 | G20: =E20+F20 -> 0.061 | I20: =G20-H20 -> 0.061 | J20: =H20/G20 -> 0 | K20: =E20+E21 -> 0.122 | L20: =F20+F21 -> 0 | M20: =K20+L20 -> 0.122 | N20: =H20+H21 -> 0 | O20: =M20-N20 -> 0.122 | P20: =N20/M20 -> 0
C21: 42064 | D21: 42369 | E21: 0.061 | G21: =E21+F21+I20 -> 0.122 | I21: =G21-H21 -> 0.122 | J21: =H21/G21 -> 0
B22: Deris S.A. | C22: 42005 | D22: 42063 | E22: 70.164 | G22: =E22+F22 -> 70.164 | H22: 0.169 | I22: =G22-H22 -> 69.995 | J22: =H22/G22 -> 0.0024086426 | K22: =E22+E23 -> 140.328 | L22: =F22+F23 -> 0 | M22: =K22+L22 -> 140.328 | N22: =H22+H23 -> 116.013 | O22: =M22-N22 -> 24.315 | P22: =N22/M22 -> 0.82672738
C23: 42064 | D23: 42369 | E23: 70.164 | G23: =E23+F23+I22 -> 140.159 | H23: 115.844 | I23: =G23-H23 -> 24.315 | J23: =H23/G23 -> 0.82651845
B24: Pesca Cisne S.A | C24: 42005 | D24: 42063 | E24: 27.254 | G24: =E24+F24 -> 27.254 | H24: 42.875 | I24: =G24-H24 -> -15.621 | J24: =H24/G24 -> 1.5731636 | K24: =E24+E25 -> 54.508 | L24: =F24+F25 -> 0 | M24: =K24+L24 -> 54.508 | N24: =H24+H25 -> 54.127 | O24: =M24-N24 -> 0.381 | P24: =N24/M24 -> 0.9930102
C25: 42064 | D25: 42369 | E25: 27.254 | G25: =E25+F25+I24 -> 11.633 | H25: 11.252 | I25: =G25-H25 -> 0.381 | J25: =H25/G25 -> 0.96724835
B26: Sur Austral S.A. Pesq. | C26: 42005 | D26: 42063 | E26: 0.03 | G26: =E26+F26 -> 0.03 | I26: =G26-H26 -> 0.03 | J26: =H26/G26 -> 0 | K26: =E26+E27 -> 0.06 | L26: =F26+F27 -> 0 | M26: =K26+L26 -> 0.06 | N26: =H26+H27 -> 0 | O26: =M26-N26 -> 0.06 | P26: =N26/M26 -> 0
C27: 42064 | D27: 42369 | E27: 0.03 | G27: =E27+F27+I26 -> 0.06 | I27: =G27-H27 -> 0.06 | J27: =H27/G27 -> 0
A29: Merluza del sur NE F/H (41º28,6 LS al 47º LS) (Res Ex. N°3510/14. Modificada por Res Ex. N°1919/15 | B29: Emdepes S.A. | C29: 42005 | D29: 42035 | E29: 174.061 | F29: =253.457 -> 253.457 | G29: =E29+F29 -> 427.518 | I29: =G29-H29 -> 427.518 | J29: =H29/G29 -> 0 | K29: =E29+E30 -> 497.061 | L29: =F29+F30 -> 535.266 | M29: =K29+L29 -> 1032.327 | N29: =H29+H30 -> 1031.673 | O29: =M29-N29 -> 0.654 | P29: =N29/M29 -> 0.99936648
C30: 42036 | D30: 42369 | E30: 323 | F30: =281.809 -> 281.809 | G30: =E30+F30+I29 -> 1032.327 | H30: 1031.673 | I30: =G30-H30 -> 0.654 | J30: =H30/G30 -> 0.99936648
B31: Grimar S.A. Pesq. | C31: 42005 | D31: 42035 | E31: 40.42 | F31: =17.91+387.736+68.671+4.576+20.345+19.926+8.489+215.459+12.732+7.159+18.315+16.555+8.283+18.764+0.031698 -> 824.9517 | G31: =E31+F31 -> 865.3717 | H31: 47.83 | I31: =G31-H31 -> 817.5417 | J31: =H31/G31 -> 0.055271047 | K31: =E31+E32 -> 115.426 | L31: =F31+F32 -> 824.9517 | M31: =K31+L31 -> 940.3777 | N31: =H31+H32 -> 990.622 | O31: =M31-N31 -> -50.244302 | P31: =N31/M31 -> 1.0534299
C32: 42036 | D32: 42369 | E32: 75.006 | G32: 887.952 | H32: 942.792 | I32: =G32-H32 -> -54.84 | J32: =H32/G32 -> 1.0617601
B33: Deris S.A. | C33: 42005 | D33: 42035 | E33: 632.229 | F33: =70.075+20.904+276.15+600+200 -> 1167.129 | G33: =E33+F33 -> 1799.358 | I33: =G33-H33 -> 1799.358 | J33: =H33/G33 -> 0 | K33: =E33+E34 -> 1805.442 | L33: =F33+F34 -> 1167.129 | M33: =K33+L33 -> 2972.571 | N33: =H33+H34 -> 2944.326 | O33: =M33-N33 -> 28.245 | P33: =N33/M33 -> 0.99049812
C34: 42036 | D34: 42369 | E34: 1173.213 | G34: =E34+F34+I33 -> 2972.571 | H34: 2944.326 | I34: =G34-H34 -> 28.245 | J34: =H34/G34 -> 0.99049812
B35: Pesca Cisne S.A. | C35: 42005 | D35: 42035 | E35: 40.601 | G35: =E35+F35 -> 40.601 | I35: =G35-H35 -> 40.601 | J35: =H35/G35 -> 0 | K35: =E35+E36 -> 115.943 | L35: =F35+F36 -> 0 | M35: =K35+L35 -> 115.943 | N35: =H35+H36 -> 0 | O35: =M35-N35 -> 115.943 | P35: =N35/M35 -> 0
C36: 42036 | D36: 42369 | E36: 75.342 | G36: =E36+F36+I35 -> 115.943 | I36: =G36-H36 -> 115.943 | J36: =H36/G36 -> 0
B37: Sur Austral S.A. Pesq. | C37: 42005 | D37: 42035 | E37: 477.69 | F37: =-0.03898 -> -0.03898 | G37: =E37+F37 -> 477.65102 | H37: 35.301 | I37: =G37-H37 -> 442.35002 | J37: =H37/G37 -> 0.073905422 | K37: =E37+E38 -> 1364.129 | L37: =F37+F38 -> -0.03898 | M37: =K37+L37 -> 1364.09 | N37: =H37+H38 -> 1359.935 | O37: =M37-N37 -> 4.15502 | P37: =N37/M37 -> 0.996954
C38: 42036 | D38: 42369 | E38: 886.439 | G38: =E38+F38+I37 -> 1328.789 | H38: 1324.634 | I38: =G38-H38 -> 4.15502 | J38: =H38/G38 -> 0.99687308
B39: Congelados del Pacífico S.A. | C39: 42005 | D39: 42035 | E39: 0 | F39: =0.03898 -> 0.03898 | G39: =E39+F39 -> 0.03898 | H39: 0 | I39: =G39-H39 -> 0.03898 | J39: =H39/G39 -> 0 | K39: =E39+E40 -> 0 | L39: =F39+F40 -> 0.03898 | M39: =K39+L39 -> 0.03898 | N39: =H39+H40 -> 0.137 | O39: =M39-N39 -> -0.09802 | P39: =N39/M39 -> 3.5146229
C40: 42036 | D40: 42369 | E40: 0 | G40: =E40+F40+I39 -> 0.03898 | H40: 0.137 | I40: =G40-H40 -> -0.09802 | J40: =H40/G40 -> 3.5146229
A42: Merluza Del Sur SE Fabrica (47º LS al 57º LS) (Res Ex. N°3510/14. Modificada por Res Ex. N°1919/15 | B42: Emdepes S.A. | C42: 42005 | D42: 42035 | E42: 253.457 | F42: =-253.457 -> -253.457 | G42: =E42+F42 -> 0 | I42: =G42-H42 -> 0 | J42: =H42/G42 -> #DIV/0! | K42: =E42+E43 -> 724.62 | L42: =F42+F43 -> -535.266 | M42: =K42+L42 -> 189.354 | N42: =H42+H43 -> 98.394 | O42: =M42-N42 -> 90.96 | P42: =N42/M42 -> 0.5196299
C43: 41671 | D43: 42369 | E43: 471.163 | F43: =-281.809 -> -281.809 | G43: =E43+F43+I42 -> 189.354 | H43: 98.394 | I43: =G43-H43 -> 90.96 | J43: =H43/G43 -> 0.5196299
B44: Grimar S.A. Pesq. | C44: 42005 | D44: 42035 | E44: 0.49 | F44: =35.875 -> 35.875 | G44: =E44+F44 -> 36.365 | I44: =G44-H44 -> 36.365 | J44: =H44/G44 -> 0 | K44: =E44+E45 -> 1.4 | L44: =F44+F45 -> 35.875 | M44: =K44+L44 -> 37.275 | N44: =H44+H45 -> 0 | O44: =M44-N44 -> 37.275 | P44: =N44/M44 -> 0
C45: 41671 | D45: 42369 | E45: 0.91 | G45: =E45+F45+I44 -> 37.275 | I45: =G45-H45 -> 37.275 | J45: =H45/G45 -> 0
B46: Deris S.A. | C46: 42005 | D46: 42035 | E46: 471.697 | F46: =824.178-600-200+29.485+0.004576 -> 53.667576 | G46: =E46+F46 -> 525.36458 | I46: =G46-H46 -> 525.36458 | J46: =H46/G46 -> 0 | K46: =E46+E47 -> 1348.557 | L46: =F46+F47 -> 53.667576 | M46: =K46+L46 -> 1402.2246 | N46: =H46+H47 -> 1190.658 | O46: =M46-N46 -> 211.56658 | P46: =N46/M46 -> 0.84912076
...

Sheet Crustaceos  LTP
B1: 2015. CUOTAS LTP Y SU CONSUMO DE RECURSOS CRUSTÁCEOS al 31 de diciembre del 2015 | AV1: * registra la sumatoria de los traspasos en todas las regiones
C4: Periodo | E4: Cuota II Región (t) | H4: Operación II región | K4: Cuota III Región (t) | N4: Operación III Región | Q4: Cuota IV Región (t) | T4: Operación IV Región | W4: Cuota V Región (t) | Z4: Operación V Región | AC4: Cuota VI Región (t) | AF4: Operación VI Región | AI4: Cuota VII Región (t) | AL4: Operación VII Región | AO4: Cuota VIII Región (t) | AR4: Operación VIII Región | AU4: Cuota y Operación Camaron Nailon II-VIII | BA4: Resumen Global Anual II-VIII
A5: Unidad de pesquería | B5: Armador | C5: Inicial | D5: Final | E5: Cuota Asignada | F5: Traspaso, Cesion, Arriendo, etc) | G5: Cuota Efectiva | H5: Desembarque (t) | I5: Saldo (t) | J5: Cuota Total efectiva | K5: Cuota Asignada | L5: Traspaso, Cesion, Arriendo, etc) | M5: Cuota Efectiva | N5: Desembarque (t) | O5: Saldo (t) | P5: Cuota Total efectiva | Q5: Cuota Asignada | R5: Traspaso, Cesion, Arriendo, etc) | S5: Cuota Efectiva | T5: Desembarque (t) | U5: Saldo (t) | V5: Cuota Total efectiva | W5: Cuota Asignada | X5: Traspaso, Cesion, Arriendo, etc) | Y5: Cuota Efectiva | Z5: Desembarque (t) | AA5: Saldo (t) | AB5: Cuota Total efectiva | AC5: Cuota Asignada | AD5: Traspaso, Cesion, Arriendo, etc) | AE5: Cuota Efectiva | AF5: Desembarque (t) | AG5: Saldo (t) | AH5: Cuota Total efectiva | AI5: Cuota Asignada | AJ5: Traspaso, Cesion, Arriendo, etc) | AK5: Cuota Efectiva | AL5: Desembarque (t) | AM5: Saldo (t) | AN5: Cuota Total efectiva | AO5: Cuota Asignada | AP5: Traspaso, Cesion, Arriendo, etc) | AQ5: Cuota Efectiva | AR5: Desembarque (t) | AS5: Saldo (t) | AT5: Cuota Total efectiva | AU5: Cuota Asignada II-VIII | AV5: * Traspaso, Cesion, Arriendo, etc) | AW5: Cuota Efectiva | AX5: Desembarque (t) II-VIII | AY5: Saldo (t) | AZ5: % consumido | BA5: Cuota Total | BB5: * Traspaso, Cesion, Arriendo, etc) | BC5: Cuota Efectiva | BD5: Desembarque (t) | BE5: Saldo (t) | BF5: % consumido
A6: Camarón nailon II-VIII | B6: Antarctic Seafood S.A. | C6: 42005 | D6: 42216 | E6: 1.398 | G6: =E6+F6 -> 1.398 | I6: =G6-H6 -> 1.398 | J6: =E6+E7+F6+F7 -> 1.747 | K6: 6.466 | M6: =K6+L6 -> 6.466 | O6: =M6-N6 -> 6.466 | P6: =K6+K7+L6+L7 -> 8.039 | Q6: 44.734 | S6: =Q6+R6 -> 44.734 | T6: 33.895 | U6: =S6-T6 -> 10.839 | V6: =Q6+Q7+R6+R7 -> 55.918 | W6: 83.877 | Y6: =W6+X6 -> 83.877 | Z6: 77.779 | AA6: =Y6-Z6 -> 6.098 | AB6: =W6+W7+X6+X7 -> 104.846 | AC6: 142.591 | AE6: =AC6+AD6 -> 142.591 | AF6: 49.746 | AG6: =AE6-AF6 -> 92.845 | AH6: =AC6+AC7+AD6+AD7 -> 178.239 | AI6: 141.193 | AK6: =AI6+AJ6 -> 141.193 | AL6: 137.93 | AM6: =AK6-AL6 -> 3.263 | AN6: =AI6+AI7+AJ6+AJ7 -> 176.491 | AO6: 142.591 | AQ6: =AO6+AP6 -> 142.591 | AR6: 141.052 | AS6: =AQ6-AR6 -> 1.539 | AT6: =AO6+AO7+AP6+AP7 -> 178.239 | AU6: =E6+K6+Q6+W6+AC6+AI6+AO6 -> 562.85 | AV6: =F6+L6+R6+X6+AD6+AJ6+AP6 -> 0 | AW6: =AU6+AV6 -> 562.85 | AX6: =H6+N6+T6+Z6+AF6+AL6+AR6 -> 440.402 | AY6: =AW6-AX6 -> 122.448 | AZ6: =AX6/AW6 -> 0.78245003 | BA6: =AU6+AU7 -> 703.519 | BB6: =AV6+AV7 -> 0 | BC6: =BA6+BB6 -> 703.519 | BD6: =AX6+AX7 -> 638.827 | BE6: =BC6-BD6 -> 64.692 | BF6: =BD6/BC6 -> 0.90804513
C7: 42278 | D7: 42369 | E7: 0.349 | G7: =E7+F7+I6 -> 1.747 | I7: =G7-H7 -> 1.747 | K7: 1.573 | M7: =K7+L7+O6 -> 8.039 | O7: =M7-N7 -> 8.039 | Q7: 11.184 | S7: =Q7+R7+U6 -> 22.023 | T7: 20.322 | U7: =S7-T7 -> 1.701 | W7: 20.969 | Y7: =W7+X7+AA6 -> 27.067 | Z7: 12.891 | AA7: =Y7-Z7 -> 14.176 | AC7: 35.648 | AE7: =AC7+AD7+AG6 -> 128.493 | AF7: 91.02 | AG7: =AE7-AF7 -> 37.473 | AI7: 35.298 | AK7: =AI7+AJ7+AM6 -> 38.561 | AL7: 37.549 | AM7: =AK7-AL7 -> 1.012 | AO7: 35.648 | AQ7: =AO7+AP7+AS6 -> 37.187 | AR7: 36.643 | AS7: =AQ7-AR7 -> 0.544 | AU7: =E7+K7+Q7+W7+AC7+AI7+AO7 -> 140.669 | AV7: =F7+L7+R7+X7+AD7+AJ7+AP7 -> 0 | AW7: =AU7+AV7+AY6 -> 263.117 | AX7: =H7+N7+T7+Z7+AF7+AL7+AR7 -> 198.425 | AY7: =AW7-AX7 -> 64.692 | AZ7: =AX7/AW7 -> 0.75413219
B8: Baycic Baycic Maria | C8: 41640 | D8: 42216 | E8: 0.533 | F8: =-0.533 -> -0.533 | G8: =E8+F8 -> 0 | I8: =G8-H8 -> 0 | J8: =E8+E9+F8+F9 -> 0 | K8: 2.465 | L8: =-2.465 -> -2.465 | M8: =K8+L8 -> 0 | O8: =M8-N8 -> 0 | P8: =K8+K9+L8+L9 -> 0 | Q8: 17.058 | R8: =-17.058 -> -17.058 | S8: =Q8+R8 -> 0 | U8: =S8-T8 -> 0 | V8: =Q8+Q9+R8+R9 -> 0 | W8: 31.984 | X8: =-31.984 -> -31.984 | Y8: =W8+X8 -> 0 | AA8: =Y8-Z8 -> 0 | AB8: =W8+W9+X8+X9 -> 0 | AC8: 54.373 | AD8: =-54.373 -> -54.373 | AE8: =AC8+AD8 -> 0 | AG8: =AE8-AF8 -> 0 | AH8: =AC8+AC9+AD8+AD9 -> 0 | AI8: 53.84 | AJ8: =-53.84 -> -53.84 | AK8: =AI8+AJ8 -> 0 | AM8: =AK8-AL8 -> 0 | AN8: =AI8+AI9+AJ8+AJ9 -> 0 | AO8: 54.373 | AP8: =-54.373 -> -54.373 | AQ8: =AO8+AP8 -> 0 | AS8: =AQ8-AR8 -> 0 | AT8: =AO8+AO9+AP8+AP9 -> 0 | AU8: =E8+K8+Q8+W8+AC8+AI8+AO8 -> 214.626 | AV8: =F8+L8+R8+X8+AD8+AJ8+AP8 -> -214.626 | AW8: =AU8+AV8 -> 0 | AX8: =H8+N8+T8+Z8+AF8+AL8+AR8 -> 0 | AY8: =AW8-AX8 -> 0 | AZ8: =AX8/AW8 -> #DIV/0! | BA8: =AU8+AU9 -> 268.266 | BB8: =AV8+AV9 -> -268.266 | BC8: =BA8+BB8 -> 0 | BD8: =AX8+AX9 -> 0 | BE8: =BC8-BD8 -> 0 | BF8: =BD8/BC8 -> #DIV/0!
C9: 42278 | D9: 42369 | E9: 0.133 | F9: =-0.133 -> -0.133 | G9: =E9+F9+I8 -> 0 | I9: =G9-H9 -> 0 | K9: 0.6 | L9: =-0.6 -> -0.6 | M9: =K9+L9+O8 -> 0 | O9: =M9-N9 -> 0 | Q9: 4.265 | R9: =-4.265 -> -4.265 | S9: =Q9+R9+U8 -> 0 | U9: =S9-T9 -> 0 | W9: 7.996 | X9: =-7.996 -> -7.996 | Y9: =W9+X9+AA8 -> 0 | AA9: =Y9-Z9 -> 0 | AC9: 13.593 | AD9: =-13.593 -> -13.593 | AE9: =AC9+AD9+AG8 -> 0 | AG9: =AE9-AF9 -> 0 | AI9: 13.46 | AJ9: =-13.46 -> -13.46 | AK9: =AI9+AJ9+AM8 -> 0 | AM9: =AK9-AL9 -> 0 | AO9: 13.593 | AP9: =-13.593 -> -13.593 | AQ9: =AO9+AP9+AS8 -> 0 | AS9: =AQ9-AR9 -> 0 | AU9: =E9+K9+Q9+W9+AC9+AI9+AO9 -> 53.64 | AV9: =F9+L9+R9+X9+AD9+AJ9+AP9 -> -53.64 | AW9: =AU9+AV9+AY8 -> 0 | AX9: =H9+N9+T9+Z9+AF9+AL9+AR9 -> 0 | AY9: =AW9-AX9 -> 0 | AZ9: =AX9/AW9 -> #DIV/0!
B10: Blumar S.A. | C10: 41640 | D10: 42216 | E10: 0.171 | G10: =E10+F10 -> 0.171 | I10: =G10-H10 -> 0.171 | J10: =E10+E11+F10+F11 -> 0.214 | K10: 0.791 | M10: =K10+L10 -> 0.791 | O10: =M10-N10 -> 0.791 | P10: =K10+K11+L10+L11 -> 0.984 | Q10: 5.476 | R10: -0.04026 | S10: =Q10+R10 -> 5.43574 | U10: =S10-T10 -> 5.43574 | V10: =Q10+Q11+R10+R11 -> 6.80474 | W10: 10.268 | X10: -0.04026 | Y10: =W10+X10 -> 10.22774 | AA10: =Y10-Z10 -> 10.22774 | AB10: =W10+W11+X10+X11 -> 12.79474 | AC10: 17.455 | AD10: -0.04026 | AE10: =AC10+AD10 -> 17.41474 | AG10: =AE10-AF10 -> 17.41474 | AH10: =AC10+AC11+AD10+AD11 -> 21.77874 | AI10: 17.284 | AJ10: =-0.04026-17.244 -> -17.28426 | AK10: =AI10+AJ10 -> -0.00026 | AM10: =AK10-AL10 -> -0.00026 | AN10: =AI10+AI11+AJ10+AJ11 -> 2.31974 | AO10: 17.455 | AP10: =-0.04026-17.415 -> -17.45526 | AQ10: =AO10+AP10 -> -0.00026 | AS10: =AQ10-AR10 -> -0.00026 | AT10: =AO10+AO11+AP10+AP11 -> 2.37274 | AU10: =E10+K10+Q10+W10+AC10+AI10+AO10 -> 68.9 | AV10: =F10+L10+R10+X10+AD10+AJ10+AP10 -> -34.8603 | AW10: =AU10+AV10 -> 34.0397 | AX10: =H10+N10+T10+Z10+AF10+AL10+AR10 -> 0 | AY10: =AW10-AX10 -> 34.0397 | AZ10: =AX10/AW10 -> 0 | BA10: =AU10+AU11 -> 86.121 | BB10: =AV10+AV11 -> -39.01334 | BC10: =BA10+BB10 -> 47.10766 | BD10: =AX10+AX11 -> 0 | BE10: =BC10-BD10 -> 47.10766 | BF10: =BD10/BC10 -> 0
C11: 42278 | D11: 42369 | E11: 0.043 | G11: =E11+F11+I10 -> 0.214 | I11: =G11-H11 -> 0.214 | K11: 0.193 | M11: =K11+L11+O10 -> 0.984 | O11: =M11-N11 -> 0.984 | Q11: 1.369 | S11: =Q11+R11+U10 -> 6.80474 | U11: =S11-T11 -> 6.80474 | W11: 2.567 | Y11: =W11+X11+AA10 -> 12.79474 | AA11: =Y11-Z11 -> 12.79474 | AC11: 4.364 | AE11: =AC11+AD11+AG10 -> 21.77874 | AG11: =AE11-AF11 -> 21.77874 | AI11: 4.321 | AJ11: =-2.001 -> -2.001 | AK11: =AI11+AJ11+AM10 -> 2.31974 | AM11: =AK11-AL11 -> 2.31974 | AO11: 4.364 | AP11: =-1.991 -> -1.991 | AQ11: =AO11+AP11+AS10 -> 2.37274 | AS11: =AQ11-AR11 -> 2.37274 | AU11: =E11+K11+Q11+W11+AC11+AI11+AO11 -> 17.221 | AV11: =F11+L11+R11+X11+AD11+AJ11+AP11-0.16104016 -> -4.1530402 | AW11: =AU11+AV11+AY10 -> 47.10766 | AX11: =H11+N11+T11+Z11+AF11+AL11+AR11 -> 0 | AY11: =AW11-AX11 -> 47.10766 | AZ11: =AX11/AW11 -> 0
B12: Bracpesca S.A | C12: 41640 | D12: 42216 | E12: 1.373 | G12: =E12+F12 -> 1.373 | I12: =G12-H12 -> 1.373 | J12: =E12+E13+F12+F13 -> 1.716 | K12: 6.349 | M12: =K12+L12 -> 6.349 | O12: =M12-N12 -> 6.349 | P12: =K12+K13+L12+L13 -> 7.893 | Q12: 43.928 | R12: =-39.334 -> -39.334 | S12: =Q12+R12 -> 4.594 | T12: 8.938 | U12: =S12-T12 -> -4.344 | V12: =Q12+Q13+R12+R13 -> 15.576 | W12: 82.364 | Y12: =W12+X12 -> 82.364 | Z12: 57.115 | AA12: =Y12-Z12 -> 25.249 | AB12: =W12+W13+X12+X13 -> 102.955 | AC12: 140.019 | AE12: =AC12+AD12 -> 140.019 | AF12: 29.985 | AG12: =AE12-AF12 -> 110.034 | AH12: =AC12+AC13+AD12+AD13 -> 175.024 | AI12: 138.646 | AK12: =AI12+AJ12 -> 138.646 | AL12: 133.969 | AM12: =AK12-AL12 -> 4.677 | AN12: =AI12+AI13+AJ12+AJ13 -> 173.308 | AO12: 140.019 | AQ12: =AO12+AP12 -> 140.019 | AR12: 70.761 | AS12: =AQ12-AR12 -> 69.258 | AT12: =AO12+AO13+AP12+AP13 -> 175.024 | AU12: =E12+K12+Q12+W12+AC12+AI12+AO12 -> 552.698 | AV12: =F12+L12+R12+X12+AD12+AJ12+AP12 -> -39.334 | AW12: =AU12+AV12 -> 513.364 | AX12: =H12+N12+T12+Z12+AF12+AL12+AR12 -> 300.768 | AY12: =AW12-AX12 -> 212.596 | AZ12: =AX12/AW12 -> 0.58587669 | BA12: =AU12+AU13 -> 690.83 | BB12: =AV12+AV13 -> -39.334 | BC12: =BA12+BB12 -> 651.496 | BD12: =AX12+AX13 -> 354.62 | BE12: =BC12-BD12 -> 296.876 | BF12: =BD12/BC12 -> 0.54431647
C13: 42278 | D13: 42369 | E13: 0.343 | G13: =E13+F13+I12 -> 1.716 | I13: =G13-H13 -> 1.716 | K13: 1.544 | M13: =K13+L13+O12 -> 7.893 | O13: =M13-N13 -> 7.893 | Q13: 10.982 | S13: =Q13+R13+U12 -> 6.638 | T13: 4.578 | U13: =S13-T13 -> 2.06 | W13: 20.591 | Y13: =W13+X13+AA12 -> 45.84 | Z13: 8.378 | AA13: =Y13-Z13 -> 37.462 | AC13: 35.005 | AE13: =AC13+AD13+AG12 -> 145.039 | AF13: 2.201 | AG13: =AE13-AF13 -> 142.838 | AI13: 34.662 | AK13: =AI13+AJ13+AM12 -> 39.339 | AL13: 33.946 | AM13: =AK13-AL13 -> 5.393 | AO13: 35.005 | AQ13: =AO13+AP13+AS12 -> 104.263 | AR13: 4.749 | AS13: =AQ13-AR13 -> 99.514 | AU13: =E13+K13+Q13+W13+AC13+AI13+AO13 -> 138.132 | AV13: =F13+L13+R13+X13+AD13+AJ13+AP13 -> 0 | AW13: =AU13+AV13+AY12 -> 350.728 | AX13: =H13+N13+T13+Z13+AF13+AL13+AR13 -> 53.852 | AY13: =AW13-AX13 -> 296.876 | AZ13: =AX13/AW13 -> 0.15354349
B14: Camanchaca Pesca Sur S.A. | C14: 41640 | D14: 42216 | E14: 0.007 | G14: =E14+F14 -> 0.007 | I14: =G14-H14 -> 0.007 | J14: =E14+E15+F14+F15 -> 0.009 | K14: 0.033 | M14: =K14+L14 -> 0.033 | O14: =M14-N14 -> 0.033 | P14: =K14+K15+L14+L15 -> 0.041 | Q14: 0.228 | S14: =Q14+R14 -> 0.228 | U14: =S14-T14 -> 0.228 | V14: =Q14+Q15+R14+R15 -> 0.285 | W14: 0.427 | X14: =-0.0040269-0.0040269 -> -0.0080538 | Y14: =W14+X14 -> 0.4189462 | AA14: =Y14-Z14 -> 0.4189462 | AB14: =W14+W15+X14+X15 -> 0.5259462 | AC14: 0.727 | AE14: =AC14+AD14 -> 0.727 | AG14: =AE14-AF14 -> 0.727 | AH14: =AC14+AC15+AD14+AD15 -> 0.909 | AI14: 0.719 | AJ14: =19.245 -> 19.245 | AK14: =AI14+AJ14 -> 19.964 | AM14: =AK14-AL14 -> 19.964 | AN14: =AI14+AI15+AJ14+AJ15 -> 20.144 | AO14: 0.727 | AP14: =19.406 -> 19.406 | AQ14: =AO14+AP14 -> 20.133 | AS14: =AQ14-AR14 -> 20.133 | AT14: =AO14+AO15+AP14+AP15 -> 20.315 | AU14: =E14+K14+Q14+W14+AC14+AI14+AO14 -> 2.868 | AV14: =F14+L14+R14+X14+AD14+AJ14+AP14 -> 38.642946 | AW14: =AU14+AV14 -> 41.510946 | AX14: =H14+N14+T14+Z14+AF14+AL14+AR14 -> 0 | AY14: =AW14-AX14 -> 41.510946 | AZ14: =AX14/AW14 -> 0 | BA14: =AU14+AU15 -> 3.586 | BB14: =AV14+AV15 -> 38.642946 | BC14: =BA14+BB14 -> 42.228946 | BD14: =AX14+AX15 -> 37.871 | BE14: =BC14-BD14 -> 4.3579462 | BF14: =BD14/BC14 -> 0.89680192
C15: 42278 | D15: 42369 | E15: 0.002 | G15: =E15+F15+I14 -> 0.009 | I15: =G15-H15 -> 0.009 | K15: 0.008 | M15: =K15+L15+O14 -> 0.041 | O15: =M15-N15 -> 0.041 | Q15: 0.057 | S15: =Q15+R15+U14 -> 0.285 | U15: =S15-T15 -> 0.285 | W15: 0.107 | Y15: =W15+X15+AA14 -> 0.5259462 | AA15: =Y15-Z15 -> 0.5259462 | AC15: 0.182 | AE15: =AC15+AD15+AG14 -> 0.909 | AG15: =AE15-AF15 -> 0.909 | AI15: 0.18 | AK15: =AI15+AJ15+AM14 -> 20.144 | AL15: 20.876 | AM15: =AK15-AL15 -> -0.732 | AO15: 0.182 | AQ15: =AO15+AP15+AS14 -> 20.315 | AR15: 16.995 | AS15: =AQ15-AR15 -> 3.32 | AU15: =E15+K15+Q15+W15+AC15+AI15+AO15 -> 0.718 | AV15: =F15+L15+R15+X15+AD15+AJ15+AP15 -> 0 | AW15: =AU15+AV15+AY14 -> 42.228946 | AX15: =H15+N15+T15+Z15+AF15+AL15+AR15 -> 37.871 | AY15: =AW15-AX15 -> 4.3579462 | AZ15: =AX15/AW15 -> 0.89680192
B16: Antonio Cruz Cordova nakouzi E.I.R.L. | C16: 41640 | D16: 42216 | E16: 0.044 | G16: =E16+F16 -> 0.044 | I16: =G16-H16 -> 0.044 | J16: =E16+E17+F16+F17 -> 0.055 | K16: 0.204 | M16: =K16+L16 -> 0.204 | O16: =M16-N16 -> 0.204 | P16: =K16+K17+L16+L17 -> 0.254 | Q16: 1.413 | S16: =Q16+R16 -> 1.413 | U16: =S16-T16 -> 1.413 | V16: =Q16+Q17+R16+R17 -> 1.766 | W16: 2.65 | Y16: =W16+X16 -> 2.65 | AA16: =Y16-Z16 -> 2.65 | AB16: =W16+W17+X16+X17 -> 22.313 | AC16: 4.505 | AE16: =AC16+AD16 -> 4.505 | AG16: =AE16-AF16 -> 4.505 | AH16: =AC16+AC17+AD16+AD17 -> 5.631 | AI16: 4.461 | AK16: =AI16+AJ16 -> 4.461 | AM16: =AK16-AL16 -> 4.461 | AN16: =AI16+AI17+AJ16+AJ17 -> 5.576 | AO16: 4.505 | AQ16: =AO16+AP16 -> 4.505 | AS16: =AQ16-AR16 -> 4.505 | AT16: =AO16+AO17+AP16+AP17 -> 5.631 | AU16: =E16+K16+Q16+W16+AC16+AI16+AO16 -> 17.782 | AV16: =F16+L16+R16+X16+AD16+AJ16+AP16 -> 0 | AW16: =AU16+AV16 -> 17.782 | AX16: =H16+N16+T16+Z16+AF16+AL16+AR16 -> 0 | AY16: =AW16-AX16 -> 17.782 | AZ16: =AX16/AW16 -> 0 | BA16: =AU16+AU17 -> 22.226 | BB16: =AV16+AV17 -> 19 | BC16: =BA16+BB16 -> 41.226 | BD16: =AX16+AX17 -> 21.254 | BE16: =BC16-BD16 -> 19.972 | BF16: =BD16/BC16 -> 0.51554844
C17: 42278 | D17: 42369 | E17: 0.011 | G17: =E17+F17+I16 -> 0.055 | I17: =G17-H17 -> 0.055 | K17: 0.05 | M17: =K17+L17+O16 -> 0.254 | O17: =M17-N17 -> 0.254 | Q17: 0.353 | S17: =Q17+R17+U16 -> 1.766 | U17: =S17-T17 -> 1.766 | W17: 0.663 | X17: =19 -> 19 | Y17: =W17+X17+AA16 -> 22.313 | Z17: 21.254 | AA17: =Y17-Z17 -> 1.059 | AC17: 1.126 | AE17: =AC17+AD17+AG16 -> 5.631 | AG17: =AE17-AF17 -> 5.631 | AI17: 1.115 | AK17: =AI17+AJ17+AM16 -> 5.576 | AM17: =AK17-AL17 -> 5.576 | AO17: 1.126 | AQ17: =AO17+AP17+AS16 -> 5.631 | AS17: =AQ17-AR17 -> 5.631 | AU17: =E17+K17+Q17+W17+AC17+AI17+AO17 -> 4.444 | AV17: =F17+L17+R17+X17+AD17+AJ17+AP17 -> 19 | AW17: =AU17+AV17+AY16 -> 41.226 | AX17: =H17+N17+T17+Z17+AF17+AL17+AR17 -> 21.254 | AY17: =AW17-AX17 -> 19.972 | AZ17: =AX17/AW17 -> 0.51554844
B18: Costa Brava Ltda. Pesq. | C18: 41640 | D18: 42216 | E18: 0.195 | F18: =-0.195 -> -0.195 | G18: =E18+F18 -> 0 | I18: =G18-H18 -> 0 | J18: =E18+E19+F18+F19 -> 0 | K18: 0.901 | L18: =-0.901 -> -0.901 | M18: =K18+L18 -> 0 | O18: =M18-N18 -> 0 | P18: =K18+K19+L18+L19 -> 0 | Q18: 6.237 | R18: =-6.237 -> -6.237 | S18: =Q18+R18 -> 0 | U18: =S18-T18 -> 0 | V18: =Q18+Q19+R18+R19 -> 0 | W18: 11.694 | X18: =-11.694 -> -11.694 | Y18: =W18+X18 -> 0 | AA18: =Y18-Z18 -> 0 | AB18: =W18+W19+X18+X19 -> 0 | AC18: 19.88 | AD18: =-19.88 -> -19.88 | AE18: =AC18+AD18 -> 0 | AG18: =AE18-AF18 -> 0 | AH18: =AC18+AC19+AD18+AD19 -> 0 | AI18: 19.685 | AJ18: =-19.685 -> -19.685 | AK18: =AI18+AJ18 -> 0 | AM18: =AK18-AL18 -> 0 | AN18: =AI18+AI19+AJ18+AJ19 -> 0 | AO18: 19.88 | AP18: =-19.88 -> -19.88 | AQ18: =AO18+AP18 -> 0 | AS18: =AQ18-AR18 -> 0 | AT18: =AO18+AO19+AP18+AP19 -> 0 | AU18: =E18+K18+Q18+W18+AC18+AI18+AO18 -> 78.472 | AV18: =F18+L18+R18+X18+AD18+AJ18+AP18 -> -78.472 | AW18: =AU18+AV18 -> 0 | AX18: =H18+N18+T18+Z18+AF18+AL18+AR18 -> 0 | AY18: =AW18-AX18 -> 0 | AZ18: =AX18/AW18 -> #DIV/0! | BA18: =AU18+AU19 -> 98.084 | BB18: =AV18+AV19 -> -98.084 | BC18: =BA18+BB18 -> 0 | BD18: =AX18+AX19 -> 0 | BE18: =BC18-BD18 -> 0 | BF18: =BD18/BC18 -> #DIV/0!
C19: 42278 | D19: 42369 | E19: 0.049 | F19: =-0.049 -> -0.049 | G19: =E19+F19+I18 -> 0 | I19: =G19-H19 -> 0 | K19: 0.219 | L19: =-0.219 -> -0.219 | M19: =K19+L19+O18 -> 0 | O19: =M19-N19 -> 0 | Q19: 1.559 | R19: =-1.559 -> -1.559 | S19: =Q19+R19+U18 -> 0 | U19: =S19-T19 -> 0 | W19: 2.924 | X19: =-2.924 -> -2.924 | Y19: =W19+X19+AA18 -> 0 | AA19: =Y19-Z19 -> 0 | AC19: 4.97 | AD19: =-4.97 -> -4.97 | AE19: =AC19+AD19+AG18 -> 0 | AG19: =AE19-AF19 -> 0 | AI19: 4.921 | AJ19: =-4.921 -> -4.921 | AK19: =AI19+AJ19+AM18 -> 0 | AM19: =AK19-AL19 -> 0 | AO19: 4.97 | AP19: =-4.97 -> -4.97 | AQ19: =AO19+AP19+AS18 -> 0 | AS19: =AQ19-AR19 -> 0 | AU19: =E19+K19+Q19+W19+AC19+AI19+AO19 -> 19.612 | AV19: =F19+L19+R19+X19+AD19+AJ19+AP19 -> -19.612 | AW19: =AU19+AV19+AY18 -> 0 | AX19: =H19+N19+T19+Z19+AF19+AL19+AR19 -> 0 | AY19: =AW19-AX19 -> 0 | AZ19: =AX19/AW19 -> #DIV/0!
B20: Grimar S.A. Pesq. | C20: 41640 | D20: 42216 | E20: 0.027 | G20: =E20+F20 -> 0.027 | I20: =G20-H20 -> 0.027 | J20: =E20+E21+F20+F21 -> 0.034 | K20: 0.124 | M20: =K20+L20 -> 0.124 | O20: =M20-N20 -> 0.124 | P20: =K20+K21+L20+L21 -> 0.154 | Q20: 0.855 | S20: =Q20+R20 -> 0.855 | U20: =S20-T20 -> 0.855 | V20: =Q20+Q21+R20+R21 -> 1.069 | W20: 1.603 | Y20: =W20+X20 -> 1.603 | AA20: =Y20-Z20 -> 1.603 | AB20: =W20+W21+X20+X21 -> 2.004 | AC20: 2.725 | AE20: =AC20+AD20 -> 2.725 | AG20: =AE20-AF20 -> 2.725 | AH20: =AC20+AC21+AD20+AD21 -> 3.406 | AI20: 2.699 | AK20: =AI20+AJ20 -> 2.699 | AM20: =AK20-AL20 -> 2.699 | AN20: =AI20+AI21+AJ20+AJ21 -> 3.374 | AO20: 2.725 | AQ20: =AO20+AP20 -> 2.725 | AS20: =AQ20-AR20 -> 2.725 | AT20: =AO20+AO21+AP20+AP21 -> 3.406 | AU20: =E20+K20+Q20+W20+AC20+AI20+AO20 -> 10.758 | AV20: =F20+L20+R20+X20+AD20+AJ20+AP20 -> 0 | AW20: =AU20+AV20 -> 10.758 | AX20: =H20+N20+T20+Z20+AF20+AL20+AR20 -> 0 | AY20: =AW20-AX20 -> 10.758 | AZ20: =AX20/AW20 -> 0 | BA20: =AU20+AU21 -> 13.447 | BB20: =AV20+AV21 -> 0 | BC20: =BA20+BB20 -> 13.447 | BD20: =AX20+AX21 -> 0 | BE20: =BC20-BD20 -> 13.447 | BF20: =BD20/BC20 -> 0
C21: 42278 | D21: 42369 | E21: 0.007 | G21: =E21+F21+I20 -> 0.034 | I21: =G21-H21 -> 0.034 | K21: 0.03 | M21: =K21+L21+O20 -> 0.154 | O21: =M21-N21 -> 0.154 | Q21: 0.214 | S21: =Q21+R21+U20 -> 1.069 | U21: =S21-T21 -> 1.069 | W21: 0.401 | Y21: =W21+X21+AA20 -> 2.004 | AA21: =Y21-Z21 -> 2.004 | AC21: 0.681 | AE21: =AC21+AD21+AG20 -> 3.406 | AG21: =AE21-AF21 -> 3.406 | AI21: 0.675 | AK21: =AI21+AJ21+AM20 -> 3.374 | AM21: =AK21-AL21 -> 3.374 | AO21: 0.681 | AQ21: =AO21+AP21+AS20 -> 3.406 | AS21: =AQ21-AR21 -> 3.406 | AU21: =E21+K21+Q21+W21+AC21+AI21+AO21 -> 2.689 | AV21: =F21+L21+R21+X21+AD21+AJ21+AP21 -> 0 | AW21: =AU21+AV21+AY20 -> 13.447 | AX21: =H21+N21+T21+Z21+AF21+AL21+AR21 -> 0 | AY21: =AW21-AX21 -> 13.447 | AZ21: =AX21/AW21 -> 0
B22: Isladamas S.A. Pesq. | C22: 41640 | D22: 42216 | E22: 1.234 | F22: =0.195+0.347 -> 0.542 | G22: =E22+F22 -> 1.776 | I22: =G22-H22 -> 1.776 | J22: 2.803 | K22: 5.706 | L22: =0.901+1.607 -> 2.508 | M22: =K22+L22 -> 8.214 | O22: =M22-N22 -> 8.214 | P22: =K22+K23+L22+L23 -> 10.212 | Q22: 39.479 | R22: =6.237+11.117 -> 17.354 | S22: =Q22+R22 -> 56.833 | T22: 15.433 | U22: =S22-T22 -> 41.4 | V22: =Q22+Q23+X22+R23 -> 86.220974 | W22: 74.023 | X22: =-0.004026+11.694+20.844 -> 32.533974 | Y22: =W22+X22 -> 106.55697 | Z22: 83.847 | AA22: =Y22-Z22 -> 22.709974 | AB22: =W22+W23+X22+X23 -> 114.19797 | AC22: 125.839 | AD22: =19.88+35.435 -> 55.315 | AE22: =AC22+AD22 -> 181.154 | AF22: 87.861 | AG22: =AE22-AF22 -> 93.293 | AH22: =AC22+AC23+AD22+AD23 -> 226.443 | AI22: 124.605 | AJ22: =19.685+35.087 -> 54.772 | AK22: =AI22+AJ22 -> 179.377 | AL22: 176.465 | AM22: =AK22-AL22 -> 2.912 | AN22: =AI22+AI23+AJ22+AJ23 -> 224.221 | AO22: 125.839 | AP22: =19.88+35.435 -> 55.315 | AQ22: =AO22+AP22 -> 181.154 | AR22: 94.739 | AS22: =AQ22-AR22 -> 86.415 | AT22: =AO22+AO23+AP22+AP23 -> 226.443 | AU22: =E22+K22+Q22+W22+AC22+AI22+AO22 -> 496.725 | AV22: =F22+L22+X22+R22+AD22+AJ22+AP22 -> 218.33997 | AW22: =AU22+AV22 -> 715.06497 | AX22: =H22+N22+T22+Z22+AF22+AL22+AR22 -> 458.345 | AY22: =AW22-AX22 -> 256.71997 | AZ22: =AX22/AW22 -> 0.64098371 | BA22: =AU22+AU23 -> 620.868 | BB22: =AV22+AV23 -> 253.90997 | BC22: =BA22+BB22 -> 874.77797 | BD22: =AX22+AX23 -> 611.282 | BE22: =BC22-BD22 -> 263.49597 | BF22: =BD22/BC22 -> 0.69878531
C23: 42278 | D23: 42369 | E23: 0.308 | F23: =0.049+0.087 -> 0.136 | G23: =E23+F23+I22 -> 2.22 | I23: =G23-H23 -> 2.22 | K23: 1.388 | L23: =0.219+0.391 -> 0.61 | M23: =K23+L23+O22 -> 10.212 | N23: 10.236 | O23: =M23-N23 -> -0.024 | Q23: 9.87 | R23: =1.559+2.779 -> 4.338 | S23: =Q23+R23+U22 -> 55.608 | T23: 11.961 | U23: =S23-T23 -> 43.647 | W23: 18.506 | X23: =2.924+5.211-19 -> -10.865 | Y23: =W23+X23+AA22 -> 30.350974 | Z23: 26.743 | AA23: =Y23-Z23 -> 3.607974 | AC23: 31.46 | AD23: =4.97+8.859 -> 13.829 | AE23: =AC23+AD23+AG22 -> 138.582 | AF23: 19.935 | AG23: =AE23-AF23 -> 118.647 | AI23: 31.151 | AJ23: =4.921+8.772 -> 13.693 | AK23: =AI23+AJ23+AM22 -> 47.756 | AL23: 43.457 | AM23: =AK23-AL23 -> 4.299 | AO23: 31.46 | AP23: =4.97+8.859 -> 13.829 | AQ23: =AO23+AP23+AS22 -> 131.704 | AR23: 40.605 | AS23: =AQ23-AR23 -> 91.099 | AU23: =E23+K23+Q23+W23+AC23+AI23+AO23 -> 124.143 | AV23: =F23+L23+R23+X23+AD23+AJ23+AP23 -> 35.57 | AW23: =AU23+AV23+AY22 -> 416.43297 | AX23: =H23+N23+T23+Z23+AF23+AL23+AR23 -> 152.937 | AY23: =AW23-AX23 -> 263.49597 | AZ23: =AX23/AW23 -> 0.36725478
B24: Landes S.A. Soc. Pesq. | C24: 41640 | D24: 42216 | E24: 0.015 | G24: =E24+F24 -> 0.015 | I24: =G24-H24 -> 0.015 | J24: =E24+E25+F24+F25 -> 0.019 | K24: 0.067 | M24: =K24+L24 -> 0.067 | O24: =M24-N24 -> 0.067 | P24: =K24+K25+L24+L25 -> 0.083 | Q24: 0.467 | S24: =Q24+R24 -> 0.467 | U24: =S24-T24 -> 0.467 | V24: =Q24+Q25+R24+R25 -> 0.584 | W24: 0.875 | Y24: =W24+X24 -> 0.875 | AA24: =Y24-Z24 -> 0.875 | AB24: =W24+W25+X24+X25 -> 1.094 | AC24: 1.488 | AE24: =AC24+AD24 -> 1.488 | AG24: =AE24-AF24 -> 1.488 | AH24: =AC24+AC25+AD24+AD25 -> 1.86 | AI24: 1.473 | AK24: =AI24+AJ24 -> 1.473 | AM24: =AK24-AL24 -> 1.473 | AN24: =AI24+AI25+AJ24+AJ25 -> 1.841 | AO24: 1.488 | AQ24: =AO24+AP24 -> 1.488 | AS24: =AQ24-AR24 -> 1.488 | AT24: =AO24+AO25+AP24+AP25 -> 1.86 | AU24: =E24+K24+Q24+W24+AC24+AI24+AO24 -> 5.873 | AV24: =F24+L24+R24+X24+AD24+AJ24+AP24 -> 0 | AW24: =AU24+AV24 -> 5.873 | AX24: =H24+N24+T24+Z24+AF24+AL24+AR24 -> 0 | AY24: =AW24-AX24 -> 5.873 | AZ24: =AX24/AW24 -> 0 | BA24: =AU24+AU25 -> 7.341 | BB24: =AV24+AV25 -> 0 | BC24: =BA24+BB24 -> 7.341 | BD24: =AX24+AX25 -> 0 | BE24: =BC24-BD24 -> 7.341 | BF24: =BD24/BC24 -> 0
C25: 42278 | D25: 42369 | E25: 0.004 | G25: =E25+F25+I24 -> 0.019 | I25: =G25-H25 -> 0.019 | K25: 0.016 | M25: =K25+L25+O24 -> 0.083 | O25: =M25-N25 -> 0.083 | Q25: 0.117 | S25: =Q25+R25+U24 -> 0.584 | U25: =S25-T25 -> 0.584 | W25: 0.219 | Y25: =W25+X25+AA24 -> 1.094 | AA25: =Y25-Z25 -> 1.094 | AC25: 0.372 | AE25: =AC25+AD25+AG24 -> 1.86 | AG25: =AE25-AF25 -> 1.86 | AI25: 0.368 | AK25: =AI25+AJ25+AM24 -> 1.841 | AM25: =AK25-AL25 -> 1.841 | AO25: 0.372 | AQ25: =AO25+AP25+AS24 -> 1.86 | AS25: =AQ25-AR25 -> 1.86 | AU25: =E25+K25+Q25+W25+AC25+AI25+AO25 -> 1.468 | AV25: =F25+L25+R25+X25+AD25+AJ25+AP25 -> 0 | AW25: =AU25+AV25+AY24 -> 7.341 | AX25: =H25+N25+T25+Z25+AF25+AL25+AR25 -> 0 | AY25: =AW25-AX25 -> 7.341 | AZ25: =AX25/AW25 -> 0
B26: Morozin Baycic Maria Ana | C26: 41640 | D26: 42216 | E26: 0.306 | F26: =-0.306 -> -0.306 | G26: =E26+F26 -> 0 | I26: =G26-H26 -> 0 | J26: =E26+E27+F26+F27 -> 0 | K26: 1.414 | L26: =-1.414 -> -1.414 | M26: =K26+L26 -> 0 | O26: =M26-N26 -> 0 | P26: =K26+K27+L26+L27 -> 0 | Q26: 9.784 | R26: =-9.784 -> -9.784 | S26: =Q26+R26 -> 0 | U26: =S26-T26 -> 0 | V26: =Q26+Q27+R26+R27 -> 0 | W26: 18.345 | X26: =-18.345 -> -18.345 | Y26: =W26+X26 -> 0 | AA26: =Y26-Z26 -> 0 | AB26: =W26+W27+X26+X27 -> 0 | AC26: 31.186 | AD26: =-31.186 -> -31.186 | AE26: =AC26+AD26 -> 0 | AG26: =AE26-AF26 -> 0 | AH26: =AC26+AC27+AD26+AD27 -> 0 | AI26: 30.881 | AJ26: =-30.881 -> -30.881 | AK26: =AI26+AJ26 -> 0 | AM26: =AK26-AL26 -> 0 | AN26: =AI26+AI27+AJ26+AJ27 -> 0 | AO26: 31.186 | AP26: =-31.186 -> -31.186 | AQ26: =AO26+AP26 -> 0 | AS26: =AQ26-AR26 -> 0 | AT26: =AO26+AO27+AP26+AP27 -> 0 | AU26: =E26+K26+Q26+W26+AC26+AI26+AO26 -> 123.102 | AV26: =F26+L26+R26+X26+AD26+AJ26+AP26 -> -123.102 | AW26: =AU26+AV26 -> 0 | AX26: =H26+N26+T26+Z26+AF26+AL26+AR26 -> 0 | AY26: =AW26-AX26 -> 0 | AZ26: =AX26/AW26 -> #DIV/0! | BA26: =AU26+AU27 -> 153.868 | BB26: =AV26+AV27 -> -153.868 | BC26: =BA26+BB26 -> 0 | BD26: =AX26+AX27 -> 0 | BE26: =BC26-BD26 -> 0 | BF26: =BD26/BC26 -> #DIV/0!
C27: 42278 | D27: 42369 | E27: 0.076 | F27: =-0.076 -> -0.076 | G27: =E27+F27+I26 -> 0 | I27: =G27-H27 -> 0 | K27: 0.344 | L27: =-0.344 -> -0.344 | M27: =K27+L27+O26 -> 0 | O27: =M27-N27 -> 0 | Q27: 2.446 | R27: =-2.446 -> -2.446 | S27: =Q27+R27+U26 -> 0 | U27: =S27-T27 -> 0 | W27: 4.586 | X27: =-4.586 -> -4.586 | Y27: =W27+X27+AA26 -> 0 | AA27: =Y27-Z27 -> 0 | AC27: 7.797 | AD27: =-7.797 -> -7.797 | AE27: =AC27+AD27+AG26 -> 0 | AG27: =AE27-AF27 -> 0 | AI27: 7.72 | AJ27: =-7.72 -> -7.72 | AK27: =AI27+AJ27+AM26 -> 0 | AM27: =AK27-AL27 -> 0 | AO27: 7.797 | AP27: =-7.797 -> -7.797 | AQ27: =AO27+AP27+AS26 -> 0 | AS27: =AQ27-AR27 -> 0 | AU27: =E27+K27+Q27+W27+AC27+AI27+AO27 -> 30.766 | AV27: =F27+L27+R27+X27+AD27+AJ27+AP27 -> -30.766 | AW27: =AU27+AV27+AY26 -> 0 | AX27: =H27+N27+T27+Z27+AF27+AL27+AR27 -> 0 | AY27: =AW27-AX27 -> 0 | AZ27: =AX27/AW27 -> #DIV/0!
B28: Morozin Yurecic Mario | C28: 41640 | D28: 42216 | E28: 0.69 | F28: =-0.69 -> -0.69 | G28: =E28+F28 -> 0 | I28: =G28-H28 -> 0 | J28: =E28+E29+F28+F29 -> 0 | K28: 3.189 | L28: =-3.189 -> -3.189 | M28: =K28+L28 -> 0 | O28: =M28-N28 -> 0 | P28: =K28+K29+L28+L29 -> 0 | Q28: 22.066 | R28: =-22.066 -> -22.066 | S28: =Q28+R28 -> 0 | U28: =S28-T28 -> 0 | V28: =Q28+Q29+R28+R29 -> 0 | W28: 41.374 | X28: =-41.374 -> -41.374 | Y28: =W28+X28 -> 0 | AA28: =Y28-Z28 -> 0 | AB28: =W28+W29+X28+X29 -> 0 | AC28: 70.336 | AD28: =-70.336 -> -70.336 | AE28: =AC28+AD28 -> 0 | AG28: =AE28-AF28 -> 0 | AH28: =AC28+AC29+AD28+AD29 -> 0 | AI28: 69.647 | AJ28: =-69.647 -> -69.647 | AK28: =AI28+AJ28 -> 0 | AM28: =AK28-AL28 -> 0 | AN28: =AI28+AI29+AJ28+AJ29 -> 0 | AO28: 70.336 | AP28: =-70.336 -> -70.336 | AQ28: =AO28+AP28 -> 0 | AS28: =AQ28-AR28 -> 0 | AT28: =AO28+AO29+AP28+AP29 -> 0 | AU28: =E28+K28+Q28+W28+AC28+AI28+AO28 -> 277.638 | AV28: =F28+L28+R28+X28+AD28+AJ28+AP28 -> -277.638 | AW28: =AU28+AV28 -> 0 | AX28: =H28+N28+T28+Z28+AF28+AL28+AR28 -> 0 | AY28: =AW28-AX28 -> 0 | AZ28: =AX28/AW28 -> #DIV/0! | BA28: =AU28+AU29 -> 347.027 | BB28: =AV28+AV29 -> -347.027 | BC28: =BA28+BB28 -> 0 | BD28: =AX28+AX29 -> 0 | BE28: =BC28-BD28 -> 0 | BF28: =BD28/BC28 -> #DIV/0!
C29: 42278 | D29: 42369 | E29: 0.172 | F29: =-0.172 -> -0.172 | G29: =E29+F29+I28 -> 0 | I29: =G29-H29 -> 0 | K29: 0.776 | L29: =-0.776 -> -0.776 | M29: =K29+L29+O28 -> 0 | O29: =M29-N29 -> 0 | Q29: 5.517 | R29: =-5.517 -> -5.517 | S29: =Q29+R29+U28 -> 0 | U29: =S29-T29 -> 0 | W29: 10.344 | X29: =-10.344 -> -10.344 | Y29: =W29+X29+AA28 -> 0 | AA29: =Y29-Z29 -> 0 | AC29: 17.584 | AD29: =-17.584 -> -17.584 | AE29: =AC29+AD29+AG28 -> 0 | AG29: =AE29-AF29 -> 0 | AI29: 17.412 | AJ29: =-17.412 -> -17.412 | AK29: =AI29+AJ29+AM28 -> 0 | AM29: =AK29-AL29 -> 0 | AO29: 17.584 | AP29: =-17.584 -> -17.584 | AQ29: =AO29+AP29+AS28 -> 0 | AS29: =AQ29-AR29 -> 0 | AU29: =E29+K29+Q29+W29+AC29+AI29+AO29 -> 69.389 | AV29: =F29+L29+R29+X29+AD29+AJ29+AP29 -> -69.389 | AW29: =AU29+AV29+AY28 -> 0 | AX29: =H29+N29+T29+Z29+AF29+AL29+AR29 -> 0 | AY29: =AW29-AX29 -> 0 | AZ29: =AX29/AW29 -> #DIV/0!
B30: Quintero Ltda. Soc. Pesq. | C30: 41640 | D30: 42216 | E30: 0.165 | F30: =-0.165 -> -0.165 | G30: =E30+F30 -> 0 | I30: =G30-H30 -> 0 | J30: =E30+E31+F30+F31 -> 0 | K30: 0.764 | L30: =-0.764 -> -0.764 | M30: =K30+L30 -> 0 | O30: =M30-N30 -> 0 | P30: =K30+K31+L30+L31 -> 0 | Q30: 5.283 | R30: =-5.283 -> -5.283 | S30: =Q30+R30 -> 0 | U30: =S30-T30 -> 0 | V30: =Q30+Q31+R30+R31 -> 99.997 | W30: 9.905 | X30: =-9.905 -> -9.905 | Y30: =W30+X30 -> 0 | AA30: =Y30-Z30 -> 0 | AB30: =W30+W31+X30+X31 -> 0 | AC30: 16.839 | AD30: =-16.839 -> -16.839 | AE30: =AC30+AD30 -> 0 | AG30: =AE30-AF30 -> 0 | AH30: =AC30+AC31+AD30+AD31 -> 0 | AI30: 16.674 | AJ30: =-16.674 -> -16.674 | AK30: =AI30+AJ30 -> 0 | AM30: =AK30-AL30 -> 0 | AN30: =AI30+AI31+AJ30+AJ31 -> 0 | AO30: 16.839 | AP30: =-16.839 -> -16.839 | AQ30: =AO30+AP30 -> 0 | AS30: =AQ30-AR30 -> 0 | AT30: =AO30+AO31+AP30+AP31 -> 0 | AU30: =E30+K30+Q30+W30+AC30+AI30+AO30 -> 66.469 | AV30: =F30+L30+R30+X30+AD30+AJ30+AP30 -> -66.469 | AW30: =AU30+AV30 -> 0 | AX30: =H30+N30+T30+Z30+AF30+AL30+AR30 -> 0 | AY30: =AW30-AX30 -> 0 | AZ30: =AX30/AW30 -> #DIV/0! | BA30: =AU30+AU31 -> 83.081 | BB30: =AV30+AV31 -> 16.916 | BC30: =BA30+BB30 -> 99.997 | BD30: =AX30+AX31 -> 76.412 | BE30: =BC30-BD30 -> 23.585 | BF30: =BD30/BC30 -> 0.76414292
C31: 42278 | D31: 42369 | E31: 0.041 | F31: =-0.041 -> -0.041 | G31: =E31+F31+I30 -> 0 | I31: =G31-H31 -> 0 | K31: 0.186 | L31: =-0.186 -> -0.186 | M31: =K31+L31+O30 -> 0 | O31: =M31-N31 -> 0 | Q31: 1.321 | R31: =-1.321+99.997 -> 98.676 | S31: =Q31+R31+U30 -> 99.997 | T31: 76.412 | U31: =S31-T31 -> 23.585 | W31: 2.476 | X31: =-2.476 -> -2.476 | Y31: =W31+X31+AA30 -> 0 | AA31: =Y31-Z31 -> 0 | AC31: 4.21 | AD31: =-4.21 -> -4.21 | AE31: =AC31+AD31+AG30 -> 0 | AG31: =AE31-AF31 -> 0 | AI31: 4.168 | AJ31: =-4.168 -> -4.168 | AK31: =AI31+AJ31+AM30 -> 0 | AM31: =AK31-AL31 -> 0 | AO31: 4.21 | AP31: =-4.21 -> -4.21 | AQ31: =AO31+AP31+AS30 -> 0 | AS31: =AQ31-AR31 -> 0 | AU31: =E31+K31+Q31+W31+AC31+AI31+AO31 -> 16.612 | AV31: =F31+L31+R31+X31+AD31+AJ31+AP31 -> 83.385 | AW31: =AU31+AV31+AY30 -> 99.997 | AX31: =H31+N31+T31+Z31+AF31+AL31+AR31 -> 76.412 | AY31: =AW31-AX31 -> 23.585 | AZ31: =AX31/AW31 -> 0.76414292
B32: Quintero S.A., Pesquera | C32: 41640 | D32: 42216 | E32: 1.203 | F32: =0.69+0.165+0.306+0.533 -> 1.694 | G32: =E32+F32 -> 2.897 | I32: =G32-H32 -> 2.897 | J32: =E32+E33+F32+F33 -> 3.62 | K32: 5.563 | L32: =3.189+0.764+1.414+2.465 -> 7.832 | M32: =K32+L32 -> 13.395 | O32: =M32-N32 -> 13.395 | P32: =K32+K33+L32+L33 -> 16.654 | Q32: 38.491 | R32: =22.066+5.283+9.784+17.058+9.384 -> 63.575 | S32: =Q32+R32 -> 102.066 | T32: 99.271 | U32: =S32-T32 -> 2.795 | V32: =Q32+Q33+R32+R33 -> 127.37 | W32: 72.17 | X32: =41.374+9.905+18.345+31.984+17.595-0.1 -> 119.103 | Y32: =W32+X32 -> 191.273 | Z32: 186.488 | AA32: =Y32-Z32 -> 4.785 | AB32: =W32+W33+X32+X33 -> 238.948 | AC32: 122.69 | AD32: =70.336+16.839+31.186+54.373+29.912 -> 202.646 | AE32: =AC32+AD32 -> 325.336 | AF32: 323.773 | AG32: =AE32-AF32 -> 1.563 | AH32: =AC32+AC33+AD32+AD33 -> 406.487 | AI32: 121.487 | AJ32: =69.647+16.674+30.881+53.84+29.619 -> 200.661 | AK32: =AI32+AJ32 -> 322.148 | AL32: 318.548 | AM32: =AK32-AL32 -> 3.6 | AN32: =AI32+AI33+AJ32+AJ33 -> 402.465 | AO32: 122.69 | AP32: =70.336+16.839+31.186+54.373+29.912 -> 202.646 | AQ32: =AO32+AP32 -> 325.336 | AR32: 26.852 | AS32: =AQ32-AR32 -> 298.484 | AT32: =AO32+AO33+AP32+AP33 -> 406.487 | AU32: =E32+K32+Q32+W32+AC32+AI32+AO32 -> 484.294 | AV32: =F32+L32+R32+X32+AD32+AJ32+AP32 -> 798.157 | AW32: =AU32+AV32 -> 1282.451 | AX32: =H32+N32+T32+Z32+AF32+AL32+AR32 -> 954.932 | AY32: =AW32-AX32 -> 327.519 | AZ32: =AX32/AW32 -> 0.7446148 | BA32: =AU32+AU33 -> 605.33 | BB32: =AV32+AV33 -> 996.701 | BC32: =BA32+BB32 -> 1602.031 | BD32: =AX32+AX33 -> 1457.679 | BE32: =BC32-BD32 -> 144.352 | BF32: =BD32/BC32 -> 0.90989438
C33: 42278 | D33: 42369 | E33: 0.301 | F33: =0.172+0.041+0.076+0.133 -> 0.422 | G33: =E33+F33+I32 -> 3.62 | I33: =G33-H33 -> 3.62 | K33: 1.353 | L33: =0.776+0.186+0.344+0.6 -> 1.906 | M33: =K33+L33+O32 -> 16.654 | O33: =M33-N33 -> 16.654 | Q33: 9.623 | R33: =5.517+1.321+2.446+4.265+2.132 -> 15.681 | S33: =Q33+R33+U32 -> 28.099 | T33: 18.91 | U33: =S33-T33 -> 9.189 | W33: 18.043 | X33: =10.344+2.476+4.586+7.996+4.23 -> 29.632 | Y33: =W33+X33+AA32 -> 52.46 | Z33: 47.939 | AA33: =Y33-Z33 -> 4.521 | AC33: 30.672 | AD33: =17.584+4.21+7.797+13.593+7.295 -> 50.479 | AE33: =AC33+AD33+AG32 -> 82.714 | AF33: 79.507 | AG33: =AE33-AF33 -> 3.207 | AI33: 30.372 | AJ33: =17.412+4.168+7.72+13.46+7.185 -> 49.945 | AK33: =AI33+AJ33+AM32 -> 83.917 | AL33: 82.833 | AM33: =AK33-AL33 -> 1.084 | AO33: 30.672 | AP33: =17.584+4.21+7.797+13.593+7.295 -> 50.479 | AQ33: =AO33+AP33+AS32 -> 379.635 | AR33: 273.558 | AS33: =AQ33-AR33 -> 106.077 | AU33: =E33+K33+Q33+W33+AC33+AI33+AO33 -> 121.036 | AV33: =F33+L33+R33+X33+AD33+AJ33+AP33 -> 198.544 | AW33: =AU33+AV33+AY32 -> 647.099 | AX33: =H33+N33+T33+Z33+AF33+AL33+AR33 -> 502.747 | AY33: =AW33-AX33 -> 144.352 | AZ33: =AX33/AW33 -> 0.7769244
B34: Rubio y Mauad Ltda. | C34: 41640 | D34: 42216 | E34: 0.293 | G34: =E34+F34 -> 0.293 | I34: =G34-H34 -> 0.293 | J34: =E34+E35+F34+F35 -> 0.366 | K34: 1.356 | M34: =K34+L34 -> 1.356 | O34: =M34-N34 -> 1.356 | P34: =K34+K35+L34+L35 -> 1.686 | Q34: 9.384 | R34: =-9.384 -> -9.384 | S34: =Q34+R34 -> 0 | U34: =S34-T34 -> 0 | V34: =Q34+Q35+R34+R35 -> 35.213627 | W34: 17.595 | X34: =-17.595 -> -17.595 | Y34: =W34+X34 -> 0 | AA34: =Y34-Z34 -> 0 | AB34: =W34+W35+X34+X35 -> 0.169054 | AC34: 29.912 | AD34: =-29.912 -> -29.912 | AE34: =AC34+AD34 -> 0 | AG34: =AE34-AF34 -> 0 | AH34: =AC34+AC35+AD34+AD35 -> 0.1829158 | AI34: 29.619 | AJ34: =-29.619 -> -29.619 | AK34: =AI34+AJ34 -> 0 | AM34: =AK34-AL34 -> 0 | AN34: =AI34+AI35+AJ34+AJ35 -> 0.2199184 | AO34: 29.912 | AP34: =-29.912 -> -29.912 | AQ34: =AO34+AP34 -> 0 | AS34: =AQ34-AR34 -> 0 | AT34: =AO34+AO35+AP34+AP35 -> 0.1829158 | AU34: =E34+K34+Q34+W34+AC34+AI34+AO34 -> 118.071 | AV34: =F34+L34+R34+X34+AD34+AJ34+AP34 -> -116.422 | AW34: =AU34+AV34 -> 1.649 | AX34: =H34+N34+T34+Z34+AF34+AL34+AR34 -> 0 | AY34: =AW34-AX34 -> 1.649 | AZ34: =AX34/AW34 -> 0 | BA34: =AU34+AU35 -> 147.58 | BB34: =AV34+AV35 -> -109.55957 | BC34: =BA34+BB34 -> 38.020431 | BD34: =AX34+AX35 -> 0.25 | BE34: =BC34-BD34 -> 37.770431 | BF34: =BD34/BC34 -> 0.006575412
C35: 42278 | D35: 42369 | E35: 0.073 | G35: =E35+F35+I34 -> 0.366 | I35: =G35-H35 -> 0.366 | K35: 0.33 | M35: =K35+L35+O34 -> 1.686 | O35: =M35-N35 -> 1.686 | Q35: 2.346 | R35: =-2.132373+35 -> 32.867627 | S35: =Q35+R35+U34 -> 35.213627 | T35: 0.25 | U35: =S35-T35 -> 34.963627 | W35: 4.399 | X35: =-4.229946 -> -4.229946 | Y35: =W35+X35+AA34 -> 0.169054 | AA35: =Y35-Z35 -> 0.169054 | AC35: 7.478 | AD35: =-7.2950842 -> -7.2950842 | AE35: =AC35+AD35+AG34 -> 0.1829158 | AG35: =AE35-AF35 -> 0.1829158 | AI35: 7.405 | AJ35: =-7.1850816 -> -7.1850816 | AK35: =AI35+AJ35+AM34 -> 0.2199184 | AM35: =AK35-AL35 -> 0.2199184 | AO35: 7.478 | AP35: =-7.2950842 -> -7.2950842 | AQ35: =AO35+AP35+AS34 -> 0.1829158 | AS35: =AQ35-AR35 -> 0.1829158 | AU35: =E35+K35+Q35+W35+AC35+AI35+AO35 -> 29.509 | AV35: =F35+L35+R35+X35+AD35+AJ35+AP35 -> 6.862431 | AW35: =AU35+AV35+AY34 -> 38.020431 | AX35: =H35+N35+T35+Z35+AF35+AL35+AR35 -> 0.25 | AY35: =AW35-AX35 -> 37.770431 | AZ35: =AX35/AW35 -> 0.006575412
B36: Sunrise S.A. Pesq. | C36: 41640 | D36: 42216 | E36: 0.347 | F36: =-0.347 -> -0.347 | G36: =E36+F36 -> 0 | I36: =G36-H36 -> 0 | J36: =E36+E37+F36+F37 -> 0 | K36: 1.607 | L36: =-1.607 -> -1.607 | M36: =K36+L36 -> 0 | O36: =M36-N36 -> 0 | P36: =K36+K37+L36+L37 -> 0 | Q36: 11.117 | R36: =-11.117 -> -11.117 | S36: =Q36+R36 -> 0 | U36: =S36-T36 -> 0 | V36: =Q36+Q37+R36+R37 -> 0 | W36: 20.844 | X36: =-20.844 -> -20.844 | Y36: =W36+X36 -> 0 | AA36: =Y36-Z36 -> 0 | AB36: =W36+W37+X36+X37 -> 0 | AC36: 35.435 | AD36: =-35.435 -> -35.435 | AE36: =AC36+AD36 -> 0 | AG36: =AE36-AF36 -> 0 | AH36: =AC36+AC37+AD36+AD37 -> 0 | AI36: 35.087 | AJ36: =-35.087 -> -35.087 | AK36: =AI36+AJ36 -> 0 | AM36: =AK36-AL36 -> 0 | AN36: =AI36+AI37+AJ36+AJ37 -> 0 | AO36: 35.435 | AP36: =-35.435 -> -35.435 | AQ36: =AO36+AP36 -> 0 | AS36: =AQ36-AR36 -> 0 | AT36: =AO36+AO37+AP36+AP37 -> 0 | AU36: =E36+K36+Q36+W36+AC36+AI36+AO36 -> 139.872 | AV36: =F36+L36+R36+X36+AD36+AJ36+AP36 -> -139.872 | AW36: =AU36+AV36 -> 0 | AX36: =H36+N36+T36+Z36+AF36+AL36+AR36 -> 0 | AY36: =AW36-AX36 -> 0 | AZ36: =AX36/AW36 -> #DIV/0! | BA36: =AU36+AU37 -> 174.83 | BB36: =AV36+AV37 -> -174.83 | BC36: =BA36+BB36 -> 0 | BD36: =AX36+AX37 -> 0 | BE36: =BC36-BD36 -> 0 | BF36: =BD36/BC36 -> #DIV/0!
