Workbook

Sheet Resumen LTP
A2: Informe
A3: Resumen LTP 2013
A4: Desde el 10 de Agosto al 31 de diciembre 2013
C5: Periodo LMC (desde el 10 de febrero hasta el 9 de agosto del 2013) | G5: Periodo LTP ( desde el 10 de agosto hasta el 31 de diciembre de 2013
A6: Unidad de Pesquería | B6: Zona | C6: Cuota LMC según D.Ex 198 y sus modificaciones. | D6: Cesiones o traspasos | E6: Cuota final | F6: Desembarque (t) | G6: Cuota LTP (Remanente LMC R.Ex. Nº 2342 modificada por Res Nº2939) | H6: Arriendos u otro | I6: Incremento Jurel Res Nº 3241. Incremento anchoveta y Sardina española Res Nº 3365 | J6: Cuota Final | K6: Desembarque total (t) | L6: Aguas internacionales | M6: Saldo total (t) | N6: % LTP consumido 2013 | O6: % total consumido
A7: Anchoveta | B7: XV- I - II | C7: ='Pelagicos LMC y LTP '!C6+'Pelagicos LMC y LTP '!C7+'Pelagicos LMC y LTP '!C8+'Pelagicos LMC y LTP '!C9 -> 598733.2 | D7: =SUM('Pelagicos LMC y LTP '!D6:D9) -> 0 | E7: =C7+D7 -> 598733.2 | F7: =SUM('Pelagicos LMC y LTP '!F6:F9) -> 169072.55 | G7: =SUM('Pelagicos LMC y LTP '!G6:G9) -> 429660.65 | H7: =SUM('Pelagicos LMC y LTP '!I6:I9) -> -30004.259 | I7: ='Pelagicos LMC y LTP '!H6:H9 -> 2580.167 | J7: =SUM(G7:I7) -> 402236.56 | K7: =SUM('Pelagicos LMC y LTP '!K6:K9) -> 347952.48 | M7: =J7-K7 -> 54284.074 | N7: =K7/J7 -> 0.8650444 | O7: =(K7+F7)/(C7+D7+H7+P8) -> 0.90908867 | Q7: =F7+K7 -> 517025.03
A8: Anchoveta | B8: III - IV | C8: ='Pelagicos LMC y LTP '!C11+'Pelagicos LMC y LTP '!C12+'Pelagicos LMC y LTP '!C13+'Pelagicos LMC y LTP '!C14+'Pelagicos LMC y LTP '!C15+'Pelagicos LMC y LTP '!C16+'Pelagicos LMC y LTP '!C17+'Pelagicos LMC y LTP '!C18 -> 28393.001 | D8: =SUM('Pelagicos LMC y LTP '!D11:D18) -> -26086.515 | E8: =C8+D8 -> 2306.486 | F8: =SUM('Pelagicos LMC y LTP '!F11:F18) -> 0 | G8: =SUM('Pelagicos LMC y LTP '!G11:G18) -> 2306.486 | H8: =SUM('Pelagicos LMC y LTP '!I11:I18) -> 0 | I8: ='Pelagicos LMC y LTP '!H11+'Pelagicos LMC y LTP '!H12+'Pelagicos LMC y LTP '!H13+'Pelagicos LMC y LTP '!H14+'Pelagicos LMC y LTP '!H15+'Pelagicos LMC y LTP '!H16+'Pelagicos LMC y LTP '!H17+'Pelagicos LMC y LTP '!H18 -> 0 | J8: =SUM(G8:I8) -> 2306.486 | K8: =SUM('Pelagicos LMC y LTP '!K11:K18) -> 0 | M8: =J8-K8 -> 2306.486 | N8: =K8/J8 -> 0 | O8: =(K8+F8)/(C8+D8+H8+P9) -> 0 | Q8: =F8+K8 -> 0
A9: Anchoveta | B9: V - X | C9: ='Pelagicos LMC y LTP '!C20+'Pelagicos LMC y LTP '!C21+'Pelagicos LMC y LTP '!C22+'Pelagicos LMC y LTP '!C23+'Pelagicos LMC y LTP '!C24+'Pelagicos LMC y LTP '!C25+'Pelagicos LMC y LTP '!C26+'Pelagicos LMC y LTP '!C27+'Pelagicos LMC y LTP '!C28+'Pelagicos LMC y LTP '!C29+'Pelagicos LMC y LTP '!C30+'Pelagicos LMC y LTP '!C31+'Pelagicos LMC y LTP '!C32+'Pelagicos LMC y LTP '!C33+'Pelagicos LMC y LTP '!C34+'Pelagicos LMC y LTP '!C35+'Pelagicos LMC y LTP '!C36 -> 25527.998 | D9: =SUM('Pelagicos LMC y LTP '!D20:D36) -> -3083 | E9: =C9+D9 -> 22444.998 | F9: =SUM('Pelagicos LMC y LTP '!F20:F36) -> 1551.163 | G9: =SUM('Pelagicos LMC y LTP '!G20:G36) -> 20893.835 | H9: =SUM('Pelagicos LMC y LTP '!I20:I36) -> 1761.389 | J9: =SUM(G9:I9) -> 22655.224 | K9: =SUM('Pelagicos LMC y LTP '!K20:K36) -> 4222.392 | M9: =J9-K9 -> 18432.832 | N9: =K9/J9 -> 0.18637609 | O9: =(K9+F9)/(C9+D9+H9+P10) -> 0.2385137 | Q9: =F9+K9 -> 5773.555
A10: Camarón nailon | B10: II-VIII | C10: ='Crustaceos LMC y LTP'!C6+'Crustaceos LMC y LTP'!C7+'Crustaceos LMC y LTP'!C8+'Crustaceos LMC y LTP'!C9+'Crustaceos LMC y LTP'!C10+'Crustaceos LMC y LTP'!C11+'Crustaceos LMC y LTP'!C12+'Crustaceos LMC y LTP'!C13+'Crustaceos LMC y LTP'!C14+'Crustaceos LMC y LTP'!C15+'Crustaceos LMC y LTP'!C16+'Crustaceos LMC y LTP'!C17+'Crustaceos LMC y LTP'!C18+'Crustaceos LMC y LTP'!C19+'Crustaceos LMC y LTP'!C20+'Crustaceos LMC y LTP'!C21+'Crustaceos LMC y LTP'!C22+'Crustaceos LMC y LTP'!C23 -> 3051.7 | D10: =SUM('Crustaceos LMC y LTP'!D6:D22) -> 0 | E10: =C10+D10 -> 3051.7 | F10: =SUM('Crustaceos LMC y LTP'!F6:F23) -> 1420.984 | G10: =SUM('Crustaceos LMC y LTP'!G7:G23) -> 1630.716 | H10: =SUM('Crustaceos LMC y LTP'!H7:H23) -> -6.532 | J10: =SUM(G10:I10) -> 1624.184 | K10: =SUM('Crustaceos LMC y LTP'!J7:J23) -> 1212.35 | M10: =J10-K10 -> 411.834 | N10: =K10/J10 -> 0.74643636 | O10: =(K10+F10)/(C10+D10+H10+P11) -> 0.8647582 | Q10: =F10+K10 -> 2633.334
A11: Congrio dorado | B11: NE F + H | C11: ='Demersales LMC y LTP '!C7+'Demersales LMC y LTP '!C8+'Demersales LMC y LTP '!C9+'Demersales LMC y LTP '!C10+'Demersales LMC y LTP '!C11 -> 542.601 | D11: =SUM('Demersales LMC y LTP '!D7:D11) -> 0 | E11: =C11+D11 -> 542.601 | F11: =SUM('Demersales LMC y LTP '!F7:F11) -> 46.949 | G11: =SUM('Demersales LMC y LTP '!G7:G11) -> 495.652 | H11: =SUM('Demersales LMC y LTP '!H7:H11) -> -8.8817842e-15 | J11: =SUM(G11:I11) -> 495.652 | K11: =SUM('Demersales LMC y LTP '!J7:J11) -> 455.38 | M11: =J11-K11 -> 40.272 | N11: =K11/J11 -> 0.91874945 | O11: =(K11+F11)/(C11+D11+H11+P12) -> 0.92577972 | Q11: =F11+K11 -> 502.329
A12: Congrio dorado | B12: SE | C12: ='Demersales LMC y LTP '!C13+'Demersales LMC y LTP '!C14+'Demersales LMC y LTP '!C15+'Demersales LMC y LTP '!C16+'Demersales LMC y LTP '!C17 -> 326.5 | D12: =SUM('Demersales LMC y LTP '!D13:D17) -> 0 | E12: =C12+D12 -> 326.5 | F12: =SUM('Demersales LMC y LTP '!F13:F17) -> 158.571 | G12: =SUM('Demersales LMC y LTP '!G13:G17) -> 167.929 | H12: =SUM('Demersales LMC y LTP '!H13:H17) -> 0.63 | J12: =SUM(G12:I12) -> 168.559 | K12: =SUM('Demersales LMC y LTP '!J13:J17) -> 95.173 | M12: =J12-K12 -> 73.386 | N12: =K12/J12 -> 0.56462722 | O12: =(K12+F12)/(C12+D12+H12+P13) -> 0.77566717 | Q12: =F12+K12 -> 253.744
A13: Jurel | B13: XV - I - II | C13: ='Pelagicos LMC y LTP '!C38+'Pelagicos LMC y LTP '!C39+'Pelagicos LMC y LTP '!C40+'Pelagicos LMC y LTP '!C41 -> 33953.904 | D13: =SUM('Pelagicos LMC y LTP '!D38:D41) -> -5646.628 | E13: =C13+D13 -> 28307.276 | F13: =SUM('Pelagicos LMC y LTP '!F38:F41) -> 15304.6 | G13: =SUM('Pelagicos LMC y LTP '!G38:G41) -> 13002.676 | H13: =SUM('Pelagicos LMC y LTP '!I38:I41) -> -6525 | I13: ='Pelagicos LMC y LTP '!H38+'Pelagicos LMC y LTP '!H39+'Pelagicos LMC y LTP '!H40+'Pelagicos LMC y LTP '!H41 -> 684.001 | J13: =SUM(G13:I13) -> 7161.677 | K13: =SUM('Pelagicos LMC y LTP '!K38:K41) -> 717.8 | M13: =J13-K13 -> 6443.877 | N13: =K13/J13 -> 0.10022792 | O13: =(K13+F13)/(C13+D13+H13+P14) -> 0.73557052 | Q13: =F13+K13 -> 16022.4
A14: Jurel | B14: III - IV | C14: ='Pelagicos LMC y LTP '!C43+'Pelagicos LMC y LTP '!C44+'Pelagicos LMC y LTP '!C45+'Pelagicos LMC y LTP '!C46+'Pelagicos LMC y LTP '!C47+'Pelagicos LMC y LTP '!C48+'Pelagicos LMC y LTP '!C49+'Pelagicos LMC y LTP '!C50+'Pelagicos LMC y LTP '!C51+'Pelagicos LMC y LTP '!C52+'Pelagicos LMC y LTP '!C53+'Pelagicos LMC y LTP '!C54+'Pelagicos LMC y LTP '!C55 -> 4921.498 | D14: =SUM('Pelagicos LMC y LTP '!D43:D55) -> 8231.924 | E14: =C14+D14 -> 13153.422 | F14: =SUM('Pelagicos LMC y LTP '!F43:F55) -> 12514.743 | G14: =SUM('Pelagicos LMC y LTP '!G43:G55) -> 638.679 | H14: =SUM('Pelagicos LMC y LTP '!I43:I55) -> -38.188 | I14: ='Pelagicos LMC y LTP '!H43+'Pelagicos LMC y LTP '!H44+'Pelagicos LMC y LTP '!H45+'Pelagicos LMC y LTP '!H46+'Pelagicos LMC y LTP '!H47+'Pelagicos LMC y LTP '!H48+'Pelagicos LMC y LTP '!H49+'Pelagicos LMC y LTP '!H50+'Pelagicos LMC y LTP '!H51+'Pelagicos LMC y LTP '!H52+'Pelagicos LMC y LTP '!H53+'Pelagicos LMC y LTP '!H54+'Pelagicos LMC y LTP '!H55 -> 144.002 | J14: =SUM(G14:I14) -> 744.493 | K14: =SUM('Pelagicos LMC y LTP '!K43:K55) -> 25.23 | L14: 38.5 | M14: =J14-K14 -> 719.263 | N14: =K14/J14 -> 0.033888834 | O14: =(K14+F14)/(C14+D14+H14+P15) -> 0.95613795 | Q14: =F14+K14 -> 12539.973
A15: Jurel | B15: V - IX | C15: =SUM('Pelagicos LMC y LTP '!C57:C78) -> 121428.2 | D15: =SUM('Pelagicos LMC y LTP '!D57:D78) -> 11816.128 | E15: =C15+D15 -> 133244.33 | F15: =SUM('Pelagicos LMC y LTP '!F57:F78) -> 126136.18 | G15: =SUM('Pelagicos LMC y LTP '!G57:G78) -> 7108.154 | H15: =SUM('Pelagicos LMC y LTP '!I57:I78) -> 7991.385 | I15: ='Pelagicos LMC y LTP '!H57+'Pelagicos LMC y LTP '!H58+'Pelagicos LMC y LTP '!H59+'Pelagicos LMC y LTP '!H60+'Pelagicos LMC y LTP '!H61+'Pelagicos LMC y LTP '!H62+'Pelagicos LMC y LTP '!H63+'Pelagicos LMC y LTP '!H64+'Pelagicos LMC y LTP '!H65+'Pelagicos LMC y LTP '!H66+'Pelagicos LMC y LTP '!H67+'Pelagicos LMC y LTP '!H68+'Pelagicos LMC y LTP '!H69+'Pelagicos LMC y LTP '!H70+'Pelagicos LMC y LTP '!H71+'Pelagicos LMC y LTP '!H72+'Pelagicos LMC y LTP '!H73+'Pelagicos LMC y LTP '!H74+'Pelagicos LMC y LTP '!H75+'Pelagicos LMC y LTP '!H76+'Pelagicos LMC y LTP '!H77+'Pelagicos LMC y LTP '!H78 -> 3090.003 | J15: =SUM(G15:I15) -> 18189.542 | K15: =SUM('Pelagicos LMC y LTP '!K57:K78) -> 9370.876 | L15: 700.336 | M15: =J15-K15 -> 8818.666 | N15: =K15/J15 -> 0.51517933 | O15: =(K15+F15)/(C15+D15+H15+P16) -> 0.95943899 | Q15: =F15+K15 -> 135507.05
A16: Jurel | B16: XIV - X | C16: =SUM('Pelagicos LMC y LTP '!C80:C101) -> 16994.588 | D16: =SUM('Pelagicos LMC y LTP '!D80:D101) -> -11314.415 | E16: =C16+D16 -> 5680.173 | F16: =SUM('Pelagicos LMC y LTP '!F80:F101) -> 4479.645 | G16: =SUM('Pelagicos LMC y LTP '!G80:G101) -> 1200.528 | H16: =SUM('Pelagicos LMC y LTP '!I80:I101) -> -999.497 | I16: ='Pelagicos LMC y LTP '!H80+'Pelagicos LMC y LTP '!H81+'Pelagicos LMC y LTP '!H82+'Pelagicos LMC y LTP '!H83+'Pelagicos LMC y LTP '!H84+'Pelagicos LMC y LTP '!H85+'Pelagicos LMC y LTP '!H86+'Pelagicos LMC y LTP '!H87+'Pelagicos LMC y LTP '!H88+'Pelagicos LMC y LTP '!H89+'Pelagicos LMC y LTP '!H90+'Pelagicos LMC y LTP '!H91+'Pelagicos LMC y LTP '!H92+'Pelagicos LMC y LTP '!H93+'Pelagicos LMC y LTP '!H94+'Pelagicos LMC y LTP '!H95+'Pelagicos LMC y LTP '!H96+'Pelagicos LMC y LTP '!H97+'Pelagicos LMC y LTP '!H98+'Pelagicos LMC y LTP '!H99+'Pelagicos LMC y LTP '!H100+'Pelagicos LMC y LTP '!H101 -> 433.001 | J16: =SUM(G16:I16) -> 634.032 | K16: =SUM('Pelagicos LMC y LTP '!K80:K101) -> 172.732 | L16: 4625.692 | M16: =J16-K16 -> 461.3 | N16: =K16/J16 -> 0.2724342 | O16: =(K16+F16)/(C16+D16+H16+P17) -> 0.99395408 | Q16: =F16+K16 -> 4652.377
A17: Langostino amarillo | B17: III-IV | C17: =SUM('Crustaceos LMC y LTP'!C26:C36) -> 1167.997 | D17: =SUM('Crustaceos LMC y LTP'!D26:D36) -> -60 | E17: =C17+D17 -> 1107.997 | F17: =SUM('Crustaceos LMC y LTP'!F26:F36) -> 728.272 | G17: =SUM('Crustaceos LMC y LTP'!G27:G36) -> 379.725 | H17: =SUM('Crustaceos LMC y LTP'!H27:H36) -> -85 | J17: =SUM(G17:I17) -> 294.725 | K17: =SUM('Crustaceos LMC y LTP'!J27:J36) -> 183.997 | M17: =J17-K17 -> 110.728 | N17: =K17/J17 -> 0.62430062 | O17: =(K17+F17)/(C17+D17+H17+P18) -> 0.89176117 | Q17: =F17+K17 -> 912.269
A18: Langostino colorado | B18: I -IV | C18: =SUM('Crustaceos LMC y LTP'!C38:C43) -> 1132.998 | D18: =SUM('Crustaceos LMC y LTP'!D38:D43) -> 0 | E18: =C18+D18 -> 1132.998 | F18: =SUM('Crustaceos LMC y LTP'!F38:F43) -> 551.798 | G18: =SUM('Crustaceos LMC y LTP'!G39:G43) -> 581.2 | H18: =SUM('Crustaceos LMC y LTP'!H39:H43) -> -16.5 | J18: =SUM(G18:I18) -> 564.7 | K18: =SUM('Crustaceos LMC y LTP'!J39:J43) -> 161.292 | M18: =J18-K18 -> 403.408 | N18: =K18/J18 -> 0.28562423 | O18: =(K18+F18)/(C18+D18+H18+P19) -> 0.63868453 | Q18: =F18+K18 -> 713.09
A19: Merluza común | B19: IV- 41º 28, 6 | C19: =SUM('Demersales LMC y LTP '!C62:C83) -> 20915.602 | D19: =SUM('Demersales LMC y LTP '!D62:D81) -> 0 | E19: =C19+D19 -> 20915.602 | F19: =SUM('Demersales LMC y LTP '!F62:F83) -> 12431.975 | G19: =SUM('Demersales LMC y LTP '!G62:G83) -> 8483.627 | H19: =SUM('Demersales LMC y LTP '!H62:H83) -> -0.3 | J19: =SUM(G19:I19) -> 8483.327 | K19: =SUM('Demersales LMC y LTP '!J62:J81) -> 7876.829 | M19: =J19-K19 -> 606.498 | N19: =K19/J19 -> 0.92850706 | O19: =(K19+F19)/(C19+D19+H19+P20) -> 0.97100219 | Q19: =F19+K19 -> 20308.804
A20: Merluza de cola | B20: V -X | C20: =SUM('Demersales LMC y LTP '!C36:C54) -> 34307.898 | D20: =SUM('Demersales LMC y LTP '!D36:D54) -> -3639.442 | E20: =C20+D20 -> 30668.456 | F20: =SUM('Demersales LMC y LTP '!F36:F54) -> 10342.455 | G20: =SUM('Demersales LMC y LTP '!G36:G54) -> 20326.001 | H20: =SUM('Demersales LMC y LTP '!H36:H54) -> 0 | J20: =SUM(G20:I20) -> 20326.001 | K20: =SUM('Demersales LMC y LTP '!J36:J54) -> 9596.677 | M20: =J20-K20 -> 10729.324 | N20: =K20/J20 -> 0.47213798 | O20: =(K20+F20)/(C20+D20+H20+P21) -> 0.65015115 | Q20: =F20+K20 -> 19939.132
A21: Merluza de cola | B21: XI -XII | C21: =SUM('Demersales LMC y LTP '!C56:C60) -> 23609.307 | D21: =SUM('Demersales LMC y LTP '!D56:D60) -> 5640.195 | E21: =C21+D21 -> 29249.502 | F21: =SUM('Demersales LMC y LTP '!F56:F60) -> 18723.427 | G21: =SUM('Demersales LMC y LTP '!G56:G60) -> 10526.075 | H21: =SUM('Demersales LMC y LTP '!H56:H60) -> 0 | J21: =SUM(G21:I21) -> 10526.075 | K21: =SUM('Demersales LMC y LTP '!J56:J60) -> 8751.183 | M21: =J21-K21 -> 1774.892 | N21: =K21/J21 -> 0.8313814 | O21: =(K21+F21)/(C21+D21+H21+P22) -> 0.9393189 | Q21: =F21+K21 -> 27474.61
A22: Merluza de tres aletas | B22: 41º28,6 - XII | C22: =SUM('Demersales LMC y LTP '!C31:C34) -> 24857.5 | D22: =SUM('Demersales LMC y LTP '!D31:D34) -> 0 | E22: =C22+D22 -> 24857.5 | F22: =SUM('Demersales LMC y LTP '!F31:F34) -> 951.784 | G22: =SUM('Demersales LMC y LTP '!G31:G34) -> 23905.716 | H22: =SUM('Demersales LMC y LTP '!H31:H34) -> 0 | J22: =SUM(G22:I22) -> 23905.716 | K22: =SUM('Demersales LMC y LTP '!J31:J34) -> 14351.542 | M22: =J22-K22 -> 9554.174 | N22: =K22/J22 -> 0.60033935 | O22: =(K22+F22)/(C22+D22+H22+P23) -> 0.6156422 | Q22: =F22+K22 -> 15303.326
A23: Merluza del sur | B23: NE F + H | C23: =SUM('Demersales LMC y LTP '!C19:C23) -> 4616.001 | D23: =SUM('Demersales LMC y LTP '!D19:D23) -> 2857.707 | E23: =C23+D23 -> 7473.708 | F23: =SUM('Demersales LMC y LTP '!F19:F23) -> 4867.654 | G23: =SUM('Demersales LMC y LTP '!G19:G23) -> 2606.054 | H23: =SUM('Demersales LMC y LTP '!H19:H23) -> 3279.02 | J23: =SUM(G23:I23) -> 5885.074 | K23: =SUM('Demersales LMC y LTP '!J19:J23) -> 5182.378 | M23: =J23-K23 -> 702.696 | N23: =K23/J23 -> 0.88059691 | O23: =(K23+F23)/(C23+D23+H23+P24) -> 0.93464951 | Q23: =F23+K23 -> 10050.032
A24: Merluza del sur | B24: SE | C24: =SUM('Demersales LMC y LTP '!C25:C29) -> 3217.999 | D24: =SUM('Demersales LMC y LTP '!D25:D29) -> 276.344 | E24: =C24+D24 -> 3494.343 | F24: =SUM('Demersales LMC y LTP '!F25:F29) -> 2071.849 | G24: =SUM('Demersales LMC y LTP '!G25:G29) -> 1422.494 | H24: =SUM('Demersales LMC y LTP '!H25:H29) -> -439.261 | J24: =SUM(G24:I24) -> 983.233 | K24: =SUM('Demersales LMC y LTP '!J25:J29) -> 880.853 | M24: =J24-K24 -> 102.38 | N24: =K24/J24 -> 0.89587412 | O24: =(K24+F24)/(C24+D24+H24+P25) -> 0.96648862 | Q24: =F24+K24 -> 2952.702
A25: Sardina común | B25: V -X | C25: =SUM('Pelagicos LMC y LTP '!C103:C119) -> 128462 | D25: =SUM('Pelagicos LMC y LTP '!D103:D119) -> -31116.99 | E25: =C25+D25 -> 97345.01 | F25: =SUM('Pelagicos LMC y LTP '!F103:F119) -> 14099.565 | G25: =SUM('Pelagicos LMC y LTP '!G103:G119) -> 83245.445 | H25: =SUM('Pelagicos LMC y LTP '!I103:I119) -> 15800.702 | J25: =SUM(G25:I25) -> 99046.147 | K25: =SUM('Pelagicos LMC y LTP '!K103:K119) -> 40173.117 | M25: =J25-K25 -> 58873.03 | N25: =K25/J25 -> 0.4056 | O25: =(K25+F25)/(C25+D25+H25+P26) -> 0.47967069 | Q25: =F25+K25 -> 54272.682
A26: Sardina española | B26: XV- I - II | C26: =SUM('Pelagicos LMC y LTP '!C121:C124) -> 1439.999 | D26: =SUM('Pelagicos LMC y LTP '!D121:D124) -> 0 | E26: =C26+D26 -> 1439.999 | F26: =SUM('Pelagicos LMC y LTP '!F121:F124) -> 0 | G26: =SUM('Pelagicos LMC y LTP '!G121:G124) -> 1439.999 | H26: =SUM('Pelagicos LMC y LTP '!I121:I124) -> 0 | I26: ='Pelagicos LMC y LTP '!H121+'Pelagicos LMC y LTP '!H122+'Pelagicos LMC y LTP '!H123+'Pelagicos LMC y LTP '!H124 -> 30.001 | J26: =SUM(G26:I26) -> 1470 | K26: =SUM('Pelagicos LMC y LTP '!K121:K124) -> 0 | M26: =J26-K26 -> 1470 | N26: =K26/J26 -> 0 | O26: =(K26+F26)/(C26+D26+H26+P27) -> 0 | Q26: =F26+K26 -> 0
A27: Sardina española | B27: III - IV | C27: =SUM('Pelagicos LMC y LTP '!C126:C133) -> 625 | D27: =SUM('Pelagicos LMC y LTP '!D126:D133) -> -159.596 | E27: =C27+D27 -> 465.404 | F27: =SUM('Pelagicos LMC y LTP '!F126:F133) -> 0 | G27: =SUM('Pelagicos LMC y LTP '!G126:G133) -> 465.404 | H27: =SUM('Pelagicos LMC y LTP '!I126:I133) -> 0 | J27: =SUM(G27:I27) -> 465.404 | K27: =SUM('Pelagicos LMC y LTP '!K126:K133) -> 0 | M27: =J27-K27 -> 465.404 | N27: =K27/J27 -> 0 | O27: =(K27+F27)/(C27+D27+H27+P28) -> 0 | Q27: =F27+K27 -> 0
A29: Nota: desembarque aguas internacionales Jurel desde III a X regiones, esta incorporado en la columna de desembarque total, solo se incorpora el dato para tenerlo de referencia

Sheet Pelagicos LMC y LTP 
B1: CONTROL DE CUOTAS RECURSOS PELÁGICOS, LMC Y LTP, AL 31 DE DICIEMBRE DE 2013
G3: Control cuota LTP (desde el 10 de agosto hasta el 31 de diciembre del 2013)
C4: Periodo LMC (desde el 10 de febrero hasta el 9 de agosto del 2013) | G4: Cuota (Ton) | K4: Operación
A5: Unidad de pesquería | B5: Armador | C5: Cuota LMC según D.Ex 198 y sus modificaciones. | D5: Cesiones o traspasos | E5: Cuota final | F5: Desembarque (t) | G5: Cuota LTP (Remanente LMC R.Ex. Nº 2342 modificada por Res Nº2939) | H5: Incremento Jurel Res Nº 3241. Incremento anchoveta y Sardina española Res Nº 3365 | I5: Arriendos u otro | J5: Cuota final | K5: Desembarque (t) | L5: Saldo (t) | M5: % consumido
A6: Anchoveta XV - I - II | B6: Arica Seafood Producer S.A. | C6: 4259.268 | D6: 0 | E6: =C6+D6 -> 4259.268 | F6: 0 | G6: =E6-F6 -> 4259.268 | H6: 92.992 | I6: -4.259 | J6: =G6+I6+H6 -> 4348.001 | K6: 0 | L6: =J6-K6 -> 4348.001 | M6: =K6/J6 -> 0
B7: Camanchaca S.A. Cia. Pesq. | C7: 118178.68 | D7: 0 | E7: =C7+D7 -> 118178.68 | F7: 39549.71 | G7: =E7-F7 -> 78628.967 | H7: 2580.167 | I7: 0 | J7: =G7+I7+H7 -> 81209.134 | K7: 77506.242 | L7: =J7-K7 -> 3702.892 | M7: =K7/J7 -> 0.95440301
B8: Corpesca S.A. | C8: 442560.59 | D8: 0 | E8: =C8+D8 -> 442560.59 | F8: 120349.1 | G8: =E8-F8 -> 322211.49 | H8: 9662.32 | I8: -30000 | J8: =G8+I8+H8 -> 301873.81 | K8: 269587.31 | L8: =J8-K8 -> 32286.5 | M8: =K8/J8 -> 0.89304637
B9: Orizón S.A | C9: 33734.664 | D9: 0 | E9: =C9+D9 -> 33734.664 | F9: 9173.741 | G9: =E9-F9 -> 24560.923 | H9: 736.521 | I9: 0 | J9: =G9+I9+H9 -> 25297.444 | K9: 858.93 | L9: =J9-K9 -> 24438.514 | M9: =K9/J9 -> 0.033953233
A11: Anchoveta III - IV | B11: Alimentos Marinos S.A., | C11: 995.322 | D11: 0 | E11: =C11+D11 -> 995.322 | F11: 0 | G11: =E11-F11 -> 995.322 | H11: 0 | I11: 0 | J11: =G11+I11+H11 -> 995.322 | K11: 0 | L11: =J11-K11 -> 995.322 | M11: =K11/J11 -> 0
B12: Bahia Caldera S.A. Pesq. | C12: 7890.792 | D12: -7890.792 | E12: =C12+D12 -> 0 | F12: 0 | G12: =E12-F12 -> 0 | H12: 0 | I12: 0 | J12: =G12+I12+H12 -> 0 | K12: 0 | L12: =J12-K12 -> 0 | M12: =K12/J12 -> #DIV/0!
B13: Blumar S.A. | C13: 6165.475 | D13: -6165.475 | E13: =C13+D13 -> 0 | F13: 0 | G13: =E13-F13 -> 0 | H13: 0 | I13: 0 | J13: =G13+I13+H13 -> 0 | K13: 0 | L13: =J13-K13 -> 0 | M13: =K13/J13 -> #DIV/0!
B14: Camanchaca S.A. Cia. Pesq. | C14: 901.018 | D14: 0 | E14: =C14+D14 -> 901.018 | F14: 0 | G14: =E14-F14 -> 901.018 | H14: 0 | I14: 0 | J14: =G14+I14+H14 -> 901.018 | K14: 0 | L14: =J14-K14 -> 901.018 | M14: =K14/J14 -> 0
B15: Corpesca S.A., | C15: 3280.494 | D15: -3280.494 | E15: =C15+D15 -> 0 | F15: 0 | G15: =E15-F15 -> 0 | H15: 0 | I15: 0 | J15: =G15+I15+H15 -> 0 | K15: 0 | L15: =J15-K15 -> 0 | M15: =K15/J15 -> #DIV/0!
B16: Inversiones Pesqueras S.A. | C16: 324.413 | D16: 0 | E16: =C16+D16 -> 324.413 | F16: 0 | G16: =E16-F16 -> 324.413 | H16: 0 | I16: 0 | J16: =G16+I16+H16 -> 324.413 | K16: 0 | L16: =J16-K16 -> 324.413 | M16: =K16/J16 -> 0
B17: Orizón S.A. | C17: 8749.754 | D17: -8749.754 | E17: =C17+D17 -> 0 | F17: 0 | G17: =E17-F17 -> 0 | H17: 0 | I17: 0 | J17: =G17+I17+H17 -> 0 | K17: 0 | L17: =J17-K17 -> 0 | M17: =K17/J17 -> #DIV/0!
B18: Camanchaca Pesca Sur S.A. | C18: 85.733 | D18: 0 | E18: =C18+D18 -> 85.733 | F18: 0 | G18: =E18-F18 -> 85.733 | H18: 0 | I18: 0 | J18: =G18+I18+H18 -> 85.733 | K18: 0 | L18: =J18-K18 -> 85.733 | M18: =K18/J18 -> 0
A20: Anchoveta V-X | B20: Alimentos Marinos S.A. | C20: 4751.238 | D20: -801.727 | E20: =C20+D20 -> 3949.511 | F20: 0 | G20: =E20-F20 -> 3949.511 | H20: 0 | I20: 0 | J20: =G20+I20+H20 -> 3949.511 | K20: 859.905 | L20: =J20-K20 -> 3089.606 | M20: =K20/J20 -> 0.21772442
B21: Berta Elena Ltda. Soc. Pesq. | C21: 89.447 | D21: 0 | E21: =C21+D21 -> 89.447 | F21: 59.749 | G21: =E21-F21 -> 29.698 | H21: 0 | I21: =-29.698 -> -29.698 | J21: =G21+I21+H21 -> 0 | K21: 0 | L21: =J21-K21 -> 0 | M21: =K21/J21 -> #DIV/0!
B22: Blumar S.A. | C22: 6002.154 | D22: -1300 | E22: =C22+D22 -> 4702.154 | F22: 439.06 | G22: =E22-F22 -> 4263.094 | H22: 0 | I22: 0 | J22: =G22+I22+H22 -> 4263.094 | K22: 426.227 | L22: =J22-K22 -> 3836.867 | M22: =K22/J22 -> 0.099980671
B23: Camanchaca Pesca Sur S.A. | C23: 3951.992 | D23: -600 | E23: =C23+D23 -> 3351.992 | F23: 43.644 | G23: =E23-F23 -> 3308.348 | H23: 0 | I23: 0 | J23: =G23+I23+H23 -> 3308.348 | K23: 409.845 | L23: =J23-K23 -> 2898.503 | M23: =K23/J23 -> 0.12388207
B24: Camanchaca S.A. Cia. Pesq. | C24: 220.746 | D24: 0 | E24: =C24+D24 -> 220.746 | F24: 0 | G24: =E24-F24 -> 220.746 | H24: 0 | I24: 0 | J24: =G24+I24+H24 -> 220.746 | K24: 0 | L24: =J24-K24 -> 220.746 | M24: =K24/J24 -> 0
B25: Centro Sur S.A. Pesq. | C25: 541.988 | D25: -30.159 | E25: =C25+D25 -> 511.829 | F25: 0 | G25: =E25-F25 -> 511.829 | H25: 0 | I25: =97.375 -> 97.375 | J25: =G25+I25+H25 -> 609.204 | K25: 0 | L25: =J25-K25 -> 609.204 | M25: =K25/J25 -> 0
B26: Foodcorp S.A. | C26: 1015.023 | D26: -171.276 | E26: =C26+D26 -> 843.747 | F26: 0 | G26: =E26-F26 -> 843.747 | H26: 0 | I26: 0 | J26: =G26+I26+H26 -> 843.747 | K26: 317.867 | L26: =J26-K26 -> 525.88 | M26: =K26/J26 -> 0.3767326
B27: Genmar Ltda. Soc. Pesq. | C27: 7.738 | D27: 0 | E27: =C27+D27 -> 7.738 | F27: 0 | G27: =E27-F27 -> 7.738 | H27: 0 | I27: 0 | J27: =G27+I27+H27 -> 7.738 | K27: 0 | L27: =J27-K27 -> 7.738 | M27: =K27/J27 -> 0
B28: Inostroza Concha Pelantaro | C28: 23.959 | D28: 0 | E28: =C28+D28 -> 23.959 | F28: 16.004 | G28: =E28-F28 -> 7.955 | H28: 0 | I28: =-7.955 -> -7.955 | J28: =G28+I28+H28 -> 0 | K28: 0 | L28: =J28-K28 -> 0 | M28: =K28/J28 -> #DIV/0!
B29: Inversiones Pesqueras S.A. | C29: 397.223 | D29: -22.103 | E29: =C29+D29 -> 375.12 | F29: 0 | G29: =E29-F29 -> 375.12 | H29: 0 | I29: 0 | J29: =G29+I29+H29 -> 375.12 | K29: 158.673 | L29: =J29-K29 -> 216.447 | M29: =K29/J29 -> 0.42299264
B30: Isla Quihua S.A. Pesq. | C30: 211.527 | D30: -35.693 | E30: =C30+D30 -> 175.834 | F30: 0 | G30: =E30-F30 -> 175.834 | H30: 0 | I30: 0 | J30: =G30+I30+H30 -> 175.834 | K30: 0 | L30: =J30-K30 -> 175.834 | M30: =K30/J30 -> 0
B31: Landes S.A. Soc. Pesq. | C31: 1787.509 | D31: 0 | E31: =C31+D31 -> 1787.509 | F31: 591.28 | G31: =E31-F31 -> 1196.229 | H31: 0 | I31: 1391.389 | J31: =G31+I31+H31 -> 2587.618 | K31: 1025.503 | L31: =J31-K31 -> 1562.115 | M31: =K31/J31 -> 0.39631159
B32: Lota Protein S.A. | C32: 295.166 | D32: 0 | E32: =C32+D32 -> 295.166 | F32: 197.166 | G32: =E32-F32 -> 98 | H32: 0 | I32: =200+170+7.955+29.698 -> 407.653 | J32: =G32+I32+H32 -> 505.653 | K32: 220.644 | L32: =J32-K32 -> 285.009 | M32: =K32/J32 -> 0.43635458
B33: Mar profundo S.A. Soc. Pesq. | C33: 105.28 | D33: -17.765 | E33: =C33+D33 -> 87.515 | F33: 0 | G33: =E33-F33 -> 87.515 | H33: 0 | I33: 0 | J33: =G33+I33+H33 -> 87.515 | K33: 0 | L33: =J33-K33 -> 87.515 | M33: =K33/J33 -> 0
B34: Orizón S.A. | C34: 5439.927 | D34: 0 | E34: =C34+D34 -> 5439.927 | F34: 204.26 | G34: =E34-F34 -> 5235.667 | H34: 0 | I34: 0 | J34: =G34+I34+H34 -> 5235.667 | K34: 803.728 | L34: =J34-K34 -> 4431.939 | M34: =K34/J34 -> 0.15351014
B35: Salmoalimentos S.A. | C35: 103.113 | D35: -5.738 | E35: =C35+D35 -> 97.375 | F35: 0 | G35: =E35-F35 -> 97.375 | H35: 0 | I35: =-97.375 -> -97.375 | J35: =G35+I35+H35 -> 0 | K35: 0 | L35: =J35-K35 -> 0 | M35: =K35/J35 -> #DIV/0!
B36: San Antonio S.A. Pesq. | C36: 583.968 | D36: -98.539 | E36: =C36+D36 -> 485.429 | F36: 0 | G36: =E36-F36 -> 485.429 | H36: 0 | I36: 0 | J36: =G36+I36+H36 -> 485.429 | K36: 0 | L36: =J36-K36 -> 485.429 | M36: =K36/J36 -> 0
A38: Jurel XV-I-II | B38: Arica Seafood Producer S.A. | C38: 140.067 | D38: 0 | E38: =C38+D38 -> 140.067 | F38: 0 | G38: =E38-F38 -> 140.067 | H38: 2.822 | I38: 0 | J38: =G38+I38+H38 -> 142.889 | K38: 0 | L38: =J38-K38 -> 142.889 | M38: =K38/J38 -> 0
B39: Camanchaca S.A. Cia. Pesq. | C39: 5934.147 | D39: -2296.56 | E39: =C39+D39 -> 3637.587 | F39: 2361.46 | G39: =E39-F39 -> 1276.127 | H39: 119.543 | I39: =-1525 -> -1525 | J39: =G39+I39+H39 -> -129.33 | K39: 11.377 | L39: =J39-K39 -> -140.707 | M39: 1.101
B40: Corpesca S.A. | C40: 25786.779 | D40: -3098.58 | E40: =C40+D40 -> 22688.199 | F40: 11971.507 | G40: =E40-F40 -> 10716.692 | H40: 519.474 | I40: =-2000-3000 -> -5000 | J40: =G40+I40+H40 -> 6236.166 | K40: 706.423 | L40: =J40-K40 -> 5529.743 | M40: =K40/J40 -> 0.11327841
B41: Orizón S.A. | C41: 2092.911 | D41: -251.488 | E41: =C41+D41 -> 1841.423 | F41: 971.633 | G41: =E41-F41 -> 869.79 | H41: 42.162 | I41: 0 | J41: =G41+I41+H41 -> 911.952 | K41: 0 | L41: =J41-K41 -> 911.952 | M41: =K41/J41 -> 0
A43: Jurel III - IV | B43: Alimentos Marinos S.A. | C43: 411.729 | D43: 0 | E43: =C43+D43 -> 411.729 | F43: 241.602 | G43: =E43-F43 -> 170.127 | H43: 12.047 | I43: 0 | J43: =G43+I43+H43 -> 182.174 | K43: 0 | L43: =J43-K43 -> 182.174 | M43: =K43/J43 -> 0
B44: Arica Seafood Producer S.A | C44: 1.497 | D44: 0 | E44: =C44+D44 -> 1.497 | F44: 0 | G44: =E44-F44 -> 1.497 | H44: 0.044 | I44: 0 | J44: =G44+I44+H44 -> 1.541 | K44: 0 | L44: =J44-K44 -> 1.541 | M44: =K44/J44 -> 0
B45: Bahia Caldera S.A. Pesq. | C45: 21.816 | D45: 0 | E45: =C45+D45 -> 21.816 | F45: 17.041 | G45: =E45-F45 -> 4.775 | H45: 0.638 | I45: 0 | J45: =G45+I45+H45 -> 5.413 | K45: 0 | L45: =J45-K45 -> 5.413 | M45: =K45/J45 -> 0
...

Sheet Crustaceos  LMC y LTP
B1: CONTROL DE CUOTAS RECURSOS CRUSTÁCEOS, LMC Y LTP, AL 31 DE DICIEMBRE DE 2013
G3: Control cuota LTP (desde el 10 de agosto hasta el 31 de diciembre del 2013)
C4: Periodo LMC (desde el 10 de febrero hasta el 9 de agosto del 2013) | G4: Cuota (Ton) | J4: Operación
A5: Unidad de pesquería | B5: Armador o Asociatividad | C5: Cuota LMC según D.Ex 198 y sus modificaciones. | D5: Cesiones o traspasos | E5: Cuota final | F5: Desembarque (t) | G5: Cuota LTP (Remanente LMC R.Ex. Nº 2342) | H5: Arriendos u otro | I5: Cuota final | J5: Desembarque (t) | K5: Saldo (t) | L5: % consumido
A6: Camarón nailon II-VIII | B6: Amancay Ltda. Pesq. | C6: 111.865 | D6: -111.865 | E6: =C6+D6 -> 0 | F6: 0 | G6: =E6-F6 -> 0
B7: Antarctic Seafood S.A. | C7: 533.266 | D7: 0 | E7: =C7+D7 -> 533.266 | F7: 212.874 | G7: =E7-F7 -> 320.392 | H7: 0 | I7: =G7+H7 -> 320.392 | J7: 318.667 | K7: =I7-J7 -> 1.725 | L7: =J7/I7 -> 0.99461597
B8: Baycic Baycic Maria | C8: 203.345 | D8: 0 | E8: =C8+D8 -> 203.345 | F8: 129.018 | G8: =E8-F8 -> 74.327 | H8: =-61.262 -> -61.262 | I8: =G8+H8 -> 13.065 | J8: 13.065 | K8: =I8-J8 -> 0 | L8: =J8/I8 -> 1
B9: Blumar S.A. | C9: 65.28 | D9: 0 | E9: =C9+D9 -> 65.28 | F9: 0 | G9: =E9-F9 -> 65.28 | H9: 0 | I9: =G9+H9 -> 65.28 | J9: 0.295 | K9: =I9-J9 -> 64.985 | L9: =J9/I9 -> 0.0045189951
B10: Bracpesca S.A | C10: 523.648 | D10: 0 | E10: =C10+D10 -> 523.648 | F10: 151.577 | G10: =E10-F10 -> 372.071 | H10: 0 | I10: =G10+H10 -> 372.071 | J10: 189.032 | K10: =I10-J10 -> 183.039 | L10: =J10/I10 -> 0.50805357
B11: Camanchaca Pesca Sur S.A. | C11: 2.717 | D11: 0 | E11: =C11+D11 -> 2.717 | F11: 0 | G11: =E11-F11 -> 2.717 | H11: 0 | I11: =G11+H11 -> 2.717 | J11: 0 | K11: =I11-J11 -> 2.717 | L11: =J11/I11 -> 0
B12: Concepción Ltda. Pesq. | C12: 16.85 | D12: 0 | E12: =C12+D12 -> 16.85 | F12: 10.318 | G12: =E12-F12 -> 6.532 | H12: =-6.532 -> -6.532 | I12: =G12+H12 -> 0 | J12: 0 | K12: =I12-J12 -> 0 | L12: =J12/I12 -> #DIV/0!
B13: Costa Brava Ltda. Pesq. | C13: 74.349 | D13: 0 | E13: =C13+D13 -> 74.349 | F13: 42.691 | G13: =E13-F13 -> 31.658 | H13: =-31.658 -> -31.658 | I13: =G13+H13 -> 0 | J13: 0 | K13: =I13-J13 -> 0 | L13: =J13/I13 -> #DIV/0!
B14: Gonzalez Rivera Marcelino | C14: 5.564 | D14: -5.564 | E14: =C14+D14 -> 0 | F14: 0 | G14: =E14-F14 -> 0
B15: Landes S.A. Soc. Pesq. | C15: 0 | D15: 5.564 | E15: =C15+D15 -> 5.564 | F15: 0 | G15: =E15-F15 -> 5.564 | H15: 0 | I15: =G15+H15 -> 5.564 | J15: 0 | K15: =I15-J15 -> 5.564 | L15: =J15/I15 -> 0
B16: Grimar S.A. Pesq. | C16: 10.192 | D16: 0 | E16: =C16+D16 -> 10.192 | F16: 5.852 | G16: =E16-F16 -> 4.34 | H16: 0 | I16: =G16+H16 -> 4.34 | J16: 0 | K16: =I16-J16 -> 4.34 | L16: =J16/I16 -> 0
B17: Isladamas S.A. Pesq. | C17: 470.617 | D17: 0 | E17: =C17+D17 -> 470.617 | F17: 270.227 | G17: =E17-F17 -> 200.39 | H17: 0 | I17: =G17+H17 -> 200.39 | J17: 149.841 | K17: =I17-J17 -> 50.549 | L17: =J17/I17 -> 0.74774689
B18: Morozin Baycic Maria Ana | C18: 116.63 | D18: -116.63 | E18: =C18+D18 -> 0 | F18: 0 | G18: =E18-F18 -> 0 | H18: 0 | I18: =G18+H18 -> 0 | J18: 0 | K18: =I18-J18 -> 0 | L18: =J18/I18 -> #DIV/0!
B19: Morozin Yurecic Mario | C19: 263.045 | D19: 0 | E19: =C19+D19 -> 263.045 | F19: 165.847 | G19: =E19-F19 -> 97.198 | H19: 0 | I19: =G19+H19 -> 97.198 | J19: 96.229 | K19: =I19-J19 -> 0.969 | L19: =J19/I19 -> 0.99003066
B20: Quintero Ltda. Soc. Pesq. | C20: 62.973 | D20: 116.63 | E20: =C20+D20 -> 179.603 | F20: 57.501 | G20: =E20-F20 -> 122.102 | H20: 0 | I20: =G20+H20 -> 122.102 | J20: 121.163 | K20: =I20-J20 -> 0.939 | L20: =J20/I20 -> 0.99230971
B21: Quintero S.A., Pesquera | C21: 458.838 | D21: 0 | E21: =C21+D21 -> 458.838 | F21: 292.303 | G21: =E21-F21 -> 166.535 | H21: =61.262 -> 61.262 | I21: =G21+H21 -> 227.797 | J21: 225.318 | K21: =I21-J21 -> 2.479 | L21: =J21/I21 -> 0.9891175
B22: Rubio y Mauad Ltda. | C22: 0 | D22: 111.865 | E22: =C22+D22 -> 111.865 | F22: 6.683 | G22: =E22-F22 -> 105.182 | H22: 0 | I22: =G22+H22 -> 105.182 | J22: 10.777 | K22: =I22-J22 -> 94.405 | L22: =J22/I22 -> 0.1024605
B23: Sunrise S.A. Pesq. | C23: 132.521 | D23: 0 | E23: =C23+D23 -> 132.521 | F23: 76.093 | G23: =E23-F23 -> 56.428 | H23: =31.658 -> 31.658 | I23: =G23+H23 -> 88.086 | J23: 87.963 | K23: =I23-J23 -> 0.123 | L23: =J23/I23 -> 0.99860364
B24: Antonio Cruz Cordova Nakouzi | C24: 0 | D24: 0 | E24: =C24+D24 -> 0 | F24: 0 | G24: =E24-F24 -> 0 | H24: =6.532 -> 6.532 | I24: =G24+H24 -> 6.532 | J24: 6.037 | K24: =I24-J24 -> 0.495 | L24: =J24/I24 -> 0.92421923
A26: Langostino amarillo III-IV | B26: Amancay Ltda. Pesq. | C26: 61.066 | D26: -61.066 | E26: =C26+D26 -> 0 | F26: 0 | G26: =E26-F26 -> 0 | H26: 0
B27: Antarctic Seafood S.A | C27: 456.866 | D27: 0 | E27: =C27+D27 -> 456.866 | F27: 294.88 | G27: =E27-F27 -> 161.986 | H27: 0 | I27: =G27+H27 -> 161.986 | J27: 97.414 | K27: =I27-J27 -> 64.572 | L27: =J27/I27 -> 0.60137296
B28: Baycic Baycic Maria | C28: 32.958 | D28: 11.872 | E28: =C28+D28 -> 44.83 | F28: 35.456 | G28: =E28-F28 -> 9.374 | H28: =-9.374 -> -9.374 | I28: =G28+H28 -> 0 | J28: 0 | K28: =I28-J28 -> 0 | L28: =J28/I28 -> #DIV/0!
B29: Bracpesca S.A | C29: 475.754 | D29: -60 | E29: =C29+D29 -> 415.754 | F29: 308.04 | G29: =E29-F29 -> 107.714 | H29: -45 | I29: =G29+H29 -> 62.714 | J29: 58.415 | K29: =I29-J29 -> 4.299 | L29: =J29/I29 -> 0.93145071
B30: Grimar S.A. Pesq. | C30: 0.238 | D30: 0 | E30: =C30+D30 -> 0.238 | F30: 0.114 | G30: =E30-F30 -> 0.124 | H30: 0 | I30: =G30+H30 -> 0.124 | J30: 0 | K30: =I30-J30 -> 0.124 | L30: =J30/I30 -> 0
B31: Isladamas S.A. Pesq. | C31: 60.283 | D31: 0 | E31: =C31+D31 -> 60.283 | F31: 28.9 | G31: =E31-F31 -> 31.383 | H31: 0 | I31: =G31+H31 -> 31.383 | J31: 11.286 | K31: =I31-J31 -> 20.097 | L31: =J31/I31 -> 0.35962145
B32: Morozin Baycic Maria Ana | C32: 8.194 | D32: -8.194 | E32: =C32+D32 -> 0 | F32: 0 | G32: =E32-F32 -> 0 | H32: 0 | I32: =G32+H32 -> 0 | J32: 0 | K32: =I32-J32 -> 0 | L32: =J32/I32 -> #DIV/0!
B33: Mororzin Yurecic Mario | C33: 3.678 | D33: -3.678 | E33: =C33+D33 -> 0 | F33: 0 | G33: =E33-F33 -> 0 | H33: 0 | I33: =G33+H33 -> 0 | J33: 0 | K33: =I33-J33 -> 0 | L33: =J33/I33 -> #DIV/0!
B34: Quinteros S.A. Pesq. | C34: 39.194 | D34: 0 | E34: =C34+D34 -> 39.194 | F34: 30.476 | G34: =E34-F34 -> 8.718 | H34: =9.374 -> 9.374 | I34: =G34+H34 -> 18.092 | J34: 16.882 | K34: =I34-J34 -> 1.21 | L34: =J34/I34 -> 0.93311961
B35: Rubio y Mauad Ltda. | C35: 0 | D35: 61.066 | E35: =C35+D35 -> 61.066 | F35: 16.136 | G35: =E35-F35 -> 44.93 | H35: -40 | I35: =G35+H35 -> 4.93 | J35: 0 | K35: =I35-J35 -> 4.93 | L35: =J35/I35 -> 0
B36: Sunrise S.A. Pesq. | C36: 29.766 | D36: 0 | E36: =C36+D36 -> 29.766 | F36: 14.27 | G36: =E36-F36 -> 15.496 | H36: 0 | I36: =G36+H36 -> 15.496 | J36: 0 | K36: =I36-J36 -> 15.496 | L36: =J36/I36 -> 0
A38: Langostino colorado XV- IV | B38: Amancay Ltda. Pesq. | C38: 24.085 | D38: -24.085 | E38: =C38+D38 -> 0 | F38: 0 | G38: =E38-F38 -> 0
B39: Antarctic Seafood S.A | C39: 286.202 | D39: 0 | E39: =C39+D39 -> 286.202 | F39: 255.074 | G39: =E39-F39 -> 31.128 | H39: 0 | I39: =G39+H39 -> 31.128 | J39: 19.207 | K39: =I39-J39 -> 11.921 | L39: =J39/I39 -> 0.6170329
B40: Bracpesca S.A | C40: 572.926 | D40: 0 | E40: =C40+D40 -> 572.926 | F40: 242.975 | G40: =E40-F40 -> 329.951 | H40: 0 | I40: =G40+H40 -> 329.951 | J40: 135.909 | K40: =I40-J40 -> 194.042 | L40: =J40/I40 -> 0.41190662
B41: Isladamas S.A. | C41: 130.499 | D41: 0 | E41: =C41+D41 -> 130.499 | F41: 25.229 | G41: =E41-F41 -> 105.27 | H41: 0 | I41: =G41+H41 -> 105.27 | J41: 6.176 | K41: =I41-J41 -> 99.094 | L41: =J41/I41 -> 0.058668187
B42: Rubio y Mauad Ltda. | C42: 0 | D42: 24.085 | E42: =C42+D42 -> 24.085 | F42: 5.459 | G42: =E42-F42 -> 18.626 | H42: -16.5 | I42: =G42+H42 -> 2.126 | J42: 0 | K42: =I42-J42 -> 2.126 | L42: =J42/I42 -> 0
B43: Sunrise S.A. Pesq. | C43: 119.286 | D43: 0 | E43: =C43+D43 -> 119.286 | F43: 23.061 | G43: =E43-F43 -> 96.225 | H43: 0 | I43: =G43+H43 -> 96.225 | J43: 0 | K43: =I43-J43 -> 96.225 | L43: =J43/I43 -> 0

Sheet Demersales LMC y LTP 
B2: CONTROL DE CUOTAS RECURSOS DEMERSALES, LMC Y LTP, AL 31 DE DICIEMBRE DE 2013
G4: Control cuota LTP (desde el 10 de agosto hasta el 31 de diciembre del 2013)
C5: Periodo LMC (desde el 10 de febrero hasta el 9 de agosto del 2013) | G5: Cuota (Ton) | J5: Operación
A6: Unidad de pesquería | B6: Armador o Asociatividad | C6: Cuota LMC según D.Ex 198 y sus modificaciones. | D6: Cesiones o traspasos | E6: Cuota final | F6: Desembarque (t) | G6: Cuota LTP (Remanente LMC R.Ex. Nº 2342 modificada por Res Nº2939) | H6: Arriendos, cesión, traspaso u otro. | I6: Cuota final | J6: Desembarque (t) | K6: Saldo (t) | L6: % consumido
A7: Congrio dorado NE H/F (41º28,6 LS hasta 47º) | B7: Emdepes S.A. | C7: 1.402 | D7: 0 | E7: =C7+D7 -> 1.402 | F7: 0.046 | G7: =E7-F7 -> 1.356 | H7: =0.577 -> 0.577 | I7: =G7+H7 -> 1.933 | J7: 0 | K7: =I7-J7 -> 1.933 | L7: =J7/I7 -> 0
B8: Pesca Chile S.A. | C8: 377.617 | D8: 0 | E8: =C8+D8 -> 377.617 | F8: 12.477 | G8: =E8-F8 -> 365.14 | H8: =6.73-125.472-0.577 -> -119.319 | I8: =G8+H8 -> 245.821 | J8: 279.211 | K8: =I8-J8 -> -33.39 | L8: =J8/I8 -> 1.1358305
B9: Pesca Cisne S.A | C9: 32.828 | D9: 0 | E9: =C9+D9 -> 32.828 | F9: 30.106 | G9: =E9-F9 -> 2.722 | H9: 0 | I9: =G9+H9 -> 2.722 | J9: 0 | K9: =I9-J9 -> 2.722 | L9: =J9/I9 -> 0
B10: Grimar S.A.Pesq. | C10: 19.817 | D10: 0 | E10: =C10+D10 -> 19.817 | F10: 0.655 | G10: =E10-F10 -> 19.162 | H10: =15+125.472-20 -> 120.472 | I10: =G10+H10 -> 139.634 | J10: 71.477 | K10: =I10-J10 -> 68.157 | L10: =J10/I10 -> 0.51188822
B11: Sur Austral S.A. Pesq. | C11: 110.937 | D11: 0 | E11: =C11+D11 -> 110.937 | F11: 3.665 | G11: =E11-F11 -> 107.272 | H11: =-15-6.73+20 -> -1.73 | I11: =G11+H11 -> 105.542 | J11: 104.692 | K11: =I11-J11 -> 0.85 | L11: =J11/I11 -> 0.99194633
A13: Congrio dorado SE (47º hasta 57º) | B13: Emdepes S.A., | C13: 56.698 | D13: 0 | E13: =C13+D13 -> 56.698 | F13: 30.388 | G13: =E13-F13 -> 26.31 | H13: =-11.294-1.88 -> -13.174 | I13: =G13+H13 -> 13.136 | J13: 11.915 | K13: =I13-J13 -> 1.221 | L13: =J13/I13 -> 0.90704933
B14: Grimar S.A.Pesq. | C14: 0.169 | D14: 0 | E14: =C14+D14 -> 0.169 | F14: 0.091 | G14: =E14-F14 -> 0.078 | H14: 0 | I14: =G14+H14 -> 0.078 | J14: 0 | K14: =I14-J14 -> 0.078 | L14: =J14/I14 -> 0
B15: Pesca Chile S.A. | C15: 194.139 | D15: 0 | E15: =C15+D15 -> 194.139 | F15: 104.052 | G15: =E15-F15 -> 90.087 | H15: =11.924 -> 11.924 | I15: =G15+H15 -> 102.011 | J15: 83.258 | K15: =I15-J15 -> 18.753 | L15: =J15/I15 -> 0.81616688
B16: Pesca Cisne S.A | C16: 75.411 | D16: 0 | E16: =C16+D16 -> 75.411 | F16: 23.996 | G16: =E16-F16 -> 51.415 | H16: 0 | I16: =G16+H16 -> 51.415 | J16: 0 | K16: =I16-J16 -> 51.415 | L16: =J16/I16 -> 0
B17: Sur Austral S.A. Pesq. | C17: 0.083 | D17: 0 | E17: =C17+D17 -> 0.083 | F17: 0.044 | G17: =E17-F17 -> 0.039 | H17: =1.88 -> 1.88 | I17: =G17+H17 -> 1.919 | J17: 0 | K17: =I17-J17 -> 1.919 | L17: =J17/I17 -> 0
A19: Merluza del sur NE F/H (41º28,6 LS al 47º LS) | B19: Emdepes S.A. | C19: 643.45 | D19: 411.739 | E19: =C19+D19 -> 1055.189 | F19: 680.057 | G19: =E19-F19 -> 375.132 | H19: =190+230.941+102.503+302.402+6-14.779 -> 817.067 | I19: =G19+H19 -> 1192.199 | J19: 1188.354 | K19: =I19-J19 -> 3.845 | L19: =J19/I19 -> 0.99677487
B20: Pesca Chile S.A. | C20: 2151.985 | D20: 1377.041 | E20: =C20+D20 -> 3529.026 | F20: 2274.415 | G20: =E20-F20 -> 1254.611 | H20: =661+63.033+173.207-447.227-302.402+216.886-76 -> 288.497 | I20: =G20+H20 -> 1543.108 | J20: 1136.126 | K20: =I20-J20 -> 406.982 | L20: =J20/I20 -> 0.73625825
B21: Pesca Cisne S.A. | C21: 150.089 | D21: 0 | E21: =C21+D21 -> 150.089 | F21: 147.669 | G21: =E21-F21 -> 2.42 | H21: 0 | I21: =G21+H21 -> 2.42 | J21: 0 | K21: =I21-J21 -> 2.42 | L21: =J21/I21 -> 0
B22: Grimar S.A. Pesq. | C22: 130.32 | D22: 83.391 | E22: =C22+D22 -> 213.711 | F22: 137.734 | G22: =E22-F22 -> 75.977 | H22: =296.276+200+162+115+156.344+68.104+44.387-6+100 -> 1136.111 | I22: =G22+H22 -> 1212.088 | J22: 1193.248 | K22: =I22-J22 -> 18.84 | L22: =J22/I22 -> 0.98445657
B23: Sur Austral S.A. Pesq. | C23: 1540.157 | D23: 985.536 | E23: =C23+D23 -> 2525.693 | F23: 1627.779 | G23: =E23-F23 -> 897.914 | H23: =564.832-162-102.503-115+447.227-216.886+292.505+78.399+110+100.464+90.307+48.041+1.959-100 -> 1037.345 | I23: =G23+H23 -> 1935.259 | J23: 1664.65 | K23: =I23-J23 -> 270.609 | L23: =J23/I23 -> 0.8601691
A25: Merluza Del Sur SE Fabrica (47º LS al 57º LS) | B25: Emdepes S.A. | C25: 935.351 | D25: 96.099 | E25: =C25+D25 -> 1031.45 | F25: 583.115 | G25: =E25-F25 -> 448.335 | H25: =-131.313-48.041+14.779 -> -164.575 | I25: =G25+H25 -> 283.76 | J25: 283.091 | K25: =I25-J25 -> 0.669 | L25: =J25/I25 -> 0.99764237
B26: Grimar S.A. Pesq. | C26: 1.806 | D26: 0.185 | E26: =C26+D26 -> 1.991 | F26: 1.126 | G26: =E26-F26 -> 0.865 | H26: 0 | I26: =G26+H26 -> 0.865 | J26: 0 | K26: =I26-J26 -> 0.865 | L26: =J26/I26 -> 0
B27: Pesca Chile S.A. | C27: 1740.736 | D27: 178.678 | E27: =C27+D27 -> 1919.414 | F27: 1085.207 | G27: =E27-F27 -> 834.207 | H27: =-661+277.219-173.207+131.313+76.948+76 -> -272.727 | I27: =G27+H27 -> 561.48 | J27: 597.762 | K27: =I27-J27 -> -36.282 | L27: =J27/I27 -> 1.0646185
B28: Pesca Cisne S.A. | C28: 526.642 | D28: 0 | E28: =C28+D28 -> 526.642 | F28: 394.007 | G28: =E28-F28 -> 132.635 | H28: 0 | I28: =G28+H28 -> 132.635 | J28: 0 | K28: =I28-J28 -> 132.635 | L28: =J28/I28 -> 0
B29: Sur Austral S.A. Pesq. | C29: 13.464 | D29: 1.382 | E29: =C29+D29 -> 14.846 | F29: 8.394 | G29: =E29-F29 -> 6.452 | H29: =48.041-48.041-1.959 -> -1.959 | I29: =G29+H29 -> 4.493 | J29: 0 | K29: =I29-J29 -> 4.493 | L29: =J29/I29 -> 0
A31: Merluza tres aletas NE/SE (41º28,6 LS hasta 57º) | B31: Emdepes S.A. | C31: 24829.297 | D31: 0 | E31: =C31+D31 -> 24829.297 | F31: 950.704 | G31: =E31-F31 -> 23878.593 | H31: =-985.721-2129.26-1500 -> -4614.981 | I31: =G31+H31 -> 19263.612 | J31: 12671.772 | K31: =I31-J31 -> 6591.84 | L31: =J31/I31 -> 0.65780872
B32: Grimar S.A. Pesq. | C32: 0.731 | D32: 0 | E32: =C32+D32 -> 0.731 | F32: 0.028 | G32: =E32-F32 -> 0.703 | H32: =1500 -> 1500 | I32: =G32+H32 -> 1500.703 | J32: 605.015 | K32: =I32-J32 -> 895.688 | L32: =J32/I32 -> 0.40315439
B33: Pesca Chile S.A. | C33: 25.474 | D33: 0 | E33: =C33+D33 -> 25.474 | F33: 0.975 | G33: =E33-F33 -> 24.499 | H33: =2129.26 -> 2129.26 | I33: =G33+H33 -> 2153.759 | J33: 296.287 | K33: =I33-J33 -> 1857.472 | L33: =J33/I33 -> 0.13756739
B34: Sur Austral S.A. Pesq. | C34: 1.998 | D34: 0 | E34: =C34+D34 -> 1.998 | F34: 0.077 | G34: =E34-F34 -> 1.921 | H34: =985.721 -> 985.721 | I34: =G34+H34 -> 987.642 | J34: 778.468 | K34: =I34-J34 -> 209.174 | L34: =J34/I34 -> 0.78820868
A36: Merluza cola V-X | B36: Alimentos Marinos S.A. | C36: 4430.669 | D36: 0 | E36: =C36+D36 -> 4430.669 | F36: 1831.372 | G36: =E36-F36 -> 2599.297 | H36: =-2599.297 -> -2599.297 | I36: =G36+H36 -> 0 | J36: 0 | K36: =I36-J36 -> 0 | L36: =J36/I36 -> #DIV/0!
B37: Bio Bio S.A.Pesq. | C37: 374.821 | D37: -134.54 | E37: =C37+D37 -> 240.281 | F37: 71.555 | G37: =E37-F37 -> 168.726 | H37: =2559.239-480.671 -> 2078.568 | I37: =G37+H37 -> 2247.294 | J37: 1101.365 | K37: =I37-J37 -> 1145.929 | L37: =J37/I37 -> 0.49008496
B38: Blumar S.A. | C38: 7702.93 | D38: -2764.934 | E38: =C38+D38 -> 4937.996 | F38: 1470.522 | G38: =E38-F38 -> 3467.474 | H38: =480.671 -> 480.671 | I38: =G38+H38 -> 3948.145 | J38: 1516.019 | K38: =I38-J38 -> 2432.126 | L38: =J38/I38 -> 0.3839826
B39: Camanchaca S.A. CIA. Pesq. | C39: 23.11 | D39: 0 | E39: =C39+D39 -> 23.11 | F39: 0 | G39: =E39-F39 -> 23.11 | H39: 0 | I39: =G39+H39 -> 23.11 | J39: 0 | K39: =I39-J39 -> 23.11 | L39: =J39/I39 -> 0
B40: Centro Sur S.A. Pesq. | C40: 1139.42 | D40: 0 | E40: =C40+D40 -> 1139.42 | F40: 0 | G40: =E40-F40 -> 1139.42 | H40: 0 | I40: =G40+H40 -> 1139.42 | J40: 0 | K40: =I40-J40 -> 1139.42 | L40: =J40/I40 -> 0
B41: Foodcorp S.A. | C41: 3743.874 | D41: 1209.646 | E41: =C41+D41 -> 4953.52 | F41: 3794.373 | G41: =E41-F41 -> 1159.147 | H41: =-450-187.194-522 -> -1159.194 | I41: =G41+H41 -> -0.047 | J41: 0 | K41: =I41-J41 -> -0.047 | L41: =J41/I41 -> 0
B42: Grimar S.A.Pesq. | C42: 129.759 | D42: 41.925 | E42: =C42+D42 -> 171.684 | F42: 131.509 | G42: =E42-F42 -> 40.175 | H42: =450 -> 450 | I42: =G42+H42 -> 490.175 | J42: 494.291 | K42: =I42-J42 -> -4.116 | L42: =J42/I42 -> 1.008397
B43: Inostroza Concha Pelantaro. | C43: 10.365 | D43: 0 | E43: =C43+D43 -> 10.365 | F43: 0 | G43: =E43-F43 -> 10.365 | H43: =-10.365 -> -10.365 | I43: =G43+H43 -> 0 | J43: 0 | K43: =I43-J43 -> 0 | L43: =J43/I43 -> #DIV/0!
B44: Inversiones Pesqueras S.A. | C44: 182.951 | D44: 0 | E44: =C44+D44 -> 182.951 | F44: 0 | G44: =E44-F44 -> 182.951 | H44: 0 | I44: =G44+H44 -> 182.951 | J44: 0 | K44: =I44-J44 -> 182.951 | L44: =J44/I44 -> 0
B45: Isla Quihua S.A. Pesq. | C45: 324.646 | D45: 0 | E45: =C45+D45 -> 324.646 | F45: 134.189 | G45: =E45-F45 -> 190.457 | H45: =187.194+2599.297+143.714+53.733 -> 2983.938 | I45: =G45+H45 -> 3174.395 | J45: 3171.071 | K45: =I45-J45 -> 3.324 | L45: =J45/I45 -> 0.99895287
B46: Landes S.A. Pesq. | C46: 1618.495 | D46: 0 | E46: =C46+D46 -> 1618.495 | F46: 0 | G46: =E46-F46 -> 1618.495 | H46: 0 | I46: =G46+H46 -> 1618.495 | J46: 0 | K46: =I46-J46 -> 1618.495 | L46: =J46/I46 -> 0
B47: Lota Protein S.A. | C47: 1014.125 | D47: 0 | E47: =C47+D47 -> 1014.125 | F47: 0 | G47: =E47-F47 -> 1014.125 | H47: =10.365 -> 10.365 | I47: =G47+H47 -> 1024.49 | J47: 0 | K47: =I47-J47 -> 1024.49 | L47: =J47/I47 -> 0
...

Sheet Pescas de Investigación
C2: Al 31 de diciembre de 2013
B4: Resolución Nº 1526/2013: Pesca de Investigación vigente entre el 27.06.13 y 30.11.13
B5: Zona | C5: Imputa a reserva de Inv. | D5: Cuota (ton) | E5: Desembarque (ton) | F5: Saldo | H5: Embarcaciones autorizadas
A6: Langostino amarillo | B6: III-IV | C6: D.Ex. Nº 1336/12 | D6: 30 | E6: 20.125 | F6: =D6-E6 -> 9.875 | H6: Don Jose Miguel
B7: V-VIII | C7: D.Ex. Nº 1189/12 | D7: 45 | E7: 44.899 | F7: =D7-E7 -> 0.101 | H7: Foche
A8: Langostino colorado | B8: II-IV | C8: D.Ex. Nº 1336/12 | D8: 30 | E8: 19.5 | F8: =D8-E8 -> 10.5 | H8: Amancay I
B9: V-VIII | C9: D.Ex. Nº 1188/12 | D9: 50 | E9: 49.887 | F9: =D9-E9 -> 0.113 | H9: Isla Orcas
A10: Merluza Común | B10: IV-VIII | C10: D.Ex. Nº 1336/12 | D10: 15 | E10: 0.283 | F10: =D10-E10 -> 14.717
A11: Camaron nailón | B11: II-VIII | C11: D.Ex. Nº 1336/12 | D11: 15 | E11: 10.51 | F11: =D11-E11 -> 4.49
B14: Resolución Nº 2254/2013: Pesca de Investigación vigente entre el 19.08.13 y 31.08.13
B15: Zona | C15: Imputa a reserva de Inv. | D15: Cuota (ton) | E15: Desembarque (ton) | F15: Saldo | H15: Embarcaciones autorizadas
A16: Bacalao de profundidad | B16: 47º LS-XII | C16: D.Ex. Nº 1237/12 | D16: 30 | E16: 9.629 | F16: =D16-E16 -> 20.371 | H16: Globalpesca II
B21: Resolución Nº 2582/2013: Pesca de Investigación vigente entre el 08.10.13 y 31.12.13
B22: Zona | C22: Imputa a reserva de Inv. | D22: Cuota (ton) | E22: Desembarque (ton) | F22: Saldo | H22: Embarcaciones autorizadas | I22: Caracter
A23: Langostino amarillo | B23: III-IV | C23: D.Ex. Nº 195/13 | D23: 10 | E23: 16.545 | F23: =D23-E23 -> -6.545 | H23: Don Jose Miguel | I23: Titular
B24: V-VIII | C24: D.Ex. Nº 1189/12 | D24: 15 | E24: 16.29 | F24: =D24-E24 -> -1.29 | H24: Foche | I24: Suplente
A25: Langostino colorado | B25: II-IV | C25: D.Ex. Nº 195/13 | D25: 10 | E25: 0.307 | F25: =D25-E25 -> 9.693 | H25: Amancay I | I25: Suplente
B26: V-VIII | C26: D.Ex. Nº 1188/12 | D26: 25 | E26: 13.276 | F26: =D26-E26 -> 11.724 | H26: Isla Orcas | I26: Titular
A27: Merluza Común | B27: IV-VIII | C27: D.Ex. Nº 195/13 | D27: 10 | E27: 0.029 | F27: =D27-E27 -> 9.971
A28: Camaron nailón | B28: II-VIII | C28: D.Ex. Nº 195/13 | D28: 80 | E28: 61.071 | F28: =D28-E28 -> 18.929

Sheet REsumen consumo cuotas
A3: Unidad de Pesquería | B3: Zona | C3: Cuota Global (D.Ex Nº 195) y sus modificaciones (D.Ex. Nº 427, Nº 579, Nº 846, Nº 1198 y Nº 1058 | D3: Cesiones o traspasos periodo LMC | E3: Arriendos u otro, periodo LTP | F3: Cuota Final | G3: Desembarques Industriales entre el 1 y el 31 de enero de 2013 | H3: Desembarques Industriales entre el 10 de febrero y el 31 de diciembre de 2013 | I3: % Consumido de la cuota global sin considerar periodo entre el 1 y el 9 de febrero | J3: Desembarques entre el 1 y el 9 de febrero | K3: % Consumido de la cuota global considerando desembarques industriales de todo el 2013
A4: Anchoveta | B4: XV- I - II | C4: 668624 | D4: 0 | E4: -30004.259 | F4: =C4+D4+E4 -> 638619.74 | G4: 56818.8 | H4: 517025.03 | I4: =(G4+H4)/F4 -> 0.89856889 | J4: 12241.451 | K4: =(G4+H4+J4)/F4 -> 0.9177375 | L4: √ | M4: =F4+F5+F6 -> 665132.61 | N4: =G4+G5+G6+H4+H5+H6+J4+J5+J6 -> 591858.84 | O4: =M4-N4 -> 73273.776 | P4: =N4/M4 -> 0.88983584
A5: Anchoveta | B5: III - IV | C5: 28393 | D5: -26086.515 | E5: 0 | F5: =C5+D5+E5 -> 2306.485 | G5: 0 | H5: 0 | I5: =(G5+H5)/F5 -> 0 | J5: 0 | K5: =(G5+H5+J5)/F5 -> 0 | L5: √
A6: Anchoveta | B6: V - X | C6: 25528 | D6: -3083 | E6: 1761.389 | F6: =C6+D6+E6 -> 24206.389 | G6: 0 | H6: 5773.555 | I6: =(G6+H6)/F6 -> 0.23851368 | J6: 0 | K6: =(G6+H6+J6)/F6 -> 0.23851368 | L6: √
A7: Camarón nailon | B7: II-VIII | C7: 3725 | D7: 0 | E7: -6.532 | F7: =C7+D7+E7 -> 3718.468 | G7: 632.34 | H7: 2633.334 | I7: =(G7+H7)/F7 -> 0.87823103 | J7: 137.235 | K7: =(G7+H7+J7)/F7 -> 0.91513736 | L7: √
A8: Congrio dorado | B8: NE F + H | C8: 554 | D8: 0 | E8: 0 | F8: =C8+D8+E8 -> 554 | G8: 11.4 | H8: 502.329 | I8: =(G8+H8)/F8 -> 0.92730866 | J8: 0 | K8: =(G8+H8+J8)/F8 -> 0.92730866 | L8: √ | M8: =F8+F9 -> 881.13 | N8: =G8+G9+H8+H9+J8+J9 -> 767.473 | O8: =M8-N8 -> 113.657 | P8: =N8/M8 -> 0.87100995
A9: Congrio dorado | B9: SE | C9: 326.5 | D9: 0 | E9: 0.63 | F9: =C9+D9+E9 -> 327.13 | G9: 0 | H9: 253.744 | I9: =(G9+H9)/F9 -> 0.77566717 | J9: 0 | K9: =(G9+H9+J9)/F9 -> 0.77566717 | L9: √
A10: Jurel | B10: XV - I - II | C10: 34825 | D10: -5646.628 | E10: -6525 | F10: =C10+D10+E10 -> 22653.372 | G10: 187.1 | H10: 16022.4 | I10: =(G10+H10)/F10 -> 0.71554469 | J10: 27.273 | K10: =(G10+H10+J10)/F10 -> 0.71674861 | L10: √ | M10: =F10+F11+F12+F13 -> 224338.71 | N10: =G10+G11+G12+G13+H10+H11+H12+H13+J10+J11+J12+J13 -> 218641.17 | O10: =M10-N10 -> 5697.544 | P10: =N10/M10 -> 0.97460294 | Q10: =F10+F11+F12+F13 -> 224338.71 | R10: =G10+G11+G12+G13+H10+H11+H12+H13+J10+J11+J12+J13 -> 218641.17 | S10: =R10/Q10 -> 0.97460294
A11: Jurel | B11: III - IV | C11: 7322 | D11: 8231.924 | E11: -38.188 | F11: =C11+D11+E11 -> 15515.736 | G11: 2256.5 | H11: 12539.973 | I11: =(G11+H11)/F11 -> 0.953643 | J11: 0 | K11: =(G11+H11+J11)/F11 -> 0.953643 | L11: √
A12: Jurel | B12: V - IX | C12: 156707 | D12: 11816.128 | E12: 7991.385 | F12: =C12+D12+E12 -> 176514.51 | G12: 32188.8 | H12: 135507.05 | I12: =(G12+H12)/F12 -> 0.95004002 | J12: 10223.589 | K12: =(G12+H12+J12)/F12 -> 1.0079593 | L12: √
A13: Jurel | B13: XIV - X | C13: 21969 | D13: -11314.415 | E13: -999.497 | F13: =C13+D13+E13 -> 9655.088 | G13: 4538.5 | H13: 4652.377 | I13: =(G13+H13)/F13 -> 0.95192058 | J13: 497.602 | K13: =(G13+H13+J13)/F13 -> 1.0034584 | L13: √
A14: Langostino amarillo | B14: III-IV | C14: 1182 | D14: -60 | E14: -85 | F14: =C14+D14+E14 -> 1037 | G14: 0 | H14: 912.269 | I14: =(G14+H14)/F14 -> 0.87971938 | J14: 0 | K14: =(G14+H14+J14)/F14 -> 0.87971938 | L14: √
A15: Langostino colorado | B15: I -IV | C15: 1154 | D15: 0 | E15: -16.5 | F15: =C15+D15+E15 -> 1137.5 | G15: 0 | H15: 713.09 | I15: =(G15+H15)/F15 -> 0.62689231 | J15: 0 | K15: =(G15+H15+J15)/F15 -> 0.62689231 | L15: √
A16: Merluza común | B16: IV- 41º 28, 6 | C16: 23540 | D16: 0 | E16: -0.3 | F16: =C16+D16+E16 -> 23539.7 | G16: 2624.4 | H16: 20308.804 | I16: =(G16+H16)/F16 -> 0.97423519 | J16: 557.422 | K16: =(G16+H16+J16)/F16 -> 0.99791527 | L16: √
A17: Merluza de cola | B17: V -X | C17: 35400 | D17: -3639.442 | E17: 0 | F17: =C17+D17+E17 -> 31760.558 | G17: 1092.108 | H17: 19939.132 | I17: =(G17+H17)/F17 -> 0.66218106 | J17: 625.403 | K17: =(G17+H17+J17)/F17 -> 0.68187225 | L17: √ | M17: =F17+F18 -> 61010.86 | N17: =G17+G18+H17+H18+J17+J18 -> 49132.056 | O17: =M17-N17 -> 11878.804 | P17: =N17/M17 -> 0.80530017
A18: Merluza de cola | B18: XI -XII | C18: 23610.107 | D18: 5640.195 | E18: 0 | F18: =C18+D18+E18 -> 29250.302 | G18: 0.803 | H18: 27474.61 | I18: =(G18+H18)/F18 -> 0.93932066 | J18: 0 | K18: =(G18+H18+J18)/F18 -> 0.93932066 | L18: √
A19: Merluza de tres aletas | B19: 41º28,6 - XII | C19: 24857.5 | D19: 0 | E19: 0 | F19: =C19+D19+E19 -> 24857.5 | G19: 0 | H19: 15303.326 | I19: =(G19+H19)/F19 -> 0.6156422 | J19: 0 | K19: =(G19+H19+J19)/F19 -> 0.6156422 | L19: √
A20: Merluza del sur | B20: NE F + H | C20: 5046 | D20: 2857.707 | E20: 3279.02 | F20: =C20+D20+E20 -> 11182.727 | G20: 430 | H20: 10050.032 | I20: =(G20+H20)/F20 -> 0.93716246 | J20: 90.187 | K20: =(G20+H20+J20)/F20 -> 0.94522731 | L20: √ | M20: =F20+F21 -> 14237.81 | N20: =G20+G21+H20+H21+J20+J21 -> 13522.921 | O20: =M20-N20 -> 714.889 | P20: =N20/M20 -> 0.9497894
A21: Merluza del sur | B21: SE | C21: 3218 | D21: 276.344 | E21: -439.261 | F21: =C21+D21+E21 -> 3055.083 | G21: 0 | H21: 2952.702 | I21: =(G21+H21)/F21 -> 0.96648831 | J21: 0 | K21: =(G21+H21+J21)/F21 -> 0.96648831 | L21: √
A22: Sardina común | B22: V -X | C22: 128462 | D22: -31116.99 | E22: 15800.702 | F22: =C22+D22+E22 -> 113145.71 | G22: 0 | H22: 54272.682 | I22: =(G22+H22)/F22 -> 0.47967069 | J22: 0 | K22: =(G22+H22+J22)/F22 -> 0.47967069 | L22: √
A23: Sardina española | B23: XV- I - II | C23: 1470 | D23: 0 | E23: 0 | F23: =C23+D23+E23 -> 1470 | G23: 0 | H23: 0 | I23: =(G23+H23)/F23 -> 0 | J23: 0 | K23: =(G23+H23+J23)/F23 -> 0 | L23: √
A24: Sardina española | B24: III - IV | C24: 625 | D24: -159.596 | E24: 0 | F24: =C24+D24+E24 -> 465.404 | G24: 0 | H24: 0 | I24: =(G24+H24)/F24 -> 0 | J24: 0 | K24: =(G24+H24+J24)/F24 -> 0 | L24: √
D26: =+D20+E20 -> 6136.727 | I26: =+(G20+H20+J20) -> 10570.219
D27: =+D21+E21 -> -162.917 | I27: =+(G21+H21+J21) -> 2952.702

Sheet Hoja1
E5: 598733.2 | F5: 0 | G5: 169072.55
E6: 28393.001 | F6: -26086.515 | G6: 0
E7: 25527.998 | F7: -3083 | G7: 1551.163
E8: 3051.7 | F8: 0 | G8: 1420.984
E9: 542.601 | F9: 0 | G9: 46.949
E10: 326.5 | F10: 0 | G10: 158.571
E11: 33953.904 | F11: -5646.628 | G11: 15304.6
E12: 4921.498 | F12: 8231.924 | G12: 12514.743
E13: 121428.2 | F13: 11816.128 | G13: 126136.18
E14: 16994.588 | F14: -11314.415 | G14: 4479.645
E15: 1167.997 | F15: -60 | G15: 728.272
E16: 1132.998 | F16: 0 | G16: 551.798
... E25: 625 | F25: -159.596 | G25: 0
