Workbook

Sheet Resumen LTP
A2: Informe
A3: Resumen LTP 2014
A4: Al 31 de Diciembre de 2014
A5: Unidad de Pesquería | B5: Zona | C5: Cuota LTP D.Ex Nº 3789 | D5: Arriendos u otro | E5: Cuota Final | F5: Desembarque total (t) | G5: Aguas internacionales | H5: Saldo total (t) | I5: % consumido 2014
A6: Anchoveta | B6: XV- I - II | C6: =SUM('Pelagicos LTP '!E6:E13) -> 622449 | D6: =SUM('Pelagicos LTP '!F6:F13) -> -34427.978 | E6: =C6+D6 -> 588021.02 | F6: =SUM('Pelagicos LTP '!H6:H13) -> 582421.98 | H6: =E6-F6 -> 5599.04 | I6: =F6/E6 -> 0.99047816
A7: Anchoveta | B7: III - IV | C7: =SUM('Pelagicos LTP '!E16:E35) -> 25787.999 | D7: =SUM('Pelagicos LTP '!F16:F35) -> -12328.369 | E7: =C7+D7 -> 13459.63 | F7: =SUM('Pelagicos LTP '!H16:H35) -> 855.235 | H7: =E7-F7 -> 12604.395 | I7: =F7/E7 -> 0.063540752
A8: Anchoveta | B8: V - X | C8: =SUM('Pelagicos LTP '!E38:E91) -> 9091 | D8: =SUM('Pelagicos LTP '!F38:F91) -> -3909.1671 | E8: =C8+D8 -> 5181.8329 | F8: =SUM('Pelagicos LTP '!H38:H91) -> 3714.964 | H8: =E8-F8 -> 1466.8689 | I8: =F8/E8 -> 0.71692084
A9: Camarón nailon | B9: II-VIII | C9: =SUM('Crustaceos LTP'!AU6:AU49) -> 3656.047 | D9: =SUM('Crustaceos LTP'!AV6:AV49,'Crustaceos LTP'!AW6:AW49) -> 29.91324 | E9: =C9+D9 -> 3685.9602 | F9: =SUM('Crustaceos LTP'!AY6:AY49) -> 3457.254 | H9: =E9-F9 -> 228.70624 | I9: =F9/E9 -> 0.93795206
A10: Congrio dorado | B10: NE F + H | C10: =SUM('Demersales LTP '!E7:E18) -> 371 | D10: =SUM('Demersales LTP '!F7:F18) -> -1.2434498e-14 | E10: =C10+D10 -> 371 | F10: =SUM('Demersales LTP '!H7:H18) -> 142.107 | H10: =E10-F10 -> 228.893 | I10: =F10/E10 -> 0.38303774
A11: Congrio dorado | B11: SE | C11: =SUM('Demersales LTP '!E20:E31) -> 132 | D11: =SUM('Demersales LTP '!F20:F31) -> 0 | E11: =C11+D11 -> 132 | F11: =SUM('Demersales LTP '!H20:H31) -> 112.515 | H11: =E11-F11 -> 19.485 | I11: =F11/E11 -> 0.85238636
A12: Jurel | B12: XV - I - II | C12: =SUM('Pelagicos LTP '!E94:E101) -> 40541.004 | D12: =SUM('Pelagicos LTP '!F94:F101) -> -20087.134 | E12: =C12+D12 -> 20453.87 | F12: =SUM('Pelagicos LTP '!H94:H101) -> 16609.319 | H12: =E12-F12 -> 3844.551 | I12: =F12/E12 -> 0.81203797
A13: Jurel | B13: III - IV | C13: =SUM('Pelagicos LTP '!E104:E133) -> 8566.999 | D13: =SUM('Pelagicos LTP '!F104:F133) -> -2133.466 | E13: =C13+D13 -> 6433.533 | F13: =SUM('Pelagicos LTP '!H104:H133) -> 5818.638 | G13: 1131.25 | H13: =E13-F13 -> 614.895 | I13: =F13/E13 -> 0.90442343
A14: Jurel | B14: V - IX | C14: =SUM('Pelagicos LTP '!E136:E199) -> 183371 | D14: =SUM('Pelagicos LTP '!F136:F199) -> 31218.147 | E14: =C14+D14 -> 214589.15 | F14: =SUM('Pelagicos LTP '!H136:H199) -> 203757.62 | G14: 2008.341 | H14: =E14-F14 -> 10831.53 | I14: =F14/E14 -> 0.94952433
A15: Jurel | B15: XIV - X | C15: =SUM('Pelagicos LTP '!E202:E251) -> 25706.997 | D15: =SUM('Pelagicos LTP '!F202:F251) -> -3963.787 | E15: =C15+D15 -> 21743.21 | F15: =SUM('Pelagicos LTP '!H202:H251) -> 20825.237 | G15: 843.352 | H15: =E15-F15 -> 917.973 | I15: =F15/E15 -> 0.95778116
A16: Langostino amarillo | B16: III-IV | C16: =SUM('Crustaceos LTP'!Q55:Q93) -> 1198.001 | D16: =SUM('Crustaceos LTP'!R55:R93,'Crustaceos LTP'!S55:S93) -> 0 | E16: =C16+D16 -> 1198.001 | F16: =SUM('Crustaceos LTP'!U55:U93) -> 1025.012 | H16: =E16-F16 -> 172.989 | I16: =F16/E16 -> 0.85560196
A17: Langostino colorado | B17: I -IV | C17: =SUM('Crustaceos LTP'!W98:W127) -> 43.001 | D17: =SUM('Crustaceos LTP'!X98:X127,'Crustaceos LTP'!Y98:Y127) -> 157.842 | E17: =C17+D17 -> 200.843 | F17: =SUM('Crustaceos LTP'!AA98:AA127) -> 159.847 | H17: =E17-F17 -> 40.996 | I17: =F17/E17 -> 0.79588036
A18: Merluza común | B18: IV- 41º 28, 6 | C18: =SUM('Demersales LTP '!E156:E215) -> 11166 | D18: =SUM('Demersales LTP '!F156:F215) -> 13.246 | E18: =C18+D18 -> 11179.246 | F18: =SUM('Demersales LTP '!H156:H215) -> 10886.994 | H18: =E18-F18 -> 292.252 | I18: =F18/E18 -> 0.97385763
A19: Merluza de cola | B19: V -X | C19: =SUM('Demersales LTP '!E72:E137) -> 23909.996 | D19: =SUM('Demersales LTP '!F72:F137) -> -10977.963 | E19: =C19+D19 -> 12932.033 | F19: =SUM('Demersales LTP '!H72:H137) -> 12566 | H19: =E19-F19 -> 366.033 | I19: =F19/E19 -> 0.97169563
A20: Merluza de cola | B20: XI -XII | C20: =SUM('Demersales LTP '!E139:E154) -> 15939.928 | D20: =SUM('Demersales LTP '!F139:F154) -> 10977.964 | E20: =C20+D20 -> 26917.892 | F20: =SUM('Demersales LTP '!H139:H154) -> 26551.647 | H20: =E20-F20 -> 366.245 | I20: =F20/E20 -> 0.98639399
A21: Merluza de tres aletas | B21: 41º28,6 - XII | C21: =SUM('Demersales LTP '!E61:E70) -> 14300 | D21: =SUM('Demersales LTP '!F61:F70) -> -3.4083847e-14 | E21: =C21+D21 -> 14300 | F21: =SUM('Demersales LTP '!H61:H70) -> 9942.857 | H21: =E21-F21 -> 4357.143 | I21: =F21/E21 -> 0.69530469
A22: Merluza del sur | B22: NE F + H | C22: =SUM('Demersales LTP '!E33:E46) -> 2913.001 | D22: =SUM('Demersales LTP '!F33:F46) -> 2495.247 | E22: =C22+D22 -> 5408.248 | F22: =SUM('Demersales LTP '!H33:H46) -> 5381.7 | H22: =E22-F22 -> 26.548 | I22: =F22/E22 -> 0.9950912
A23: Merluza del sur | B23: SE | C23: =SUM('Demersales LTP '!E48:E59) -> 1863 | D23: =SUM('Demersales LTP '!F48:F59) -> -475.805 | E23: =C23+D23 -> 1387.195 | F23: =SUM('Demersales LTP '!H48:H59) -> 1224.733 | H23: =E23-F23 -> 162.462 | I23: =F23/E23 -> 0.88288453
A24: Sardina común | B24: V -X | C24: =SUM('Pelagicos LTP '!E254:E313) -> 123307 | D24: =SUM('Pelagicos LTP '!F254:F313) -> -46600.667 | E24: =C24+D24 -> 76706.332 | F24: =SUM('Pelagicos LTP '!H254:H313) -> 75206.881 | H24: =E24-F24 -> 1499.451 | I24: =F24/E24 -> 0.98045206
A25: Sardina española | B25: XV- I - II | C25: =SUM('Pelagicos LTP '!E316:E323) -> 588 | D25: =SUM('Pelagicos LTP '!F316:F323) -> -1.932 | E25: =C25+D25 -> 586.068 | F25: =SUM('Pelagicos LTP '!H316:H323) -> 0 | H25: =E25-F25 -> 586.068 | I25: =F25/E25 -> 0
A26: Sardina española | B26: III - IV | C26: =SUM('Pelagicos LTP '!E326:E347) -> 700 | D26: =SUM('Pelagicos LTP '!F326:F347) -> -99.90997 | E26: =C26+D26 -> 600.09003 | F26: =SUM('Pelagicos LTP '!H326:H347) -> 8.446 | H26: =E26-F26 -> 591.64403 | I26: =F26/E26 -> 0.014074555
A28: Nota: desembarque aguas internacionales Jurel desde III a X regiones, esta incorporado en la columna de desembarque total, solo se incorpora el dato para tenerlo de referencia

Sheet Pelagicos LTP 
B1: 2014. CUOTAS LTP Y SU CONSUMO DE RECURSOS PELÁGICOS al 31 de diciembre de 2014
C4: Periodo | E4: Cuota (t) | H4: Operación | K4: Global
A5: Unidad de pesquería | B5: Titular de cuota LTP | C5: Inicial | D5: Final | E5: Cuota Asignada | F5: Traspaso, Cesion, Arriendo, etc) | G5: Cuota Efectiva | H5: Desembarque (t) | I5: Saldo (t) | J5: % consumido | K5: Cuota (t) | L5: Desembarque (t) | M5: Saldo (t) | N5: % consumido
A6: Anchoveta XV - I - II | B6: Arica Seafood Producer S.A. | C6: 39083 | D6: 39263 | E6: 3320.985 | F6: =-3320.985 -> -3320.985 | G6: =E6+F6 -> 0 | I6: =G6-H6 -> 0 | J6: =H6/G6 -> #DIV/0! | K6: =E6+E7+F6+F7 -> 0 | L6: =H6+H7 -> 0 | M6: =K6-L6 -> 0 | N6: =L6/K6 -> #DIV/0!
C7: 39264 | D7: 39447 | E7: 1106.993 | F7: =-1106.993 -> -1106.993 | G7: =E7+F7+I6 -> 0 | I7: =G7-H7 -> 0 | J7: =H7/G7 -> #DIV/0!
B8: Camanchaca S.A. Cia. Pesq. | C8: 39083 | D8: 39263 | E8: 92144.847 | G8: =+E8+F8 -> 92144.847 | H8: 64993.394 | I8: =G8-H8 -> 27151.453 | J8: =H8/G8 -> 0.70533943 | K8: =E8+E9+F8+F9 -> 122859.73 | L8: =H8+H9 -> 122770.28 | M8: =K8-L8 -> 89.45 | N8: =L8/K8 -> 0.99927193
C9: 39264 | D9: 39447 | E9: 30714.883 | G9: =E9+F9+I8 -> 57866.336 | H9: 57776.886 | I9: =G9-H9 -> 89.45 | J9: =H9/G9 -> 0.9984542 | O9: 32728
B10: Corpesca S.A. | C10: 39083 | D10: 39263 | E10: 371371.17 | G10: =E10+F10 -> 371371.17 | H10: 223426.06 | I10: =G10-H10 -> 147945.11 | J10: =H10/G10 -> 0.60162469 | K10: =E10+E11+F10+F11 -> 465161.29 | L10: =H10+H11 -> 459651.7 | M10: =K10-L10 -> 5509.59 | N10: =L10/K10 -> 0.98815553 | O10: =+O9-H9 -> -25048.886
C11: 39264 | D11: 39447 | E11: 123790.12 | F11: =-20000-5000-5000 -> -30000 | G11: =E11+F11+I10 -> 241735.23 | H11: 236225.64 | I11: =G11-H11 -> 5509.59 | J11: =H11/G11 -> 0.97720816
B12: Orizón S.A | C12: 39083 | D12: 39263 | E12: 0 | G12: =E12+F12 -> 0 | I12: =G12-H12 -> 0 | J12: =H12/G12 -> #DIV/0! | K12: =E12+E13+F12+F13 -> 0 | L12: =H12+H13 -> 0 | M12: =K12-L12 -> 0 | N12: =L12/K12 -> #DIV/0!
C13: 39264 | D13: 39447 | E13: 0 | G13: =E13+F13+I12 -> 0 | I13: =G13-H13 -> 0 | J13: =H13/G13 -> #DIV/0!
A16: Anchoveta III - IV | B16: Alimentos Marinos S.A., | C16: 39083 | D16: 39386 | E16: 858.817 | F16: =777.446-554 -> 223.446 | G16: =E16+F16 -> 1082.263 | I16: =G16-H16 -> 1082.263 | J16: =H16/G16 -> 0 | K16: =E16+E17+F16+F17 -> 1144.887 | L16: =H16+H17 -> 855.235 | M16: =K16-L16 -> 289.652 | N16: =L16/K16 -> 0.74700385
C17: 39387 | D17: 39447 | E17: 45.186 | F17: =17.438 -> 17.438 | G17: =E17+F17+I16 -> 1144.887 | H17: 855.235 | I17: =G17-H17 -> 289.652 | J17: =H17/G17 -> 0.74700385
B18: Bahia Caldera S.A. Pesq. | C18: 39083 | D18: 39386 | E18: 6808.598 | F18: =-3166.828-2641.77 -> -5808.598 | G18: =E18+F18 -> 1000 | I18: =G18-H18 -> 1000 | J18: =H18/G18 -> 0 | K18: =E18+E19+F18+F19 -> 0 | L18: =H18+H19 -> 0 | M18: =K18-L18 -> 0 | N18: =L18/K18 -> #DIV/0!
C19: 39387 | D19: 39447 | E19: 358.23 | F19: =-358.23-1000 -> -1358.23 | G19: =E19+F19+I18 -> 0 | I19: =G19-H19 -> 0 | J19: =H19/G19 -> #DIV/0!
B20: Blumar S.A. | C20: 39083 | D20: 39386 | E20: 5319.902 | F20: =-3.09-5316.812 -> -5319.902 | G20: =E20+F20 -> 0 | I20: =G20-H20 -> 0 | J20: =H20/G20 -> #DIV/0! | K20: =E20+E21+F20+F21 -> 1000 | L20: =H20+H21 -> 0 | M20: =K20-L20 -> 1000 | N20: =L20/K20 -> 0
C21: 39387 | D21: 39447 | E21: 279.903 | F21: =-279.903+1000 -> 720.097 | G21: =E21+F21+I20 -> 1000 | I21: =G21-H21 -> 1000 | J21: =H21/G21 -> 0
B22: Camanchaca S.A. Cia. Pesq. | C22: 39083 | D22: 39386 | E22: 777.446 | F22: =-777.446 -> -777.446 | G22: =E22+F22 -> 0 | I22: =G22-H22 -> 0 | J22: =H22/G22 -> #DIV/0! | K22: =E22+E23+F22+F23 -> 23.466846 | L22: =H22+H23 -> 0 | M22: =K22-L22 -> 23.466846 | N22: =L22/K22 -> 0
C23: 39387 | D23: 39447 | E23: 40.905 | F23: =-17.4381544 -> -17.438154 | G23: =E23+F23+I22 -> 23.466846 | I23: =G23-H23 -> 23.466846 | J23: =H23/G23 -> 0
B24: Corpesca S.A., | C24: 39083 | D24: 39386 | E24: 0 | G24: =E24+F24 -> 0 | I24: =G24-H24 -> 0 | J24: =H24/G24 -> #DIV/0! | K24: =E24+E25+F24+F25 -> 0 | L24: =H24+H25 -> 0 | M24: =K24-L24 -> 0 | N24: =L24/K24 -> #DIV/0!
C25: 39387 | D25: 39447 | E25: 0 | G25: =E25+F25+I24 -> 0 | I25: =G25-H25 -> 0 | J25: =H25/G25 -> #DIV/0!
B26: Inversiones Pesqueras S.A. | C26: 39083 | D26: 39386 | E26: 279.921 | F26: =-0.258 -> -0.258 | G26: =E26+F26 -> 279.663 | I26: =G26-H26 -> 279.663 | J26: =H26/G26 -> 0 | K26: =E26+E27+F26+F27 -> 294.391 | L26: =H26+H27 -> 0 | M26: =K26-L26 -> 294.391 | N26: =L26/K26 -> 0
C27: 39387 | D27: 39447 | E27: 14.728 | G27: =E27+F27+I26 -> 294.391 | I27: =G27-H27 -> 294.391 | J27: =H27/G27 -> 0
B28: Orizón S.A. | C28: 39083 | D28: 39386 | E28: 10380.341 | F28: =-10.826 -> -10.826 | G28: =E28+F28 -> 10369.515 | I28: =G28-H28 -> 10369.515 | J28: =H28/G28 -> 0 | K28: =E28+E29+F28+F29 -> 10915.67 | L28: =H28+H29 -> 0 | M28: =K28-L28 -> 10915.67 | N28: =L28/K28 -> 0
C29: 39387 | D29: 39447 | E29: 546.155 | G29: =E29+F29+I28 -> 10915.67 | I29: =G29-H29 -> 10915.67 | J29: =H29/G29 -> 0
B30: Camanchaca Pesca Sur S.A. | C30: 39083 | D30: 39386 | E30: 73.975 | G30: =E30+F30 -> 73.975 | I30: =G30-H30 -> 73.975 | J30: =H30/G30 -> 0 | K30: =E30+E31+F30+F31 -> 77.867 | L30: =H30+H31 -> 0 | M30: =K30-L30 -> 77.867 | N30: =L30/K30 -> 0
C31: 39387 | D31: 39447 | E31: 3.892 | G31: =E31+F31+I30 -> 77.867 | I31: =G31-H31 -> 77.867 | J31: =H31/G31 -> 0
B32: Centro Sur Pesq. S.A. | C32: 39083 | D32: 39386 | E32: 0 | F32: =0.258 -> 0.258 | G32: =E32+F32 -> 0.258 | I32: =G32-H32 -> 0.258 | J32: =H32/G32 -> 0 | K32: =E32+E33+F32+F33 -> 0.258 | L32: =H32+H33 -> 0 | M32: =K32-L32 -> 0.258 | N32: =L32/K32 -> 0
C33: 39387 | D33: 39447 | E33: 0 | G33: =E33+F33+I32 -> 0.258 | I33: =G33-H33 -> 0.258 | J33: =H33/G33 -> 0
B34: Landes S.A. | C34: 39083 | D34: 39386 | E34: 0 | F34: =3.09 -> 3.09 | G34: =E34+F34 -> 3.09 | I34: =G34-H34 -> 3.09 | J34: =H34/G34 -> 0 | K34: =E34+E35+F34+F35 -> 3.09 | L34: =H34+H35 -> 0 | M34: =K34-L34 -> 3.09 | N34: =L34/K34 -> 0
C35: 39387 | D35: 39447 | E35: 0 | G35: =E35+F35+I34 -> 3.09 | I35: =G35-H35 -> 3.09 | J35: =H35/G35 -> 0
A38: Anchoveta V-X | B38: Alimentos Marinos S.A. | C38: 39083 | D38: 39202 | E38: 1438.139 | F38: =-70-950-70-70-315-40-40+207.961+2.492+15.329+8.0655352 -> -1321.1525 | G38: =E38+F38 -> 116.98654 | I38: =G38-H38 -> 116.98654 | J38: =H38/G38 -> 0 | K38: =E38+E39+E40+F38+F39+F40 -> 250.85254 | L38: =H38+H39+H40 -> 81.328 | M38: =K38-L38 -> 169.52454 | N38: =L38/K38 -> 0.32420641
C39: 39203 | D39: 39691 | E39: 169.182 | F39: =-120 -> -120 | G39: =E39+F39+I38 -> 166.16854 | H39: 31.313 | I39: =G39-H39 -> 134.85554 | J39: =H39/G39 -> 0.18844121
C40: 39692 | D40: 39813 | E40: 84.684 | G40: =E40+F40+I39 -> 219.53954 | H40: 50.015 | I40: =G40-H40 -> 169.52454 | J40: =H40/G40 -> 0.22781774
B41: Berta Elena Ltda. Soc. Pesq. | C41: 39083 | D41: 39202 | E41: 27.075 | F41: =-27.075 -> -27.075 | G41: =E41+F41 -> 0 | I41: =G41-H41 -> 0 | J41: =H41/G41 -> #DIV/0! | K41: =E41+E42+E43+F41+F42+F43 -> 0 | L41: =H41+H42+H43 -> 0 | M41: =K41-L41 -> 0 | N41: =L41/K41 -> #DIV/0!
C42: 39203 | D42: 39691 | E42: 3.185 | F42: =-3.185 -> -3.185 | G42: =E42+F42+I41 -> 0 | I42: =G42-H42 -> 0 | J42: =H42/G42 -> #DIV/0!
C43: 39692 | D43: 39813 | E43: 1.594 | F43: =-1.594 -> -1.594 | G43: =E43+F43+I42 -> 0 | I43: =G43-H43 -> 0 | J43: =H43/G43 -> #DIV/0!
B44: Blumar S.A. | C44: 39083 | D44: 39202 | E44: 1816.775 | F44: =-680-340-70-160-20 -> -1270 | G44: =E44+F44 -> 546.775 | I44: =G44-H44 -> 546.775 | J44: =H44/G44 -> 0 | K44: =E44+E45+E46+F44+F45+F46 -> 867.479 | L44: =H44+H45+H46 -> 66.287 | M44: =K44-L44 -> 801.192 | N44: =L44/K44 -> 0.076413377
C45: 39203 | D45: 39691 | E45: 213.724 | G45: =E45+F45+I44 -> 760.499 | H45: 66.287 | I45: =G45-H45 -> 694.212 | J45: =H45/G45 -> 0.087162508
C46: 39692 | D46: 39813 | E46: 106.98 | G46: =E46+F46+I45 -> 801.192 | I46: =G46-H46 -> 801.192 | J46: =H46/G46 -> 0
...

Sheet Crustaceos  LTP
B1: 2014. CUOTAS LTP Y SU CONSUMO DE RECURSOS CRUSTÁCEOS al 31 de diciembre 2014 | AV1: * registra la sumatoria de los traspasos en todas las regiones
AV2: ** registra los traspasos realizados en toda la unidad de pesqueria. Certificados que no identifican la región.
C4: Periodo | E4: Cuota II Región (t) | H4: Operación II región | K4: Cuota III Región (t) | N4: Operación III Región | Q4: Cuota IV Región (t) | T4: Operación IV Región | W4: Cuota V Región (t) | Z4: Operación V Región | AC4: Cuota VI Región (t) | AF4: Operación VI Región | AI4: Cuota VII Región (t) | AL4: Operación VII Región | AO4: Cuota VIII Región (t) | AR4: Operación VIII Región | AU4: Cuota y Operación Camaron Nailon II-VIII | AY4: Operación II-VIII | BB4: Global II-VIII
A5: Unidad de pesquería | B5: Armador | C5: Inicial | D5: Final | E5: Cuota Asignada | F5: Traspaso, Cesion, Arriendo, etc) | G5: Cuota Efectiva | H5: Desembarque (t) | I5: Saldo (t) | J5: Cuota Total | K5: Cuota Asignada | L5: Traspaso, Cesion, Arriendo, etc) | M5: Cuota Efectiva | N5: Desembarque (t) | O5: Saldo (t) | P5: Cuota Total | Q5: Cuota Asignada | R5: Traspaso, Cesion, Arriendo, etc) | S5: Cuota Efectiva | T5: Desembarque (t) | U5: Saldo (t) | V5: Cuota Total | W5: Cuota Asignada | X5: Traspaso, Cesion, Arriendo, etc) | Y5: Cuota Efectiva | Z5: Desembarque (t) | AA5: Saldo (t) | AB5: Cuota Total | AC5: Cuota Asignada | AD5: Traspaso, Cesion, Arriendo, etc) | AE5: Cuota Efectiva | AF5: Desembarque (t) | AG5: Saldo (t) | AH5: Cuota Total | AI5: Cuota Asignada | AJ5: Traspaso, Cesion, Arriendo, etc) | AK5: Cuota Efectiva | AL5: Desembarque (t) | AM5: Saldo (t) | AN5: Cuota Total | AO5: Cuota Asignada | AP5: Traspaso, Cesion, Arriendo, etc) | AQ5: Cuota Efectiva | AR5: Desembarque (t) | AS5: Saldo (t) | AT5: Cuota Total | AU5: Cuota Asignada II-VIII | AV5: * Traspaso, Cesion, Arriendo, etc) | AW5: **Traspaso, Cesion, Arriendo, etc) | AX5: Cuota Efectiva | AY5: Desembarque (t) II-VIII | AZ5: Saldo (t) | BA5: % consumido | BB5: Cuota Total | BC5: Desembarque (t) | BD5: Saldo (t) | BE5: % consumido
A6: Camarón nailon II-VIII | B6: Antarctic Seafood S.A. | C6: 41640 | D6: 41882 | E6: 0.699 | G6: =E6+F6 -> 0.699 | I6: =G6-H6 -> 0.699 | J6: =E6+E7+F6+F7 -> 1.048 | K6: 0.349 | L6: =4.216 -> 4.216 | M6: =K6+L6 -> 4.565 | O6: =M6-N6 -> 4.565 | P6: =K6+K7+L6+L7 -> 0.698 | Q6: 36.696 | R6: =6.817 -> 6.817 | S6: =Q6+R6 -> 43.513 | T6: 55.117 | U6: =S6-T6 -> -11.604 | V6: =Q6+Q7+R6+R7 -> 87.73216 | W6: 66.752 | Y6: =W6+X6 -> 66.752 | Z6: 75.722 | AA6: =Y6-Z6 -> -8.97 | AB6: =W6+W7+X6+X7 -> 121.7834 | AC6: 113.059 | AD6: =0.8 -> 0.8 | AE6: =AC6+AD6 -> 113.859 | AF6: 135.871 | AG6: =AE6-AF6 -> -22.012 | AH6: =AC6+AC7+AD6+AD7 -> 178.243 | AI6: 95.235 | AJ6: =19.978 -> 19.978 | AK6: =AI6+AJ6 -> 115.213 | AL6: 110.47 | AM6: =AK6-AL6 -> 4.743 | AN6: =AI6+AI7+AJ6+AJ7 -> 186.472 | AO6: 92.964 | AP6: =19.502 -> 19.502 | AQ6: =AO6+AP6 -> 112.466 | AR6: 115.094 | AS6: =AQ6-AR6 -> -2.628 | AT6: =AO6+AO7+AP6+AP7 -> 188.6594 | AU6: =E6+K6+Q6+W6+AC6+AI6+AO6 -> 405.754 | AV6: =F6+L6+R6+X6+AD6+AJ6+AP6 -> 51.313 | AW6: =13.444 -> 13.444 | AX6: =AU6+AV6+AW6 -> 470.511 | AY6: =H6+N6+T6+Z6+AF6+AL6+AR6 -> 492.274 | AZ6: =AX6-AY6 -> -21.763 | BA6: =AY6/AX6 -> 1.046254 | BB6: =AU6+AU7+AV6+AV7+AW6+AW7 -> 782.63596 | BC6: =AY6+AY7 -> 762.388 | BD6: =BB6-BC6 -> 20.24796 | BE6: =BC6/BB6 -> 0.97412851
C7: 41883 | D7: 42004 | E7: 0.349 | G7: =E7+F7+I6 -> 1.048 | I7: =G7-H7 -> 1.048 | K7: 0.349 | L7: =1.488-5.704 -> -4.216 | M7: =K7+L7+O6 -> 0.698 | O7: =M7-N7 -> 0.698 | Q7: 35.298 | R7: =6.417+2.50416 -> 8.92116 | S7: =Q7+R7+U6 -> 32.61516 | T7: 32.517 | U7: =S7-T7 -> 0.09816 | W7: 39.143 | X7: =11.68+4.2084 -> 15.8884 | Y7: =W7+X7+AA6 -> 46.0614 | Z7: 45.906 | AA7: =Y7-Z7 -> 0.1554 | AC7: 58.889 | AD7: =5.495 -> 5.495 | AE7: =AC7+AD7+AG6 -> 42.372 | AF7: 42.311 | AG7: =AE7-AF7 -> 0.061 | AI7: 51.375 | AJ7: =8.124+16.664-4.904 -> 19.884 | AK7: =AI7+AJ7+AM6 -> 76.002 | AL7: 75.989 | AM7: =AK7-AL7 -> 0.013 | AO7: 47.705 | AP7: =8.044+16.236+4.2084 -> 28.4884 | AQ7: =AO7+AP7+AS6 -> 73.5654 | AR7: 73.391 | AS7: =AQ7-AR7 -> 0.1744 | AU7: =E7+K7+Q7+W7+AC7+AI7+AO7 -> 233.108 | AV7: =F7+L7+R7+X7+AD7+AJ7+AP7 -> 74.46096 | AW7: =4.556 -> 4.556 | AX7: =AU7+AV7+AZ6+AW7 -> 290.36196 | AY7: =H7+N7+T7+Z7+AF7+AL7+AR7 -> 270.114 | AZ7: =AX7-AY7 -> 20.24796 | BA7: =AY7/AX7 -> 0.93026649
B8: Baycic Baycic Maria | C8: 41640 | D8: 41882 | E8: 0.267 | F8: =-0.267 -> -0.267 | G8: =E8+F8 -> 0 | I8: =G8-H8 -> 0 | J8: =E8+E9+F8+F9 -> 0 | K8: 0.133 | L8: =-0.133 -> -0.133 | M8: =K8+L8 -> 0 | O8: =M8-N8 -> 0 | P8: =K8+K9+L8+L9 -> 0 | Q8: 13.993 | R8: =-13.993 -> -13.993 | S8: =Q8+R8 -> 0 | U8: =S8-T8 -> 0 | V8: =Q8+Q9+R8+R9 -> 0 | W8: 25.454 | X8: =-25.454 -> -25.454 | Y8: =W8+X8 -> 0 | AA8: =Y8-Z8 -> 0 | AB8: =W8+W9+X8+X9 -> 0 | AC8: 43.112 | AD8: =-43.112 -> -43.112 | AE8: =AC8+AD8 -> 0 | AG8: =AE8-AF8 -> 0 | AH8: =AC8+AC9+AD8+AD9 -> 0 | AI8: 36.315 | AJ8: =-36.315 -> -36.315 | AK8: =AI8+AJ8 -> 0 | AM8: =AK8-AL8 -> 0 | AN8: =AI8+AI9+AJ8+AJ9 -> 0 | AO8: 35.449 | AP8: =-35.449 -> -35.449 | AQ8: =AO8+AP8 -> 0 | AS8: =AQ8-AR8 -> 0 | AT8: =AO8+AO9+AP8+AP9 -> 0 | AU8: =E8+K8+Q8+W8+AC8+AI8+AO8 -> 154.723 | AV8: =F8+L8+R8+X8+AD8+AJ8+AP8 -> -154.723 | AX8: =AU8+AV8+AW8 -> 0 | AY8: =H8+N8+T8+Z8+AF8+AL8+AR8 -> 0 | AZ8: =AX8-AY8 -> 0 | BA8: =AY8/AX8 -> #DIV/0! | BB8: =AU8+AU9+AV8+AV9+AW8+AW9 -> 0 | BC8: =AY8+AY9 -> 0 | BD8: =BB8-BC8 -> 0 | BE8: =BC8/BB8 -> #DIV/0!
C9: 41883 | D9: 42004 | E9: 0.133 | F9: =-0.133 -> -0.133 | G9: =E9+F9+I8 -> 0 | I9: =G9-H9 -> 0 | K9: 0.133 | L9: =-0.133 -> -0.133 | M9: =K9+L9+O8 -> 0 | O9: =M9-N9 -> 0 | Q9: 13.46 | R9: =-13.46 -> -13.46 | S9: =Q9+R9+U8 -> 0 | U9: =S9-T9 -> 0 | W9: 14.926 | X9: =-14.926 -> -14.926 | Y9: =W9+X9+AA8 -> 0 | AA9: =Y9-Z9 -> 0 | AC9: 22.455 | AD9: =-22.455 -> -22.455 | AE9: =AC9+AD9+AG8 -> 0 | AG9: =AE9-AF9 -> 0 | AI9: 19.59 | AJ9: =-19.59 -> -19.59 | AK9: =AI9+AJ9+AM8 -> 0 | AM9: =AK9-AL9 -> 0 | AO9: 18.191 | AP9: =-18.191 -> -18.191 | AQ9: =AO9+AP9+AS8 -> 0 | AS9: =AQ9-AR9 -> 0 | AU9: =E9+K9+Q9+W9+AC9+AI9+AO9 -> 88.888 | AV9: =F9+L9+R9+X9+AD9+AJ9+AP9 -> -88.888 | AX9: =AU9+AV9+AZ8+AW9 -> 0 | AY9: =H9+N9+T9+Z9+AF9+AL9+AR9 -> 0 | AZ9: =AX9-AY9 -> 0 | BA9: =AY9/AX9 -> #DIV/0!
B10: Blumar S.A. | C10: 41640 | D10: 41882 | E10: 0.086 | G10: =E10+F10 -> 0.086 | I10: =G10-H10 -> 0.086 | J10: =E10+E11+F10+F11 -> 0.129 | K10: 0.043 | M10: =K10+L10 -> 0.043 | O10: =M10-N10 -> 0.043 | P10: =K10+K11+L10+L11 -> 0.086 | Q10: 4.492 | S10: =Q10+R10 -> 4.492 | U10: =S10-T10 -> 4.492 | V10: =Q10+Q11+R10+R11 -> 2.396 | W10: 8.171 | Y10: =W10+X10 -> 8.171 | AA10: =Y10-Z10 -> 8.171 | AB10: =W10+W11+X10+X11 -> 1.283 | AC10: 13.84 | AE10: =AC10+AD10 -> 13.84 | AG10: =AE10-AF10 -> 13.84 | AH10: =AC10+AC11+AD10+AD11 -> 15.554 | AI10: 11.658 | AK10: =AI10+AJ10 -> 11.658 | AM10: =AK10-AL10 -> 11.658 | AN10: =AI10+AI11+AJ10+AJ11 -> 1.283 | AO10: 11.38 | AQ10: =AO10+AP10 -> 11.38 | AS10: =AQ10-AR10 -> 11.38 | AT10: =AO10+AO11+AP10+AP11 -> 0.984 | AU10: =E10+K10+Q10+W10+AC10+AI10+AO10 -> 49.67 | AV10: =F10+L10+R10+X10+AD10+AJ10+AP10 -> 0 | AW10: =-0.7652 -> -0.7652 | AX10: =AU10+AV10+AW10 -> 48.9048 | AY10: =H10+N10+T10+Z10+AF10+AL10+AR10 -> 0 | AZ10: =AX10-AY10 -> 48.9048 | BA10: =AY10/AX10 -> 0 | BB10: =AU10+AU11+AV10+AV11+AW10+AW11 -> 20.9498 | BC10: =AY10+AY11 -> 0 | BD10: =BB10-BC10 -> 20.9498 | BE10: =BC10/BB10 -> 0
C11: 41883 | D11: 42004 | E11: 0.043 | G11: =E11+F11+I10 -> 0.129 | I11: =G11-H11 -> 0.129 | K11: 0.043 | M11: =K11+L11+O10 -> 0.086 | O11: =M11-N11 -> 0.086 | Q11: 4.321 | R11: =-6.417 -> -6.417 | S11: =Q11+R11+U10 -> 2.396 | U11: =S11-T11 -> 2.396 | W11: 4.792 | X11: =-11.68 -> -11.68 | Y11: =W11+X11+AA10 -> 1.283 | AA11: =Y11-Z11 -> 1.283 | AC11: 7.209 | AD11: =-5.495 -> -5.495 | AE11: =AC11+AD11+AG10 -> 15.554 | AG11: =AE11-AF11 -> 15.554 | AI11: 6.289 | AJ11: =-16.664 -> -16.664 | AK11: =AI11+AJ11+AM10 -> 1.283 | AM11: =AK11-AL11 -> 1.283 | AO11: 5.84 | AP11: =-16.236 -> -16.236 | AQ11: =AO11+AP11+AS10 -> 0.984 | AS11: =AQ11-AR11 -> 0.984 | AU11: =E11+K11+Q11+W11+AC11+AI11+AO11 -> 28.537 | AV11: =F11+L11+R11+X11+AD11+AJ11+AP11 -> -56.492 | AX11: =AU11+AV11+AZ10+AW11 -> 20.9498 | AY11: =H11+N11+T11+Z11+AF11+AL11+AR11 -> 0 | AZ11: =AX11-AY11 -> 20.9498 | BA11: =AY11/AX11 -> 0
B12: Bracpesca S.A | C12: 41640 | D12: 41882 | E12: 0.686 | G12: =E12+F12 -> 0.686 | I12: =G12-H12 -> 0.686 | J12: =E12+E13+F12+F13 -> 1.029 | K12: 0.343 | M12: =K12+L12 -> 0.343 | O12: =M12-N12 -> 0.343 | P12: =K12+K13+L12+L13 -> 0.686 | Q12: 36.034 | S12: =Q12+R12 -> 36.034 | T12: 29.525 | U12: =S12-T12 -> 6.509 | V12: =Q12+Q13+R12+R13 -> 70.696 | W12: 65.548 | Y12: =W12+X12 -> 65.548 | Z12: 61.918 | AA12: =Y12-Z12 -> 3.63 | AB12: =W12+W13+X12+X13 -> 93.985 | AC12: 111.02 | AE12: =AC12+AD12 -> 111.02 | AF12: 105.275 | AG12: =AE12-AF12 -> 5.745 | AH12: =AC12+AC13+AD12+AD13 -> 168.847 | AI12: 93.518 | AK12: =AI12+AJ12 -> 93.518 | AL12: 119.225 | AM12: =AK12-AL12 -> -25.707 | AN12: =AI12+AI13+AJ12+AJ13 -> 153.966 | AO12: 91.287 | AQ12: =AO12+AP12 -> 91.287 | AR12: 52.106 | AS12: =AQ12-AR12 -> 39.181 | AT12: =AO12+AO13+AP12+AP13 -> 138.132 | AU12: =E12+K12+Q12+W12+AC12+AI12+AO12 -> 398.436 | AV12: =F12+L12+R12+X12+AD12+AJ12+AP12 -> 0 | AX12: =AU12+AV12+AW12 -> 398.436 | AY12: =H12+N12+T12+Z12+AF12+AL12+AR12 -> 368.049 | AZ12: =AX12-AY12 -> 30.387 | BA12: =AY12/AX12 -> 0.9237343 | BB12: =AU12+AU13+AV12+AV13+AW12+AW13 -> 627.341 | BC12: =AY12+AY13 -> 622.842 | BD12: =BB12-BC12 -> 4.499 | BE12: =BC12/BB12 -> 0.99282846
C13: 41883 | D13: 42004 | E13: 0.343 | G13: =E13+F13+I12 -> 1.029 | I13: =G13-H13 -> 1.029 | K13: 0.343 | M13: =K13+L13+O12 -> 0.686 | O13: =M13-N13 -> 0.686 | Q13: 34.662 | S13: =Q13+R13+U12 -> 41.171 | T13: 39.033 | U13: =S13-T13 -> 2.138 | W13: 38.437 | X13: =-10 -> -10 | Y13: =W13+X13+AA12 -> 32.067 | Z13: 31.877 | AA13: =Y13-Z13 -> 0.19 | AC13: 57.827 | AE13: =AC13+AD13+AG12 -> 63.572 | AF13: 63.183 | AG13: =AE13-AF13 -> 0.389 | AI13: 50.448 | AJ13: =10 -> 10 | AK13: =AI13+AJ13+AM12 -> 34.741 | AL13: 34.692 | AM13: =AK13-AL13 -> 0.049 | AO13: 46.845 | AQ13: =AO13+AP13+AS12 -> 86.026 | AR13: 86.008 | AS13: =AQ13-AR13 -> 0.018 | AU13: =E13+K13+Q13+W13+AC13+AI13+AO13 -> 228.905 | AV13: =F13+L13+R13+X13+AD13+AJ13+AP13 -> 0 | AX13: =AU13+AV13+AZ12+AW13 -> 259.292 | AY13: =H13+N13+T13+Z13+AF13+AL13+AR13 -> 254.793 | AZ13: =AX13-AY13 -> 4.499 | BA13: =AY13/AX13 -> 0.98264891
B14: Camanchaca Pesca Sur S.A. | C14: 41640 | D14: 41882 | E14: 0.004 | G14: =E14+F14 -> 0.004 | I14: =G14-H14 -> 0.004 | J14: =E14+E15+F14+F15 -> 0.006 | K14: 0.002 | M14: =K14+L14 -> 0.002 | O14: =M14-N14 -> 0.002 | P14: =K14+K15+L14+L15 -> 0.004 | Q14: 0.187 | S14: =Q14+R14 -> 0.187 | U14: =S14-T14 -> 0.187 | V14: =Q14+Q15+R14+R15 -> 0.367 | W14: 0.34 | Y14: =W14+X14 -> 0.34 | AA14: =Y14-Z14 -> 0.34 | AB14: =W14+W15+X14+X15 -> 0.539 | AC14: 0.576 | AE14: =AC14+AD14 -> 0.576 | AG14: =AE14-AF14 -> 0.576 | AH14: =AC14+AC15+AD14+AD15 -> 0.876 | AI14: 0.486 | AK14: =AI14+AJ14 -> 0.486 | AM14: =AK14-AL14 -> 0.486 | AN14: =AI14+AI15+AJ14+AJ15 -> 0.748 | AO14: 0.474 | AQ14: =AO14+AP14 -> 0.474 | AS14: =AQ14-AR14 -> 0.474 | AT14: =AO14+AO15+AP14+AP15 -> 0.717 | AU14: =E14+K14+Q14+W14+AC14+AI14+AO14 -> 2.069 | AV14: =F14+L14+R14+X14+AD14+AJ14+AP14 -> 0 | AW14: =-0.06964-0.06964 -> -0.13928 | AX14: =AU14+AV14+AW14 -> 1.92972 | AY14: =H14+N14+T14+Z14+AF14+AL14+AR14 -> 0 | AZ14: =AX14-AY14 -> 1.92972 | BA14: =AY14/AX14 -> 0 | BB14: =AU14+AU15+AV14+AV15+AW14+AW15 -> 2.42132 | BC14: =AY14+AY15 -> 0.603 | BD14: =BB14-BC14 -> 1.81832 | BE14: =BC14/BB14 -> 0.24903771
C15: 41883 | D15: 42004 | E15: 0.002 | G15: =E15+F15+I14 -> 0.006 | I15: =G15-H15 -> 0.006 | K15: 0.002 | M15: =K15+L15+O14 -> 0.004 | O15: =M15-N15 -> 0.004 | Q15: 0.18 | S15: =Q15+R15+U14 -> 0.367 | U15: =S15-T15 -> 0.367 | W15: 0.199 | Y15: =W15+X15+AA14 -> 0.539 | AA15: =Y15-Z15 -> 0.539 | AC15: 0.3 | AE15: =AC15+AD15+AG14 -> 0.876 | AG15: =AE15-AF15 -> 0.876 | AI15: 0.262 | AK15: =AI15+AJ15+AM14 -> 0.748 | AL15: 0.486 | AM15: =AK15-AL15 -> 0.262 | AO15: 0.243 | AQ15: =AO15+AP15+AS14 -> 0.717 | AR15: 0.117 | AS15: =AQ15-AR15 -> 0.6 | AU15: =E15+K15+Q15+W15+AC15+AI15+AO15 -> 1.188 | AV15: =F15+L15+R15+X15+AD15+AJ15+AP15 -> 0 | AW15: =-0.6964 -> -0.6964 | AX15: =AU15+AV15+AZ14+AW15 -> 2.42132 | AY15: =H15+N15+T15+Z15+AF15+AL15+AR15 -> 0.603 | AZ15: =AX15-AY15 -> 1.81832 | BA15: =AY15/AX15 -> 0.24903771
B16: Antonio Cruz Cordova nakouzi E.I.R.L. | C16: 41640 | D16: 41882 | E16: 0.022 | G16: =E16+F16 -> 0.022 | I16: =G16-H16 -> 0.022 | J16: =E16+E17+F16+F17 -> 0.033 | K16: 0.011 | M16: =K16+L16 -> 0.011 | O16: =M16-N16 -> 0.011 | P16: =K16+K17+L16+L17 -> 0.022 | Q16: 1.159 | S16: =Q16+R16 -> 1.159 | U16: =S16-T16 -> 1.159 | V16: =Q16+Q17+R16+R17 -> 2.274 | W16: 2.109 | Y16: =W16+X16 -> 2.109 | AA16: =Y16-Z16 -> 2.109 | AB16: =W16+W17+X16+X17 -> 3.346 | AC16: 3.572 | AE16: =AC16+AD16 -> 3.572 | AG16: =AE16-AF16 -> 3.572 | AH16: =AC16+AC17+AD16+AD17 -> 5.433 | AI16: 3.009 | AK16: =AI16+AJ16 -> 3.009 | AM16: =AK16-AL16 -> 3.009 | AN16: =AI16+AI17+AJ16+AJ17 -> 4.632 | AO16: 2.937 | AQ16: =AO16+AP16 -> 2.937 | AS16: =AQ16-AR16 -> 2.937 | AT16: =AO16+AO17+AP16+AP17 -> 4.444 | AU16: =E16+K16+Q16+W16+AC16+AI16+AO16 -> 12.819 | AV16: =F16+L16+R16+X16+AD16+AJ16+AP16 -> 0 | AW16: =-13.444 -> -13.444 | AX16: =AU16+AV16+AW16 -> -0.625 | AY16: =H16+N16+T16+Z16+AF16+AL16+AR16 -> 0 | AZ16: =AX16-AY16 -> -0.625 | BA16: =AY16/AX16 -> 0 | BB16: =AU16+AU17+AV16+AV17+AW16+AW17 -> 2.184 | BC16: =AY16+AY17 -> 0 | BD16: =BB16-BC16 -> 2.184 | BE16: =BC16/BB16 -> 0
C17: 41883 | D17: 42004 | E17: 0.011 | G17: =E17+F17+I16 -> 0.033 | I17: =G17-H17 -> 0.033 | K17: 0.011 | M17: =K17+L17+O16 -> 0.022 | O17: =M17-N17 -> 0.022 | Q17: 1.115 | S17: =Q17+R17+U16 -> 2.274 | U17: =S17-T17 -> 2.274 | W17: 1.237 | Y17: =W17+X17+AA16 -> 3.346 | AA17: =Y17-Z17 -> 3.346 | AC17: 1.861 | AE17: =AC17+AD17+AG16 -> 5.433 | AG17: =AE17-AF17 -> 5.433 | AI17: 1.623 | AK17: =AI17+AJ17+AM16 -> 4.632 | AM17: =AK17-AL17 -> 4.632 | AO17: 1.507 | AQ17: =AO17+AP17+AS16 -> 4.444 | AS17: =AQ17-AR17 -> 4.444 | AU17: =E17+K17+Q17+W17+AC17+AI17+AO17 -> 7.365 | AV17: =F17+L17+R17+X17+AD17+AJ17+AP17 -> 0 | AW17: =-4.556 -> -4.556 | AX17: =AU17+AV17+AZ16+AW17 -> 2.184 | AY17: =H17+N17+T17+Z17+AF17+AL17+AR17 -> 0 | AZ17: =AX17-AY17 -> 2.184 | BA17: =AY17/AX17 -> 0
B18: Costa Brava Ltda. Pesq. | C18: 41640 | D18: 41882 | E18: 0.097 | F18: =-0.097 -> -0.097 | G18: =E18+F18 -> 0 | I18: =G18-H18 -> 0 | J18: =E18+E19+F18+F19 -> 0 | K18: 0.049 | L18: =-0.049 -> -0.049 | M18: =K18+L18 -> 0 | O18: =M18-N18 -> 0 | P18: =K18+K19+L18+L19 -> 0 | Q18: 5.116 | R18: =-5.116 -> -5.116 | S18: =Q18+R18 -> 0 | U18: =S18-T18 -> 0 | V18: =Q18+Q19+R18+R19 -> 0 | W18: 9.307 | X18: =-9.307 -> -9.307 | Y18: =W18+X18 -> 0 | AA18: =Y18-Z18 -> 0 | AB18: =W18+W19+X18+X19 -> 0 | AC18: 15.763 | AD18: =-15.763 -> -15.763 | AE18: =AC18+AD18 -> 0 | AG18: =AE18-AF18 -> 0 | AH18: =AC18+AC19+AD18+AD19 -> 0 | AI18: 13.278 | AJ18: =-13.278 -> -13.278 | AK18: =AI18+AJ18 -> 0 | AM18: =AK18-AL18 -> 0 | AN18: =AI18+AI19+AJ18+AJ19 -> 0 | AO18: 12.961 | AP18: =-12.961 -> -12.961 | AQ18: =AO18+AP18 -> 0 | AS18: =AQ18-AR18 -> 0 | AT18: =AO18+AO19+AP18+AP19 -> 0 | AU18: =E18+K18+Q18+W18+AC18+AI18+AO18 -> 56.571 | AV18: =F18+L18+R18+X18+AD18+AJ18+AP18 -> -56.571 | AX18: =AU18+AV18+AW18 -> 0 | AY18: =H18+N18+T18+Z18+AF18+AL18+AR18 -> 0 | AZ18: =AX18-AY18 -> 0 | BA18: =AY18/AX18 -> #DIV/0! | BB18: =AU18+AU19+AV18+AV19+AW18+AW19 -> 0 | BC18: =AY18+AY19 -> 0 | BD18: =BB18-BC18 -> 0 | BE18: =BC18/BB18 -> #DIV/0!
C19: 41883 | D19: 42004 | E19: 0.049 | F19: =-0.049 -> -0.049 | G19: =E19+F19+I18 -> 0 | I19: =G19-H19 -> 0 | K19: 0.049 | L19: =-0.049 -> -0.049 | M19: =K19+L19+O18 -> 0 | O19: =M19-N19 -> 0 | Q19: 4.921 | R19: =-4.921 -> -4.921 | S19: =Q19+R19+U18 -> 0 | U19: =S19-T19 -> 0 | W19: 5.457 | X19: =-5.457 -> -5.457 | Y19: =W19+X19+AA18 -> 0 | AA19: =Y19-Z19 -> 0 | AC19: 8.21 | AD19: =-8.21 -> -8.21 | AE19: =AC19+AD19+AG18 -> 0 | AG19: =AE19-AF19 -> 0 | AI19: 7.163 | AJ19: =-7.163 -> -7.163 | AK19: =AI19+AJ19+AM18 -> 0 | AM19: =AK19-AL19 -> 0 | AO19: 6.651 | AP19: =-6.651 -> -6.651 | AQ19: =AO19+AP19+AS18 -> 0 | AS19: =AQ19-AR19 -> 0 | AU19: =E19+K19+Q19+W19+AC19+AI19+AO19 -> 32.5 | AV19: =F19+L19+R19+X19+AD19+AJ19+AP19 -> -32.5 | AX19: =AU19+AV19+AZ18+AW19 -> 0 | AY19: =H19+N19+T19+Z19+AF19+AL19+AR19 -> 0 | AZ19: =AX19-AY19 -> 0 | BA19: =AY19/AX19 -> #DIV/0!
B20: Grimar S.A. Pesq. | C20: 41640 | D20: 41882 | E20: 0.013 | G20: =E20+F20 -> 0.013 | I20: =G20-H20 -> 0.013 | J20: =E20+E21+F20+F21 -> 0.02 | K20: 0.007 | M20: =K20+L20 -> 0.007 | O20: =M20-N20 -> 0.007 | P20: =K20+K21+L20+L21 -> 0.014 | Q20: 0.701 | S20: =Q20+R20 -> 0.701 | U20: =S20-T20 -> 0.701 | V20: =Q20+Q21+R20+R21 -> 1.376 | W20: 1.276 | Y20: =W20+X20 -> 1.276 | AA20: =Y20-Z20 -> 1.276 | AB20: =W20+W21+X20+X21 -> 2.024 | AC20: 2.161 | AE20: =AC20+AD20 -> 2.161 | AG20: =AE20-AF20 -> 2.161 | AH20: =AC20+AC21+AD20+AD21 -> 3.287 | AI20: 1.82 | AK20: =AI20+AJ20 -> 1.82 | AM20: =AK20-AL20 -> 1.82 | AN20: =AI20+AI21+AJ20+AJ21 -> 2.802 | AO20: 1.777 | AQ20: =AO20+AP20 -> 1.777 | AS20: =AQ20-AR20 -> 1.777 | AT20: =AO20+AO21+AP20+AP21 -> 2.689 | AU20: =E20+K20+Q20+W20+AC20+AI20+AO20 -> 7.755 | AV20: =F20+L20+R20+X20+AD20+AJ20+AP20 -> 0 | AX20: =AU20+AV20+AW20 -> 7.755 | AY20: =H20+N20+T20+Z20+AF20+AL20+AR20 -> 0 | AZ20: =AX20-AY20 -> 7.755 | BA20: =AY20/AX20 -> 0 | BB20: =AU20+AU21+AV20+AV21+AW20+AW21 -> 12.212 | BC20: =AY20+AY21 -> 0 | BD20: =BB20-BC20 -> 12.212 | BE20: =BC20/BB20 -> 0
C21: 41883 | D21: 42004 | E21: 0.007 | G21: =E21+F21+I20 -> 0.02 | I21: =G21-H21 -> 0.02 | K21: 0.007 | M21: =K21+L21+O20 -> 0.014 | O21: =M21-N21 -> 0.014 | Q21: 0.675 | S21: =Q21+R21+U20 -> 1.376 | U21: =S21-T21 -> 1.376 | W21: 0.748 | Y21: =W21+X21+AA20 -> 2.024 | AA21: =Y21-Z21 -> 2.024 | AC21: 1.126 | AE21: =AC21+AD21+AG20 -> 3.287 | AG21: =AE21-AF21 -> 3.287 | AI21: 0.982 | AK21: =AI21+AJ21+AM20 -> 2.802 | AM21: =AK21-AL21 -> 2.802 | AO21: 0.912 | AQ21: =AO21+AP21+AS20 -> 2.689 | AS21: =AQ21-AR21 -> 2.689 | AU21: =E21+K21+Q21+W21+AC21+AI21+AO21 -> 4.457 | AV21: =F21+L21+R21+X21+AD21+AJ21+AP21 -> 0 | AX21: =AU21+AV21+AZ20+AW21 -> 12.212 | AY21: =H21+N21+T21+Z21+AF21+AL21+AR21 -> 0 | AZ21: =AX21-AY21 -> 12.212 | BA21: =AY21/AX21 -> 0
B22: Isladamas S.A. Pesq. | C22: 41640 | D22: 41882 | E22: 0.617 | F22: =0.097+0.173 -> 0.27 | G22: =E22+F22 -> 0.887 | I22: =G22-H22 -> 0.887 | J22: =E22+E23+F22+F23 -> 1.331 | K22: 0.308 | L22: =0.049+0.087 -> 0.136 | M22: =K22+L22 -> 0.444 | O22: =M22-N22 -> 0.444 | P22: =K22+K23+L22+L23 -> 0.888 | Q22: 32.385 | R22: =5.116+9.119 -> 14.235 | S22: =Q22+R22 -> 46.62 | T22: 27.99 | U22: =S22-T22 -> 18.63 | V22: =Q22+Q23+R22+R23 -> 88.95984 | W22: 58.91 | X22: =9.307+16.588 -> 25.895 | Y22: =W22+X22 -> 84.805 | Z22: 81.978 | AA22: =Y22-Z22 -> 2.827 | AB22: =W22+W23+X22+X23 -> 130.3246 | AC22: 99.777 | AD22: =15.763+28.096 -> 43.859 | AE22: =AC22+AD22 -> 143.636 | AF22: 135.505 | AG22: =AE22-AF22 -> 8.131 | AH22: =AC22+AC23+AD22+AD23 -> 218.45 | AI22: 84.047 | AJ22: =13.278+23.667 -> 36.945 | AK22: =AI22+AJ22 -> 120.992 | AL22: 109.482 | AM22: =AK22-AL22 -> 11.51 | AN22: =AI22+AI23+AJ22+AJ23 -> 191.165 | AO22: 82.042 | AP22: =12.961+23.102 -> 36.063 | AQ22: =AO22+AP22 -> 118.105 | AR22: 88.767 | AS22: =AQ22-AR22 -> 29.338 | AT22: =AO22+AO23+AP22+AP23 -> 174.5036 | AU22: =E22+K22+Q22+W22+AC22+AI22+AO22 -> 358.086 | AV22: =F22+L22+R22+X22+AD22+AJ22+AP22 -> 157.403 | AW22: =-0.03478 -> -0.03478 | AX22: =AU22+AV22+AW22 -> 515.45422 | AY22: =H22+N22+T22+Z22+AF22+AL22+AR22 -> 443.722 | AZ22: =AX22-AY22 -> 71.73222 | BA22: =AY22/AX22 -> 0.86083688 | BB22: =AU22+AU23+AV22+AV23+AW22+AW23 -> 805.58726 | BC22: =AY22+AY23 -> 711.607 | BD22: =BB22-BC22 -> 93.98026 | BE22: =BC22/BB22 -> 0.88333944
C23: 41883 | D23: 42004 | E23: 0.308 | F23: =0.049+0.087 -> 0.136 | G23: =E23+F23+I22 -> 1.331 | I23: =G23-H23 -> 1.331 | K23: 0.308 | L23: =0.049+0.087 -> 0.136 | M23: =K23+L23+O22 -> 0.888 | O23: =M23-N23 -> 0.888 | Q23: 31.151 | R23: =4.921+8.772-2.50416 -> 11.18884 | S23: =Q23+R23+U22 -> 60.96984 | T23: 13.972 | U23: =S23-T23 -> 46.99784 | W23: 34.544 | X23: =5.457+9.727-4.2084 -> 10.9756 | Y23: =W23+X23+AA22 -> 48.3466 | Z23: 35.731 | AA23: =Y23-Z23 -> 12.6156 | AC23: 51.97 | AD23: =8.21+14.634 -> 22.844 | AE23: =AC23+AD23+AG22 -> 82.945 | AF23: 77.344 | AG23: =AE23-AF23 -> 5.601 | AI23: 45.339 | AJ23: =7.163+12.767+4.904 -> 24.834 | AK23: =AI23+AJ23+AM22 -> 81.683 | AL23: 81.769 | AM23: =AK23-AL23 -> -0.086 | AO23: 42.101 | AP23: =6.651+11.855-4.2084 -> 14.2976 | AQ23: =AO23+AP23+AS22 -> 85.7366 | AR23: 59.069 | AS23: =AQ23-AR23 -> 26.6676 | AU23: =E23+K23+Q23+W23+AC23+AI23+AO23 -> 205.721 | AV23: =F23+L23+R23+X23+AD23+AJ23+AP23 -> 84.41204 | AX23: =AU23+AV23+AZ22+AW23 -> 361.86526 | AY23: =H23+N23+T23+Z23+AF23+AL23+AR23 -> 267.885 | AZ23: =AX23-AY23 -> 93.98026 | BA23: =AY23/AX23 -> 0.74028936
B24: Landes S.A. Soc. Pesq. | C24: 41640 | D24: 41882 | E24: 0.007 | G24: =E24+F24 -> 0.007 | I24: =G24-H24 -> 0.007 | J24: =E24+E25+F24+F25 -> 0.011 | K24: 0.004 | M24: =K24+L24 -> 0.004 | O24: =M24-N24 -> 0.004 | P24: =K24+K25+L24+L25 -> 0.008 | Q24: 0.383 | S24: =Q24+R24 -> 0.383 | U24: =S24-T24 -> 0.383 | V24: =Q24+Q25+R24+R25 -> 0.751 | W24: 0.696 | Y24: =W24+X24 -> 0.696 | AA24: =Y24-Z24 -> 0.696 | AB24: =W24+W25+X24+X25 -> 1.104 | AC24: 1.18 | AE24: =AC24+AD24 -> 1.18 | AG24: =AE24-AF24 -> 1.18 | AH24: =AC24+AC25+AD24+AD25 -> 1.794 | AI24: 0.994 | AK24: =AI24+AJ24 -> 0.994 | AM24: =AK24-AL24 -> 0.994 | AN24: =AI24+AI25+AJ24+AJ25 -> 1.53 | AO24: 0.97 | AQ24: =AO24+AP24 -> 0.97 | AS24: =AQ24-AR24 -> 0.97 | AT24: =AO24+AO25+AP24+AP25 -> 1.468 | AU24: =E24+K24+Q24+W24+AC24+AI24+AO24 -> 4.234 | AV24: =F24+L24+R24+X24+AD24+AJ24+AP24 -> 0 | AX24: =AU24+AV24+AW24 -> 4.234 | AY24: =H24+N24+T24+Z24+AF24+AL24+AR24 -> 0 | AZ24: =AX24-AY24 -> 4.234 | BA24: =AY24/AX24 -> 0 | BB24: =AU24+AU25+AV24+AV25+AW24+AW25 -> 6.666 | BC24: =AY24+AY25 -> 0 | BD24: =BB24-BC24 -> 6.666 | BE24: =BC24/BB24 -> 0
C25: 41883 | D25: 42004 | E25: 0.004 | G25: =E25+F25+I24 -> 0.011 | I25: =G25-H25 -> 0.011 | K25: 0.004 | M25: =K25+L25+O24 -> 0.008 | O25: =M25-N25 -> 0.008 | Q25: 0.368 | S25: =Q25+R25+U24 -> 0.751 | U25: =S25-T25 -> 0.751 | W25: 0.408 | Y25: =W25+X25+AA24 -> 1.104 | AA25: =Y25-Z25 -> 1.104 | AC25: 0.614 | AE25: =AC25+AD25+AG24 -> 1.794 | AG25: =AE25-AF25 -> 1.794 | AI25: 0.536 | AK25: =AI25+AJ25+AM24 -> 1.53 | AM25: =AK25-AL25 -> 1.53 | AO25: 0.498 | AQ25: =AO25+AP25+AS24 -> 1.468 | AS25: =AQ25-AR25 -> 1.468 | AU25: =E25+K25+Q25+W25+AC25+AI25+AO25 -> 2.432 | AV25: =F25+L25+R25+X25+AD25+AJ25+AP25 -> 0 | AX25: =AU25+AV25+AZ24+AW25 -> 6.666 | AY25: =H25+N25+T25+Z25+AF25+AL25+AR25 -> 0 | AZ25: =AX25-AY25 -> 6.666 | BA25: =AY25/AX25 -> 0
B26: Morozin Baycic Maria Ana | C26: 41640 | D26: 41882 | E26: 0.153 | F26: =-0.153 -> -0.153 | G26: =E26+F26 -> 0 | I26: =G26-H26 -> 0 | J26: =E26+E27+F26+F27 -> 0 | K26: 0.076 | L26: =-0.076 -> -0.076 | M26: =K26+L26 -> 0 | O26: =M26-N26 -> 0 | P26: =K26+K27+L26+L27 -> 0 | Q26: 8.026 | R26: =-8.026 -> -8.026 | S26: =Q26+R26 -> 0 | U26: =S26-T26 -> 0 | V26: =Q26+Q27+R26+R27 -> 0 | W26: 14.599 | X26: =-14.599 -> -14.599 | Y26: =W26+X26 -> 0 | AA26: =Y26-Z26 -> 0 | AB26: =W26+W27+X26+X27 -> 0 | AC26: 24.727 | AD26: =-24.727 -> -24.727 | AE26: =AC26+AD26 -> 0 | AG26: =AE26-AF26 -> 0 | AH26: =AC26+AC27+AD26+AD27 -> 0 | AI26: 20.829 | AJ26: =-20.829 -> -20.829 | AK26: =AI26+AJ26 -> 0 | AM26: =AK26-AL26 -> 0 | AN26: =AI26+AI27+AJ26+AJ27 -> 0 | AO26: 20.332 | AP26: =-20.332 -> -20.332 | AQ26: =AO26+AP26 -> 0 | AS26: =AQ26-AR26 -> 0 | AT26: =AO26+AO27+AP26+AP27 -> 0 | AU26: =E26+K26+Q26+W26+AC26+AI26+AO26 -> 88.742 | AV26: =F26+L26+R26+X26+AD26+AJ26+AP26 -> -88.742 | AX26: =AU26+AV26+AW26 -> 0 | AY26: =H26+N26+T26+Z26+AF26+AL26+AR26 -> 0 | AZ26: =AX26-AY26 -> 0 | BA26: =AY26/AX26 -> #DIV/0! | BB26: =AU26+AU27+AV26+AV27+AW26+AW27 -> 0 | BC26: =AY26+AY27 -> 0 | BD26: =BB26-BC26 -> 0 | BE26: =BC26/BB26 -> #DIV/0!
C27: 41883 | D27: 42004 | E27: 0.076 | F27: =-0.076 -> -0.076 | G27: =E27+F27+I26 -> 0 | I27: =G27-H27 -> 0 | K27: 0.076 | L27: =-0.076 -> -0.076 | M27: =K27+L27+O26 -> 0 | O27: =M27-N27 -> 0 | Q27: 7.72 | R27: =-7.72 -> -7.72 | S27: =Q27+R27+U26 -> 0 | U27: =S27-T27 -> 0 | W27: 8.561 | X27: =-8.561 -> -8.561 | Y27: =W27+X27+AA26 -> 0 | AA27: =Y27-Z27 -> 0 | AC27: 12.88 | AD27: =-12.88 -> -12.88 | AE27: =AC27+AD27+AG26 -> 0 | AG27: =AE27-AF27 -> 0 | AI27: 11.236 | AJ27: =-11.236 -> -11.236 | AK27: =AI27+AJ27+AM26 -> 0 | AM27: =AK27-AL27 -> 0 | AO27: 10.434 | AP27: =-10.434 -> -10.434 | AQ27: =AO27+AP27+AS26 -> 0 | AS27: =AQ27-AR27 -> 0 | AU27: =E27+K27+Q27+W27+AC27+AI27+AO27 -> 50.983 | AV27: =F27+L27+R27+X27+AD27+AJ27+AP27 -> -50.983 | AX27: =AU27+AV27+AZ26+AW27 -> 0 | AY27: =H27+N27+T27+Z27+AF27+AL27+AR27 -> 0 | AZ27: =AX27-AY27 -> 0 | BA27: =AY27/AX27 -> #DIV/0!
B28: Morozin Yurecic Mario | C28: 41640 | D28: 41882 | E28: 0.345 | F28: =-0.345 -> -0.345 | G28: =E28+F28 -> 0 | I28: =G28-H28 -> 0 | J28: =E28+E29+F28+F29 -> 0 | K28: 0.172 | L28: =-0.172 -> -0.172 | M28: =K28+L28 -> 0 | O28: =M28-N28 -> 0 | P28: =K28+K29+L28+L29 -> 0 | Q28: 18.101 | R28: =-18.101 -> -18.101 | S28: =Q28+R28 -> 0 | U28: =S28-T28 -> 0 | V28: =Q28+Q29+R28+R29 -> 0 | W28: 32.927 | X28: =-32.927 -> -32.927 | Y28: =W28+X28 -> 0 | AA28: =Y28-Z28 -> 0 | AB28: =W28+W29+X28+X29 -> 0 | AC28: 55.769 | AD28: =-55.769 -> -55.769 | AE28: =AC28+AD28 -> 0 | AG28: =AE28-AF28 -> 0 | AH28: =AC28+AC29+AD28+AD29 -> 0 | AI28: 46.977 | AJ28: =-46.977 -> -46.977 | AK28: =AI28+AJ28 -> 0 | AM28: =AK28-AL28 -> 0 | AN28: =AI28+AI29+AJ28+AJ29 -> 0 | AO28: 45.856 | AP28: =-45.856 -> -45.856 | AQ28: =AO28+AP28 -> 0 | AS28: =AQ28-AR28 -> 0 | AT28: =AO28+AO29+AP28+AP29 -> 0 | AU28: =E28+K28+Q28+W28+AC28+AI28+AO28 -> 200.147 | AV28: =F28+L28+R28+X28+AD28+AJ28+AP28 -> -200.147 | AX28: =AU28+AV28+AW28 -> 0 | AY28: =H28+N28+T28+Z28+AF28+AL28+AR28 -> 0 | AZ28: =AX28-AY28 -> 0 | BA28: =AY28/AX28 -> #DIV/0! | BB28: =AU28+AU29+AV28+AV29+AW28+AW29 -> 0 | BC28: =AY28+AY29 -> 0 | BD28: =BB28-BC28 -> 0 | BE28: =BC28/BB28 -> #DIV/0!
C29: 41883 | D29: 42004 | E29: 0.172 | F29: =-0.172 -> -0.172 | G29: =E29+F29+I28 -> 0 | I29: =G29-H29 -> 0 | K29: 0.172 | L29: =-0.172 -> -0.172 | M29: =K29+L29+O28 -> 0 | O29: =M29-N29 -> 0 | Q29: 17.412 | R29: =-17.412 -> -17.412 | S29: =Q29+R29+U28 -> 0 | U29: =S29-T29 -> 0 | W29: 19.308 | X29: =-19.308 -> -19.308 | Y29: =W29+X29+AA28 -> 0 | AA29: =Y29-Z29 -> 0 | AC29: 29.048 | AD29: =-29.048 -> -29.048 | AE29: =AC29+AD29+AG28 -> 0 | AG29: =AE29-AF29 -> 0 | AI29: 25.342 | AJ29: =-25.342 -> -25.342 | AK29: =AI29+AJ29+AM28 -> 0 | AM29: =AK29-AL29 -> 0 | AO29: 23.532 | AP29: =-23.532 -> -23.532 | AQ29: =AO29+AP29+AS28 -> 0 | AS29: =AQ29-AR29 -> 0 | AU29: =E29+K29+Q29+W29+AC29+AI29+AO29 -> 114.986 | AV29: =F29+L29+R29+X29+AD29+AJ29+AP29 -> -114.986 | AX29: =AU29+AV29+AZ28+AW29 -> 0 | AY29: =H29+N29+T29+Z29+AF29+AL29+AR29 -> 0 | AZ29: =AX29-AY29 -> 0 | BA29: =AY29/AX29 -> #DIV/0!
B30: Quintero Ltda. Soc. Pesq. | C30: 41640 | D30: 41882 | E30: 0.083 | F30: =-0.083 -> -0.083 | G30: =E30+F30 -> 0 | I30: =G30-H30 -> 0 | J30: =E30+E31+F30+F31 -> 0 | K30: 0.041 | L30: =-0.041 -> -0.041 | M30: =K30+L30 -> 0 | O30: =M30-N30 -> 0 | P30: =K30+K31+L30+L31 -> 0 | Q30: 4.333 | R30: =-4.333 -> -4.333 | S30: =Q30+R30 -> 0 | U30: =S30-T30 -> 0 | V30: =Q30+Q31+R30+R31 -> 0 | W30: 7.883 | X30: =-7.883 -> -7.883 | Y30: =W30+X30 -> 0 | AA30: =Y30-Z30 -> 0 | AB30: =W30+W31+X30+X31 -> 0 | AC30: 13.351 | AD30: =-13.351 -> -13.351 | AE30: =AC30+AD30 -> 0 | AG30: =AE30-AF30 -> 0 | AH30: =AC30+AC31+AD30+AD31 -> 0 | AI30: 11.246 | AJ30: =-11.246 -> -11.246 | AK30: =AI30+AJ30 -> 0 | AM30: =AK30-AL30 -> 0 | AN30: =AI30+AI31+AJ30+AJ31 -> 0 | AO30: 10.978 | AP30: =-10.978 -> -10.978 | AQ30: =AO30+AP30 -> 0 | AS30: =AQ30-AR30 -> 0 | AT30: =AO30+AO31+AP30+AP31 -> 0 | AU30: =E30+K30+Q30+W30+AC30+AI30+AO30 -> 47.915 | AV30: =F30+L30+R30+X30+AD30+AJ30+AP30 -> -47.915 | AX30: =AU30+AV30+AW30 -> 0 | AY30: =H30+N30+T30+Z30+AF30+AL30+AR30 -> 0 | AZ30: =AX30-AY30 -> 0 | BA30: =AY30/AX30 -> #DIV/0! | BB30: =AU30+AU31+AV30+AV31+AW30+AW31 -> 0 | BC30: =AY30+AY31 -> 0 | BD30: =BB30-BC30 -> 0 | BE30: =BC30/BB30 -> #DIV/0!
C31: 41883 | D31: 42004 | E31: 0.041 | F31: =-0.041 -> -0.041 | G31: =E31+F31+I30 -> 0 | I31: =G31-H31 -> 0 | K31: 0.041 | L31: =-0.041 -> -0.041 | M31: =K31+L31+O30 -> 0 | O31: =M31-N31 -> 0 | Q31: 4.168 | R31: =-4.168 -> -4.168 | S31: =Q31+R31+U30 -> 0 | U31: =S31-T31 -> 0 | W31: 4.622 | X31: =-4.622 -> -4.622 | Y31: =W31+X31+AA30 -> 0 | AA31: =Y31-Z31 -> 0 | AC31: 6.954 | AD31: =-6.954 -> -6.954 | AE31: =AC31+AD31+AG30 -> 0 | AG31: =AE31-AF31 -> 0 | AI31: 6.067 | AJ31: =-6.067 -> -6.067 | AK31: =AI31+AJ31+AM30 -> 0 | AM31: =AK31-AL31 -> 0 | AO31: 5.634 | AP31: =-5.634 -> -5.634 | AQ31: =AO31+AP31+AS30 -> 0 | AS31: =AQ31-AR31 -> 0 | AU31: =E31+K31+Q31+W31+AC31+AI31+AO31 -> 27.527 | AV31: =F31+L31+R31+X31+AD31+AJ31+AP31 -> -27.527 | AX31: =AU31+AV31+AZ30+AW31 -> 0 | AY31: =H31+N31+T31+Z31+AF31+AL31+AR31 -> 0 | AZ31: =AX31-AY31 -> 0 | BA31: =AY31/AX31 -> #DIV/0!
B32: Quintero S.A., Pesquera | C32: 41640 | D32: 41882 | E32: 0.601 | F32: =0.267+0.153+0.345+0.083 -> 0.848 | G32: =E32+F32 -> 1.449 | I32: =G32-H32 -> 1.449 | J32: =E32+E33+F32+F33 -> 2.172 | K32: 0.301 | L32: =0.133+0.076+0.172+0.041 -> 0.422 | M32: =K32+L32 -> 0.723 | O32: =M32-N32 -> 0.723 | P32: =K32+K33+L32+L33 -> 1.986 | Q32: 31.575 | R32: =13.993+8.026+18.101+4.333 -> 44.453 | S32: =Q32+R32 -> 76.028 | T32: 74.98 | U32: =S32-T32 -> 1.048 | V32: =Q32+Q33+R32+R33 -> 149.16 | W32: 57.436 | X32: =25.454+14.599+32.927+7.883-17.529 -> 63.334 | Y32: =W32+X32 -> 120.77 | Z32: 132.99 | AA32: =Y32-Z32 -> -12.22 | AB32: =W32+W33+X32+X33 -> 211.867 | AC32: 97.28 | AD32: =43.112+24.727+55.769+13.351+7.529 -> 144.488 | AE32: =AC32+AD32 -> 241.768 | AF32: 233.312 | AG32: =AE32-AF32 -> 8.456 | AH32: =AC32+AC33+AD32+AD33 -> 373.775 | AI32: 81.994 | AJ32: =36.315+20.829+46.977+11.246 -> 115.367 | AK32: =AI32+AJ32 -> 197.361 | AL32: 196.628 | AM32: =AK32-AL32 -> 0.733 | AN32: =AI32+AI33+AJ32+AJ33 -> 293.8 | AO32: 79.989 | AP32: =35.449+20.332+45.856+10.978 -> 112.615 | AQ32: =AO32+AP32 -> 192.604 | AR32: 190.931 | AS32: =AQ32-AR32 -> 1.673 | AT32: =AO32+AO33+AP32+AP33 -> 291.442 | AU32: =E32+K32+Q32+W32+AC32+AI32+AO32 -> 349.176 | AV32: =F32+L32+R32+X32+AD32+AJ32+AP32 -> 481.527 | AW32: =-0.0348 -> -0.0348 | AX32: =AU32+AV32+AW32 -> 830.6682 | AY32: =H32+N32+T32+Z32+AF32+AL32+AR32 -> 828.841 | AZ32: =AX32-AY32 -> 1.8272 | BA32: =AY32/AX32 -> 0.99780033 | BB32: =AU32+AU33+AV32+AV33+AW32+AW33 -> 1324.1672 | BC32: =AY32+AY33 -> 1309.204 | BD32: =BB32-BC32 -> 14.9632 | BE32: =BC32/BB32 -> 0.98869992
C33: 41883 | D33: 42004 | E33: 0.301 | F33: =0.133+0.076+0.172+0.041 -> 0.422 | G33: =E33+F33+I32 -> 2.172 | I33: =G33-H33 -> 2.172 | K33: 0.301 | L33: =0.133+0.076+0.712+0.041 -> 0.962 | M33: =K33+L33+O32 -> 1.986 | O33: =M33-N33 -> 1.986 | Q33: 30.372 | R33: =13.46+7.72+17.412+4.168 -> 42.76 | S33: =Q33+R33+U32 -> 74.18 | T33: 72.669 | U33: =S33-T33 -> 1.511 | W33: 33.68 | X33: =14.926+8.561+19.308+4.622+10 -> 57.417 | Y33: =W33+X33+AA32 -> 78.877 | Z33: 78.839 | AA33: =Y33-Z33 -> 0.038 | AC33: 50.67 | AD33: =22.455+12.88+29.048+6.954+10 -> 81.337 | AE33: =AC33+AD33+AG32 -> 140.463 | AF33: 137.606 | AG33: =AE33-AF33 -> 2.857 | AI33: 44.204 | AJ33: =19.59+11.236+25.342+6.067-10 -> 52.235 | AK33: =AI33+AJ33+AM32 -> 97.172 | AL33: 95.687 | AM33: =AK33-AL33 -> 1.485 | AO33: 41.047 | AP33: =18.191+10.434+23.532+5.634 -> 57.791 | AQ33: =AO33+AP33+AS32 -> 100.511 | AR33: 95.562 | AS33: =AQ33-AR33 -> 4.949 | AU33: =E33+K33+Q33+W33+AC33+AI33+AO33 -> 200.575 | AV33: =F33+L33+R33+X33+AD33+AJ33+AP33 -> 292.924 | AX33: =AU33+AV33+AZ32+AW33 -> 495.3262 | AY33: =H33+N33+T33+Z33+AF33+AL33+AR33 -> 480.363 | AZ33: =AX33-AY33 -> 14.9632 | BA33: =AY33/AX33 -> 0.96979122
B34: Rubio y Mauad Ltda. | C34: 41640 | D34: 41882 | E34: 0.147 | G34: =E34+F34 -> 0.147 | I34: =G34-H34 -> 0.147 | J34: =E34+E35+F34+F35 -> 0.22 | K34: 0.073 | L34: =-4.216 -> -4.216 | M34: =K34+L34 -> -4.143 | O34: =M34-N34 -> -4.143 | P34: =K34+K35+L34+L35 -> 0.146 | Q34: 7.698 | R34: =-6.817 -> -6.817 | S34: =Q34+R34 -> 0.881 | T34: 3.665 | U34: =S34-T34 -> -2.784 | V34: =Q34+Q35+R34+R35 -> 38.286 | W34: 14.003 | X34: =17.529 -> 17.529 | Y34: =W34+X34 -> 31.532 | Z34: 25.802 | AA34: =Y34-Z34 -> 5.73 | AB34: =W34+W35+X34+X35 -> 39.743 | AC34: 23.717 | AD34: =-0.8-7.529 -> -8.329 | AE34: =AC34+AD34 -> 15.388 | AF34: 14.889 | AG34: =AE34-AF34 -> 0.499 | AH34: =AC34+AC35+AD34+AD35 -> 17.741 | AI34: 19.978 | AJ34: =-19.978 -> -19.978 | AK34: =AI34+AJ34 -> 0 | AM34: =AK34-AL34 -> 0 | AN34: =AI34+AI35+AJ34+AJ35 -> 2.653 | AO34: 19.501 | AP34: =-19.502 -> -19.502 | AQ34: =AO34+AP34 -> -0.001 | AS34: =AQ34-AR34 -> -0.001 | AT34: =AO34+AO35+AP34+AP35 -> 1.962 | AU34: =E34+K34+Q34+W34+AC34+AI34+AO34 -> 85.117 | AV34: =F34+L34+R34+X34+AD34+AJ34+AP34 -> -41.313 | AX34: =AU34+AV34+AW34 -> 43.804 | AY34: =H34+N34+T34+Z34+AF34+AL34+AR34 -> 44.356 | AZ34: =AX34-AY34 -> -0.552 | BA34: =AY34/AX34 -> 1.0126016 | BB34: =AU34+AU35+AV34+AV35+AW34+AW35 -> 100.751 | BC34: =AY34+AY35 -> 50.579 | BD34: =BB34-BC34 -> 50.172 | BE34: =BC34/BB34 -> 0.50201983
C35: 41883 | D35: 42004 | E35: 0.073 | G35: =E35+F35+I34 -> 0.22 | I35: =G35-H35 -> 0.22 | K35: 0.073 | L35: =-1.488+5.704 -> 4.216 | M35: =K35+L35+O34 -> 0.146 | O35: =M35-N35 -> 0.146 | Q35: 7.405 | R35: =30 -> 30 | S35: =Q35+R35+U34 -> 34.621 | T35: 6.223 | U35: =S35-T35 -> 28.398 | W35: 8.211 | Y35: =W35+X35+AA34 -> 13.941 | AA35: =Y35-Z35 -> 13.941 | AC35: 12.353 | AD35: =-10 -> -10 | AE35: =AC35+AD35+AG34 -> 2.852 | AG35: =AE35-AF35 -> 2.852 | AI35: 10.777 | AJ35: =-8.124 -> -8.124 | AK35: =AI35+AJ35+AM34 -> 2.653 | AM35: =AK35-AL35 -> 2.653 | AO35: 10.007 | AP35: =-8.044 -> -8.044 | AQ35: =AO35+AP35+AS34 -> 1.962 | AS35: =AQ35-AR35 -> 1.962 | AU35: =E35+K35+Q35+W35+AC35+AI35+AO35 -> 48.899 | AV35: =F35+L35+R35+X35+AD35+AJ35+AP35 -> 8.048 | AX35: =AU35+AV35+AZ34+AW35 -> 56.395 | AY35: =H35+N35+T35+Z35+AF35+AL35+AR35 -> 6.223 | AZ35: =AX35-AY35 -> 50.172 | BA35: =AY35/AX35 -> 0.11034666
B36: Sunrise S.A. Pesq. | C36: 41640 | D36: 41882 | E36: 0.174 | F36: =-0.173 -> -0.173 | G36: =E36+F36 -> 0.001 | I36: =G36-H36 -> 0.001 | J36: =E36+E37+F36+F37 -> 0.001 | K36: 0.087 | L36: =-0.087 -> -0.087 | M36: =K36+L36 -> 0 | O36: =M36-N36 -> 0 | P36: =K36+K37+L36+L37 -> 0 | Q36: 9.119 | R36: =-9.119 -> -9.119 | S36: =Q36+R36 -> 0 | U36: =S36-T36 -> 0 | V36: =Q36+Q37+R36+R37 -> 0 | W36: 16.588 | X36: =-16.588 -> -16.588 | Y36: =W36+X36 -> 0 | AA36: =Y36-Z36 -> 0 | AB36: =W36+W37+X36+X37 -> 0 | AC36: 28.096 | AD36: =-28.096 -> -28.096 | AE36: =AC36+AD36 -> 0 | AG36: =AE36-AF36 -> 0 | AH36: =AC36+AC37+AD36+AD37 -> 0 | AI36: 23.667 | AJ36: =-23.667 -> -23.667 | AK36: =AI36+AJ36 -> 0 | AM36: =AK36-AL36 -> 0 | AN36: =AI36+AI37+AJ36+AJ37 -> 0 | AO36: 23.102 | AP36: =-23.102 -> -23.102 | AQ36: =AO36+AP36 -> 0 | AS36: =AQ36-AR36 -> 0 | AT36: =AO36+AO37+AP36+AP37 -> 0 | AU36: =E36+K36+Q36+W36+AC36+AI36+AO36 -> 100.833 | AV36: =F36+L36+R36+X36+AD36+AJ36+AP36 -> -100.832 | AX36: =AU36+AV36+AW36 -> 0.001 | AY36: =H36+N36+T36+Z36+AF36+AL36+AR36 -> 0 | AZ36: =AX36-AY36 -> 0.001 | BA36: =AY36/AX36 -> 0 | BB36: =AU36+AU37+AV36+AV37+AW36+AW37 -> 0.001 | BC36: =AY36+AY37 -> 0.031 | BD36: =BB36-BC36 -> -0.03 | BE36: =BC36/BB36 -> 31
C37: 41883 | D37: 42004 | E37: 0.087 | F37: =-0.087 -> -0.087 | G37: =E37+F37+I36 -> 0.001 | I37: =G37-H37 -> 0.001 | K37: 0.087 | L37: =-0.087 -> -0.087 | M37: =K37+L37+O36 -> 0 | O37: =M37-N37 -> 0 | Q37: 8.772 | R37: =-8.772 -> -8.772 | S37: =Q37+R37+U36 -> 0 | U37: =S37-T37 -> 0 | W37: 9.727 | X37: =-9.727 -> -9.727 | Y37: =W37+X37+AA36 -> 0 | AA37: =Y37-Z37 -> 0 | AC37: 14.634 | AD37: =-14.634 -> -14.634 | AE37: =AC37+AD37+AG36 -> 0 | AG37: =AE37-AF37 -> 0 | AI37: 12.767 | AJ37: =-12.767 -> -12.767 | AK37: =AI37+AJ37+AM36 -> 0 | AM37: =AK37-AL37 -> 0 | AO37: 11.855 | AP37: =-11.855 -> -11.855 | AQ37: =AO37+AP37+AS36 -> 0 | AR37: 0.031 | AS37: =AQ37-AR37 -> -0.031 | AU37: =E37+K37+Q37+W37+AC37+AI37+AO37 -> 57.929 | AV37: =F37+L37+R37+X37+AD37+AJ37+AP37 -> -57.929 | AX37: =AU37+AV37+AZ36+AW37 -> 0.001 | AY37: =H37+N37+T37+Z37+AF37+AL37+AR37 -> 0.031 | AZ37: =AX37-AY37 -> -0.03 | BA37: =AY37/AX37 -> 31
B38: Congelados del Pacifico | C38: 41640 | D38: 41882 | E38: 0 | G38: =E38+F38 -> 0 | I38: =G38-H38 -> 0 | J38: =E38+E39+F38+F39 -> 0 | K38: 0 | M38: =K38+L38 -> 0 | O38: =M38-N38 -> 0 | P38: =K38+K39+L38+L39 -> 0 | Q38: 0 | S38: =Q38+R38 -> 0 | U38: =S38-T38 -> 0 | V38: =Q38+Q39+R38+R39 -> 0 | W38: 0 | Y38: =W38+X38 -> 0 | AA38: =Y38-Z38 -> 0 | AB38: =W38+W39+X38+X39 -> 0 | AC38: 0 | AE38: =AC38+AD38 -> 0 | AG38: =AE38-AF38 -> 0 | AH38: =AC38+AC39+AD38+AD39 -> 0 | AI38: 0 | AK38: =AI38+AJ38 -> 0 | AM38: =AK38-AL38 -> 0 | AN38: =AI38+AI39+AJ38+AJ39 -> 0 | AO38: 0 | AQ38: =AO38+AP38 -> 0 | AS38: =AQ38-AR38 -> 0 | AT38: =AO38+AO39+AP38+AP39 -> 0 | AU38: =E38+K38+Q38+W38+AC38+AI38+AO38 -> 0 | AV38: =F38+L38+R38+X38+AD38+AJ38+AP38 -> 0 | AW38: =0.7652 -> 0.7652 | AX38: =AU38+AV38+AW38 -> 0.7652 | AY38: =H38+N38+T38+Z38+AF38+AL38+AR38 -> 0 | AZ38: =AX38-AY38 -> 0.7652 | BA38: =AY38/AX38 -> 0 | BB38: =AU38+AU39+AV38+AV39+AW38+AW39 -> 0.7652 | BC38: =AY38+AY39 -> 0 | BD38: =BB38-BC38 -> 0.7652 | BE38: =BC38/BB38 -> 0
C39: 41883 | D39: 42004 | E39: 0 | G39: =E39+F39+I38 -> 0 | I39: =G39-H39 -> 0 | K39: 0 | M39: =K39+L39+O38 -> 0 | O39: =M39-N39 -> 0 | Q39: 0 | S39: =Q39+R39+U38 -> 0 | U39: =S39-T39 -> 0 | W39: 0 | Y39: =W39+X39+AA38 -> 0 | AA39: =Y39-Z39 -> 0 | AC39: 0 | AE39: =AC39+AD39+AG38 -> 0 | AG39: =AE39-AF39 -> 0 | AI39: 0 | AK39: =AI39+AJ39+AM38 -> 0 | AM39: =AK39-AL39 -> 0 | AO39: 0 | AQ39: =AO39+AP39+AS38 -> 0 | AS39: =AQ39-AR39 -> 0 | AU39: =E39+K39+Q39+W39+AC39+AI39+AO39 -> 0 | AV39: =F39+L39+R39+X39+AD39+AJ39+AP39 -> 0 | AX39: =AU39+AV39+AZ38+AW39 -> 0.7652 | AY39: =H39+N39+T39+Z39+AF39+AL39+AR39 -> 0 | AZ39: =AX39-AY39 -> 0.7652 | BA39: =AY39/AX39 -> 0
B40: Enfemar Ltda. Soc. Pesq. | C40: 41640 | D40: 41882 | E40: 0 | G40: =E40+F40 -> 0 | I40: =G40-H40 -> 0 | J40: =E40+E41+F40+F41 -> 0 | K40: 0 | M40: =K40+L40 -> 0 | O40: =M40-N40 -> 0 | P40: =K40+K41+L40+L41 -> 0 | Q40: 0 | S40: =Q40+R40 -> 0 | U40: =S40-T40 -> 0 | V40: =Q40+Q41+R40+R41 -> 0 | W40: 0 | Y40: =W40+X40 -> 0 | AA40: =Y40-Z40 -> 0 | AB40: =W40+W41+X40+X41 -> 0 | AC40: 0 | AE40: =AC40+AD40 -> 0 | AG40: =AE40-AF40 -> 0 | AH40: =AC40+AC41+AD40+AD41 -> 0 | AI40: 0 | AK40: =AI40+AJ40 -> 0 | AM40: =AK40-AL40 -> 0 | AN40: =AI40+AI41+AJ40+AJ41 -> 0 | AO40: 0 | AQ40: =AO40+AP40 -> 0 | AS40: =AQ40-AR40 -> 0 | AT40: =AO40+AO41+AP40+AP41 -> 0 | AU40: =E40+K40+Q40+W40+AC40+AI40+AO40 -> 0 | AV40: =F40+L40+R40+X40+AD40+AJ40+AP40 -> 0 | AW40: =0.0348 -> 0.0348 | AX40: =AU40+AV40+AW40 -> 0.0348 | AY40: =H40+N40+T40+Z40+AF40+AL40+AR40 -> 0 | AZ40: =AX40-AY40 -> 0.0348 | BA40: =AY40/AX40 -> 0 | BB40: =AU40+AU41+AV40+AV41+AW40+AW41 -> 0.0348 | BC40: =AY40+AY41 -> 0 | BD40: =BB40-BC40 -> 0.0348 | BE40: =BC40/BB40 -> 0
C41: 41883 | D41: 42004 | E41: 0 | G41: =E41+F41+I40 -> 0 | I41: =G41-H41 -> 0 | K41: 0 | M41: =K41+L41+O40 -> 0 | O41: =M41-N41 -> 0 | Q41: 0 | S41: =Q41+R41+U40 -> 0 | U41: =S41-T41 -> 0 | W41: 0 | Y41: =W41+X41+AA40 -> 0 | AA41: =Y41-Z41 -> 0 | AC41: 0 | AE41: =AC41+AD41+AG40 -> 0 | AG41: =AE41-AF41 -> 0 | AI41: 0 | AK41: =AI41+AJ41+AM40 -> 0 | AM41: =AK41-AL41 -> 0 | AO41: 0 | AQ41: =AO41+AP41+AS40 -> 0 | AS41: =AQ41-AR41 -> 0 | AU41: =E41+K41+Q41+W41+AC41+AI41+AO41 -> 0 | AV41: =F41+L41+R41+X41+AD41+AJ41+AP41 -> 0 | AX41: =AU41+AV41+AZ40+AW41 -> 0.0348 | AY41: =H41+N41+T41+Z41+AF41+AL41+AR41 -> 0 | AZ41: =AX41-AY41 -> 0.0348 | BA41: =AY41/AX41 -> 0
...

Sheet Demersales LTP 
B2: 2014. CUOTAS LTP Y SU CONSUMO DE RECURSOS PECES DEMERSALES al 31 de Diciembre de 2014.
C5: Periodo | E5: Cuota (t) | H5: Operación | K5: Global
A6: Unidad de pesquería | B6: Armador | C6: Inicial | D6: Final | E6: Cuota Asignada | F6: Traspaso, Cesion, Arriendo, etc) | G6: Cuota Efectiva | H6: Desembarque (t) | I6: Saldo (t) | J6: % consumido | K6: Cuota Total | L6: Desembarque (t) | M6: Saldo (t) | N6: % consumido
A7: Congrio dorado NE H/F (41º28,6 LS hasta 47º) | B7: Emdepes S.A. | C7: 41640 | D7: 41698 | E7: 0.469 | F7: =0.949 -> 0.949 | G7: =E7+F7 -> 1.418 | I7: =G7-H7 -> 1.418 | J7: =H7/G7 -> 0 | K7: =E7+E8+F7+F8 -> 1.887 | L7: =H7+H8 -> 0 | M7: =K7-L7 -> 1.887 | N7: =L7/K7 -> 0
C8: 41699 | D8: 42004 | E8: 0.469 | G8: =E8+F8+I7 -> 1.887 | I8: =G8-H8 -> 1.887 | J8: =H8/G8 -> 0
B9: Pesca Chile S.A. | C9: 41640 | D9: 41698 | E9: 128.862 | F9: =-0.949-192.308 -> -193.257 | G9: =E9+F9 -> -64.395 | I9: =G9-H9 -> -64.395 | J9: =H9/G9 -> 0 | K9: =E9+E10+F9+F10 -> 64.467 | L9: =H9+H10 -> 64.467 | M9: =K9-L9 -> 0 | N9: =L9/K9 -> 1
C10: 41699 | D10: 42004 | E10: 128.862 | G10: =E10+F10+I9 -> 64.467 | H10: 64.467 | I10: =G10-H10 -> 0 | J10: =H10/G10 -> 1
B11: Pesca Cisne S.A | C11: 41640 | D11: 41698 | E11: 10.992 | G11: =E11+F11 -> 10.992 | I11: =G11-H11 -> 10.992 | J11: =H11/G11 -> 0 | K11: =E11+E12+F11+F12 -> 21.984 | L11: =H11+H12 -> 18.157 | M11: =K11-L11 -> 3.827 | N11: =L11/K11 -> 0.82591885
C12: 41699 | D12: 42004 | E12: 10.992 | G12: =E12+F12+I11 -> 21.984 | H12: 18.157 | I12: =G12-H12 -> 3.827 | J12: =H12/G12 -> 0.82591885
B13: Grimar S.A.Pesq. | C13: 41640 | D13: 41698 | E13: 6.847 | F13: =95 -> 95 | G13: =E13+F13 -> 101.847 | H13: 2.476 | I13: =G13-H13 -> 99.371 | J13: =H13/G13 -> 0.024310976 | K13: =E13+E14+F13+F14 -> 108.694 | L13: =H13+H14 -> 14.261 | M13: =K13-L13 -> 94.433 | N13: =L13/K13 -> 0.13120319
C14: 41699 | D14: 42004 | E14: 6.847 | G14: =E14+F14+I13 -> 106.218 | H14: 11.785 | I14: =G14-H14 -> 94.433 | J14: =H14/G14 -> 0.11095106
B15: Sur Austral S.A. Pesq. | C15: 41640 | D15: 41698 | E15: 38.33 | F15: =95 -> 95 | G15: =E15+F15 -> 133.33 | H15: 1.162 | I15: =G15-H15 -> 132.168 | J15: =H15/G15 -> 0.0087152179 | K15: =E15+E16+F15+F16 -> 171.66 | L15: =H15+H16 -> 45.222 | M15: =K15-L15 -> 126.438 | N15: =L15/K15 -> 0.26343936
C16: 41699 | D16: 42004 | E16: 38.33 | G16: =E16+F16+I15 -> 170.498 | H16: 44.06 | I16: =G16-H16 -> 126.438 | J16: =H16/G16 -> 0.25841945
B17: Deris S.A. | C17: 41640 | D17: 41698 | E17: 0 | F17: =192.308-95-95 -> 2.308 | G17: =E17+F17 -> 2.308 | I17: =G17-H17 -> 2.308 | J17: =H17/G17 -> 0 | K17: =E17+E18+F17+F18 -> 2.308 | L17: =H17+H18 -> 0 | M17: =K17-L17 -> 2.308 | N17: =L17/K17 -> 0
C18: 41699 | D18: 42004 | E18: 0 | G18: =E18+F18+I17 -> 2.308 | I18: =G18-H18 -> 2.308 | J18: =H18/G18 -> 0
A20: Congrio dorado SE (47º hasta 57º) | B20: Emdepes S.A., | C20: 41640 | D20: 41698 | E20: 11.461 | G20: =E20+F20 -> 11.461 | I20: =G20-H20 -> 11.461 | J20: =H20/G20 -> 0 | K20: =E20+E21+F20+F21 -> 22.922 | L20: =H20+H21 -> 22.549 | M20: =K20-L20 -> 0.373 | N20: =L20/K20 -> 0.98372742
C21: 41699 | D21: 42004 | E21: 11.461 | G21: =E21+F21+I20 -> 22.922 | H21: 22.549 | I21: =G21-H21 -> 0.373 | J21: =H21/G21 -> 0.98372742
B22: Grimar S.A.Pesq. | C22: 41640 | D22: 41698 | E22: 0.034 | G22: =E22+F22 -> 0.034 | I22: =G22-H22 -> 0.034 | J22: =H22/G22 -> 0 | K22: =E22+E23+F22+F23 -> 0.068 | L22: =H22+H23 -> 0 | M22: =K22-L22 -> 0.068 | N22: =L22/K22 -> 0
C23: 41699 | D23: 42004 | E23: 0.034 | G23: =E23+F23+I22 -> 0.068 | I23: =G23-H23 -> 0.068 | J23: =H23/G23 -> 0
B24: Pesca Chile S.A. | C24: 41640 | D24: 41698 | E24: 39.244 | F24: =0.285-18.688 -> -18.403 | G24: =E24+F24 -> 20.841 | H24: 41.942 | I24: =G24-H24 -> -21.101 | J24: =H24/G24 -> 2.0124754 | K24: =E24+E25+F24+F25 -> 60.085 | L24: =H24+H25 -> 60.085 | M24: =K24-L24 -> 0 | N24: =L24/K24 -> 1
C25: 41699 | D25: 42004 | E25: 39.244 | G25: =E25+F25+I24 -> 18.143 | H25: 18.143 | I25: =G25-H25 -> 0 | J25: =H25/G25 -> 1
B26: Pesca Cisne S.A | C26: 41640 | D26: 41698 | E26: 15.244 | F26: =-0.285 -> -0.285 | G26: =E26+F26 -> 14.959 | I26: =G26-H26 -> 14.959 | J26: =H26/G26 -> 0 | K26: =E26+E27+F26+F27 -> 30.203 | L26: =H26+H27 -> 29.881 | M26: =K26-L26 -> 0.322 | N26: =L26/K26 -> 0.98933881
C27: 41699 | D27: 42004 | E27: 15.244 | G27: =E27+F27+I26 -> 30.203 | H27: 29.881 | I27: =G27-H27 -> 0.322 | J27: =H27/G27 -> 0.98933881
B28: Sur Austral S.A. Pesq. | C28: 41640 | D28: 41698 | E28: 0.017 | G28: =E28+F28 -> 0.017 | I28: =G28-H28 -> 0.017 | J28: =H28/G28 -> 0 | K28: =E28+E29+F28+F29 -> 0.034 | L28: =H28+H29 -> 0 | M28: =K28-L28 -> 0.034 | N28: =L28/K28 -> 0
C29: 41699 | D29: 42004 | E29: 0.017 | G29: =E29+F29+I28 -> 0.034 | I29: =G29-H29 -> 0.034 | J29: =H29/G29 -> 0
B30: Deris S.A. | C30: 41640 | D30: 41698 | E30: 0 | F30: =18.688 -> 18.688 | G30: =E30+F30 -> 18.688 | I30: =G30-H30 -> 18.688 | J30: =H30/G30 -> 0 | K30: =E30+E31+F30+F31 -> 18.688 | L30: =H30+H31 -> 0 | M30: =K30-L30 -> 18.688 | N30: =L30/K30 -> 0
C31: 41699 | D31: 42004 | E31: 0 | G31: =E31+F31+I30 -> 18.688 | I31: =G31-H31 -> 18.688 | J31: =H31/G31 -> 0
A33: Merluza del sur NE F/H (41º28,6 LS al 47º LS) | B33: Emdepes S.A. | C33: 41640 | D33: 41670 | E33: 130.067 | F33: =189.512+192.829+276.77+195.151+164.278+26.13 -> 1044.67 | G33: =E33+F33 -> 1174.737 | I33: =G33-H33 -> 1174.737 | J33: =H33/G33 -> 0 | K33: =E33+E34+F33+F34 -> 1565.19 | L33: =H33+H34 -> 1565.182 | M33: =K33-L33 -> 0.008 | N33: =L33/K33 -> 0.99999489
C34: 41671 | D34: 41851 | E34: 241.39 | F34: =110.488+38.575 -> 149.063 | G34: =E34+F34+I33 -> 1565.19 | H34: 1565.182 | I34: =G34-H34 -> 0.008 | J34: =H34/G34 -> 0.99999489
B35: Pesca Chile S.A. | C35: 41640 | D35: 41670 | E35: 472.435 | F35: =276.798-276.77-106.195+200-93.833 -> 0 | G35: =E35+F35 -> 472.435 | I35: =G35-H35 -> 472.435 | J35: =H35/G35 -> 0 | K35: =E35+E36+F35+F36 -> 1276.89 | L35: =H35+H36 -> 1276.89 | M35: =K35-L35 -> 0 | N35: =L35/K35 -> 1
C36: 41671 | D36: 41851 | E36: 876.784 | F36: =-72.329 -> -72.329 | G36: =E36+F36+I35 -> 1276.89 | H36: 1276.89 | I36: =G36-H36 -> 0 | J36: =H36/G36 -> 1
