Workbook

Sheet Global LMC
A2: Informe
A3: Resumen LMC 2012
A4: Al 31 de diciembre del 2012
A5: Unidad de Pesquería | B5: Zona | C5: Cuota Global (t) | D5: Desembarque total (t) | E5: Aguas internacionales | F5: Saldo total (t) | G5: % consumido 2012 | H5: % consumido 2011
A6: Anchoveta | B6: XV- I - II | C6: =+SUM('Res LMC'!E7:E8) -> 640518.93 | D6: =+SUM('Res LMC'!G7:G8) -> 630901.79 | F6: =+C6-D6 -> 9617.144 | G6: =D6/C6 -> 0.98498539 | H6: 0.74852482
A7: Anchoveta | B7: III - IV | C7: =+SUM('Res LMC'!E9:E10) -> 87.414 | D7: =+SUM('Res LMC'!G9:G10) -> 0 | F7: =+C7-D7 -> 87.414 | G7: =D7/C7 -> 0 | H7: 0.072569921
A8: Anchoveta | B8: V - X | C8: =+SUM('Res LMC'!E11:E13) -> 21942.443 | D8: =+SUM('Res LMC'!G11:G13) -> 13226.056 | F8: =+C8-D8 -> 8716.3874 | G8: =D8/C8 -> 0.60276131 | H8: 0.46247535
A9: Camarón nailon | B9: II-VIII | C9: =+SUM('Res LMC'!E14:E16) -> 3901 | D9: =+SUM('Res LMC'!G14:G16) -> 3300.956 | F9: =+C9-D9 -> 600.044 | G9: =D9/C9 -> 0.846182 | H9: 0.87964718
A10: Congrio dorado | B10: NE F + H | C10: =+SUM('Res LMC'!E17:E18) -> 1092 | D10: =+SUM('Res LMC'!G17:G18) -> 1051.96 | F10: =+C10-D10 -> 40.04 | G10: =D10/C10 -> 0.96333333 | H10: 0.59805187
A11: Congrio dorado | B11: SE | C11: =+SUM('Res LMC'!E19:E20) -> 649 | D11: =+SUM('Res LMC'!G19:G20) -> 491.115 | F11: =+C11-D11 -> 157.885 | G11: =D11/C11 -> 0.75672573 | H11: 0.76223058
A12: Jurel | B12: XV - I - II | C12: =+SUM('Res LMC'!E21:E22) -> 20832.004 | D12: =+SUM('Res LMC'!G21:G22) -> 13051.611 | F12: =+C12-D12 -> 7780.393 | G12: =D12/C12 -> 0.6265173 | H12: 0.77893614
A13: Jurel | B13: III - IV | C13: =+SUM('Res LMC'!E23:E24) -> 12612.583 | D13: =+SUM('Res LMC'!G23:G24) -> 9028.661 | E13: 533.318 | F13: =+C13-D13 -> 3583.922 | G13: =D13/C13 -> 0.71584552 | H13: 0.9324254
A14: Jurel | B14: V - IX | C14: =+SUM('Res LMC'!E25:E26) -> 188873.86 | D14: =+SUM('Res LMC'!G25:G26) -> 181916.77 | E14: 217.421 | F14: =+C14-D14 -> 6957.086 | G14: =D14/C14 -> 0.96316544 | H14: 0.84937562
A15: Jurel | B15: XIV - X | C15: =+SUM('Res LMC'!E27:E28) -> 9873.6057 | D15: =+SUM('Res LMC'!G27:G28) -> 9471.121 | E15: 3387.56 | F15: =+C15-D15 -> 402.48474 | G15: =D15/C15 -> 0.9592363 | H15: 0.67941495
A16: Langostino amarillo | B16: III-IV | C16: =+SUM('Res LMC'!E29:E31) -> 1990.498 | D16: =+SUM('Res LMC'!G29:G31) -> 1707.03 | F16: =+C16-D16 -> 283.468 | G16: =D16/C16 -> 0.85758941 | H16: 0.81494989
A17: Langostino colorado | B17: I -IV | C17: =+SUM('Res LMC'!E32:E34) -> 1124.999 | D17: =+SUM('Res LMC'!G32:G34) -> 1117.725 | F17: =+C17-D17 -> 7.274 | G17: =D17/C17 -> 0.99353422 | H17: 0.41773702
A18: Merluza común | B18: IV- 41º 28, 6 | C18: =+SUM('Res LMC'!E35:E36) -> 28499.152 | D18: =+SUM('Res LMC'!G35:G36) -> 24978.409 | F18: =+C18-D18 -> 3520.743 | G18: =D18/C18 -> 0.87646148 | H18: 0.90854677
A19: Merluza de cola | B19: V -X | C19: =+SUM('Res LMC'!E37:E38) -> 62312.71 | D19: =+SUM('Res LMC'!G37:G38) -> 30437.265 | F19: =+C19-D19 -> 31875.445 | G19: =D19/C19 -> 0.48845998 | H19: 0.40409792
A20: Merluza de cola | B20: XI -XII | C20: =+SUM('Res LMC'!E39:E40) -> 32689.758 | D20: =+SUM('Res LMC'!G39:G40) -> 31487.829 | F20: =+C20-D20 -> 1201.929 | G20: =D20/C20 -> 0.96323225 | H20: 0.95977463
A21: Merluza de tres aletas | B21: 41º28,6 - XII | C21: =+SUM('Res LMC'!E41:E42) -> 19366.002 | D21: =+SUM('Res LMC'!G41:G42) -> 16673.333 | F21: =+C21-D21 -> 2692.669 | G21: =D21/C21 -> 0.86095896 | H21: 0.81084526
A22: Merluza del sur | B22: NE F + H | C22: =+SUM('Res LMC'!E43:E44) -> 10133.647 | D22: =+SUM('Res LMC'!G43:G44) -> 9911.338 | F22: =+C22-D22 -> 222.309 | G22: =D22/C22 -> 0.97806229 | H22: 0.95222288
A23: Merluza del sur | B23: SE | C23: =+SUM('Res LMC'!E45:E46) -> 4578.43 | D23: =+SUM('Res LMC'!G45:G46) -> 4186.612 | F23: =+C23-D23 -> 391.818 | G23: =D23/C23 -> 0.91442088 | H23: 0.82624482
A24: Sardina común | B24: V -X | C24: =+SUM('Res LMC'!E47:E49) -> 241054.43 | D24: =+SUM('Res LMC'!G47:G49) -> 201235.83 | F24: =+C24-D24 -> 39818.604 | G24: =D24/C24 -> 0.83481489 | H24: 0.64185737
A25: Sardina española | B25: XV- I - II | C25: =+SUM('Res LMC'!E50:E51) -> 1500 | D25: =+SUM('Res LMC'!G50:G51) -> 0 | F25: =+C25-D25 -> 1500 | G25: =D25/C25 -> 0 | H25: 0
A26: Sardina española | B26: III - IV | C26: =+SUM('Res LMC'!E52:E53) -> 465.404 | D26: =+SUM('Res LMC'!G52:G53) -> 0 | F26: =+C26-D26 -> 465.404 | G26: =D26/C26 -> 0 | H26: 0
A28: Nota: desembarque aguas internacionales Jurel desde III a X regiones, esta incorporado en la columna de desembarque total, solo se incorpora el dato para tenerlo de referencia
C30: 6917
C31: 4423
F32: =+C23-D23 -> 391.818
C33: =+C30-C22 -> -3216.647
C34: =+C31-C23 -> -155.43

Sheet Res LMC
A2: Resumen LMC 2012
A3: Al 31 de diciembre del 2012
A5: RESUMEN LMC 2012 | B5: Zona | C5: Cuota Global (t) | D5: Cuota Período | G5: Desembarque (t) | H5: Saldo (t) | I5: % Disponible
D6: Período | E6: autorizada (t) | F6: efectiva (t)
A7: Anchoveta | B7: XV -I - II | C7: =+SUM(E7:E8) -> 640518.93 | D7: enero - junio | E7: =+Anchoveta!D14 -> 480948.93 | F7: =+E7 -> 480948.93 | G7: =+Anchoveta!F14 -> 181157.29 | H7: =+F7-G7 -> 299791.64 | I7: =1-G7/F7 -> 0.62333363
B8: XV -I - II | D8: julio-diciembre | E8: =+Anchoveta!D15 -> 159569.99 | F8: =+E8+H7 -> 459361.64 | G8: =+Anchoveta!F15 -> 449744.49 | H8: =+F8-G8 -> 9617.144 | I8: =1-G8/F8 -> 0.020935888
B9: III - IV | C9: =SUM(E9:E10) -> 87.414 | D9: enero - octubre | E9: =+Anchoveta!D34 -> 83.042 | F9: =+E9 -> 83.042 | G9: =+Anchoveta!F34 -> 0 | H9: =+F9-G9 -> 83.042 | I9: =1-G9/F9 -> 1
B10: III - IV | D10: noviembre - diciembre | E10: =+Anchoveta!D35 -> 4.372 | F10: =+E10+H9 -> 87.414 | G10: =+Anchoveta!F35 -> 0 | H10: =+F10-G10 -> 87.414 | I10: =1-G10/F10 -> 1
B11: V - X | C11: =SUM(E11:E13) -> 21942.443 | D11: enero-abril | E11: =+Anchoveta!D63 -> 18651.257 | F11: =+E11 -> 18651.257 | G11: =+Anchoveta!F63 -> 3269.203 | H11: =+F11-G11 -> 15382.054 | I11: =1-G11/F11 -> 0.82471943
B12: V - X | D12: mayo-agosto | E12: =+Anchoveta!D64 -> 2194.6062 | F12: =+E12+H11 -> 17576.66 | G12: =+Anchoveta!F64 -> 1956.553 | H12: =+F12-G12 -> 15620.107 | I12: =1-G12/F12 -> 0.8886846
B13: V - X | D13: septiembre-diciembre | E13: =+Anchoveta!D65 -> 1096.5802 | F13: =+E13+H12 -> 16716.687 | G13: =+Anchoveta!F65 -> 8000.3 | H13: =+F13-G13 -> 8716.3874 | I13: =1-G13/F13 -> 0.52141834
A14: Camarón nailon | B14: II - VIII | C14: =SUM(E14:E16) -> 3901 | D14: enero - marzo | E14: =+'C.nailon'!D58 -> 1755.253 | F14: =+E14 -> 1755.253 | G14: =+'C.nailon'!F58 -> 1453.465 | H14: =+F14-G14 -> 301.788 | I14: =1-G14/F14 -> 0.17193419
B15: II - VIII | D15: abril - agosto | E15: =+'C.nailon'!D59 -> 975.249 | F15: =+E15+H14 -> 1277.037 | G15: =+'C.nailon'!F59 -> 673.831 | H15: =+F15-G15 -> 603.206 | I15: =1-G15/F15 -> 0.4723481
B16: II - VIII | D16: septiembre - diciembre | E16: =+'C.nailon'!D60 -> 1170.498 | F16: =+E16+H15 -> 1773.704 | G16: =+'C.nailon'!F60 -> 1173.66 | H16: =+F16-G16 -> 600.044 | I16: =1-G16/F16 -> 0.33829996
A17: Congrio dorado | B17: NE F + H | C17: =+E18+E17 -> 1092 | D17: enero-febrero | E17: =+'C.dorado'!D14 -> 545 | F17: =+E17 -> 545 | G17: =+'C.dorado'!F14 -> 25.09 | H17: =+F17-G17 -> 519.91 | I17: =1-G17/F17 -> 0.9539633
B18: NE F + H | D18: marzo - diciembre | E18: =+'C.dorado'!D15 -> 547 | F18: =+E18+H17 -> 1066.91 | G18: =+'C.dorado'!F15 -> 1026.87 | H18: =+F18-G18 -> 40.04 | I18: =1-G18/F18 -> 0.037528939
B19: SE | C19: =SUM(E19:E20) -> 649 | D19: enero-febrero | E19: =+'C.dorado'!D26 -> 324.008 | F19: =+E19 -> 324.008 | G19: =+'C.dorado'!F26 -> 1.338 | H19: =+F19-G19 -> 322.67 | I19: =1-G19/F19 -> 0.99587047
B20: SE | D20: marzo - diciembre | E20: =+'C.dorado'!D27 -> 324.992 | F20: =+E20+H19 -> 647.662 | G20: =+'C.dorado'!F27 -> 489.777 | H20: =+F20-G20 -> 157.885 | I20: =1-G20/F20 -> 0.24377685
A21: Jurel | B21: XV -I - II | C21: =SUM(E21:E22) -> 20832.004 | D21: enero - septiembre | E21: =+Jurel!D14 -> 19790.76 | F21: =+E21 -> 19790.76 | G21: =+Jurel!F14 -> 12193.386 | H21: =+F21-G21 -> 7597.374 | I21: =1-G21/F21 -> 0.3838849
B22: XV -I - II | D22: octubre - diciembre | E22: =+Jurel!D15 -> 1041.244 | F22: =+E22+H21 -> 8638.618 | G22: =+Jurel!F15 -> 858.225 | H22: =+F22-G22 -> 7780.393 | I22: =1-G22/F22 -> 0.90065251
B23: III - IV | C23: =SUM(E23:E24) -> 12612.583 | D23: enero - septiembre | E23: =+Jurel!D42 -> 11981.572 | F23: =+E23 -> 11981.572 | G23: =+Jurel!F42 -> 9028.661 | H23: =+F23-G23 -> 2952.911 | I23: =1-G23/F23 -> 0.24645439
B24: III - IV | D24: octubre - diciembre | E24: =+Jurel!D43 -> 631.011 | F24: =+E24+H23 -> 3583.922 | G24: =+Jurel!F43 -> 0 | H24: =+F24-G24 -> 3583.922 | I24: =1-G24/F24 -> 1
B25: V - IX | C25: =SUM(E25:E26) -> 188873.86 | D25: enero - septiembre | E25: =+Jurel!D74 -> 179430.03 | F25: =+E25 -> 179430.03 | G25: =+Jurel!F74 -> 177830.82 | H25: =+F25-G25 -> 1599.209 | I25: =1-G25/F25 -> 0.0089127166
B26: V - IX | D26: octubre - diciembre | E26: =+Jurel!D75 -> 9443.829 | F26: =+E26+H25 -> 11043.038 | G26: =+Jurel!F75 -> 4085.952 | H26: =+F26-G26 -> 6957.086 | I26: =1-G26/F26 -> 0.62999747
B27: XIV - X | C27: =SUM(E27:E28) -> 9873.6057 | D27: enero - septiembre | E27: =+Jurel!D108 -> 9379.962 | F27: =+E27 -> 9379.962 | G27: =+Jurel!F108 -> 9471.026 | H27: =+F27-G27 -> -91.064 | I27: =1-G27/F27 -> -0.0097083549
B28: XIV - X | D28: octubre - diciembre | E28: =+Jurel!D109 -> 493.64374 | F28: =+E28+H27 -> 402.57974 | G28: =+Jurel!F109 -> 0.095 | H28: =+F28-G28 -> 402.48474 | I28: =1-G28/F28 -> 0.99976402
A29: Langostino amarillo | B29: III - IV | C29: =SUM(E29:E31) -> 1990.498 | D29: abril - junio | E29: =+'L.amarillo'!D34 -> 995.752 | F29: =+E29 -> 995.752 | G29: =+'L.amarillo'!F34 -> 852.279 | H29: =+F29-G29 -> 143.473 | I29: =1-G29/F29 -> 0.14408507
B30: III - IV | D30: julio - septiembre | E30: =+'L.amarillo'!D35 -> 597.249 | F30: =+E30+H29 -> 740.722 | G30: =+'L.amarillo'!F35 -> 459.138 | H30: =+F30-G30 -> 281.584 | I30: =1-G30/F30 -> 0.38014802
B31: III - IV | D31: octubre -diciembre | E31: =+'L.amarillo'!D36 -> 397.497 | F31: =+E31+H30 -> 679.081 | G31: =+'L.amarillo'!F36 -> 395.613 | H31: =+F31-G31 -> 283.468 | I31: =1-G31/F31 -> 0.41742885
A32: Langostino colorado | B32: II - IV | C32: =SUM(E32:E34) -> 1124.999 | D32: abril - junio | E32: =+'L.colorado'!D25 -> 263.498 | F32: =+E32 -> 263.498 | G32: =+'L.colorado'!F25 -> 268.14 | H32: =+F32-G32 -> -4.642 | I32: =1-G32/F32 -> -0.017616832
B33: II - IV | D33: julio - septiembre | E33: =+'L.colorado'!D26 -> 611.692 | F33: =+E33+H32 -> 607.05 | G33: =+'L.colorado'!F26 -> 165.271 | H33: =+F33-G33 -> 441.779 | I33: =1-G33/F33 -> 0.7277473
B34: II - IV | D34: octubre -diciembre | E34: =+'L.colorado'!D27 -> 249.809 | F34: =+E34+H33 -> 691.588 | G34: =+'L.colorado'!F27 -> 684.314 | H34: =+F34-G34 -> 7.274 | I34: =1-G34/F34 -> 0.010517823
A35: Merluza común | B35: IV - 41º 28,6' | C35: =SUM(E35:E36) -> 28499.152 | D35: enero - julio | E35: =+'M.común'!D42 -> 21374.114 | F35: =+E35 -> 21374.114 | G35: =+'M.común'!F42 -> 15666.398 | H35: =+F35-G35 -> 5707.716 | I35: =1-G35/F35 -> 0.26703872
D36: agosto - diciembre | E36: =+'M.común'!D43 -> 7125.038 | F36: =+E36+H35 -> 12832.754 | G36: =+'M.común'!F43 -> 9312.011 | H36: =+F36-G36 -> 3520.743 | I36: =1-G36/F36 -> 0.274356
A37: Merluza de cola | B37: V - X | C37: =SUM(E37:E38) -> 62312.71 | D37: enero - marzo | E37: =+'M.cola'!D28 -> 24925.085 | F37: =+E37 -> 24925.085 | G37: =+'M.cola'!F28 -> 7600.552 | H37: =+F37-G37 -> 17324.533 | I37: =1-G37/F37 -> 0.69506415
B38: V - X | D38: abril - diciembre | E38: =+'M.cola'!D29 -> 37387.625 | F38: =+E38+H37 -> 54712.158 | G38: =+'M.cola'!F29 -> 22836.713 | H38: =+F38-G38 -> 31875.445 | I38: =1-G38/F38 -> 0.58260259
B39: XI - XII | C39: =SUM(E39:E40) -> 32689.758 | D39: enero - marzo | E39: =+'M.cola'!D40 -> 13075.867 | F39: =+E39 -> 13075.867 | G39: =+'M.cola'!F40 -> 0.101 | H39: =+F39-G39 -> 13075.766 | I39: =1-G39/F39 -> 0.99999228
B40: XI - XII | D40: abril - diciembre | E40: =+'M.cola'!D41 -> 19613.891 | F40: =+E40+H39 -> 32689.657 | G40: =+'M.cola'!F41 -> 31487.728 | H40: =+F40-G40 -> 1201.929 | I40: =1-G40/F40 -> 0.036767868
A41: Merluza de tres aletas | B41: 41º28,6 - XII | C41: =SUM(E41:E42) -> 19366.002 | D41: enero - marzo | E41: =+'M.tres aletas'!D7 -> 7107.01 | F41: =+E41 -> 7107.01 | G41: =+'M.tres aletas'!F7 -> 0.056 | H41: =+F41-G41 -> 7106.954 | I41: =1-G41/F41 -> 0.99999212
B42: 41º28,6 - XII | D42: abril - diciembre | E42: =+'M.tres aletas'!D8 -> 12258.992 | F42: =+E42+H41 -> 19365.946 | G42: =+'M.tres aletas'!F8 -> 16673.277 | H42: =+F42-G42 -> 2692.669 | I42: =1-G42/F42 -> 0.13904144
...

Sheet C.globales
A2: Cuotas globales Sin LMC (en conjunto con artesanales), 2012
A3: Al 31 de diciembre del 2012
A5: Unidad de Pesquería | B5: Zona | C5: Cuota Global (t) | D5: Cuota Período | G5: Desembarque (t) | H5: Saldo (t) | I5: % Disponible | J5: Fecha cierre
D6: Período | E6: autorizada | F6: efectiva
A7: Alfonsino | B7: Mar Terr y ZEE | C7: =+SUM(E7:E8) -> 0 | D7: enero - septiembre | E7: Veda | F7: =+E7 -> Veda | G7: 0.092 | H7: =+F7-G7 -> #VALUE! | I7: =1-G7/F7 -> #VALUE!
D8: octubre - diciembre | E8: Veda | F8: =+E8+H7 -> #VALUE! | H8: =+F8-G8 -> #VALUE! | I8: =1-G8/F8 -> #VALUE! | K8: industrial | L8: artesanal
A9: Besugo | B9: III - X | D9: enero - julio | F9: =+E9 -> 0 | H9: =+F9-G9 -> 0 | I9: =1-G9/F9 -> #DIV/0!
D10: agosto - diciembre | F10: =+E10+H9 -> 0 | H10: =+F10-G10 -> 0 | I10: =1-G10/F10 -> #DIV/0!
A11: Merluza común | B11: F. De area | C11: =+E11 -> 120 | D11: febrero - diciembre | E11: 120 | F11: =+E11 -> 120 | G11: 4.561 | H11: =+F11-G11 -> 115.439 | I11: =1-G11/F11 -> 0.96199167 | K11: 0.633 | L11: 4.036
A12: Merluza de cola | B12: F. De area | C12: =+E12 -> 1 | D12: febrero - diciembre | E12: 1 | F12: =+E12 -> 1 | G12: 0 | H12: =+F12-G12 -> 1 | I12: =1-G12/F12 -> 1 | K12: 0 | L12: 4.384
A13: Merluza del sur | B13: F. De area | C13: =+E13 -> 204 | D13: febrero - diciembre | E13: 204 | F13: =+E13 -> 204 | G13: 347.363 | H13: =+F13-G13 -> -143.363 | I13: =1-G13/F13 -> -0.7027598 | J13: 01.02.12 | K13: 351.787 | L13: 0.282
A14: Langostino amarillo | B14: F. De area | C14: =+E14 -> 20 | D14: febrero - diciembre | E14: 20 | F14: =+E14 -> 20 | G14: 15.67 | H14: =+F14-G14 -> 4.33 | I14: =1-G14/F14 -> 0.2165 | K14: 0 | L14: 19.414
A15: Camarón nailon | B15: F. De area | C15: =+E15 -> 20 | D15: febrero - diciembre | E15: 20 | F15: =+E15 -> 20 | G15: 0 | H15: =+F15-G15 -> 20 | I15: =1-G15/F15 -> 1 | K15: 0 | L15: 0
A16: Langostino colorado | B16: F. De area | C16: =+E16 -> 12 | E16: 12 | F16: =+E16 -> 12 | G16: 20.682 | H16: =+F16-G16 -> -8.682 | I16: =1-G16/F16 -> -0.7235 | K16: 0 | L16: 20.682
A17: Congrio dorado | B17: F. De area | C17: 285 | D17: enero - diciembre | E17: 285 | F17: =+E17 -> 285 | G17: 388.564 | H17: =+F17-G17 -> -103.564 | I17: =1-G17/F17 -> -0.36338246 | J17: 26.03.12 | K17: 6.336 | L17: 382.228
A22: Unidad de Pesquería | B22: Zona | C22: Cuota | D22: Período | E22: Sector | G22: Desem. (ton) | H22: Total Desem. (ton) | J22: Saldo
A23: Caballa | B23: I-XII | C23: S/cuota | D23: enero - diciembre | E23: Artesanal | G23: 5303.847 | H23: =+SUM(G23:G24) -> 24315.386
E24: Industrial | G24: 19011.539
A25: Reineta | B25: I-XII | C25: S/cuota | D25: enero - diciembre | E25: Artesanal | G25: 20249.597 | H25: =+SUM(G25:G26) -> 22942.812
E26: Industrial | G26: 2693.215
A27: Pez espada | B27: I-XII | C27: S/cuota | D27: enero - diciembre | E27: Artesanal | G27: 5431.94 | H27: =+SUM(G27:G28) -> 6349.617
E28: Industrial | G28: 917.677
A29: Bacalao | B29: I a 47° | C29: S/cuota | D29: enero - diciembre | E29: Artesanal | G29: 2057.096 | H29: =+SUM(G29:G30) -> 2057.128
E30: Industrial | G30: 0.032
A31: Jibia o calamar rojo | B31: XV-XII | C31: 138240 | D31: febrero-diciembre | E31: Artesanal | G31: 102545.48 | H31: =G32+G31 -> 127625.21 | J31: =C31-G31 -> 35694.52
C32: 34560 | D32: febrero-diciembre | E32: Industrial | G32: 25079.725 | J32: =C32-G32 -> 9480.275

Sheet C.regionales
A2: Cuotas Regionales Crustaceos Industriales, 2012
A3: Al 31 de diciembre 2012
A5: Unidad de Pesquería | B5: Zona | C5: Cuota Global (t) | D5: Cuota Período | G5: Desembarque (t) | H5: Saldo (t) | I5: % Disponible | J5: Fecha cierre /Prom (t/día)
D6: Período | E6: autorizada | F6: efectiva
A7: Camarón nailon | B7: II | C7: =+E7+E8+E9 -> 85 | D7: enero - marzo | E7: 38 | F7: =+E7 -> 38 | H7: =+F7-G7 -> 38 | I7: =1-G7/F7 -> 1
D8: abril - agosto | E8: 21 | F8: =+E8+H7 -> 59 | H8: =+F8-G8 -> 59 | I8: =1-G8/F8 -> 1
D9: septiembre - diciembre | E9: 26 | F9: =+E9+H8 -> 85 | H9: =+F9-G9 -> 85 | I9: =1-G9/F9 -> 1
B10: III | C10: =+E10+E11+E12 -> 260 | D10: enero - marzo | E10: 117 | F10: =+E10 -> 117 | G10: 4.801 | H10: =+F10-G10 -> 112.199 | I10: =1-G10/F10 -> 0.95896581
D11: abril - agosto | E11: 65 | F11: =+E11+H10 -> 177.199 | H11: =+F11-G11 -> 177.199 | I11: =1-G11/F11 -> 1
D12: septiembre - diciembre | E12: 78 | F12: =+E12+H11 -> 255.199 | G12: 4.776 | H12: =+F12-G12 -> 250.423 | I12: =1-G12/F12 -> 0.98128519
B13: IV | C13: =+E13+E14+E15 -> 770 | D13: enero - marzo | E13: 347 | F13: =+E13 -> 347 | G13: 348.613 | H13: =+F13-G13 -> -1.613 | I13: =1-G13/F13 -> -0.004648415 | J13: 12.03.12
D14: abril - agosto | E14: 193 | F14: =+E14+H13 -> 191.387 | G14: 212.248 | H14: =+F14-G14 -> -20.861 | I14: =1-G14/F14 -> -0.10899904 | J14: 12.06.12
D15: septiembre - diciembre | E15: 230 | F15: =+E15+H14 -> 209.139 | G15: 219.846 | H15: =+F15-G15 -> -10.707 | I15: =1-G15/F15 -> -0.051195616 | J15: 30.11.12
B16: V | C16: =+E16+E17+E18 -> 705 | D16: enero - marzo | E16: 317 | F16: =+E16 -> 317 | G16: 306.075 | H16: =+F16-G16 -> 10.925 | I16: =1-G16/F16 -> 0.034463722 | J16: 12.02.12
D17: abril - agosto | E17: 176 | F17: =+E17+H16 -> 186.925 | G17: 175.99 | H17: =+F17-G17 -> 10.935 | I17: =1-G17/F17 -> 0.058499398 | J17: 06.06.12
D18: septiembre - diciembre | E18: 212 | F18: =+E18+H17 -> 222.935 | G18: 228.04 | H18: =+F18-G18 -> -5.105 | I18: =1-G18/F18 -> -0.022899051 | J18: 28.09.12
B19: VI | C19: =+E19+E20+E21 -> 642 | D19: enero - marzo | E19: 289 | F19: =+E19 -> 289 | G19: 295.536 | H19: =+F19-G19 -> -6.536 | I19: =1-G19/F19 -> -0.022615917 | J19: 26.03.12
D20: abril - agosto | E20: 161 | F20: =+E20+H19 -> 154.464 | G20: 164.559 | H20: =+F20-G20 -> -10.095 | I20: =1-G20/F20 -> -0.065355034 | J20: 19.06.12
D21: septiembre - diciembre | E21: 192 | F21: =+E21+H20 -> 181.905 | G21: 177.565 | H21: =+F21-G21 -> 4.34 | I21: =1-G21/F21 -> 0.023858608 | J21: 30.10.12
B22: VII | C22: =+E22+E23+E24 -> 1052 | D22: enero - marzo | E22: 473 | F22: =+E22 -> 473 | G22: 465.613 | H22: =+F22-G22 -> 7.387 | I22: =1-G22/F22 -> 0.015617336 | J22: 17.02.12
D23: abril - agosto | E23: 263 | F23: =+E23+H22 -> 270.387 | G23: 119.318 | H23: =+F23-G23 -> 151.069 | I23: =1-G23/F23 -> 0.55871399
D24: septiembre - diciembre | E24: 316 | F24: =+E24+H23 -> 467.069 | G24: 469.885 | H24: =+F24-G24 -> -2.816 | I24: =1-G24/F24 -> -0.0060290878 | J24: 19.11.12
B25: VIII | C25: =+E25+E26+E27 -> 442 | D25: enero - marzo | E25: 199 | F25: =+E25 -> 199 | G25: 32.881 | H25: =+F25-G25 -> 166.119 | I25: =1-G25/F25 -> 0.83476884
D26: abril - agosto | E26: 110 | F26: =+E26+H25 -> 276.119 | G26: 1.716 | H26: =+F26-G26 -> 274.403 | I26: =1-G26/F26 -> 0.99378529
D27: septiembre - diciembre | E27: 133 | F27: =+E27+H26 -> 407.403 | G27: 74.824 | H27: =+F27-G27 -> 332.579 | I27: =1-G27/F27 -> 0.8163391
A28: Langostino amarillo | B28: III | C28: =+E28+E29+E30 -> 397 | D28: abril - junio | E28: 199 | F28: =+E28 -> 199 | H28: =+F28-G28 -> 199 | I28: =1-G28/F28 -> 1
D29: julio - septiembre | E29: 119 | F29: =+E29+H28 -> 318 | G29: 20.398 | H29: =+F29-G29 -> 297.602 | I29: =1-G29/F29 -> 0.93585535
D30: octubre - diciembre | E30: 79 | F30: =+E30+H29 -> 376.602 | G30: 36.308 | H30: =+F30-G30 -> 340.294 | I30: =1-G30/F30 -> 0.90359053
B31: IV | C31: =+E31+E32+E33 -> 1586 | D31: abril - junio | E31: 793 | F31: =+E31 -> 793 | G31: 852.279 | H31: =+F31-G31 -> -59.279 | I31: =1-G31/F31 -> -0.074752837 | J31: 15.06.12
D32: julio - septiembre | E32: 476 | F32: =+E32+H31 -> 416.721 | G32: 438.74 | H32: =+F32-G32 -> -22.019 | I32: =1-G32/F32 -> -0.05283871 | J32: 30.07.12
D33: octubre - diciembre | E33: 317 | F33: =+E33+H32 -> 294.981 | G33: 359.305 | H33: =+F33-G33 -> -64.324 | I33: =1-G33/F33 -> -0.2180615 | J33: 17.10.12
A34: Langostino amarillo Licitado | B34: V | C34: =+E34+E35 -> 1050 | D34: abril - junio | E34: 525 | F34: =+E34 -> 525 | G34: 847.568 | H34: =+F34-G34 -> -322.568 | I34: =1-G34/F34 -> -0.61441524 | J34: 24.04.12
D35: julio - diciembre | E35: 525 | F35: =+E35+H34 -> 202.432 | G35: 188.882 | H35: =+F35-G35 -> 13.55 | I35: =1-G35/F35 -> 0.066936058 | J35: 06.09.12
B36: VI | C36: =+E36+E37 -> 750 | D36: abril - junio | E36: 375 | F36: =+E36 -> 375 | G36: 38.659 | H36: =+F36-G36 -> 336.341 | I36: =1-G36/F36 -> 0.89690933
D37: julio - diciembre | E37: 375 | F37: =+E37+H36 -> 711.341 | G37: 219.546 | H37: =+F37-G37 -> 491.795 | I37: =1-G37/F37 -> 0.69136321
B38: VII | C38: =+E38+E39+E40 -> 0 | D38: abril - junio | F38: =+E38 -> 0 | H38: =+F38-G38 -> 0 | I38: =1-G38/F38 -> #DIV/0!
D39: julio - septiembre | F39: =+E39+H38 -> 0 | H39: =+F39-G39 -> 0 | I39: =1-G39/F39 -> #DIV/0!
D40: octubre - diciembre | F40: =+E40+H39 -> 0 | H40: =+F40-G40 -> 0 | I40: =1-G40/F40 -> #DIV/0!
B41: VIII | C41: =+E41+E42+E43 -> 0 | D41: abril - junio | F41: =+E41 -> 0 | H41: =+F41-G41 -> 0 | I41: =1-G41/F41 -> #DIV/0!
D42: julio - septiembre | F42: =+E42+H41 -> 0 | H42: =+F42-G42 -> 0 | I42: =1-G42/F42 -> #DIV/0!
...

Sheet C.licitadas
A2: Cuotas Industriales Licitadas, año 2012
A3: Al 31 de diciembre 2012
A5: Langostino amarillo V-VIII | B5: 1800
A6: Armador | B6: % Licitado | C6: Cuota licitada (t) | D6: Sanción (t) | E6: Transferencias | G6: Cuota efectiva (t) | H6: Operación
E7: Ingresos (t) | F7: Egresos (t) | H7: Desembarque (t) | I7: Saldo (t) | J7: % consumido
A8: Camanchaca Pesca Sur | B8: 46.57 | C8: =+$B$5*B8/100 -> 838.26 | E8: 370.7352 | F8: 350 | G8: =+C8+E8-F8-D8 -> 858.9952 | H8: 519.53 | I8: =+G8-H8 -> 339.4652 | J8: =+H8/G8 -> 0.6048113
A9: Camanchaca | B9: 0 | C9: =+$B$5*B9/100 -> 0 | G9: =+C9+E9-F9-D9 -> 0 | H9: 0 | I9: =+G9-H9 -> 0 | J9: =+H9/G9 -> #DIV/0!
A10: BLUMAR | B10: 20.6 | C10: =+$B$5*B10/100 -> 370.8 | F10: 370.7352 | G10: =+C10+E10-F10-D10 -> 0.0648 | H10: 0 | I10: =+G10-H10 -> 0.0648 | J10: =+H10/G10 -> 0
A11: Viento Sur | B11: 0 | C11: =+$B$5*B11/100 -> 0 | G11: =+C11+E11-F11-D11 -> 0 | H11: 0 | I11: =+G11-H11 -> 0 | J11: =+H11/G11 -> #DIV/0!
A12: Sunise | B12: 1.16 | C12: =+$B$5*B12/100 -> 20.88 | F12: 20.88 | G12: =+C12+E12-F12-D12 -> 0 | H12: 0 | I12: =+G12-H12 -> 0 | J12: =+H12/G12 -> #DIV/0!
A13: Bracpesca | B13: 14.13 | C13: =+$B$5*B13/100 -> 254.34 | G13: =+C13+E13-F13-D13 -> 254.34 | H13: 257.432 | I13: =+G13-H13 -> -3.092 | J13: =+H13/G13 -> 1.012157
A14: Isladamas | B14: 7.92 | C14: =+$B$5*B14/100 -> 142.56 | E14: 399.68 | G14: =+C14+E14-F14-D14 -> 542.24 | H14: 391.849 | I14: =+G14-H14 -> 150.391 | J14: =+H14/G14 -> 0.72264864
A15: Veliz y veliz | B15: 0.3 | C15: =+$B$5*B15/100 -> 5.4 | F15: 5.4 | G15: =+C15+E15-F15-D15 -> 0 | H15: 0 | I15: =+G15-H15 -> 0 | J15: =+H15/G15 -> #DIV/0!
A16: Distrimar | B16: 1.53 | C16: =+$B$5*B16/100 -> 27.54 | G16: =+C16+E16-F16-D16 -> 27.54 | H16: 26.636 | I16: =+G16-H16 -> 0.904 | J16: =+H16/G16 -> 0.96717502
A17: Antartic Seafood | B17: 6.49 | C17: =+$B$5*B17/100 -> 116.82 | G17: =+C17+E17-F17-D17 -> 116.82 | H17: 119.09 | I17: =+G17-H17 -> -2.27 | J17: =+H17/G17 -> 1.0194316
A18: Friosur X | B18: 0 | C18: =+$B$5*B18/100 -> 0 | G18: =+C18+E18-F18-D18 -> 0 | H18: 0 | I18: =+G18-H18 -> 0 | J18: =+H18/G18 -> #DIV/0!
A19: Grimar S.A | B19: 1 | C19: =+$B$5*B19/100 -> 18 | F19: 18 | G19: =+C19+E19-F19-D19 -> 0 | H19: 0 | I19: =+G19-H19 -> 0 | J19: =+H19/G19 -> #DIV/0!
A20: Rubio y Mauad Ltda. | B20: 0.3 | C20: =+$B$5*B20/100 -> 5.4 | F20: 5.4 | G20: =+C20+E20-F20-D20 -> 0 | H20: 0 | I20: =+G20-H20 -> 0 | J20: =+H20/G20 -> #DIV/0!
A22: Resumen | B22: % Licitado | C22: Cuota licitada (t) | D22: Sanción (t) | E22: Transferencias | G22: Cuota efectiva (t) | H22: Operación
A23: Langostino amarillo V-VIII | E23: Ingresos (t) | F23: Egresos (t) | H23: Desembarque (t) | I23: Saldo (t) | J23: % consumido
B24: =SUM(B8:B20) -> 100 | C24: =SUM(C8:C20) -> 1800 | D24: =SUM(D8:D20) -> 0 | E24: =SUM(E8:E20) -> 770.4152 | F24: =SUM(F8:F20) -> 770.4152 | G24: =SUM(G8:G20) -> 1800 | H24: =SUM(H8:H20) -> 1314.537 | I24: =SUM(I8:I20) -> 485.463 | J24: =+H24/G24 -> 0.73029833
A26: Langostino colorado V-VIII | B26: 5000
A27: Armador | B27: % Licitado | C27: Cuota licitada (t) | D27: Sanción (t) | E27: Transferencias | G27: Cuota efectiva (t) | H27: Operación
E28: Ingresos (t) | F28: Egresos (t) | H28: Desembarque (t) | I28: Saldo (t) | J28: % consumido
A29: Camanchaca Pesca Sur S.A. | B29: 65.73 | C29: =+$B$26*B29/100 -> 3286.5 | E29: 1138.63 | F29: 450 | G29: =+C29+E29-F29-D29 -> 3975.13 | H29: 3756.074 | I29: =+G29-H29 -> 219.056 | J29: =+H29/G29 -> 0.94489337
A30: Blumar (Ex El Golfo) | B30: 22.7726 | C30: =+$B$26*B30/100 -> 1138.63 | F30: 1138.63 | G30: =+C30+E30-F30-D30 -> 0 | H30: 0 | I30: =+G30-H30 -> 0 | J30: =+H30/G30 -> #DIV/0!
A31: Distrimar | B31: 0.225 | C31: =+$B$26*B31/100 -> 11.25 | G31: =+C31+E31-F31-D31 -> 11.25 | H31: 10.806 | I31: =+G31-H31 -> 0.444 | J31: =+H31/G31 -> 0.96053333
A32: Bracpesca | B32: 4.44 | C32: =+$B$26*B32/100 -> 222 | G32: =+C32+E32-F32-D32 -> 222 | H32: 183.798 | I32: =+G32-H32 -> 38.202 | J32: =+H32/G32 -> 0.82791892
A33: Empacadora del pacifico | B33: 1.5 | C33: =+$B$26*B33/100 -> 75 | G33: =+C33+E33-F33-D33 -> 75 | H33: 0 | I33: =+G33-H33 -> 75 | J33: =+H33/G33 -> 0
A34: Alimar | B34: 0.5 | C34: =+$B$26*B34/100 -> 25 | G34: =+C34+E34-F34-D34 -> 25 | H34: 0 | I34: =+G34-H34 -> 25 | J34: =+H34/G34 -> 0
A35: Sunise | B35: 0.5 | C35: =+$B$26*B35/100 -> 25 | F35: 25 | G35: =+C35+E35-F35-D35 -> 0 | H35: 0 | I35: =+G35-H35 -> 0 | J35: =+H35/G35 -> #DIV/0!
A36: Artic S.A Elaboradora | B36: 0.5 | C36: =+$B$26*B36/100 -> 25 | G36: =+C36+E36-F36-D36 -> 25 | H36: 0 | I36: =+G36-H36 -> 25 | J36: =+H36/G36 -> 0
A37: Isladamas | B37: 1.68 | C37: =+$B$26*B37/100 -> 84 | E37: 486.25 | G37: =+C37+E37-F37-D37 -> 570.25 | H37: 550.736 | I37: =+G37-H37 -> 19.514 | J37: =+H37/G37 -> 0.96577992
A38: Antartic Seafood S.A | B38: 1.93 | C38: =+$B$26*B38/100 -> 96.5 | G38: =+C38+E38-F38-D38 -> 96.5 | H38: 94.45 | I38: =+G38-H38 -> 2.05 | J38: =+H38/G38 -> 0.97875648
A39: Bio Bio S.A | B39: 0 | C39: =+$B$26*B39/100 -> 0 | G39: =+C39+E39-F39-D39 -> 0 | H39: 0 | I39: =+G39-H39 -> 0 | J39: =+H39/G39 -> #DIV/0!
A40: RUBIO Y MAUAD LTDA. | B40: 0.225 | C40: =+$B$26*B40/100 -> 11.25 | F40: 11.25 | G40: =+C40+E40-F40-D40 -> 0 | H40: 0 | I40: =+G40-H40 -> 0 | J40: =+H40/G40 -> #DIV/0!
A42: Resumen | B42: % Licitado | C42: Cuota licitada (t) | D42: Sanción (t) | E42: Transferencias | G42: Cuota efectiva (t) | H42: Operación
A43: Langostino colorado V-VIII | E43: Ingresos (t) | F43: Egresos (t) | H43: Desembarque (t) | I43: Saldo (t) | J43: % consumido
B44: =SUM(B29:B39) -> 99.7776 | C44: =SUM(C29:C39) -> 4988.88 | D44: =SUM(D29:D39) -> 0 | E44: =SUM(E29:E39) -> 1624.88 | F44: =SUM(F29:F39) -> 1613.63 | G44: =SUM(G29:G39) -> 5000.13 | H44: =SUM(H29:H39) -> 4595.864 | I44: =SUM(I29:I39) -> 404.266 | J44: =+H44/G44 -> 0.9191489
A46: Bacalao de profundidad | B46: 3000
...

Sheet Anchoveta
A2: Anchoveta LMC 2012
A3: Al 31 de diciembre 2012
A5: Anchoveta XV - I - II | B5: Periodo | D5: Cuota (t) | F5: Operación | I5: Global | N5: ASOC 35 | O5: ENE-JUN | P5: JUL-DIC | Q5: TOTAL
A6: Armador | B6: Inicial | C6: Final | D6: Asignada | E6: Efectiva | F6: Desembarque (t) | G6: Saldo (t) | H6: % consumido | I6: Cuota (t) | J6: Desembarque (t) | K6: Saldo (t) | L6: % consumido | N6: ARICA SF | O6: 3634.789 | P6: 1362.791 | Q6: =O6+P6 -> 4997.58
A7: Arica S.Prod. S.A., Corpesca S.A, Orizon S.A. (Asociatividad 35) | B7: 39083 | C7: 39263 | D7: 380097.26 | E7: =+D7 -> 380097.26 | F7: 141971.1 | G7: =+E7-F7 -> 238126.16 | H7: =+F7/E7 -> 0.37351257 | I7: =SUM(D7:D8) -> 501854.96 | J7: =SUM(F7:F8) -> 492340.28 | K7: =+I7-J7 -> 9514.679 | L7: =+J7/I7 -> 0.98104098 | N7: CORPESCA | O7: 37673.88 | P7: 141601.19 | Q7: =O7+P7 -> 179275.07
B8: 39264 | C8: 39447 | D8: 121757.7 | E8: =+D8+G7 -> 359883.85 | F8: 350369.17 | G8: =+E8-F8 -> 9514.679 | H8: =+F8/E8 -> 0.97356181 | N8: ORIZON | O8: 28788.604 | P8: 10793.705 | Q8: =O8+P8 -> 39582.309
A9: Camanchaca S.A | B9: 39083 | C9: 39263 | D9: 100851.68 | E9: =+D9 -> 100851.68 | F9: 39186.188 | G9: =+E9-F9 -> 61665.488 | H9: =+F9/E9 -> 0.38855267 | I9: =SUM(D9:D10) -> 138663.97 | J9: =SUM(F9:F10) -> 138561.51 | K9: =+I9-J9 -> 102.465 | L9: =+J9/I9 -> 0.99926106 | N9: CUOTA ASIGNADA | O9: =SUM(O6:O8) -> 70097.273 | P9: =SUM(P6:P8) -> 153757.68 | Q9: =SUM(Q6:Q8) -> 223854.96
B10: 39264 | C10: 39447 | D10: 37812.297 | E10: =+D10+G9 -> 99477.785 | F10: 99375.32 | G10: =+E10-F10 -> 102.465 | H10: =+F10/E10 -> 0.99896997 | N10: CESIONES IND-ART | O10: =-20000+-20000 -> -40000 | P10: =-12000+-10000+-5000 -> -27000 | Q10: =O10+P10 -> -67000
N11: CUOTA EFECTIVA | O11: =O9+O10 -> 30097.273 | P11: =P9+P10 -> 126757.68 | Q11: =Q9+Q10 -> 156854.96
A12: Resumen | B12: Periodo | D12: Cuota (t) | F12: Operación | I12: Global
A13: Anchoveta XV - I - II | B13: Inicial | C13: Final | D13: Asignada | E13: Efectiva | F13: Desembarque (t) | G13: Saldo (t) | H13: % consumido | I13: Cuota (t) | J13: Desembarque (t) | K13: Saldo (t) | L13: % consumido
B14: 39083 | C14: 39263 | D14: =SUM(D7,D9) -> 480948.93 | E14: =+D14 -> 480948.93 | F14: =SUM(F7,F9) -> 181157.29 | G14: =+E14-F14 -> 299791.64 | H14: =+F14/E14 -> 0.37666637 | I14: =SUM(D14:D15) -> 640518.93 | J14: =SUM(F14:F15) -> 630901.79 | K14: =+I14-J14 -> 9617.144 | L14: =+J14/I14 -> 0.98498539
B15: 39264 | C15: 39447 | D15: =SUM(D8,D10) -> 159569.99 | E15: =+D15+G14 -> 459361.64 | F15: =SUM(F8,F10) -> 449744.49 | G15: =+E15-F15 -> 9617.144 | H15: =+F15/E15 -> 0.97906411
A17: Anchoveta III - IV | B17: Periodo | D17: Cuota (t) | F17: Operación | I17: Global
A18: Armador | B18: Inicial | C18: Final | D18: Asignada | E18: Efectiva | F18: Desembarque (t) | G18: Saldo (t) | H18: % consumido | I18: Cuota (t) | J18: Desembarque (t) | K18: Saldo (t) | L18: % consumido
A19: Corpesca S.A., Orizon S.A. (Asociatividad 95) | B19: 39083 | C19: 39386 | D19: 0 | E19: =+D19 -> 0 | G19: =+E19-F19 -> 0 | H19: =+F19/E19 -> #DIV/0! | I19: =SUM(D19:D20) -> 0 | J19: =SUM(F19:F20) -> 0 | K19: =+I19-J19 -> 0 | L19: =+J19/I19 -> #DIV/0!
B20: 39387 | C20: 39447 | D20: 0 | E20: =+D20+G19 -> 0 | G20: =+E20-F20 -> 0 | H20: =+F20/E20 -> #DIV/0!
A21: Alimentos Marinos S.A., Camanchaca S.A (Asociatividad 28) | B21: 39083 | C21: 39386 | D21: 0 | E21: =+D21 -> 0 | G21: =+E21-F21 -> 0 | H21: =+F21/E21 -> #DIV/0! | I21: =SUM(D21:D22) -> 0 | J21: =SUM(F21:F22) -> 0 | K21: =+I21-J21 -> 0 | L21: =+J21/I21 -> #DIV/0!
B22: 39387 | C22: 39447 | D22: 0 | E22: =+D22+G21 -> 0 | G22: =+E22-F22 -> 0 | H22: =+F22/E22 -> #DIV/0!
A23: Blumar S.A,. | B23: 39083 | C23: 39386 | D23: 0 | E23: =+D23 -> 0 | G23: =+E23-F23 -> 0 | H23: =+F23/E23 -> #DIV/0! | I23: =SUM(D23:D24) -> 0 | J23: =SUM(F23:F24) -> 0 | K23: =+I23-J23 -> 0 | L23: =+J23/I23 -> #DIV/0!
B24: 39387 | C24: 39447 | D24: 0 | E24: =+D24+G23 -> 0 | G24: =+E24-F24 -> 0 | H24: =+F24/E24 -> #DIV/0!
A25: Inversiones Pesqueras S.A. | B25: 39083 | C25: 39386 | D25: 0 | E25: =+D25 -> 0 | G25: =+E25-F25 -> 0 | H25: =+F25/E25 -> #DIV/0! | I25: =SUM(D25:D26) -> 0 | J25: =SUM(F25:F26) -> 0 | K25: =+I25-J25 -> 0 | L25: =+J25/I25 -> #DIV/0!
B26: 39387 | C26: 39447 | D26: 0 | E26: =+D26+G25 -> 0 | G26: =+E26-F26 -> 0 | H26: =+F26/E26 -> #DIV/0!
A27: Bahia Caldera S.A. | B27: 39083 | C27: 39386 | D27: 0 | E27: =+D27 -> 0 | G27: =+E27-F27 -> 0 | H27: =+F27/E27 -> #DIV/0! | I27: =SUM(D27:D28) -> 0 | J27: =SUM(F27:F28) -> 0 | K27: =+I27-J27 -> 0 | L27: =+J27/I27 -> #DIV/0!
B28: 39387 | C28: 39447 | D28: 0 | E28: =+D28+G27 -> 0 | G28: =+E28-F28 -> 0 | H28: =+F28/E28 -> #DIV/0!
A29: Bio Bio S.A. | B29: 39083 | C29: 39386 | D29: 83.042 | E29: =+D29 -> 83.042 | G29: =+E29-F29 -> 83.042 | H29: =+F29/E29 -> 0 | I29: =SUM(D29:D30) -> 87.414 | J29: =SUM(F29:F30) -> 0 | K29: =+I29-J29 -> 87.414 | L29: =+J29/I29 -> 0
B30: 39387 | C30: 39447 | D30: 4.372 | E30: =+D30+G29 -> 87.414 | G30: =+E30-F30 -> 87.414 | H30: =+F30/E30 -> 0
A32: Resumen | B32: Periodo | D32: Cuota (t) | F32: Operación | I32: Global
A33: Anchoveta III - IV | B33: Inicial | C33: Final | D33: Asignada | E33: Efectiva | F33: Desembarque (t) | G33: Saldo (t) | H33: % consumido | I33: Cuota (t) | J33: Desembarque (t) | K33: Saldo (t) | L33: % consumido
B34: 39083 | C34: 39386 | D34: =+D19+D21+D27+D29+D23+D25 -> 83.042 | E34: =+D34 -> 83.042 | F34: =+F19+F21+F27+F29+F23+F25 -> 0 | G34: =+E34-F34 -> 83.042 | H34: =+F34/E34 -> 0 | I34: =SUM(D34:D35) -> 87.414 | J34: =SUM(F34:F35) -> 0 | K34: =+I34-J34 -> 87.414 | L34: =+J34/I34 -> 0
B35: 39387 | C35: 39447 | D35: =+D20+D22+D28+D30+D24+D26 -> 4.372 | E35: =+D35+G34 -> 87.414 | F35: =+F20+F22+F28+F30+F24+F26 -> 0 | G35: =+E35-F35 -> 87.414 | H35: =+F35/E35 -> 0
A37: Anchoveta V-X | B37: Periodo | D37: Cuota (t) | F37: Operación | I37: Global
A38: Armador | B38: Inicial | C38: Final | D38: Asignada | E38: Efectiva | F38: Desembarque (t) | G38: Saldo (t) | H38: % consumido | I38: Cuota (t) | J38: Desembarque (t) | K38: Saldo (t) | L38: % consumido
A39: Berta Elena Ltda., Genmar Ltda., Inostroza Concha Pelantaro., Lota Protein S.A | B39: 39083 | C39: 39202 | D39: 422.173 | E39: =+D39 -> 422.173 | F39: 47.249 | G39: =+E39-F39 -> 374.924 | H39: =+F39/E39 -> 0.11191857 | I39: =SUM(D39:D41) -> 496.67 | J39: =SUM(F39:F41) -> 179.21 | K39: =+I39-J39 -> 317.46 | L39: =+J39/I39 -> 0.36082308
B40: 39203 | C40: 39691 | D40: 49.676 | E40: =+D40+G39 -> 424.6 | F40: 33.981 | G40: =+E40-F40 -> 390.619 | H40: =+F40/E40 -> 0.080030617
B41: 39692 | C41: 39813 | D41: 24.821 | E41: =+D41+G40 -> 415.44 | F41: 97.98 | G41: =+E41-F41 -> 317.46 | H41: =+F41/E41 -> 0.23584633
A42: Centro Sur S.A., Inversiones Pesqueras S.A., Salmoalimentos S.A (Asociatividad 98) | B42: 39083 | C42: 39202 | D42: 1054.942 | E42: =+D42 -> 1054.942 | F42: 5.493 | G42: =+E42-F42 -> 1049.449 | H42: =+F42/E42 -> 0.0052069213 | I42: =SUM(D42:D44) -> 1241.096 | J42: =SUM(F42:F44) -> 380.301 | K42: =+I42-J42 -> 860.795 | L42: =+J42/I42 -> 0.30642352
B43: 39203 | C43: 39691 | D43: 124.13 | E43: =+D43+G42 -> 1173.579 | G43: =+E43-F43 -> 1173.579 | H43: =+F43/E43 -> 0
B44: 39692 | C44: 39813 | D44: 62.024 | E44: =+D44+G43 -> 1235.603 | F44: 374.808 | G44: =+E44-F44 -> 860.795 | H44: =+F44/E44 -> 0.30334015
A45: Blumar S.A. | B45: 39083 | C45: 39202 | D45: 4255.021 | E45: =+D45 -> 4255.021 | F45: 95.765 | G45: =+E45-F45 -> 4159.256 | H45: =+F45/E45 -> 0.022506352 | I45: =SUM(D45:D47) -> 5005.858 | J45: =SUM(F45:F47) -> 688.778 | K45: =+I45-J45 -> 4317.08 | L45: =+J45/I45 -> 0.13759439
...

Sheet Jurel
A2: Jurel LMC 2012
A3: Al 31 de diciembre del 2012
A5: Jurel XV-I-II | B5: Periodo | D5: Cuota (t) | F5: Operación | I5: Global
A6: Armador | B6: Inicial | C6: Final | D6: Asignada | E6: Efectiva | F6: Desembarque (t) | G6: Saldo (t) | H6: % consumido | I6: Cuota (t) | J6: Desembarque (t) | K6: Saldo (t) | L6: % consumido
A7: Arica Seafood Producer S.A., Corpesca S.A., Orizon S.A. | B7: 39083 | C7: 40816 | D7: 17302.597 | E7: =+D7 -> 17302.597 | F7: 11037.109 | G7: =+E7-F7 -> 6265.488 | H7: =+F7/E7 -> 0.63788742 | I7: =SUM(D7:D8) -> 18212.932 | J7: =SUM(F7:F8) -> 11677.905 | K7: =+I7-J7 -> 6535.027 | L7: =+J7/I7 -> 0.64118754
B8: 40817 | C8: 40908 | D8: 910.335 | E8: =+D8+G7 -> 7175.823 | F8: 640.796 | G8: =+E8-F8 -> 6535.027 | H8: =+F8/E8 -> 0.089299304
A9: Camanchaca S.A | B9: 39083 | C9: 40816 | D9: 2488.163 | E9: =+D9 -> 2488.163 | F9: 1156.277 | G9: =+E9-F9 -> 1331.886 | H9: =+F9/E9 -> 0.46471111 | I9: =SUM(D9:D10) -> 2619.072 | J9: =SUM(F9:F10) -> 1373.706 | K9: =+I9-J9 -> 1245.366 | L9: =+J9/I9 -> 0.52450104
B10: 40817 | C10: 40908 | D10: 130.909 | E10: =+D10+G9 -> 1462.795 | F10: 217.429 | G10: =+E10-F10 -> 1245.366 | H10: =+F10/E10 -> 0.14863942
A12: Resumen | B12: Periodo | D12: Cuota (t) | F12: Operación | I12: Global
A13: Jurel XV-I-II | B13: Inicial | C13: Final | D13: Asignada | E13: Efectiva | F13: Desembarque (t) | G13: Saldo (t) | H13: % consumido | I13: Cuota (t) | J13: Desembarque (t) | K13: Saldo (t) | L13: % consumido
B14: 39083 | C14: 40816 | D14: =+D7+D9 -> 19790.76 | E14: =+D14 -> 19790.76 | F14: =+F7+F9 -> 12193.386 | G14: =+E14-F14 -> 7597.374 | H14: =+F14/E14 -> 0.6161151 | I14: =SUM(D14:D15) -> 20832.004 | J14: =SUM(F14:F15) -> 13051.611 | K14: =+I14-J14 -> 7780.393 | L14: =+J14/I14 -> 0.6265173
B15: 40817 | C15: 40908 | D15: =+D8+D10 -> 1041.244 | E15: =+D15+G14 -> 8638.618 | F15: =+F8+F10 -> 858.225 | G15: =+E15-F15 -> 7780.393 | H15: =+F15/E15 -> 0.099347488
A17: Jurel III - IV | B17: Periodo | D17: Cuota (t) | F17: Operación | I17: Global
A18: Armador | B18: Inicial | C18: Final | D18: Asignada | E18: Efectiva | F18: Desembarque (t) | G18: Saldo (t) | H18: % consumido | I18: Cuota (t) | J18: Desembarque (t) | K18: Saldo (t) | L18: % consumido
A19: Corpesca S.A., Orizon S.A. | B19: 39083 | C19: 40816 | D19: 9962.707 | E19: =+D19 -> 9962.707 | F19: 6919.238 | G19: =+E19-F19 -> 3043.469 | H19: =+F19/E19 -> 0.69451385 | I19: =SUM(D19:D20) -> 10487.377 | J19: =SUM(F19:F20) -> 6919.238 | K19: =+I19-J19 -> 3568.139 | L19: =+J19/I19 -> 0.65976821 | N19: oficiado 30.05.12
B20: 40817 | C20: 40908 | D20: 524.67 | E20: =+D20+G19 -> 3568.139 | G20: =+E20-F20 -> 3568.139 | H20: =+F20/E20 -> 0
A21: Bahia Caldera S.A., | B21: 39083 | C21: 40816 | D21: 32.733 | E21: =+D21 -> 32.733 | G21: =+E21-F21 -> 32.733 | H21: =+F21/E21 -> 0 | I21: =SUM(D21:D22) -> 34.457 | J21: =SUM(F21:F22) -> 0 | K21: =+I21-J21 -> 34.457 | L21: =+J21/I21 -> 0
B22: 40817 | C22: 40908 | D22: 1.724 | E22: =+D22+G21 -> 34.457 | G22: =+E22-F22 -> 34.457 | H22: =+F22/E22 -> 0
A23: Bio Bio S.A.Pesq., Camanchaca S.A. (Asociatividad 102) | B23: 39083 | C23: 40816 | D23: 91.275 | E23: =+D23 -> 91.275 | F23: 50 | G23: =+E23-F23 -> 41.275 | H23: =+F23/E23 -> 0.54779512 | I23: =SUM(D23:D24) -> 96.082 | J23: =SUM(F23:F24) -> 50 | K23: =+I23-J23 -> 46.082 | L23: =+J23/I23 -> 0.52038883
B24: 40817 | C24: 40908 | D24: 4.807 | E24: =+D24+G23 -> 46.082 | G24: =+E24-F24 -> 46.082 | H24: =+F24/E24 -> 0
A25: Alimentos Marinos S.A, Foodcorp S.A. | B25: 39083 | C25: 40816 | D25: 668.1 | E25: =+D25 -> 668.1 | F25: 697.116 | G25: =+E25-F25 -> -29.016 | H25: =+F25/E25 -> 1.0434306 | I25: =SUM(D25:D26) -> 703.292 | J25: =SUM(F25:F26) -> 697.116 | K25: =+I25-J25 -> 6.176 | L25: =+J25/I25 -> 0.99121844 | N25: oficiados 31.05.12
B26: 40817 | C26: 40908 | D26: 35.192 | E26: =+D26+G25 -> 6.176 | G26: =+E26-F26 -> 6.176 | H26: =+F26/E26 -> 0
A27: Arica Seafood Producer S.A | B27: 39083 | C27: 40816 | D27: 2.247 | E27: =+D27 -> 2.247 | G27: =+E27-F27 -> 2.247 | H27: =+F27/E27 -> 0 | I27: =SUM(D27:D28) -> 2.365 | J27: =SUM(F27:F28) -> 0 | K27: =+I27-J27 -> 2.365 | L27: =+J27/I27 -> 0
B28: 40817 | C28: 40908 | D28: 0.118 | E28: =+D28+G27 -> 2.365 | G28: =+E28-F28 -> 2.365 | H28: =+F28/E28 -> 0
A29: Blumar S.A. | B29: 39083 | C29: 40816 | D29: 1070.607 | E29: =+D29 -> 1070.607 | F29: 1302.934 | G29: =+E29-F29 -> -232.327 | H29: =+F29/E29 -> 1.2170049 | I29: =SUM(D29:D30) -> 1127 | J29: =SUM(F29:F30) -> 1302.934 | K29: =+I29-J29 -> -175.934 | L29: =+J29/I29 -> 1.1561083 | N29: oficiado 31.05.12
B30: 40817 | C30: 40908 | D30: 56.393 | E30: =+D30+G29 -> -175.934 | G30: =+E30-F30 -> -175.934 | H30: =+F30/E30 -> 0
A31: Landes S.A. | B31: 39083 | C31: 40816 | D31: 57.524 | E31: =+D31 -> 57.524 | F31: 59.373 | G31: =+E31-F31 -> -1.849 | H31: =+F31/E31 -> 1.0321431 | I31: =SUM(D31:D32) -> 60.554 | J31: =SUM(F31:F32) -> 59.373 | K31: =+I31-J31 -> 1.181 | L31: =+J31/I31 -> 0.98049675
B32: 40817 | C32: 40908 | D32: 3.03 | E32: =+D32+G31 -> 1.181 | G32: =+E32-F32 -> 1.181 | H32: =+F32/E32 -> 0
A33: Lota Protein S.A. | B33: 39083 | C33: 40816 | D33: 3.736 | E33: =+D33 -> 3.736 | G33: =+E33-F33 -> 3.736 | H33: =+F33/E33 -> 0 | I33: =SUM(D33:D34) -> 3.933 | J33: =SUM(F33:F34) -> 0 | K33: =+I33-J33 -> 3.933 | L33: =+J33/I33 -> 0
B34: 40817 | C34: 40908 | D34: 0.197 | E34: =+D34+G33 -> 3.933 | G34: =+E34-F34 -> 3.933 | H34: =+F34/E34 -> 0 | N34: =J42+J74+J108 -> 200416.55
A35: Inversiones Pesqueras S.A. | B35: 39083 | C35: 40816 | D35: 84.341 | E35: =+D35 -> 84.341 | G35: =+E35-F35 -> 84.341 | H35: =+F35/E35 -> 0 | I35: =SUM(D35:D36) -> 88.784 | J35: =SUM(F35:F36) -> 0 | K35: =+I35-J35 -> 88.784 | L35: =+J35/I35 -> 0
B36: 40817 | C36: 40908 | D36: 4.443 | E36: =+D36+G35 -> 88.784 | G36: =+E36-F36 -> 88.784 | H36: =+F36/E36 -> 0
A37: Isladamas S.A. | B37: 39083 | C37: 40816 | D37: 8.302 | E37: =+D37 -> 8.302 | G37: =+E37-F37 -> 8.302 | H37: =+F37/E37 -> 0 | I37: =SUM(D37:D38) -> 8.739 | J37: =SUM(F37:F38) -> 0 | K37: =+I37-J37 -> 8.739 | L37: =+J37/I37 -> 0
B38: 40817 | C38: 40908 | D38: 0.437 | E38: =+D38+G37 -> 8.739 | G38: =+E38-F38 -> 8.739 | H38: =+F38/E38 -> 0
A40: Resumen | B40: Periodo | D40: Cuota (t) | F40: Operación | I40: Global
A41: Jurel III - IV | B41: Inicial | C41: Final | D41: Asignada | E41: Efectiva | F41: Desembarque (t) | G41: Saldo (t) | H41: % consumido | I41: Cuota (t) | J41: Desembarque (t) | K41: Saldo (t) | L41: % consumido
B42: 39083 | C42: 40816 | D42: =+D19+D21+D23+D25+D27+D37+D29+D31+D33+D35 -> 11981.572 | E42: =+D42 -> 11981.572 | F42: =+F19+F21+F23+F25+F27+F37+F29+F31+F33+F35 -> 9028.661 | G42: =+E42-F42 -> 2952.911 | H42: =+F42/E42 -> 0.75354561 | I42: =SUM(D42:D43) -> 12612.583 | J42: =SUM(F42:F43) -> 9028.661 | K42: =+I42-J42 -> 3583.922 | L42: =+J42/I42 -> 0.71584552
B43: 40817 | C43: 40908 | D43: =+D20+D22+D24+D26+D28+D38+D30+D32+D34+D36 -> 631.011 | E43: =+D43+G42 -> 3583.922 | F43: =+F20+F22+F24+F26+F28+F38+F30+F32+F34+F36 -> 0 | G43: =+E43-F43 -> 3583.922 | H43: =+F43/E43 -> 0
A45: Jurel V-IX | B45: Periodo | D45: Cuota (t) | F45: Operación | I45: Global
A46: Armador | B46: Inicial | C46: Final | D46: Asignada | E46: Efectiva | F46: Desembarque (t) | G46: Saldo (t) | H46: % consumido | I46: Cuota (t) | J46: Desembarque (t) | K46: Saldo (t) | L46: % consumido
...

Sheet C.nailon
A2: Camarón nailon LMC 2012
A3: Al 31 de diciembre 2012
A5: Camarón nailon II - VIII | B5: Periodo | D5: Cuota (t) | F5: Operación | I5: Global
A6: Armador | B6: Inicial | C6: Final | D6: Asignada | E6: Efectiva | F6: Desembarque (t) | G6: Saldo (t) | H6: % consumido | I6: Cuota (t) | J6: Desembarque (t) | K6: Saldo (t) | L6: % consumido
A7: Costa Brava S.A. | B7: 39083 | C7: 39172 | D7: 0 | E7: =+D7 -> 0 | G7: =+E7-F7 -> 0 | H7: =+F7/E7 -> #DIV/0! | I7: =SUM(D7:D9) -> 0 | J7: =SUM(F7:F9) -> 0 | K7: =+I7-J7 -> 0 | L7: =+J7/I7 -> #DIV/0!
B8: 39173 | C8: 39325 | D8: 0 | E8: =+D8+G7 -> 0 | G8: =+E8-F8 -> 0 | H8: =+F8/E8 -> #DIV/0!
B9: 39326 | C9: 39447 | D9: 0 | E9: =+D9+G8 -> 0 | G9: =+E9-F9 -> 0 | H9: =+F9/E9 -> #DIV/0!
A10: Grimar S.A.Pesq, | B10: 39083 | C10: 39172 | D10: 5.945 | E10: =+D10 -> 5.945 | G10: =+E10-F10 -> 5.945 | H10: =+F10/E10 -> 0 | I10: =SUM(D10:D12) -> 13.213 | J10: =SUM(F10:F12) -> 0 | K10: =+I10-J10 -> 13.213 | L10: =+J10/I10 -> 0
B11: 39173 | C11: 39325 | D11: 3.303 | E11: =+D11+G10 -> 9.248 | G11: =+E11-F11 -> 9.248 | H11: =+F11/E11 -> 0
B12: 39326 | C12: 39447 | D12: 3.965 | E12: =+D12+G11 -> 13.213 | G12: =+E12-F12 -> 13.213 | H12: =+F12/E12 -> 0
A13: Isladamas S.A., | B13: 39083 | C13: 39172 | D13: 216.009 | E13: =+D13 -> 216.009 | F13: 197.571 | G13: =+E13-F13 -> 18.438 | H13: =+F13/E13 -> 0.91464245 | I13: =SUM(D13:D15) -> 480.073 | J13: =SUM(F13:F15) -> 420.753 | K13: =+I13-J13 -> 59.32 | L13: =+J13/I13 -> 0.87643546
B14: 39173 | C14: 39325 | D14: 120.018 | E14: =+D14+G13 -> 138.456 | F14: 80.562 | G14: =+E14-F14 -> 57.894 | H14: =+F14/E14 -> 0.58185994 | M14: *
B15: 39326 | C15: 39447 | D15: 144.046 | E15: =+D15+G14 -> 201.94 | F15: 142.62 | G15: =+E15-F15 -> 59.32 | H15: =+F15/E15 -> 0.70624938
A16: Sunrise S.A | B16: 39083 | C16: 39172 | D16: 179.156 | E16: =+D16 -> 179.156 | F16: 121.414 | G16: =+E16-F16 -> 57.742 | H16: =+F16/E16 -> 0.67769988 | I16: =SUM(D16:D18) -> 398.17 | J16: =SUM(F16:F18) -> 388.215 | K16: =+I16-J16 -> 9.955 | L16: =+J16/I16 -> 0.97499812
B17: 39173 | C17: 39325 | D17: 99.542 | E17: =+D17+G16 -> 157.284 | F17: 43.035 | G17: =+E17-F17 -> 114.249 | H17: =+F17/E17 -> 0.27361334
B18: 39326 | C18: 39447 | D18: 119.472 | E18: =+D18+G17 -> 233.721 | F18: 223.766 | G18: =+E18-F18 -> 9.955 | H18: =+F18/E18 -> 0.95740648
A19: Blumar S.A. | B19: 39083 | C19: 39172 | D19: 38.076 | E19: =+D19 -> 38.076 | G19: =+E19-F19 -> 38.076 | H19: =+F19/E19 -> 0 | I19: =SUM(D19:D21) -> 84.623 | J19: =SUM(F19:F21) -> 0 | K19: =+I19-J19 -> 84.623 | L19: =+J19/I19 -> 0
B20: 39173 | C20: 39325 | D20: 21.156 | E20: =+D20+G19 -> 59.232 | G20: =+E20-F20 -> 59.232 | H20: =+F20/E20 -> 0
B21: 39326 | C21: 39447 | D21: 25.391 | E21: =+D21+G20 -> 84.623 | G21: =+E21-F21 -> 84.623 | H21: =+F21/E21 -> 0
A22: Amancay Ltda | B22: 39083 | C22: 39172 | D22: 65.249 | E22: =+D22 -> 65.249 | F22: 34.891 | G22: =+E22-F22 -> 30.358 | H22: =+F22/E22 -> 0.53473616 | I22: =SUM(D22:D24) -> 145.013 | J22: =SUM(F22:F24) -> 105.242 | K22: =+I22-J22 -> 39.771 | L22: =+J22/I22 -> 0.72574183
B23: 39173 | C23: 39325 | D23: 36.253 | E23: =+D23+G22 -> 66.611 | F23: 15.872 | G23: =+E23-F23 -> 50.739 | H23: =+F23/E23 -> 0.23827896
B24: 39326 | C24: 39447 | D24: 43.511 | E24: =+D24+G23 -> 94.25 | F24: 54.479 | G24: =+E24-F24 -> 39.771 | H24: =+F24/E24 -> 0.57802653
A25: Antarctic Seafood S.A., Inversiones y Alimentos Intermark Ltda | B25: 39083 | C25: 39172 | D25: 311.044 | E25: =+D25 -> 311.044 | F25: 341.239 | G25: =+E25-F25 -> -30.195 | H25: =+F25/E25 -> 1.0970763 | I25: =SUM(D25:D27) -> 691.287 | J25: =SUM(F25:F27) -> 534.449 | K25: =+I25-J25 -> 156.838 | L25: =+J25/I25 -> 0.77312173
B26: 39173 | C26: 39325 | D26: 172.822 | E26: =+D26+G25 -> 142.627 | F26: 45.499 | G26: =+E26-F26 -> 97.128 | H26: =+F26/E26 -> 0.31900692
B27: 39326 | C27: 39447 | D27: 207.421 | E27: =+D27+G26 -> 304.549 | F27: 147.711 | G27: =+E27-F27 -> 156.838 | H27: =+F27/E27 -> 0.48501555
A28: Baycic Baycic Maria | B28: 39083 | C28: 39172 | D28: 118.607 | E28: =+D28 -> 118.607 | F28: 91.758 | G28: =+E28-F28 -> 26.849 | H28: =+F28/E28 -> 0.77363056 | I28: =SUM(D28:D30) -> 263.6 | J28: =SUM(F28:F30) -> 262.454 | K28: =+I28-J28 -> 1.146 | L28: =+J28/I28 -> 0.9956525
B29: 39173 | C29: 39325 | D29: 65.9 | E29: =+D29+G28 -> 92.749 | F29: 92.305 | G29: =+E29-F29 -> 0.444 | H29: =+F29/E29 -> 0.99521289 | M29: *
B30: 39326 | C30: 39447 | D30: 79.093 | E30: =+D30+G29 -> 79.537 | F30: 78.391 | G30: =+E30-F30 -> 1.146 | H30: =+F30/E30 -> 0.98559161
A31: Bracpesca S.A | B31: 39083 | C31: 39172 | D31: 280.687 | E31: =+D31 -> 280.687 | F31: 242.94 | G31: =+E31-F31 -> 37.747 | H31: =+F31/E31 -> 0.86551924 | I31: =SUM(D31:D33) -> 623.819 | J31: =SUM(F31:F33) -> 409.946 | K31: =+I31-J31 -> 213.873 | L31: =+J31/I31 -> 0.65715536
B32: 39173 | C32: 39325 | D32: 155.955 | E32: =+D32+G31 -> 193.702 | F32: 4.629 | G32: =+E32-F32 -> 189.073 | H32: =+F32/E32 -> 0.023897533
B33: 39326 | C33: 39447 | D33: 187.177 | E33: =+D33+G32 -> 376.25 | F33: 162.377 | G33: =+E33-F33 -> 213.873 | H33: =+F33/E33 -> 0.43156678
A34: Camanchaca S.A | B34: 39083 | C34: 39172 | D34: 1.585 | E34: =+D34 -> 1.585 | G34: =+E34-F34 -> 1.585 | H34: =+F34/E34 -> 0 | I34: =SUM(D34:D36) -> 3.523 | J34: =SUM(F34:F36) -> 3.525 | K34: =+I34-J34 -> -0.002 | L34: =+J34/I34 -> 1.0005677
B35: 39173 | C35: 39325 | D35: 0.881 | E35: =+D35+G34 -> 2.466 | F35: 3.265 | G35: =+E35-F35 -> -0.799 | H35: =+F35/E35 -> 1.3240065
B36: 39326 | C36: 39447 | D36: 1.057 | E36: =+D36+G35 -> 0.258 | F36: 0.26 | G36: =+E36-F36 -> -0.002 | H36: =+F36/E36 -> 1.0077519
A37: Concepción S.A | B37: 39083 | C37: 39172 | D37: 9.828 | E37: =+D37 -> 9.828 | G37: =+E37-F37 -> 9.828 | H37: =+F37/E37 -> 0 | I37: =SUM(D37:D39) -> 21.842 | J37: =SUM(F37:F39) -> 18.52 | K37: =+I37-J37 -> 3.322 | L37: =+J37/I37 -> 0.8479077
B38: 39173 | C38: 39325 | D38: 5.46 | E38: =+D38+G37 -> 15.288 | G38: =+E38-F38 -> 15.288 | H38: =+F38/E38 -> 0
B39: 39326 | C39: 39447 | D39: 6.554 | E39: =+D39+G38 -> 21.842 | F39: 18.52 | G39: =+E39-F39 -> 3.322 | H39: =+F39/E39 -> 0.8479077
A40: Gonzalez Rivera Marcelino | B40: 39083 | C40: 39172 | D40: 3.245 | E40: =+D40 -> 3.245 | G40: =+E40-F40 -> 3.245 | H40: =+F40/E40 -> 0 | I40: =SUM(D40:D42) -> 7.212 | J40: =SUM(F40:F42) -> 0 | K40: =+I40-J40 -> 7.212 | L40: =+J40/I40 -> 0
B41: 39173 | C41: 39325 | D41: 1.803 | E41: =+D41+G40 -> 5.048 | G41: =+E41-F41 -> 5.048 | H41: =+F41/E41 -> 0
B42: 39326 | C42: 39447 | D42: 2.164 | E42: =+D42+G41 -> 7.212 | G42: =+E42-F42 -> 7.212 | H42: =+F42/E42 -> 0
...

Sheet C.dorado
A2: Congrio dorado LMC 2012
A3: Al 31 de diciembre del 2012
A5: Congrio dorado NE H/F | B5: Periodo | D5: Cuota (t) | F5: Operación | I5: Global
A6: Armador | B6: Inicial | C6: Final | D6: Asignada | E6: Efectiva | F6: Desembarque (t) | G6: Saldo (t) | H6: % consumido | I6: Cuota (t) | J6: Desembarque (t) | K6: Saldo (t) | L6: % consumido
A7: Emdepes S.A., Grimar S.A.Pesq., Pesca Chile S.A., Sur Austral S.A | B7: 39083 | C7: 39141 | D7: 512.704 | E7: =+D7 -> 512.704 | F7: 25.09 | G7: =+E7-F7 -> 487.614 | H7: =+F7/E7 -> 0.048936618 | I7: =SUM(D7:D8) -> 1027.231 | J7: =SUM(F7:F8) -> 1043.913 | K7: =+I7-J7 -> -16.682 | L7: =+J7/I7 -> 1.0162398
B8: 39142 | C8: 39447 | D8: 514.527 | E8: =+D8+G7 -> 1002.141 | F8: 1018.823 | G8: =+E8-F8 -> -16.682 | H8: =+F8/E8 -> 1.0166464
A9: Pesca Cisne S.A | B9: 39083 | C9: 39141 | D9: 32.296 | E9: =+D9 -> 32.296 | G9: =+E9-F9 -> 32.296 | H9: =+F9/E9 -> 0 | I9: =SUM(D9:D10) -> 64.769 | J9: =SUM(F9:F10) -> 8.047 | K9: =+I9-J9 -> 56.722 | L9: =+J9/I9 -> 0.12424154
B10: 39142 | C10: 39447 | D10: 32.473 | E10: =+D10+G9 -> 64.769 | F10: 8.047 | G10: =+E10-F10 -> 56.722 | H10: =+F10/E10 -> 0.12424154
A12: Resumen | B12: Periodo | D12: Cuota (t) | F12: Operación | I12: Global
A13: Congrio dorado NE | B13: Inicial | C13: Final | D13: Asignada | E13: Efectiva | F13: Desembarque (t) | G13: Saldo (t) | H13: % consumido | I13: Cuota (t) | J13: Desembarque (t) | K13: Saldo (t) | L13: % consumido
B14: 39083 | C14: 39141 | D14: =SUM(D7,D9) -> 545 | E14: =+D14 -> 545 | F14: =SUM(F7,F9) -> 25.09 | G14: =+E14-F14 -> 519.91 | H14: =+F14/E14 -> 0.046036697 | I14: =SUM(D14:D15) -> 1092 | J14: =SUM(F14:F15) -> 1051.96 | K14: =+I14-J14 -> 40.04 | L14: =+J14/I14 -> 0.96333333
B15: 39142 | C15: 39447 | D15: =SUM(D8,D10) -> 547 | E15: =+D15+G14 -> 1066.91 | F15: =SUM(F8,F10) -> 1026.87 | G15: =+E15-F15 -> 40.04 | H15: =+F15/E15 -> 0.96247106
A17: Congrio dorado SE | B17: Periodo | D17: Cuota (t) | F17: Operación | I17: Global
A18: Armador | B18: Inicial | C18: Final | D18: Asignada | E18: Efectiva | F18: Desembarque (t) | G18: Saldo (t) | H18: % consumido | I18: Cuota (t) | J18: Desembarque (t) | K18: Saldo (t) | L18: % consumido
A19: Emdepes S.A., Grimar S.A.Pesq., Pesca Chile S.A., Sur Austral S.A | B19: 39083 | C19: 39141 | D19: 250.971 | E19: =+D19 -> 250.971 | F19: 1.338 | G19: =+E19-F19 -> 249.633 | H19: =+F19/E19 -> 0.0053312933 | I19: =SUM(D19:D20) -> 502.726 | J19: =SUM(F19:F20) -> 462.843 | K19: =+I19-J19 -> 39.883 | L19: =+J19/I19 -> 0.92066653
B20: 39142 | C20: 39447 | D20: 251.755 | E20: =+D20+G19 -> 501.388 | F20: 461.505 | G20: =+E20-F20 -> 39.883 | H20: =+F20/E20 -> 0.92045482
A21: Pesca Cisne S.A | B21: 39083 | C21: 39141 | D21: 73.037 | E21: =+D21 -> 73.037 | G21: =+E21-F21 -> 73.037 | H21: =+F21/E21 -> 0 | I21: =SUM(D21:D22) -> 146.274 | J21: =SUM(F21:F22) -> 28.272 | K21: =+I21-J21 -> 118.002 | L21: =+J21/I21 -> 0.1932811
B22: 39142 | C22: 39447 | D22: 73.237 | E22: =+D22+G21 -> 146.274 | F22: 28.272 | G22: =+E22-F22 -> 118.002 | H22: =+F22/E22 -> 0.1932811
A24: Resumen | B24: Periodo | D24: Cuota (t) | F24: Operación | I24: Global
A25: Congrio dorado SE | B25: Inicial | C25: Final | D25: Asignada | E25: Efectiva | F25: Desembarque (t) | G25: Saldo (t) | H25: % consumido | I25: Cuota (t) | J25: Desembarque (t) | K25: Saldo (t) | L25: % consumido
B26: 39083 | C26: 39141 | D26: =SUM(D19,D21) -> 324.008 | E26: =+D26 -> 324.008 | F26: =SUM(F19,F21) -> 1.338 | G26: =+E26-F26 -> 322.67 | H26: =+F26/E26 -> 0.0041295277 | I26: =SUM(D26:D27) -> 649 | J26: =SUM(F26:F27) -> 491.115 | K26: =+I26-J26 -> 157.885 | L26: =+J26/I26 -> 0.75672573
B27: 39142 | C27: 39447 | D27: =SUM(D20,D22) -> 324.992 | E27: =+D27+G26 -> 647.662 | F27: =SUM(F20,F22) -> 489.777 | G27: =+E27-F27 -> 157.885 | H27: =+F27/E27 -> 0.75622315

Sheet L.amarillo
A2: Langostino amarillo LMC 2012
A3: Al 31 de diciembre del 2012
A5: Langostino amarillo III-IV | B5: Periodo | D5: Cuota (t) | F5: Operación | I5: Global
A6: Armador | B6: Inicial | C6: Final | D6: Asignada | E6: Efectiva | F6: Desembarque (t) | G6: Saldo (t) | H6: % consumido | I6: Cuota (t) | J6: Desembarque (t) | K6: Saldo (t) | L6: % consumido
A7: Grimar S.A.Pesq., Isladamas S.A., Sunrise S.A | B7: 39173 | C7: 39263 | D7: 76.682 | E7: =+D7 -> 76.682 | F7: 13.549 | G7: =+E7-F7 -> 63.133 | H7: =+F7/E7 -> 0.17669075 | I7: =(SUM(D7:D9)) -> 153.287 | J7: =SUM(F7:F9) -> 77.418 | K7: =+I7-J7 -> 75.869 | L7: =+J7/I7 -> 0.50505261
B8: 39264 | C8: 39355 | D8: 45.993 | E8: =+D8+G7 -> 109.126 | F8: 62.187 | G8: =+E8-F8 -> 46.939 | H8: =+F8/E8 -> 0.56986419
B9: 39356 | C9: 39447 | D9: 30.612 | E9: =+D9+G8 -> 77.551 | F9: 1.682 | G9: =+E9-F9 -> 75.869 | H9: =+F9/E9 -> 0.021688953
A10: Amancay Ltda | B10: 39173 | C10: 39263 | D10: 51.865 | E10: =+D10 -> 51.865 | F10: 57.641 | G10: =+E10-F10 -> -5.776 | H10: =+F10/E10 -> 1.111366 | I10: =SUM(D10:D12) -> 103.677 | J10: =SUM(F10:F12) -> 73.896 | K10: =+I10-J10 -> 29.781 | L10: =+J10/I10 -> 0.71275211
B11: 39264 | C11: 39355 | D11: 31.108 | E11: =+D11+G10 -> 25.332 | F11: 7.984 | G11: =+E11-F11 -> 17.348 | H11: =+F11/E11 -> 0.31517448
B12: 39356 | C12: 39447 | D12: 20.704 | E12: =+D12+G11 -> 38.052 | F12: 8.271 | G12: =+E12-F12 -> 29.781 | H12: =+F12/E12 -> 0.21736045
A13: Antarctic Seafood S.A | B13: 39173 | C13: 39263 | D13: 388.023 | E13: =+D13 -> 388.023 | F13: 354.025 | G13: =+E13-F13 -> 33.998 | H13: =+F13/E13 -> 0.91238148 | I13: =SUM(D13:D15) -> 775.655 | J13: =SUM(F13:F15) -> 647.284 | K13: =+I13-J13 -> 128.371 | L13: =+J13/I13 -> 0.83449987
B14: 39264 | C14: 39355 | D14: 232.736 | E14: =+D14+G13 -> 266.734 | F14: 122.126 | G14: =+E14-F14 -> 144.608 | H14: =+F14/E14 -> 0.45785689
B15: 39356 | C15: 39447 | D15: 154.896 | E15: =+D15+G14 -> 299.504 | F15: 171.133 | G15: =+E15-F15 -> 128.371 | H15: =+F15/E15 -> 0.57138803
A16: Baycic Baycic Maria | B16: 39173 | C16: 39263 | D16: 27.992 | E16: =+D16 -> 27.992 | F16: 14.948 | G16: =+E16-F16 -> 13.044 | H16: =+F16/E16 -> 0.53400972 | I16: =SUM(D16:D18) -> 55.956 | J16: =SUM(F16:F18) -> 34.003 | K16: =+I16-J16 -> 21.953 | L16: =+J16/I16 -> 0.60767389
B17: 39264 | C17: 39355 | D17: 16.79 | E17: =+D17+G16 -> 29.834 | G17: =+E17-F17 -> 29.834 | H17: =+F17/E17 -> 0
B18: 39356 | C18: 39447 | D18: 11.174 | E18: =+D18+G17 -> 41.008 | F18: 19.055 | G18: =+E18-F18 -> 21.953 | H18: =+F18/E18 -> 0.46466543
A19: Bracpesca S.A | B19: 39173 | C19: 39263 | D19: 407.818 | E19: =+D19 -> 407.818 | F19: 379.189 | G19: =+E19-F19 -> 28.629 | H19: =+F19/E19 -> 0.92979957 | I19: =SUM(D19:D21) -> 815.224 | J19: =SUM(F19:F21) -> 809.792 | K19: =+I19-J19 -> 5.432 | L19: =+J19/I19 -> 0.9933368
B20: 39264 | C20: 39355 | D20: 244.608 | E20: =+D20+G19 -> 273.237 | F20: 266.841 | G20: =+E20-F20 -> 6.396 | H20: =+F20/E20 -> 0.97659175 | M20: *
B21: 39356 | C21: 39447 | D21: 162.798 | E21: =+D21+G20 -> 169.194 | F21: 163.762 | G21: =+E21-F21 -> 5.432 | H21: =+F21/E21 -> 0.96789484
A22: Morozin Baycic Maria Ana | B22: 39173 | C22: 39263 | D22: 6.96 | E22: =+D22 -> 6.96 | F22: 3.59 | G22: =+E22-F22 -> 3.37 | H22: =+F22/E22 -> 0.5158046 | I22: =SUM(D22:D24) -> 13.912 | J22: =SUM(F22:F24) -> 3.59 | K22: =+I22-J22 -> 10.322 | L22: =+J22/I22 -> 0.2580506
B23: 39264 | C23: 39355 | D23: 4.174 | E23: =+D23+G22 -> 7.544 | G23: =+E23-F23 -> 7.544 | H23: =+F23/E23 -> 0
B24: 39356 | C24: 39447 | D24: 2.778 | E24: =+D24+G23 -> 10.322 | G24: =+E24-F24 -> 10.322 | H24: =+F24/E24 -> 0
A25: Mororzin Yurecic Mario | B25: 39173 | C25: 39263 | D25: 3.124 | E25: =+D25 -> 3.124 | G25: =+E25-F25 -> 3.124 | H25: =+F25/E25 -> 0 | I25: =SUM(D25:D27) -> 6.245 | J25: =SUM(F25:F27) -> 5.413 | K25: =+I25-J25 -> 0.832 | L25: =+J25/I25 -> 0.86677342
B26: 39264 | C26: 39355 | D26: 1.874 | E26: =+D26+G25 -> 4.998 | G26: =+E26-F26 -> 4.998 | H26: =+F26/E26 -> 0
B27: 39356 | C27: 39447 | D27: 1.247 | E27: =+D27+G26 -> 6.245 | F27: 5.413 | G27: =+E27-F27 -> 0.832 | H27: =+F27/E27 -> 0.86677342
A28: Quinteros S.A | B28: 39173 | C28: 39263 | D28: 33.288 | E28: =+D28 -> 33.288 | F28: 29.337 | G28: =+E28-F28 -> 3.951 | H28: =+F28/E28 -> 0.88130858 | I28: =SUM(D28:D30) -> 66.542 | J28: =SUM(F28:F30) -> 55.634 | K28: =+I28-J28 -> 10.908 | L28: =+J28/I28 -> 0.83607346
B29: 39264 | C29: 39355 | D29: 19.966 | E29: =+D29+G28 -> 23.917 | G29: =+E29-F29 -> 23.917 | H29: =+F29/E29 -> 0
B30: 39356 | C30: 39447 | D30: 13.288 | E30: =+D30+G29 -> 37.205 | F30: 26.297 | G30: =+E30-F30 -> 10.908 | H30: =+F30/E30 -> 0.7068136
A32: Resumen | B32: Periodo | D32: Cuota (t) | F32: Operación | I32: Global
A33: Langostino Amarillo III - IV | B33: Inicial | C33: Final | D33: Asignada | E33: Efectiva | F33: Desembarque (t) | G33: Saldo (t) | H33: % consumido | I33: Cuota (t) | J33: Desembarque (t) | K33: Saldo (t) | L33: % consumido
B34: 39173 | C34: 39263 | D34: =+D7+D10+D13+D16+D19+D22+D25+D28 -> 995.752 | E34: =+D34 -> 995.752 | F34: =+F7+F10+F13+F16+F19+F22+F25+F28 -> 852.279 | G34: =+E34-F34 -> 143.473 | H34: =+F34/E34 -> 0.85591493 | I34: =SUM(D34:D36) -> 1990.498 | J34: =SUM(F34:F36) -> 1707.03 | K34: =+I34-J34 -> 283.468 | L34: =+J34/I34 -> 0.85758941
B35: 39264 | C35: 39355 | D35: =+D8+D11+D14+D17+D20+D23+D26+D29 -> 597.249 | E35: =+D35+G34 -> 740.722 | F35: =+F8+F11+F14+F17+F20+F23+F26+F29 -> 459.138 | G35: =+E35-F35 -> 281.584 | H35: =+F35/E35 -> 0.61985198
B36: 39356 | C36: 39447 | D36: =+D9+D12+D15+D18+D21+D24+D27+D30 -> 397.497 | E36: =+D36+G35 -> 679.081 | F36: =+F9+F12+F15+F18+F21+F24+F27+F30 -> 395.613 | G36: =+E36-F36 -> 283.468 | H36: =+F36/E36 -> 0.58257115

Sheet L.colorado
A2: Langostino colorado LMC 2012
A3: Al 31 de diciembre del 2012
A5: Langostino coloradoXV- IV | B5: Periodo | D5: Cuota (t) | F5: Operación | I5: Global
A6: Armador | B6: Inicial | C6: Final | D6: Asignada | E6: Efectiva | F6: Desembarque (t) | G6: Saldo (t) | H6: % consumido | I6: Cuota (t) | J6: Desembarque (t) | K6: Saldo (t) | L6: % consumido
A7: Isladamas S.A., Sunrise S.A | B7: 39173 | C7: 39263 | D7: 41.583 | E7: =+D7 -> 41.583 | F7: 8.872 | G7: =+E7-F7 -> 32.711 | H7: =+F7/E7 -> 0.21335642 | I7: =SUM(D7:D9) -> 177.538 | J7: =SUM(F7:F9) -> 177.034 | K7: =+I7-J7 -> 0.504 | L7: =+J7/I7 -> 0.99716117
B8: 39264 | C8: 39355 | D8: 96.532 | E8: =+D8+G7 -> 129.243 | F8: 9.86 | G8: =+E8-F8 -> 119.383 | H8: =+F8/E8 -> 0.076290399
B9: 39356 | C9: 39447 | D9: 39.423 | E9: =+D9+G8 -> 158.806 | F9: 158.302 | G9: =+E9-F9 -> 0.504 | H9: =+F9/E9 -> 0.99682632
A10: Amancay Ltda | B10: 39173 | C10: 39263 | D10: 6.2 | E10: =+D10 -> 6.2 | F10: 9.914 | G10: =+E10-F10 -> -3.714 | H10: =+F10/E10 -> 1.5990323 | I10: =SUM(D10:D12) -> 26.472 | J10: =SUM(F10:F12) -> 25.688 | K10: =+I10-J10 -> 0.784 | L10: =+J10/I10 -> 0.9703838
B11: 39264 | C11: 39355 | D11: 14.394 | E11: =+D11+G10 -> 10.68 | F11: 0 | G11: =+E11-F11 -> 10.68 | H11: =+F11/E11 -> 0
B12: 39356 | C12: 39447 | D12: 5.878 | E12: =+D12+G11 -> 16.558 | F12: 15.774 | G12: =+E12-F12 -> 0.784 | H12: =+F12/E12 -> 0.95265129
B13: 39173 | C13: 39263 | E13: =+D13 -> 0 | G13: =+E13-F13 -> 0 | H13: =+F13/E13 -> #DIV/0! | I13: =SUM(D13:D15) -> 0 | J13: =SUM(F13:F15) -> 0 | K13: =+I13-J13 -> 0 | L13: =+J13/I13 -> #DIV/0!
B14: 39264 | C14: 39355 | E14: =+D14+G13 -> 0 | G14: =+E14-F14 -> 0 | H14: =+F14/E14 -> #DIV/0!
B15: 39356 | C15: 39447 | E15: =+D15+G14 -> 0 | G15: =+E15-F15 -> 0 | H15: =+F15/E15 -> #DIV/0!
